Workbook

Sheet GLOSSÁRIO
A1: INDICADORES | B1: FONTE
A2: Desarquivamento de Processos/Documentos - Saída de Guia Fora | B2: SEI (Depachos ou Ofícios assinados na unidade Diarq)
A3: Caixas consultadas em pesquisa de desarquivamento | B3: CONTAGEM INDIVIDUAL (Caixas abertas para verificação de conteúdo em contexto de pesquisa para desarquivamento)
A4: Retorno de Processos/Documentos Desarquivados | B4: SEI (Depachos ou Ofícios assinados na unidade Diarq)
A5: Recebimento de Documentos - Guia de Transferência | B5: SEI (Depachos ou Ofícios assinados na unidade Diarq)
A6: Caixas separadas para classificação | B6: CONTAGEM INDIVIDUAL (Caixas "puxadas" nas estantes como uma pré-seleção para classificação)
A7: Processos/Documentos classificados | B7: PLANILHA
A8: Caixas separadas para eliminação | B8: CONTAGEM INDIVIDUAL (Caixas "puxadas" nas estantes como uma pré-seleção para eliminação)
A9: Caixas listadas para eliminação | B9: PLANILHA
A10: Processos/Documentos listados para eliminação | B10: PLANILHA
A11: Caixas inventariadas | B11: PLANILHA
A12: Processos/documentos inventariados | B12: PLANILHA
... A16: Caixas conferidas | B16: CONTAGEM INDIVIDUAL (Caixas consultadas para simples 'conferência de quantitativo' ou do 'conteúdo do espelho' em atividades diversas)

Sheet Patrícia
A1: INDICADORES | C1: 45810 | D1: 45811 | E1: 45812 | F1: 45813 | G1: 45814 | H1: TOTAL SEMANA | I1: 45817 | J1: 45818 | K1: 45819 | L1: 45820 | M1: 45821 | N1: TOTAL SEMANA | O1: 45824 | P1: 45825 | Q1: 45826 | R1: 45827 | S1: 45828 | T1: TOTAL SEMANA | U1: 45831 | V1: 45832 | W1: 45833 | X1: 45834 | Y1: 45835 | Z1: TOTAL SEMANA | AA1: 45838 | AB1: 45839 | AC1: 45840 | AD1: 45841 | AE1: 45842 | AF1: TOTAL SEMANA | AG1: 45845 | AH1: 45846 | AI1: 45847 | AJ1: 45848 | AK1: 45849 | AL1: TOTAL SEMANA | AM1: 45852 | AN1: 45853 | AO1: 45854 | AP1: 45855 | AQ1: 45856 | AR1: TOTAL SEMANA | AS1: 45859 | AT1: 45860 | AU1: 45861 | AV1: 45862 | AW1: 45863 | AX1: TOTAL SEMANA | AY1: 45866 | AZ1: 45867 | BA1: 45868 | BB1: 45869 | BC1: 45870 | BD1: TOTAL SEMANA
A2: Desarquivamento de Processos/Documentos - Saída de Guia Fora | B2: 1 | H2: =SUM(C2:G2) -> 0 | N2: =SUM(I2:M2) -> 0 | T2: =SUM(O2:S2) -> 0 | Z2: =SUM(U2:Y2) -> 0 | AF2: =SUM(AA2:AE2) -> 0 | AL2: =SUM(AG2:AK2) -> 0 | AR2: =SUM(AM2:AQ2) -> 0 | AX2: =SUM(AS2:AW2) -> 0 | BD2: =SUM(AY2:BC2) -> 0
A3: Caixas consultadas em pesquisa de desarquivamento | B3: 2 | H3: =SUM(C3:G3) -> 0 | N3: =SUM(I3:M3) -> 0 | T3: =SUM(O3:S3) -> 0 | Z3: =SUM(U3:Y3) -> 0 | AF3: =SUM(AA3:AE3) -> 0 | AL3: =SUM(AG3:AK3) -> 0 | AR3: =SUM(AM3:AQ3) -> 0 | AX3: =SUM(AS3:AW3) -> 0 | BD3: =SUM(AY3:BC3) -> 0
A4: Retorno de Processos/Documentos Desarquivados | B4: 3 | H4: =SUM(C4:G4) -> 0 | N4: =SUM(I4:M4) -> 0 | T4: =SUM(O4:S4) -> 0 | Z4: =SUM(U4:Y4) -> 0 | AF4: =SUM(AA4:AE4) -> 0 | AL4: =SUM(AG4:AK4) -> 0 | AR4: =SUM(AM4:AQ4) -> 0 | AX4: =SUM(AS4:AW4) -> 0 | BD4: =SUM(AY4:BC4) -> 0
A5: Recebimento de Documentos - Guia de Transferência | B5: 4 | H5: =SUM(C5:G5) -> 0 | N5: =SUM(I5:M5) -> 0 | T5: =SUM(O5:S5) -> 0 | Z5: =SUM(U5:Y5) -> 0 | AF5: =SUM(AA5:AE5) -> 0 | AL5: =SUM(AG5:AK5) -> 0 | AR5: =SUM(AM5:AQ5) -> 0 | AX5: =SUM(AS5:AW5) -> 0 | BD5: =SUM(AY5:BC5) -> 0
A6: Caixas separadas para classificação | B6: 5 | H6: =SUM(C6:G6) -> 0 | N6: =SUM(I6:M6) -> 0 | T6: =SUM(O6:S6) -> 0 | Z6: =SUM(U6:Y6) -> 0 | AF6: =SUM(AA6:AE6) -> 0 | AL6: =SUM(AG6:AK6) -> 0 | AR6: =SUM(AM6:AQ6) -> 0 | AX6: =SUM(AS6:AW6) -> 0 | BD6: =SUM(AY6:BC6) -> 0
A7: Processos/Documentos classificados | B7: 6 | H7: =SUM(C7:G7) -> 0 | N7: =SUM(I7:M7) -> 0 | T7: =SUM(O7:S7) -> 0 | Z7: =SUM(U7:Y7) -> 0 | AF7: =SUM(AA7:AE7) -> 0 | AL7: =SUM(AG7:AK7) -> 0 | AR7: =SUM(AM7:AQ7) -> 0 | AX7: =SUM(AS7:AW7) -> 0 | BD7: =SUM(AY7:BC7) -> 0
A8: Caixas separadas para eliminação | B8: 7 | H8: =SUM(C8:G8) -> 0 | N8: =SUM(I8:M8) -> 0 | T8: =SUM(O8:S8) -> 0 | Z8: =SUM(U8:Y8) -> 0 | AF8: =SUM(AA8:AE8) -> 0 | AL8: =SUM(AG8:AK8) -> 0 | AR8: =SUM(AM8:AQ8) -> 0 | AX8: =SUM(AS8:AW8) -> 0 | BD8: =SUM(AY8:BC8) -> 0
A9: Caixas listadas para eliminação | B9: 8 | H9: =SUM(C9:G9) -> 0 | N9: =SUM(I9:M9) -> 0 | T9: =SUM(O9:S9) -> 0 | Z9: =SUM(U9:Y9) -> 0 | AF9: =SUM(AA9:AE9) -> 0 | AL9: =SUM(AG9:AK9) -> 0 | AR9: =SUM(AM9:AQ9) -> 0 | AX9: =SUM(AS9:AW9) -> 0 | BD9: =SUM(AY9:BC9) -> 0
A10: Processos/Documentos listados para eliminação | B10: 9 | H10: =SUM(C10:G10) -> 0 | N10: =SUM(I10:M10) -> 0 | T10: =SUM(O10:S10) -> 0 | Z10: =SUM(U10:Y10) -> 0 | AF10: =SUM(AA10:AE10) -> 0 | AL10: =SUM(AG10:AK10) -> 0 | AR10: =SUM(AM10:AQ10) -> 0 | AX10: =SUM(AS10:AW10) -> 0 | BD10: =SUM(AY10:BC10) -> 0
A11: Caixas inventariadas | B11: 10 | H11: =SUM(C11:G11) -> 0 | N11: =SUM(I11:M11) -> 0 | T11: =SUM(O11:S11) -> 0 | Z11: =SUM(U11:Y11) -> 0 | AF11: =SUM(AA11:AE11) -> 0 | AL11: =SUM(AG11:AK11) -> 0 | AR11: =SUM(AM11:AQ11) -> 0 | AX11: =SUM(AS11:AW11) -> 0 | BD11: =SUM(AY11:BC11) -> 0
A12: Processos/documentos inventariados | B12: 11 | H12: =SUM(C12:G12) -> 0 | N12: =SUM(I12:M12) -> 0 | T12: =SUM(O12:S12) -> 0 | Z12: =SUM(U12:Y12) -> 0 | AF12: =SUM(AA12:AE12) -> 0 | AL12: =SUM(AG12:AK12) -> 0 | AR12: =SUM(AM12:AQ12) -> 0 | AX12: =SUM(AS12:AW12) -> 0 | BD12: =SUM(AY12:BC12) -> 0
A13: Documentos administrativos produzidos (Despacho, Nota Técnica, minutas diversas) | B13: 12 | H13: =SUM(C13:G13) -> 0 | J13: 1 | M13: 1 | N13: =SUM(I13:M13) -> 2 | P13: 1 | T13: =SUM(O13:S13) -> 1 | U13: 1 | V13: 1 | Z13: =SUM(U13:Y13) -> 2 | AA13: 1 | AC13: 1 | AF13: =SUM(AA13:AE13) -> 2 | AL13: =SUM(AG13:AK13) -> 0 | AR13: =SUM(AM13:AQ13) -> 0 | AX13: =SUM(AS13:AW13) -> 0 | BD13: =SUM(AY13:BC13) -> 0
A14: Orientação técnica / atendimentos realizados | B14: 13 | H14: =SUM(C14:G14) -> 0 | N14: =SUM(I14:M14) -> 0 | T14: =SUM(O14:S14) -> 0 | Z14: =SUM(U14:Y14) -> 0 | AF14: =SUM(AA14:AE14) -> 0 | AL14: =SUM(AG14:AK14) -> 0 | AR14: =SUM(AM14:AQ14) -> 0 | AX14: =SUM(AS14:AW14) -> 0 | BD14: =SUM(AY14:BC14) -> 0
A15: Caixas remanejadas | B15: 14 | H15: =SUM(C15:G15) -> 0 | N15: =SUM(I15:M15) -> 0 | T15: =SUM(O15:S15) -> 0 | Z15: =SUM(U15:Y15) -> 0 | AF15: =SUM(AA15:AE15) -> 0 | AL15: =SUM(AG15:AK15) -> 0 | AR15: =SUM(AM15:AQ15) -> 0 | AX15: =SUM(AS15:AW15) -> 0 | BD15: =SUM(AY15:BC15) -> 0
A16: Caixas conferidas | B16: 15 | H16: =SUM(C16:G16) -> 0 | N16: =SUM(I16:M16) -> 0 | T16: =SUM(O16:S16) -> 0 | Z16: =SUM(U16:Y16) -> 0 | AF16: =SUM(AA16:AE16) -> 0 | AL16: =SUM(AG16:AK16) -> 0 | AR16: =SUM(AM16:AQ16) -> 0 | AX16: =SUM(AS16:AW16) -> 0 | BD16: =SUM(AY16:BC16) -> 0
A17: OUTRA ATIVIDADE. QUAL?
A18: OBSERVAÇÃO

Sheet Marcelo
A1: INDICADORES | C1: 45810 | D1: 45811 | E1: 45812 | F1: 45813 | G1: 45814 | H1: TOTAL SEMANA | I1: 45817 | J1: 45818 | K1: 45819 | L1: 45820 | M1: 45821 | N1: TOTAL SEMANA | O1: 45824 | P1: 45825 | Q1: 45826 | R1: 45827 | S1: 45828 | T1: TOTAL SEMANA | U1: 45831 | V1: 45832 | W1: 45833 | X1: 45834 | Y1: 45835 | Z1: TOTAL SEMANA | AA1: 45838 | AB1: 45839 | AC1: 45840 | AD1: 45841 | AE1: 45842 | AF1: TOTAL SEMANA | AG1: 45845 | AH1: 45846 | AI1: 45847 | AJ1: 45848 | AK1: 45849 | AL1: TOTAL SEMANA | AM1: 45852 | AN1: 45853 | AO1: 45854 | AP1: 45855 | AQ1: 45856 | AR1: TOTAL SEMANA | AS1: 45859 | AT1: 45860 | AU1: 45861 | AV1: 45862 | AW1: 45863 | AX1: TOTAL SEMANA | AY1: 45866 | AZ1: 45867 | BA1: 45868 | BB1: 45869 | BC1: 45870 | BD1: TOTAL SEMANA
A2: Desarquivamento de Processos/Documentos - Saída de Guia Fora | B2: 1 | H2: =SUM(C2:G2) -> 0 | N2: =SUM(I2:M2) -> 0 | T2: =SUM(O2:S2) -> 0 | Z2: =SUM(U2:Y2) -> 0 | AF2: =SUM(AA2:AE2) -> 0 | AL2: =SUM(AG2:AK2) -> 0 | AR2: =SUM(AM2:AQ2) -> 0 | AX2: =SUM(AS2:AW2) -> 0 | BD2: =SUM(AY2:BC2) -> 0
A3: Caixas consultadas em pesquisa de desarquivamento | B3: 2 | H3: =SUM(C3:G3) -> 0 | N3: =SUM(I3:M3) -> 0 | T3: =SUM(O3:S3) -> 0 | Z3: =SUM(U3:Y3) -> 0 | AF3: =SUM(AA3:AE3) -> 0 | AL3: =SUM(AG3:AK3) -> 0 | AR3: =SUM(AM3:AQ3) -> 0 | AX3: =SUM(AS3:AW3) -> 0 | BD3: =SUM(AY3:BC3) -> 0
A4: Retorno de Processos/Documentos Desarquivados | B4: 3 | H4: =SUM(C4:G4) -> 0 | N4: =SUM(I4:M4) -> 0 | T4: =SUM(O4:S4) -> 0 | Z4: =SUM(U4:Y4) -> 0 | AF4: =SUM(AA4:AE4) -> 0 | AL4: =SUM(AG4:AK4) -> 0 | AR4: =SUM(AM4:AQ4) -> 0 | AX4: =SUM(AS4:AW4) -> 0 | BD4: =SUM(AY4:BC4) -> 0
A5: Recebimento de Documentos - Guia de Transferência | B5: 4 | H5: =SUM(C5:G5) -> 0 | N5: =SUM(I5:M5) -> 0 | T5: =SUM(O5:S5) -> 0 | Z5: =SUM(U5:Y5) -> 0 | AF5: =SUM(AA5:AE5) -> 0 | AL5: =SUM(AG5:AK5) -> 0 | AR5: =SUM(AM5:AQ5) -> 0 | AX5: =SUM(AS5:AW5) -> 0 | BD5: =SUM(AY5:BC5) -> 0
A6: Caixas separadas para classificação | B6: 5 | H6: =SUM(C6:G6) -> 0 | N6: =SUM(I6:M6) -> 0 | T6: =SUM(O6:S6) -> 0 | Z6: =SUM(U6:Y6) -> 0 | AF6: =SUM(AA6:AE6) -> 0 | AL6: =SUM(AG6:AK6) -> 0 | AR6: =SUM(AM6:AQ6) -> 0 | AX6: =SUM(AS6:AW6) -> 0 | BD6: =SUM(AY6:BC6) -> 0
A7: Processos/Documentos classificados | B7: 6 | H7: =SUM(C7:G7) -> 0 | N7: =SUM(I7:M7) -> 0 | T7: =SUM(O7:S7) -> 0 | Z7: =SUM(U7:Y7) -> 0 | AF7: =SUM(AA7:AE7) -> 0 | AL7: =SUM(AG7:AK7) -> 0 | AR7: =SUM(AM7:AQ7) -> 0 | AX7: =SUM(AS7:AW7) -> 0 | BD7: =SUM(AY7:BC7) -> 0
A8: Caixas separadas para eliminação | B8: 7 | H8: =SUM(C8:G8) -> 0 | N8: =SUM(I8:M8) -> 0 | T8: =SUM(O8:S8) -> 0 | Z8: =SUM(U8:Y8) -> 0 | AF8: =SUM(AA8:AE8) -> 0 | AL8: =SUM(AG8:AK8) -> 0 | AR8: =SUM(AM8:AQ8) -> 0 | AX8: =SUM(AS8:AW8) -> 0 | BD8: =SUM(AY8:BC8) -> 0
A9: Caixas listadas para eliminação | B9: 8 | H9: =SUM(C9:G9) -> 0 | N9: =SUM(I9:M9) -> 0 | T9: =SUM(O9:S9) -> 0 | Z9: =SUM(U9:Y9) -> 0 | AF9: =SUM(AA9:AE9) -> 0 | AL9: =SUM(AG9:AK9) -> 0 | AR9: =SUM(AM9:AQ9) -> 0 | AX9: =SUM(AS9:AW9) -> 0 | BD9: =SUM(AY9:BC9) -> 0
A10: Processos/Documentos listados para eliminação | B10: 9 | H10: =SUM(C10:G10) -> 0 | N10: =SUM(I10:M10) -> 0 | T10: =SUM(O10:S10) -> 0 | Z10: =SUM(U10:Y10) -> 0 | AF10: =SUM(AA10:AE10) -> 0 | AL10: =SUM(AG10:AK10) -> 0 | AR10: =SUM(AM10:AQ10) -> 0 | AX10: =SUM(AS10:AW10) -> 0 | BD10: =SUM(AY10:BC10) -> 0
A11: Caixas inventariadas | B11: 10 | H11: =SUM(C11:G11) -> 0 | N11: =SUM(I11:M11) -> 0 | T11: =SUM(O11:S11) -> 0 | Z11: =SUM(U11:Y11) -> 0 | AF11: =SUM(AA11:AE11) -> 0 | AL11: =SUM(AG11:AK11) -> 0 | AR11: =SUM(AM11:AQ11) -> 0 | AX11: =SUM(AS11:AW11) -> 0 | BD11: =SUM(AY11:BC11) -> 0
A12: Processos/documentos inventariados | B12: 11 | H12: =SUM(C12:G12) -> 0 | N12: =SUM(I12:M12) -> 0 | T12: =SUM(O12:S12) -> 0 | Z12: =SUM(U12:Y12) -> 0 | AF12: =SUM(AA12:AE12) -> 0 | AL12: =SUM(AG12:AK12) -> 0 | AR12: =SUM(AM12:AQ12) -> 0 | AX12: =SUM(AS12:AW12) -> 0 | BD12: =SUM(AY12:BC12) -> 0
A13: Documentos administrativos produzidos (Despacho, Nota Técnica, minutas diversas) | B13: 12 | H13: =SUM(C13:G13) -> 0 | N13: =SUM(I13:M13) -> 0 | T13: =SUM(O13:S13) -> 0 | Z13: =SUM(U13:Y13) -> 0 | AF13: =SUM(AA13:AE13) -> 0 | AL13: =SUM(AG13:AK13) -> 0 | AR13: =SUM(AM13:AQ13) -> 0 | AX13: =SUM(AS13:AW13) -> 0 | BD13: =SUM(AY13:BC13) -> 0
... A16: Caixas conferidas | B16: 15 | H16: =SUM(C16:G16) -> 0 | N16: =SUM(I16:M16) -> 0 | T16: =SUM(O16:S16) -> 0 | Z16: =SUM(U16:Y16) -> 0 | AF16: =SUM(AA16:AE16) -> 0 | AL16: =SUM(AG16:AK16) -> 0 | AR16: =SUM(AM16:AQ16) -> 0 | AX16: =SUM(AS16:AW16) -> 0 | BD16: =SUM(AY16:BC16) -> 0
A17: OUTRA ATIVIDADE. QUAL?
A18: OBSERVAÇÃO

Sheet TOTAL
A1: INDICADORES | B1: Fonte | C1: 04/08 a 08/08/2025 | D1: 11/08 a 15/08/2025 | E1: 18/08 a 22/08/2025 | F1: 25/08 a 29/08/2025 | G1: 01/09 a 05/09/2025 | H1: 08/09 a 12/09/2025 | I1: 15/09 a 19/09/2025 | J1: 22/09 a 26/09/2025 | K1: 29/09 a 03/10/2025
A2: Desarquivamento de Processos/Documentos - Saída de Guia Fora | B2: SEI | C2: =Diego!H2+Aelton!H2+Leonam!H2+Danilo!H2+Marcos!H2+Alessandro!H2+Carlos!H2 -> 0 | D2: =Diego!N2+Aelton!N2+Leonam!N2+Danilo!N2+Marcos!N2+Carlos!N2+Alessandro!N2 -> 1 | E2: =Diego!T2+Aelton!T2+Leonam!T2+Danilo!T2+Marcos!T2+Carlos!T2+Alessandro!T2 -> 0 | F2: =Diego!Z2+Aelton!Z2+Leonam!Z2+Danilo!Z2+Marcos!Z2+Carlos!Z2+Alessandro!Z2 -> 8 | G2: =Diego!AF2+Aelton!AF2+Leonam!AF2+Danilo!AF2+Marcos!AF2+Carlos!AF2+Alessandro!AF2 -> 0 | H2: =Diego!AL2+Aelton!AL2+Leonam!AL2+Danilo!AL2+Marcos!AL2+Carlos!AL2+Alessandro!AL2 -> 0 | I2: =Diego!AR2+Aelton!AR2+Leonam!AR2+Danilo!AR2+Marcos!AR2+Carlos!AR2+Alessandro!AR2 -> 33 | J2: =Diego!AX2+Aelton!AX2+Leonam!AX2+Danilo!AX2+Marcos!AX2+Carlos!AX2+Alessandro!AX2 -> 0 | K2: =Diego!BD2+Aelton!BD2+Leonam!BD2+Danilo!BD2+Marcos!BD2+Carlos!BD2+Alessandro!BD2 -> 4
A3: Caixas consultadas em pesquisa de desarquivamento | B3: CONTAGEM INDIVIDUAL (das caixas abertas para verificação de conteúdo em contexto de pesquisa para desarquivamento) | C3: =Diego!H3+Aelton!AF3+Leonam!H3+Danilo!H3+Marcos!H3+Alessandro!H3+Carlos!H3 -> 0 | D3: =Diego!N3+Aelton!N3+Leonam!N3+Danilo!N3+Marcos!N3+Carlos!N3+Alessandro!N3 -> 0 | E3: =Diego!T3+Aelton!T3+Leonam!T3+Danilo!T3+Marcos!T3+Carlos!T3+Alessandro!T3 -> 5 | F3: =Diego!Z3+Aelton!Z3+Leonam!Z3+Danilo!Z3+Marcos!Z3+Carlos!Z3+Alessandro!Z3 -> 0 | G3: =Diego!AF3+Aelton!AF3+Leonam!AF3+Danilo!AF3+Marcos!AF3+Carlos!AF3+Alessandro!AF3 -> 0 | H3: =Diego!AL3+Aelton!AL3+Leonam!AL3+Danilo!AL3+Marcos!AL3+Carlos!AL3+Alessandro!AL3 -> 0 | I3: =Diego!AM3+Aelton!AM3+Leonam!AM3+Danilo!AM3+Marcos!AM3+Carlos!AM3+Alessandro!AM3 -> 0 | J3: =Diego!AX3+Aelton!AX3+Leonam!AX3+Danilo!AX3+Marcos!AX3+Carlos!AX3+Alessandro!AX3 -> 0 | K3: =Diego!BD3+Aelton!BD3+Leonam!BD3+Danilo!BD3+Marcos!BD3+Carlos!BD3+Alessandro!BD3 -> 0
A4: Retorno de Processos/Documentos Desarquivados | B4: SEI | C4: =Diego!H4+Aelton!AF4+Leonam!H4+Danilo!H4+Marcos!H4+Alessandro!H4+Carlos!H4 -> 0 | D4: =Diego!N4+Aelton!N4+Leonam!N4+Danilo!N4+Marcos!N4+Carlos!N4+Alessandro!N4 -> 0 | E4: =Diego!T4+Aelton!T4+Leonam!T4+Danilo!T4+Marcos!T4+Carlos!T4+Alessandro!T4 -> 0 | F4: =Diego!Z4+Aelton!Z4+Leonam!Z4+Danilo!Z4+Marcos!Z4+Carlos!Z4+Alessandro!Z4 -> 1 | G4: =Diego!AF4+Aelton!AF4+Leonam!AF4+Danilo!AF4+Marcos!AF4+Carlos!AF4+Alessandro!AF4 -> 0 | H4: =Diego!AL4+Aelton!AL4+Leonam!AL4+Danilo!AL4+Marcos!AL4+Carlos!AL4+Alessandro!AL4 -> 0 | I4: =Diego!AM4+Aelton!AM4+Leonam!AM4+Danilo!AM4+Marcos!AM4+Carlos!AM4+Alessandro!AM4 -> 0 | J4: =Diego!AX4+Aelton!AX4+Leonam!AX4+Danilo!AX4+Marcos!AX4+Carlos!AX4+Alessandro!AX4 -> 0 | K4: =Diego!BD4+Aelton!BD4+Leonam!BD4+Danilo!BD4+Marcos!BD4+Carlos!BD4+Alessandro!BD4 -> 0
A5: Recebimento de Documentos - Guia de Transferência | B5: SEI | C5: =Diego!H5+Aelton!AF5+Leonam!H5+Danilo!H5+Marcos!H5+Alessandro!H5+Carlos!H5 -> 0 | D5: =Diego!N5+Aelton!N5+Leonam!N5+Danilo!N5+Marcos!N5+Carlos!N5+Alessandro!N5 -> 0 | E5: =Diego!T5+Aelton!T5+Leonam!T5+Danilo!T5+Marcos!T5+Carlos!T5+Alessandro!T5 -> 0 | F5: =Diego!Z5+Aelton!Z5+Leonam!Z5+Danilo!Z5+Marcos!Z5+Carlos!Z5+Alessandro!Z5 -> 1 | G5: =Diego!AF5+Aelton!AF5+Leonam!AF5+Danilo!AF5+Marcos!AF5+Carlos!AF5+Alessandro!AF5 -> 0 | H5: =Diego!AL5+Aelton!AL5+Leonam!AL5+Danilo!AL5+Marcos!AL5+Carlos!AL5+Alessandro!AL5 -> 0 | I5: =Diego!AM5+Aelton!AM5+Leonam!AM5+Danilo!AM5+Marcos!AM5+Carlos!AM5+Alessandro!AM5 -> 0 | J5: =Diego!AX5+Aelton!AX5+Leonam!AX5+Danilo!AX5+Marcos!AX5+Carlos!AX5+Alessandro!AX5 -> 0 | K5: =Diego!BD5+Aelton!BD5+Leonam!BD5+Danilo!BD5+Marcos!BD5+Carlos!BD5+Alessandro!BD5 -> 0
A6: Caixas separadas para classificação | B6: CONTAGEM INDIVIDUAL (das caixas "puxadas" nas estantes como uma pré-seleção para classificação) | C6: =Diego!H6+Aelton!AF6+Leonam!H6+Danilo!H6+Marcos!H6+Alessandro!H6+Carlos!H6 -> 0 | D6: =Diego!N6+Aelton!N6+Leonam!N6+Danilo!N6+Marcos!N6+Carlos!N6+Alessandro!N6 -> 0 | E6: =Diego!T6+Aelton!T6+Leonam!T6+Danilo!T6+Marcos!T6+Carlos!T6+Alessandro!T6 -> 0 | F6: =Diego!Z6+Aelton!Z6+Leonam!Z6+Danilo!Z6+Marcos!Z6+Carlos!Z6+Alessandro!Z6 -> 0 | G6: =Diego!AF6+Aelton!AF6+Leonam!AF6+Danilo!AF6+Marcos!AF6+Carlos!AF6+Alessandro!AF6 -> 0 | H6: =Diego!AL6+Aelton!AL6+Leonam!AL6+Danilo!AL6+Marcos!AL6+Carlos!AL6+Alessandro!AL6 -> 0 | I6: =Diego!AM6+Aelton!AM6+Leonam!AM6+Danilo!AM6+Marcos!AM6+Carlos!AM6+Alessandro!AM6 -> 0 | J6: =Diego!AX6+Aelton!AX6+Leonam!AX6+Danilo!AX6+Marcos!AX6+Carlos!AX6+Alessandro!AX6 -> 0 | K6: =Diego!BD6+Aelton!BD6+Leonam!BD6+Danilo!BD6+Marcos!BD6+Carlos!BD6+Alessandro!BD6 -> 0
A7: Processos/Documentos classificados | B7: PLANILHA | C7: =Diego!H7+Aelton!AF7+Leonam!H7+Danilo!H7+Marcos!H7+Alessandro!H7+Carlos!H7 -> 0 | D7: =Diego!N7+Aelton!N7+Leonam!N7+Danilo!N7+Marcos!N7+Carlos!N7+Alessandro!N7 -> 0 | E7: =Diego!T7+Aelton!T7+Leonam!T7+Danilo!T7+Marcos!T7+Carlos!T7+Alessandro!T7 -> 0 | F7: =Diego!Z7+Aelton!Z7+Leonam!Z7+Danilo!Z7+Marcos!Z7+Carlos!Z7+Alessandro!Z7 -> 0 | G7: =Diego!AF7+Aelton!AF7+Leonam!AF7+Danilo!AF7+Marcos!AF7+Carlos!AF7+Alessandro!AF7 -> 0 | H7: =Diego!AL7+Aelton!AL7+Leonam!AL7+Danilo!AL7+Marcos!AL7+Carlos!AL7+Alessandro!AL7 -> 0 | I7: =Diego!AM7+Aelton!AM7+Leonam!AM7+Danilo!AM7+Marcos!AM7+Carlos!AM7+Alessandro!AM7 -> 0 | J7: =Diego!AX7+Aelton!AX7+Leonam!AX7+Danilo!AX7+Marcos!AX7+Carlos!AX7+Alessandro!AX7 -> 0 | K7: =Diego!BD7+Aelton!BD7+Leonam!BD7+Danilo!BD7+Marcos!BD7+Carlos!BD7+Alessandro!BD7 -> 0
A8: Caixas separadas para eliminação | B8: CONTAGEM INDIVIDUAL (das caixas "puxadas" nas estantes como uma pré-seleção para eliminação) | C8: =Diego!H8+Aelton!AF8+Leonam!H8+Danilo!H8+Marcos!H8+Alessandro!H8+Carlos!H8 -> 0 | D8: =Diego!N8+Aelton!N8+Leonam!N8+Danilo!N8+Marcos!N8+Carlos!N8+Alessandro!N8 -> 0 | E8: =Diego!T8+Aelton!T8+Leonam!T8+Danilo!T8+Marcos!T8+Carlos!T8+Alessandro!T8 -> 0 | F8: =Diego!Z8+Aelton!Z8+Leonam!Z8+Danilo!Z8+Marcos!Z8+Carlos!Z8+Alessandro!Z8 -> 0 | G8: =Diego!AF8+Aelton!AF8+Leonam!AF8+Danilo!AF8+Marcos!AF8+Carlos!AF8+Alessandro!AF8 -> 0 | H8: =Diego!AL8+Aelton!AL8+Leonam!AL8+Danilo!AL8+Marcos!AL8+Carlos!AL8+Alessandro!AL8 -> 0 | I8: =Diego!AM8+Aelton!AM8+Leonam!AM8+Danilo!AM8+Marcos!AM8+Carlos!AM8+Alessandro!AM8 -> 0 | J8: =Diego!AX8+Aelton!AX8+Leonam!AX8+Danilo!AX8+Marcos!AX8+Carlos!AX8+Alessandro!AX8 -> 0 | K8: =Diego!BD8+Aelton!BD8+Leonam!BD8+Danilo!BD8+Marcos!BD8+Carlos!BD8+Alessandro!BD8 -> 0
A9: Caixas listadas para eliminação | B9: PLANILHA | C9: =Diego!H9+Aelton!AF9+Leonam!H9+Danilo!H9+Marcos!H9+Alessandro!H9+Carlos!H9 -> 0 | D9: =Diego!N9+Aelton!N9+Leonam!N9+Danilo!N9+Marcos!N9+Carlos!N9+Alessandro!N9 -> 0 | E9: =Diego!T9+Aelton!T9+Leonam!T9+Danilo!T9+Marcos!T9+Carlos!T9+Alessandro!T9 -> 0 | F9: =Diego!Z9+Aelton!Z9+Leonam!Z9+Danilo!Z9+Marcos!Z9+Carlos!Z9+Alessandro!Z9 -> 0 | G9: =Diego!AF9+Aelton!AF9+Leonam!AF9+Danilo!AF9+Marcos!AF9+Carlos!AF9+Alessandro!AF9 -> 0 | H9: =Diego!AL9+Aelton!AL9+Leonam!AL9+Danilo!AL9+Marcos!AL9+Carlos!AL9+Alessandro!AL9 -> 0 | I9: =Diego!AM9+Aelton!AM9+Leonam!AM9+Danilo!AM9+Marcos!AM9+Carlos!AM9+Alessandro!AM9 -> 0 | J9: =Diego!AX9+Aelton!AX9+Leonam!AX9+Danilo!AX9+Marcos!AX9+Carlos!AX9+Alessandro!AX9 -> 0 | K9: =Diego!BD9+Aelton!BD9+Leonam!BD9+Danilo!BD9+Marcos!BD9+Carlos!BD9+Alessandro!BD9 -> 0
A10: Processos/Documentos listados para eliminação | B10: PLANILHA | C10: =Diego!H10+Aelton!AF10+Leonam!H10+Danilo!H10+Marcos!H10+Alessandro!H10+Carlos!H10 -> 0 | D10: =Diego!N10+Aelton!N10+Leonam!N10+Danilo!N10+Marcos!N10+Carlos!N10+Alessandro!N10 -> 0 | E10: =Diego!T10+Aelton!T10+Leonam!T10+Danilo!T10+Marcos!T10+Carlos!T10+Alessandro!T10 -> 0 | F10: =Diego!Z10+Aelton!Z10+Leonam!Z10+Danilo!Z10+Marcos!Z10+Carlos!Z10+Alessandro!Z10 -> 0 | G10: =Diego!AF10+Aelton!AF10+Leonam!AF10+Danilo!AF10+Marcos!AF10+Carlos!AF10+Alessandro!AF10 -> 0 | H10: =Diego!AL10+Aelton!AL10+Leonam!AL10+Danilo!AL10+Marcos!AL10+Carlos!AL10+Alessandro!AL10 -> 0 | I10: =Diego!AM10+Aelton!AM10+Leonam!AM10+Danilo!AM10+Marcos!AM10+Carlos!AM10+Alessandro!AM10 -> 0 | J10: =Diego!AX10+Aelton!AX10+Leonam!AX10+Danilo!AX10+Marcos!AX10+Carlos!AX10+Alessandro!AX10 -> 0 | K10: =Diego!BD10+Aelton!BD10+Leonam!BD10+Danilo!BD10+Marcos!BD10+Carlos!BD10+Alessandro!BD10 -> 0
A11: Caixas inventariadas | B11: PLANILHA | C11: =Diego!H11+Aelton!H11+Leonam!H11+Danilo!H11+Marcos!H11+Carlos!H11+Alessandro!H11 -> 0 | D11: =Diego!N11+Aelton!N11+Leonam!N11+Danilo!N11+Marcos!N11+Carlos!N11+Alessandro!N11 -> 6 | E11: =Diego!T11+Aelton!T11+Leonam!T11+Danilo!T11+Marcos!T11+Carlos!T11+Alessandro!T11 -> 13 | F11: =Diego!Z11+Aelton!Z11+Leonam!Z11+Danilo!Z11+Marcos!Z11+Carlos!Z11+Alessandro!Z11 -> 10 | G11: =Diego!AF11+Aelton!AF11+Leonam!AF11+Danilo!AF11+Marcos!AF11+Carlos!AF11+Alessandro!AF11 -> 17 | H11: =Diego!AL11+Aelton!AL11+Leonam!AL11+Danilo!AL11+Marcos!AL11+Carlos!AL11+Alessandro!AL11 -> 1 | I11: =SUM(Diego!AR11+Aelton!AR11+Leonam!AR11+Danilo!AR11+Marcos!AR11+Carlos!AR11+Alessandro!AR11) -> 11 | J11: =Diego!AX11+Aelton!AX11+Leonam!AX11+Danilo!AX11+Marcos!AX11+Carlos!AX11+Alessandro!AX11 -> 0 | K11: =Diego!BD11+Aelton!BD11+Leonam!BD11+Danilo!BD11+Marcos!BD11+Carlos!BD11+Alessandro!BD11 -> 0
A12: Processos/documentos inventariados | B12: PLANILHA | C12: =Diego!H12+Aelton!AF12+Leonam!H12+Danilo!H12+Marcos!H12+Alessandro!H12+Carlos!H12 -> 0 | D12: =Diego!N12+Aelton!N12+Leonam!N12+Danilo!N12+Marcos!N12+Carlos!N12+Alessandro!N12 -> 0 | E12: =Diego!T12+Aelton!T12+Leonam!T12+Danilo!T12+Marcos!T12+Carlos!T12+Alessandro!T12 -> 0 | F12: =Diego!Z12+Aelton!Z12+Leonam!Z12+Danilo!Z12+Marcos!Z12+Carlos!Z12+Alessandro!Z12 -> 0 | G12: =Diego!AF12+Aelton!AF12+Leonam!AF12+Danilo!AF12+Marcos!AF12+Carlos!AF12+Alessandro!AF12 -> 0 | H12: =Diego!AL12+Aelton!AL12+Leonam!AL12+Danilo!AL12+Marcos!AL12+Carlos!AL12+Alessandro!AL12 -> 13 | I12: =Diego!AM12+Aelton!AM12+Leonam!AM12+Danilo!AM12+Marcos!AM12+Carlos!AM12+Alessandro!AM12 -> 0 | J12: =Diego!AX12+Aelton!AX12+Leonam!AX12+Danilo!AX12+Marcos!AX12+Carlos!AX12+Alessandro!AX12 -> 0 | K12: =Diego!BD12+Aelton!BD12+Leonam!BD12+Danilo!BD12+Marcos!BD12+Carlos!BD12+Alessandro!BD12 -> 0
A13: Documentos administrativos produzidos (Despacho, Nota Técnica, minutas diversas) | B13: SEI | C13: =Diego!H13+Aelton!AF13+Leonam!H13+Danilo!H13+Marcos!H13+Alessandro!H13+Carlos!H13 -> 0 | D13: =Diego!N13+Aelton!N13+Leonam!N13+Danilo!N13+Marcos!N13+Carlos!N13+Alessandro!N13 -> 1 | E13: =Diego!T13+Aelton!T13+Leonam!T13+Danilo!T13+Marcos!T13+Carlos!T13+Alessandro!T13 -> 1 | F13: =Diego!Z13+Aelton!Z13+Leonam!Z13+Danilo!Z13+Marcos!Z13+Carlos!Z13+Alessandro!Z13 -> 0 | G13: =Diego!AF13+Aelton!AF13+Leonam!AF13+Danilo!AF13+Marcos!AF13+Carlos!AF13+Alessandro!AF13 -> 0 | H13: =Diego!AL13+Aelton!AL13+Leonam!AL13+Danilo!AL13+Marcos!AL13+Carlos!AL13+Alessandro!AL13 -> 1 | I13: =Diego!AR13+Aelton!AR13+Leonam!AR13+Danilo!AR13+Marcos!AR13+Carlos!AR13+Alessandro!AR13 -> 32 | J13: =Diego!AX13+Aelton!AX13+Leonam!AX13+Danilo!AX13+Marcos!AX13+Carlos!AX13+Alessandro!AX13 -> 2 | K13: =Diego!BD13+Aelton!BD13+Leonam!BD13+Danilo!BD13+Marcos!BD13+Carlos!BD13+Alessandro!BD13 -> 3
A14: Orientação técnica / atendimentos realizados | B14: SEI, E-MAIL, TELEFONE | C14: =Diego!H14+Aelton!AF14+Leonam!H14+Danilo!H14+Marcos!H14+Alessandro!H14+Carlos!H14 -> 0 | D14: =Diego!N14+Aelton!N14+Leonam!N14+Danilo!N14+Marcos!N14+Carlos!N14+Alessandro!N14 -> 1 | E14: =Diego!T14+Aelton!T14+Leonam!T14+Danilo!T14+Marcos!T14+Carlos!T14+Alessandro!T14 -> 0 | F14: =Diego!Z14+Aelton!Z14+Leonam!Z14+Danilo!Z14+Marcos!Z14+Carlos!Z14+Alessandro!Z14 -> 0 | G14: =Diego!AF14+Aelton!AF14+Leonam!AF14+Danilo!AF14+Marcos!AF14+Carlos!AF14+Alessandro!AF14 -> 0 | H14: =Diego!AL14+Aelton!AL14+Leonam!AL14+Danilo!AL14+Marcos!AL14+Carlos!AL14+Alessandro!AL14 -> 0 | I14: =Diego!AM14+Aelton!AM14+Leonam!AM14+Danilo!AM14+Marcos!AM14+Carlos!AM14+Alessandro!AM14 -> 0 | J14: =Diego!AX14+Aelton!AX14+Leonam!AX14+Danilo!AX14+Marcos!AX14+Carlos!AX14+Alessandro!AX14 -> 0 | K14: =Diego!BD14+Aelton!BD14+Leonam!BD14+Danilo!BD14+Marcos!BD14+Carlos!BD14+Alessandro!BD14 -> 0
A15: Caixas remanejada | B15: CONTAGEM INDIVIDUAL (de caixas deslocadas visando reorganização temporária ou permanente) | C15: =Diego!H15+Aelton!H15+Leonam!H15+Danilo!H15+Marcos!H15+Carlos!H15+Alessandro!H15 -> 0 | D15: =Diego!N15+Aelton!N15+Leonam!N15+Danilo!N15+Marcos!N15+Carlos!N15+Alessandro!N15 -> 0 | E15: =Diego!T15+Aelton!T15+Leonam!T15+Danilo!T15+Marcos!T15+Carlos!T15+Alessandro!T15 -> 0 | F15: =Diego!Z15+Aelton!Z15+Leonam!Z15+Danilo!Z15+Marcos!Z15+Carlos!Z15+Alessandro!Z15 -> 0 | G15: =Diego!AF15+Aelton!AF15+Leonam!AF15+Danilo!AF15+Marcos!AF15+Carlos!AF15+Alessandro!AF15 -> 14 | H15: =Diego!AL15+Aelton!AL15+Leonam!AL15+Danilo!AL15+Marcos!AL15+Carlos!AL15+Alessandro!AL15 -> 0 | I15: =Diego!AM15+Aelton!AM15+Leonam!AM15+Danilo!AM15+Marcos!AM15+Carlos!AM15+Alessandro!AM15 -> 0 | J15: =Diego!AX15+Aelton!AX15+Leonam!AX15+Danilo!AX15+Marcos!AX15+Carlos!AX15+Alessandro!AX15 -> 0 | K15: =Diego!BD15+Aelton!BD15+Leonam!BD15+Danilo!BD15+Marcos!BD15+Carlos!BD15+Alessandro!BD15 -> 0
A16: Caixas conferidas | B16: CONTAGEM INDIVIDUAL (de caixas para simples conferência de quantitativo ou do conteúdo do espelho em atividades diversas) | C16: =Diego!H16+Aelton!H16+Leonam!H16+Danilo!H16+Marcos!H16+Carlos!H16+Alessandro!H16 -> 0 | D16: =Diego!N16+Aelton!N16+Leonam!N16+Danilo!N16+Marcos!N16+Carlos!N16+Alessandro!N16 -> 0 | E16: =Diego!T16+Aelton!T16+Leonam!T16+Danilo!T16+Marcos!T16+Carlos!T16+Alessandro!T16 -> 0 | F16: =Diego!Z16+Aelton!Z16+Leonam!Z16+Danilo!Z16+Marcos!Z16+Carlos!Z16+Alessandro!Z16 -> 33 | G16: =Diego!AF16+Aelton!AF16+Leonam!AF16+Danilo!AF16+Marcos!AF16+Carlos!AF16+Alessandro!AF16 -> 35 | H16: =Diego!AL16+Aelton!AL16+Leonam!AL16+Danilo!AL16+Marcos!AL16+Carlos!AL16+Alessandro!AL16 -> 0 | I16: =Diego!AM16+Aelton!AM16+Leonam!AM16+Danilo!AM16+Marcos!AM16+Carlos!AM16+Alessandro!AM16 -> 0 | J16: =Diego!AX16+Aelton!AX16+Leonam!AX16+Danilo!AX16+Marcos!AX16+Carlos!AX16+Alessandro!AX16 -> 0 | K16: =Diego!BD16+Aelton!BD16+Leonam!BD16+Danilo!BD16+Marcos!BD16+Carlos!BD16+Alessandro!BD16 -> 20
A17: OUTRA ATIVIDADE. QUAL?
A18: OBSERVAÇÃO

Sheet Diego
A1: INDICADORES | C1: 45873 | D1: 45874 | E1: 45875 | F1: 45876 | G1: 45877 | H1: TOTAL SEMANA | I1: 45880 | J1: 45881 | K1: 45882 | L1: 45883 | M1: 45884 | N1: TOTAL SEMANA | O1: 45887 | P1: 45888 | Q1: 45889 | R1: 45890 | S1: 45891 | T1: TOTAL SEMANA | U1: 45894 | V1: 45895 | W1: 45896 | X1: 45897 | Y1: 45898 | Z1: TOTAL SEMANA | AA1: 45901 | AB1: 45902 | AC1: 45903 | AD1: 45904 | AE1: 45905 | AF1: TOTAL SEMANA | AG1: 45908 | AH1: 45909 | AI1: 45910 | AJ1: 45911 | AK1: 45912 | AL1: TOTAL SEMANA | AM1: 45915 | AN1: 45916 | AO1: 45917 | AP1: 45918 | AQ1: 45919 | AR1: TOTAL SEMANA | AS1: 45922 | AT1: 45923 | AU1: 45924 | AV1: 45925 | AW1: 45926 | AX1: TOTAL SEMANA | AY1: 45929 | AZ1: 45930 | BA1: 45931 | BB1: 45932 | BC1: 45933 | BD1: TOTAL SEMANA
A2: Desarquivamento de Processos/Documentos - Saída de Guia Fora | B2: 1 | H2: =SUM(C2:G2) -> 0 | N2: =SUM(I2:M2) -> 0 | T2: =SUM(O2:S2) -> 0 | Z2: =SUM(U2:Y2) -> 0 | AF2: =SUM(AA2:AE2) -> 0 | AL2: =SUM(AG2:AK2) -> 0 | AR2: =SUM(AM2:AQ2) -> 0 | AX2: =SUM(AS2:AW2) -> 0 | BD2: =SUM(AY2:BC2) -> 0
A3: Caixas consultadas em pesquisa de desarquivamento | B3: 2 | H3: =SUM(C3:G3) -> 0 | N3: =SUM(I3:M3) -> 0 | T3: =SUM(O3:S3) -> 0 | Z3: =SUM(U3:Y3) -> 0 | AF3: =SUM(AA3:AE3) -> 0 | AL3: =SUM(AG3:AK3) -> 0 | AR3: =SUM(AM3:AQ3) -> 0 | AX3: =SUM(AS3:AW3) -> 0 | BD3: =SUM(AY3:BC3) -> 0
A4: Retorno de Processos/Documentos Desarquivados | B4: 3 | H4: =SUM(C4:G4) -> 0 | N4: =SUM(I4:M4) -> 0 | T4: =SUM(O4:S4) -> 0 | Z4: =SUM(U4:Y4) -> 0 | AF4: =SUM(AA4:AE4) -> 0 | AL4: =SUM(AG4:AK4) -> 0 | AR4: =SUM(AM4:AQ4) -> 0 | AX4: =SUM(AS4:AW4) -> 0 | BD4: =SUM(AY4:BC4) -> 0
A5: Recebimento de Documentos - Guia de Transferência | B5: 4 | H5: =SUM(C5:G5) -> 0 | N5: =SUM(I5:M5) -> 0 | T5: =SUM(O5:S5) -> 0 | Z5: =SUM(U5:Y5) -> 0 | AF5: =SUM(AA5:AE5) -> 0 | AL5: =SUM(AG5:AK5) -> 0 | AR5: =SUM(AM5:AQ5) -> 0 | AX5: =SUM(AS5:AW5) -> 0 | BD5: =SUM(AY5:BC5) -> 0
A6: Caixas separadas para classificação | B6: 5 | H6: =SUM(C6:G6) -> 0 | N6: =SUM(I6:M6) -> 0 | T6: =SUM(O6:S6) -> 0 | Z6: =SUM(U6:Y6) -> 0 | AF6: =SUM(AA6:AE6) -> 0 | AL6: =SUM(AG6:AK6) -> 0 | AR6: =SUM(AM6:AQ6) -> 0 | AX6: =SUM(AS6:AW6) -> 0 | BD6: =SUM(AY6:BC6) -> 0
A7: Processos/Documentos classificados | B7: 6 | H7: =SUM(C7:G7) -> 0 | N7: =SUM(I7:M7) -> 0 | T7: =SUM(O7:S7) -> 0 | Z7: =SUM(U7:Y7) -> 0 | AF7: =SUM(AA7:AE7) -> 0 | AL7: =SUM(AG7:AK7) -> 0 | AR7: =SUM(AM7:AQ7) -> 0 | AX7: =SUM(AS7:AW7) -> 0 | BD7: =SUM(AY7:BC7) -> 0
A8: Caixas separadas para eliminação | B8: 7 | H8: =SUM(C8:G8) -> 0 | N8: =SUM(I8:M8) -> 0 | T8: =SUM(O8:S8) -> 0 | Z8: =SUM(U8:Y8) -> 0 | AF8: =SUM(AA8:AE8) -> 0 | AL8: =SUM(AG8:AK8) -> 0 | AR8: =SUM(AM8:AQ8) -> 0 | AX8: =SUM(AS8:AW8) -> 0 | BD8: =SUM(AY8:BC8) -> 0
A9: Caixas listadas para eliminação | B9: 8 | H9: =SUM(C9:G9) -> 0 | N9: =SUM(I9:M9) -> 0 | T9: =SUM(O9:S9) -> 0 | Z9: =SUM(U9:Y9) -> 0 | AF9: =SUM(AA9:AE9) -> 0 | AL9: =SUM(AG9:AK9) -> 0 | AR9: =SUM(AM9:AQ9) -> 0 | AX9: =SUM(AS9:AW9) -> 0 | BD9: =SUM(AY9:BC9) -> 0
A10: Processos/Documentos listados para eliminação | B10: 9 | H10: =SUM(C10:G10) -> 0 | N10: =SUM(I10:M10) -> 0 | T10: =SUM(O10:S10) -> 0 | Z10: =SUM(U10:Y10) -> 0 | AF10: =SUM(AA10:AE10) -> 0 | AL10: =SUM(AG10:AK10) -> 0 | AR10: =SUM(AM10:AQ10) -> 0 | AX10: =SUM(AS10:AW10) -> 0 | BD10: =SUM(AY10:BC10) -> 0
A11: Caixas inventariadas | B11: 10 | H11: =SUM(C11:G11) -> 0 | N11: =SUM(I11:M11) -> 0 | T11: =SUM(O11:S11) -> 0 | Z11: =SUM(U11:Y11) -> 0 | AF11: =SUM(AA11:AE11) -> 0 | AL11: =SUM(AG11:AK11) -> 0 | AR11: =SUM(AM11:AQ11) -> 0 | AX11: =SUM(AS11:AW11) -> 0 | BD11: =SUM(AY11:BC11) -> 0
A12: Processos/documentos inventariados | B12: 11 | H12: =SUM(C12:G12) -> 0 | N12: =SUM(I12:M12) -> 0 | T12: =SUM(O12:S12) -> 0 | Z12: =SUM(U12:Y12) -> 0 | AF12: =SUM(AA12:AE12) -> 0 | AL12: =SUM(AG12:AK12) -> 0 | AR12: =SUM(AM12:AQ12) -> 0 | AX12: =SUM(AS12:AW12) -> 0 | BD12: =SUM(AY12:BC12) -> 0
A13: Documentos administrativos produzidos (Despacho, Nota Técnica, minutas diversas) | B13: 12 | H13: =SUM(C13:G13) -> 0 | N13: =SUM(I13:M13) -> 0 | T13: =SUM(O13:S13) -> 0 | Z13: =SUM(U13:Y13) -> 0 | AF13: =SUM(AA13:AE13) -> 0 | AL13: =SUM(AG13:AK13) -> 0 | AR13: =SUM(AM13:AQ13) -> 0 | AX13: =SUM(AS13:AW13) -> 0 | BD13: =SUM(AY13:BC13) -> 0
... A16: Caixas conferidas | B16: 15 | H16: =SUM(C16:G16) -> 0 | N16: =SUM(I16:M16) -> 0 | T16: =SUM(O16:S16) -> 0 | Z16: =SUM(U16:Y16) -> 0 | AF16: =SUM(AA16:AE16) -> 0 | AL16: =SUM(AG16:AK16) -> 0 | AR16: =SUM(AM16:AQ16) -> 0 | AX16: =SUM(AS16:AW16) -> 0 | BD16: =SUM(AY16:BC16) -> 0
A17: OUTRA ATIVIDADE. QUAL? | C17: Procura de caixas para eliminação. | D17: Procura de caixas para eliminação. | E17: Procura de caixas para eliminação. | F17: Palestra no Arquivo Nacional Fomos liberados do Ponto Eletrônico. | G17: Procura de caixas para eliminação. | I17: Procura de caixas para eliminação. | J17: Procura de caixas para eliminação. | K17: Procura de caixas para eliminação. | L17: Inventário de fotos LBA | M17: Inventário de fotos LBA | O17: Inventário de Fotos LBA | P17: Inventário de Fotos LBA | Q17: Inventário de Fotos LBA | R17: Inventário de Fotos LBA | S17: Inventário de Fotos LBA | U17: Inventário de Fotos LBA | V17: Inventário de Fotos LBA | W17: Inventário de Fotos LBA | X17: Inventário de Fotos LBA | Y17: Pesquisa e busca por 30 processosdo MESP. Solicitação e-mail de 26/08/2025, por Carlos Henrique Ribeiro de Sousa. | AA17: Inventário de Fotos LBA | AB17: Inventário de Fotos LBA | AC17: Inventário de Fotos LBA | AD17: Inventário de Fotos LBA | AE17: Inventário de Fotos LBA | AG17: Inventário de Fotos LBA | AH17: Inventário de Fotos LBA | AI17: Inventário de Fotos LBA | AJ17: Inventário de Fotos LBA | AK17: Inventário de Fotos LBA | AM17: Inventário de Fotos LBA | AN17: Inventário de Fotos LBA | AO17: Inventário de Fotos LBA | AP17: Inventário de Fotos LBA | AQ17: INVETARIO DE SLIDES DA LBA | AS17: INVETARIO DE SLIDES DA LBA | AT17: INVETARIO DE SLIDES DA LBA | AU17: INVETARIO DE SLIDES DA LBA | AV17: RECEBIMENTO DE 140 CAIXAS | AW17: ENTREGANDO AS DOCUMENTAÇÃO DA EMPRESA NOVA | AY17: conferindo patrimonio | AZ17: conferindo patrimonio | BA17: conferindo patrimonio | BB17: conferindo patrimonio | BC17: conferindo patrimonio
A18: OBSERVAÇÃO | J18: procurando processo solicitado | K18: procurando processo solicitado | L18: procurando processo solicitado | W18: PROCURANDO CAIXAS DA LBA | X18: PROCURANDO CAIXAS DA LBA | AA18: PROCURANDO CAIXAS DA LBA | AG18: PROCURANDO O PROCESSO DA LBA | AH18: PROCURANDO O PROCESSO DA LBA | BB18: procurando processo | BC18: procurando processo

Sheet Aelton
A1: INDICADORES | C1: 45873 | D1: 45874 | E1: 45875 | F1: 45876 | G1: 45877 | H1: TOTAL SEMANA | I1: 45880 | J1: 45881 | K1: 45882 | L1: 45883 | M1: 45884 | N1: TOTAL SEMANA | O1: 45887 | P1: 45888 | Q1: 45889 | R1: 45890 | S1: 45891 | T1: TOTAL SEMANA | U1: 45894 | V1: 45895 | W1: 45896 | X1: 45897 | Y1: 45898 | Z1: TOTAL SEMANA | AA1: 45901 | AB1: 45902 | AC1: 45903 | AD1: 45904 | AE1: 45905 | AF1: TOTAL SEMANA | AG1: 45908 | AH1: 45909 | AI1: 45910 | AJ1: 45911 | AK1: 45912 | AL1: TOTAL SEMANA | AM1: 45915 | AN1: 45916 | AO1: 45917 | AP1: 45918 | AQ1: 45919 | AR1: TOTAL SEMANA | AS1: 45922 | AT1: 45923 | AU1: 45924 | AV1: 45925 | AW1: 45926 | AX1: TOTAL SEMANA | AY1: 45929 | AZ1: 45930 | BA1: 45931 | BB1: 45932 | BC1: 45933 | BD1: TOTAL SEMANA
A2: Desarquivamento de Processos/Documentos - Saída de Guia Fora | B2: 1 | H2: =SUM(C2:G2) -> 0 | N2: =SUM(I2:M2) -> 0 | T2: =SUM(O2:S2) -> 0 | Z2: =SUM(U2:Y2) -> 0 | AF2: =SUM(AA2:AE2) -> 0 | AL2: =SUM(AG2:AK2) -> 0 | AM2: 4 | AP2: 29 | AR2: =SUM(AM2:AQ2) -> 33 | AX2: =SUM(AS2:AW2) -> 0 | BC2: 4 | BD2: =SUM(AY2:BC2) -> 4
A3: Caixas consultadas em pesquisa de desarquivamento | B3: 2 | H3: =SUM(C3:G3) -> 0 | N3: =SUM(I3:M3) -> 0 | T3: =SUM(O3:S3) -> 0 | Z3: =SUM(U3:Y3) -> 0 | AF3: =SUM(AA3:AE3) -> 0 | AL3: =SUM(AG3:AK3) -> 0 | AR3: =SUM(AM3:AQ3) -> 0 | AX3: =SUM(AS3:AW3) -> 0 | BD3: =SUM(AY3:BC3) -> 0
A4: Retorno de Processos/Documentos Desarquivados | B4: 3 | H4: =SUM(C4:G4) -> 0 | N4: =SUM(I4:M4) -> 0 | T4: =SUM(O4:S4) -> 0 | Z4: =SUM(U4:Y4) -> 0 | AF4: =SUM(AA4:AE4) -> 0 | AL4: =SUM(AG4:AK4) -> 0 | AR4: =SUM(AM4:AQ4) -> 0 | AX4: =SUM(AS4:AW4) -> 0 | BD4: =SUM(AY4:BC4) -> 0
A5: Recebimento de Documentos - Guia de Transferência | B5: 4 | H5: =SUM(C5:G5) -> 0 | N5: =SUM(I5:M5) -> 0 | T5: =SUM(O5:S5) -> 0 | Z5: =SUM(U5:Y5) -> 0 | AF5: =SUM(AA5:AE5) -> 0 | AL5: =SUM(AG5:AK5) -> 0 | AR5: =SUM(AM5:AQ5) -> 0 | AX5: =SUM(AS5:AW5) -> 0 | BD5: =SUM(AY5:BC5) -> 0
A6: Caixas separadas para classificação | B6: 5 | H6: =SUM(C6:G6) -> 0 | N6: =SUM(I6:M6) -> 0 | T6: =SUM(O6:S6) -> 0 | Z6: =SUM(U6:Y6) -> 0 | AF6: =SUM(AA6:AE6) -> 0 | AL6: =SUM(AG6:AK6) -> 0 | AR6: =SUM(AM6:AQ6) -> 0 | AX6: =SUM(AS6:AW6) -> 0 | BD6: =SUM(AY6:BC6) -> 0
A7: Processos/Documentos classificados | B7: 6 | H7: =SUM(C7:G7) -> 0 | N7: =SUM(I7:M7) -> 0 | T7: =SUM(O7:S7) -> 0 | Z7: =SUM(U7:Y7) -> 0 | AF7: =SUM(AA7:AE7) -> 0 | AL7: =SUM(AG7:AK7) -> 0 | AR7: =SUM(AM7:AQ7) -> 0 | AX7: =SUM(AS7:AW7) -> 0 | BD7: =SUM(AY7:BC7) -> 0
A8: Caixas separadas para eliminação | B8: 7 | H8: =SUM(C8:G8) -> 0 | N8: =SUM(I8:M8) -> 0 | T8: =SUM(O8:S8) -> 0 | Z8: =SUM(U8:Y8) -> 0 | AF8: =SUM(AA8:AE8) -> 0 | AL8: =SUM(AG8:AK8) -> 0 | AR8: =SUM(AM8:AQ8) -> 0 | AX8: =SUM(AS8:AW8) -> 0 | BD8: =SUM(AY8:BC8) -> 0
A9: Caixas listadas para eliminação | B9: 8 | H9: =SUM(C9:G9) -> 0 | N9: =SUM(I9:M9) -> 0 | T9: =SUM(O9:S9) -> 0 | Z9: =SUM(U9:Y9) -> 0 | AF9: =SUM(AA9:AE9) -> 0 | AL9: =SUM(AG9:AK9) -> 0 | AR9: =SUM(AM9:AQ9) -> 0 | AX9: =SUM(AS9:AW9) -> 0 | BD9: =SUM(AY9:BC9) -> 0
A10: Processos/Documentos listados para eliminação | B10: 9 | H10: =SUM(C10:G10) -> 0 | N10: =SUM(I10:M10) -> 0 | T10: =SUM(O10:S10) -> 0 | Z10: =SUM(U10:Y10) -> 0 | AF10: =SUM(AA10:AE10) -> 0 | AL10: =SUM(AG10:AK10) -> 0 | AR10: =SUM(AM10:AQ10) -> 0 | AX10: =SUM(AS10:AW10) -> 0 | BD10: =SUM(AY10:BC10) -> 0
A11: Caixas inventariadas | B11: 10 | H11: =SUM(C11:G11) -> 0 | L11: 1 | M11: 2 | N11: =SUM(I11:M11) -> 3 | S11: 2 | T11: =SUM(O11:S11) -> 2 | V11: 2 | Z11: =SUM(U11:Y11) -> 2 | AA11: 3 | AD11: 2 | AE11: 1 | AF11: =SUM(AA11:AE11) -> 6 | AG11: 1 | AL11: =SUM(AG11:AK11) -> 1 | AR11: =SUM(AM11:AQ11) -> 0 | AX11: =SUM(AS11:AW11) -> 0 | BD11: =SUM(AY11:BC11) -> 0
A12: Processos/documentos inventariados | B12: 11 | H12: =SUM(C12:G12) -> 0 | N12: =SUM(I12:M12) -> 0 | T12: =SUM(O12:S12) -> 0 | Z12: =SUM(U12:Y12) -> 0 | AF12: =SUM(AA12:AE12) -> 0 | AG12: 2 | AI12: 7 | AJ12: 4 | AL12: =SUM(AG12:AK12) -> 13 | AR12: =SUM(AM12:AQ12) -> 0 | AX12: =SUM(AS12:AW12) -> 0 | BD12: =SUM(AY12:BC12) -> 0
A13: Documentos administrativos produzidos (Despacho, Nota Técnica, minutas diversas) | B13: 12 | H13: =SUM(C13:G13) -> 0 | N13: =SUM(I13:M13) -> 0 | T13: =SUM(O13:S13) -> 0 | Z13: =SUM(U13:Y13) -> 0 | AF13: =SUM(AA13:AE13) -> 0 | AK13: 1 | AL13: =SUM(AG13:AK13) -> 1 | AN13: 1 | AP13: 1 | AQ13: 30 | AR13: =SUM(AM13:AQ13) -> 32 | AS13: 1 | AT13: 1 | AX13: =SUM(AS13:AW13) -> 2 | BC13: 3 | BD13: =SUM(AY13:BC13) -> 3
A14: Orientação técnica / atendimentos realizados | B14: 13 | H14: =SUM(C14:G14) -> 0 | J14: 1 | N14: =SUM(I14:M14) -> 1 | T14: =SUM(O14:S14) -> 0 | Z14: =SUM(U14:Y14) -> 0 | AF14: =SUM(AA14:AE14) -> 0 | AL14: =SUM(AG14:AK14) -> 0 | AR14: =SUM(AM14:AQ14) -> 0 | AX14: =SUM(AS14:AW14) -> 0 | BD14: =SUM(AY14:BC14) -> 0
A15: Caixas remanejadas | B15: 14 | H15: =SUM(C15:G15) -> 0 | N15: =SUM(I15:M15) -> 0 | T15: =SUM(O15:S15) -> 0 | Z15: =SUM(U15:Y15) -> 0 | AC15: 14 | AF15: =SUM(AA15:AE15) -> 14 | AL15: =SUM(AG15:AK15) -> 0 | AR15: =SUM(AM15:AQ15) -> 0 | AX15: =SUM(AS15:AW15) -> 0 | BD15: =SUM(AY15:BC15) -> 0
A16: Caixas conferidas | B16: 15 | H16: =SUM(C16:G16) -> 0 | N16: =SUM(I16:M16) -> 0 | T16: =SUM(O16:S16) -> 0 | W16: 4 | Y16: 7 | Z16: =SUM(U16:Y16) -> 11 | AB16: 23 | AC16: 12 | AF16: =SUM(AA16:AE16) -> 35 | AL16: =SUM(AG16:AK16) -> 0 | AR16: =SUM(AM16:AQ16) -> 0 | AX16: =SUM(AS16:AW16) -> 0 | BA16: 3 | BB16: 3 | BC16: 4 | BD16: =SUM(AY16:BC16) -> 10
A17: OUTRA ATIVIDADE. QUAL? | C17: 1. Procura de caixas para eliminação. 2. Acompanhamento da conferência dos parimônios no Bloco A, sala G-15 | D17: Procura de caixas para eliminação. | E17: 1. Procura de caixas para eliminação. 2. Acompanhamento da conferência dos parimônios no Bloco A, sala G-15 | F17: Palestra no Arquivo Nacional Fomos liberados do Ponto Eletrônico. | G17: Pesquisa e busca pelo processo 71000.004542/2005-12 (SESAN) | I17: Pesquisa e busca pelo processo 71000.004542/2005-12 (SESAN) Não encontrado registro de entrada neste arquivo. | J17: 1. E-mail de orientação de desarquivamento para o Wederson da CGPC. 2. Pesquisa e busca pelo processo 44000.006180/1997-51 | K17: 1. Pesquisa e busca pelo processo 44000.006180/1997-51. 2. Pesquisa e busca pela pasta funcional - DYLENY TEIXEIRA ALVES DA SILVA | L17: 1. Pesquisa e busca pelo processo 44000.006180/1997-51. 2. Inventário de fotos LBA. | M17: Inventário de Fotos LBA. | O17: 1. Pesquisa e buca processo 71010.117059/2008-13. 2. Pesquisa e busca processo 23132.000438/95-22. | P17: Atestado Médico | Q17: Pesquisa e busca processo 23132.000438/95-22 FUNDESPORTE. | R17: 1. Pesquisa e busca processo 23132.000438/95-22 FUNDESPORTE. 2. Inventário de Fotos LBA. 1 caixa | S17: Inventário de Fotos LBA. 2 caixas | U17: Contagem dos patrimônios da sala G-15 - Bloco A. Resultado: Positivo, nada faltando. | V17: Inventário de Fotos LBA. 2 caixas | W17: 1. Busca por caixas de fotos LBA. Total: 14 caixas. 2. Pesquisa e busca por 30 processosdo MESP. Solicitação e-mail de 26/08/2025, por Carlos Henrique Ribeiro de Sousa. | X17: Pesquisa e busca por 30 processosdo MESP. Solicitação e-mail de 26/08/2025, por Carlos Henrique Ribeiro de Sousa. | Y17: Pesquisa e busca por 30 processosdo MESP. Solicitação e-mail de 26/08/2025, por Carlos Henrique Ribeiro de Sousa. | AA17: Inventário de Fotos LBA. 3 caixas | AB17: Pesquisa e busca por caixas de fotos LBA no Bloco A - G-15 | AC17: 1. Pesquisa e busca por caixas de fotos LBA no Bloco A - G-15. 2. Acompanhamento movimentação caixas fotos LBA, do Bloco A para o DNIT. | AD17: Inventário de Fotos LBA. 2 caixas | AE17: 1. Analisando a Pasta de Rede, o Arquivo LBA para otimização das planilhas. 2. Inventário de Fotos LBA. 1 caixa. | AG17: 1. Curso Redação Oficial On-line - 8h30 às 12h. 2. Inventário de Fotos LBA. 1 caixa e 2 álbuns. | AH17: 1. Curso Redação Oficial On-line - 8h30 às 12h. 2. Pesquisa e busca por processo da LBA, imóvel Rio de Janeiro. Solicitação por e-mail da SNAS, Gustavo encaminhou em 8/9/2025. Encontrados 2 processos. | AI17: 1. Curso Redação Oficial On-line - 8h30 às 12h. 2. Inventário de Fotos LBA. 7 álbuns. | AJ17: 1. Curso Redação Oficial On-line - 8h30 às 12h. 2. Inventário de Fotos LBA. 4 álbuns. | AK17: 1. Curso Redação Oficial On-line - 8h30 às 12h. 2. Documento produzido: E-mail para fins de registro DIARQ. | AM17: 1. Contagem total do Inventário de fotos LBA. 2. Preparação desarquivamento 30 processos, ida ao Bloco A. 3. Desarquivamento Pasta Funcional. | AN17: 1. Preparação desarquivamento 30 processos, ida ao Bloco A. 2. Acompanhamento visita dos professores da UNB nos Arquivos do DNIT, a respeito das fotos LBA. | AO17: 1. Preparação desarquivamento 30 processos. | AP17: 1. Preparação desarquivamento 30 processos. 2. Desarquivamento 30 processos. | AQ17: 1. Tratando do desarqivamento dos 30 processos, pois já estão digitalizados no antigo SEI do Esporte. 2. Criação de 30 Despachos, o da demanda principal e dos 29 processos que foram exportados do SEI Esporte para DIARQ. Então tramitamos para CPAD 01/2025 da Corregedoria do Ministério do Esporte | AS17: 1. Conferência de 29 Despachos se foram enviados corretamento para o setor CPAD01/2025. 2. Criação de Despacho. | AT17: 1. Preparação do envio das 70 caixas para o DEFNAS. 2. Criação de modelo de e-mail de autorização de saída das 70 caixas, enviado para a Patrícia. | AU17: Censura de PDF's para enviar para o Arquivo Nacional. | AV17: 1. Envio de 70 caixas para o DEFNAS e recebimento de 70 caixas DEFNAS. 2. Censura de PDF's para enviar para o Arquivo Nacional. | AW17: Folga autorizada por Patrícia. | AY17: Conversa entre os terceirizados sobre a demanda da apostila que a Patrícia entregou. Resultado: Microfilmes somente resultado total; Mapas não foi possível devido serem anexos de processos; Fotos conseguiremos dar o resultado; Contagem das caixas total do Acervo conseguiremos. | AZ17: 1. Confraternização: Aniversário do Danilo. 2. Reunião com a chefe Patrícia para tratar dos tópicos da apostila. 3. Entreguei o resultado total de microfilmes e fotos da LBA, que constam nas planilhas, para a Patrícia. | BA17: Conferência caixas do DEFNAS. | BB17: Conferência caixas do DEFNAS. | BC17: 1. Conferência caixas do DEFNAS. 2. Pesquisa e busca por processos DEFNAS.
A18: OBSERVAÇÃO

Sheet Leonam
A1: INDICADORES | C1: 45873 | D1: 45874 | E1: 45875 | F1: 45876 | G1: 45877 | H1: TOTAL SEMANA | I1: 45880 | J1: 45881 | K1: 45882 | L1: 45883 | M1: 45884 | N1: TOTAL SEMANA | O1: 45887 | P1: 45888 | Q1: 45889 | R1: 45890 | S1: 45891 | T1: TOTAL SEMANA | U1: 45894 | V1: 45895 | W1: 45896 | X1: 45897 | Y1: 45898 | Z1: TOTAL SEMANA | AA1: 45901 | AB1: 45902 | AC1: 45903 | AD1: 45904 | AE1: 45905 | AF1: TOTAL SEMANA | AG1: 45908 | AH1: 45909 | AI1: 45910 | AJ1: 45911 | AK1: 45912 | AL1: TOTAL SEMANA | AM1: 45915 | AN1: 45916 | AO1: 45917 | AP1: 45918 | AQ1: 45919 | AR1: TOTAL SEMANA | AS1: 45922 | AT1: 45923 | AU1: 45924 | AV1: 45925 | AW1: 45926 | AX1: TOTAL SEMANA | AY1: 45929 | AZ1: 45930 | BA1: 45931 | BB1: 45932 | BC1: 45933 | BD1: TOTAL SEMANA
A2: Desarquivamento de Processos/Documentos - Saída de Guia Fora | B2: 1 | H2: =SUM(C2:G2) -> 0 | M2: 1 | N2: =SUM(I2:M2) -> 1 | T2: =SUM(O2:S2) -> 0 | Y2: 8 | Z2: =SUM(U2:Y2) -> 8 | AF2: =SUM(AA2:AE2) -> 0 | AL2: =SUM(AG2:AK2) -> 0 | AR2: =SUM(AM2:AQ2) -> 0 | AX2: =SUM(AS2:AW2) -> 0 | BD2: =SUM(AY2:BC2) -> 0
A3: Caixas consultadas em pesquisa de desarquivamento | B3: 2 | H3: =SUM(C3:G3) -> 0 | N3: =SUM(I3:M3) -> 0 | T3: =SUM(O3:S3) -> 0 | Z3: =SUM(U3:Y3) -> 0 | AF3: =SUM(AA3:AE3) -> 0 | AL3: =SUM(AG3:AK3) -> 0 | AR3: =SUM(AM3:AQ3) -> 0 | AX3: =SUM(AS3:AW3) -> 0 | BD3: =SUM(AY3:BC3) -> 0
A4: Retorno de Processos/Documentos Desarquivados | B4: 3 | H4: =SUM(C4:G4) -> 0 | N4: =SUM(I4:M4) -> 0 | T4: =SUM(O4:S4) -> 0 | U4: 1 | Z4: =SUM(U4:Y4) -> 1 | AF4: =SUM(AA4:AE4) -> 0 | AL4: =SUM(AG4:AK4) -> 0 | AR4: =SUM(AM4:AQ4) -> 0 | AX4: =SUM(AS4:AW4) -> 0 | BD4: =SUM(AY4:BC4) -> 0
A5: Recebimento de Documentos - Guia de Transferência | B5: 4 | H5: =SUM(C5:G5) -> 0 | N5: =SUM(I5:M5) -> 0 | T5: =SUM(O5:S5) -> 0 | V5: 1 | Z5: =SUM(U5:Y5) -> 1 | AF5: =SUM(AA5:AE5) -> 0 | AL5: =SUM(AG5:AK5) -> 0 | AR5: =SUM(AM5:AQ5) -> 0 | AX5: =SUM(AS5:AW5) -> 0 | BD5: =SUM(AY5:BC5) -> 0
A6: Caixas separadas para classificação | B6: 5 | H6: =SUM(C6:G6) -> 0 | N6: =SUM(I6:M6) -> 0 | T6: =SUM(O6:S6) -> 0 | Z6: =SUM(U6:Y6) -> 0 | AF6: =SUM(AA6:AE6) -> 0 | AL6: =SUM(AG6:AK6) -> 0 | AR6: =SUM(AM6:AQ6) -> 0 | AX6: =SUM(AS6:AW6) -> 0 | BD6: =SUM(AY6:BC6) -> 0
A7: Processos/Documentos classificados | B7: 6 | H7: =SUM(C7:G7) -> 0 | N7: =SUM(I7:M7) -> 0 | T7: =SUM(O7:S7) -> 0 | Z7: =SUM(U7:Y7) -> 0 | AF7: =SUM(AA7:AE7) -> 0 | AL7: =SUM(AG7:AK7) -> 0 | AR7: =SUM(AM7:AQ7) -> 0 | AX7: =SUM(AS7:AW7) -> 0 | BD7: =SUM(AY7:BC7) -> 0
A8: Caixas separadas para eliminação | B8: 7 | H8: =SUM(C8:G8) -> 0 | N8: =SUM(I8:M8) -> 0 | T8: =SUM(O8:S8) -> 0 | Z8: =SUM(U8:Y8) -> 0 | AF8: =SUM(AA8:AE8) -> 0 | AL8: =SUM(AG8:AK8) -> 0 | AR8: =SUM(AM8:AQ8) -> 0 | AX8: =SUM(AS8:AW8) -> 0 | BD8: =SUM(AY8:BC8) -> 0
A9: Caixas listadas para eliminação | B9: 8 | H9: =SUM(C9:G9) -> 0 | N9: =SUM(I9:M9) -> 0 | T9: =SUM(O9:S9) -> 0 | Z9: =SUM(U9:Y9) -> 0 | AF9: =SUM(AA9:AE9) -> 0 | AL9: =SUM(AG9:AK9) -> 0 | AR9: =SUM(AM9:AQ9) -> 0 | AX9: =SUM(AS9:AW9) -> 0 | BD9: =SUM(AY9:BC9) -> 0
A10: Processos/Documentos listados para eliminação | B10: 9 | H10: =SUM(C10:G10) -> 0 | N10: =SUM(I10:M10) -> 0 | T10: =SUM(O10:S10) -> 0 | Z10: =SUM(U10:Y10) -> 0 | AF10: =SUM(AA10:AE10) -> 0 | AL10: =SUM(AG10:AK10) -> 0 | AR10: =SUM(AM10:AQ10) -> 0 | AX10: =SUM(AS10:AW10) -> 0 | BD10: =SUM(AY10:BC10) -> 0
A11: Caixas inventariadas | B11: 10 | H11: =SUM(C11:G11) -> 0 | N11: =SUM(I11:M11) -> 0 | T11: =SUM(O11:S11) -> 0 | Z11: =SUM(U11:Y11) -> 0 | AF11: =SUM(AA11:AE11) -> 0 | AL11: =SUM(AG11:AK11) -> 0 | AR11: =SUM(AM11:AQ11) -> 0 | AX11: =SUM(AS11:AW11) -> 0 | BD11: =SUM(AY11:BC11) -> 0
A12: Processos/documentos inventariados | B12: 11 | H12: =SUM(C12:G12) -> 0 | N12: =SUM(I12:M12) -> 0 | T12: =SUM(O12:S12) -> 0 | Z12: =SUM(U12:Y12) -> 0 | AF12: =SUM(AA12:AE12) -> 0 | AL12: =SUM(AG12:AK12) -> 0 | AR12: =SUM(AM12:AQ12) -> 0 | AX12: =SUM(AS12:AW12) -> 0 | BD12: =SUM(AY12:BC12) -> 0
A13: Documentos administrativos produzidos (Despacho, Nota Técnica, minutas diversas) | B13: 12 | H13: =SUM(C13:G13) -> 0 | M13: 1 | N13: =SUM(I13:M13) -> 1 | T13: =SUM(O13:S13) -> 0 | Z13: =SUM(U13:Y13) -> 0 | AF13: =SUM(AA13:AE13) -> 0 | AL13: =SUM(AG13:AK13) -> 0 | AR13: =SUM(AM13:AQ13) -> 0 | AX13: =SUM(AS13:AW13) -> 0 | BD13: =SUM(AY13:BC13) -> 0
A14: Orientação técnica / atendimentos realizados | B14: 13 | H14: =SUM(C14:G14) -> 0 | N14: =SUM(I14:M14) -> 0 | T14: =SUM(O14:S14) -> 0 | Z14: =SUM(U14:Y14) -> 0 | AF14: =SUM(AA14:AE14) -> 0 | AL14: =SUM(AG14:AK14) -> 0 | AR14: =SUM(AM14:AQ14) -> 0 | AX14: =SUM(AS14:AW14) -> 0 | BD14: =SUM(AY14:BC14) -> 0
A15: Caixas remanejadas | B15: 14 | H15: =SUM(C15:G15) -> 0 | N15: =SUM(I15:M15) -> 0 | T15: =SUM(O15:S15) -> 0 | Z15: =SUM(U15:Y15) -> 0 | AF15: =SUM(AA15:AE15) -> 0 | AL15: =SUM(AG15:AK15) -> 0 | AR15: =SUM(AM15:AQ15) -> 0 | AX15: =SUM(AS15:AW15) -> 0 | BD15: =SUM(AY15:BC15) -> 0
A16: Caixas conferidas | B16: 15 | H16: =SUM(C16:G16) -> 0 | N16: =SUM(I16:M16) -> 0 | T16: =SUM(O16:S16) -> 0 | Y16: 15 | Z16: =SUM(U16:Y16) -> 15 | AF16: =SUM(AA16:AE16) -> 0 | AL16: =SUM(AG16:AK16) -> 0 | AR16: =SUM(AM16:AQ16) -> 0 | AX16: =SUM(AS16:AW16) -> 0 | BD16: =SUM(AY16:BC16) -> 0
A17: OUTRA ATIVIDADE. QUAL? | C17: Procura de caixas para eliminação. | D17: Procura de caixas para eliminação. | E17: Procura de caixas para eliminação. | F17: Palestra no Arquivo Nacional Fomos liberados do Ponto Eletrônico. | G17: Procura de caixas para eliminação. | I17: Inventário de fotos LBA. | J17: Inventário de fotos LBA. | K17: Pesquisa e busca pelo processo 44000.006180/1997-51. | L17: Inventário de fotos LBA. | M17: Pesquisa e busca dos cadernos de protocoloda SESAN-Apoio no bloco A | O17: Inventário de fotos LBA. | P17: Inventário de fotos LBA. | Q17: video conferencia - referente ao GODOCS | R17: atestado | S17: atestado | W17: Pesquisa e busca de 30 processos do esporte | X17: Pesquisa e busca de 30 processos do esporte | Y17: Pesquisa e busca de 30 processos do esporte | AA17: fazendo um - Resumo - Pesquisa na planilha Retorno SOS | AC17: recebimento das fotos da LBA do bloco A | AD17: revisando as alterações feitas no relatoria | AE17: revisando as alterações feitas no relatoria | AG17: fazendo curso de Redação Oficial e Linguagem Simples | AH17: fazendo curso de Redação Oficial e Linguagem Simples | AI17: fazendo curso de Redação Oficial e Linguagem Simples | AJ17: fazendo curso de Redação Oficial e Linguagem Simples | AK17: fazendo curso de Redação Oficial e Linguagem Simples
A18: OBSERVAÇÃO | O18: Mexendo com o sistema GOLDOCS | P18: Mexendo com o sistema GOLDOCS | Q18: Pesquisa e busca processo 23132.000438/95-22 FUNDESPORTE. | W18: Busca por caixas de fotos LBA. - Total: 14 caixas

Sheet Danilo
A1: INDICADORES | C1: 45873 | D1: 45874 | E1: 45875 | F1: 45876 | G1: 45877 | H1: TOTAL SEMANA | I1: 45880 | J1: 45881 | K1: 45882 | L1: 45883 | M1: 45884 | N1: TOTAL SEMANA | O1: 45887 | P1: 45888 | Q1: 45889 | R1: 45890 | S1: 45891 | T1: TOTAL SEMANA | U1: 45894 | V1: 45895 | W1: 45896 | X1: 45897 | Y1: 45898 | Z1: TOTAL SEMANA | AA1: 45901 | AB1: 45902 | AC1: 45903 | AD1: 45904 | AE1: 45905 | AF1: TOTAL SEMANA | AG1: 45908 | AH1: 45909 | AI1: 45910 | AJ1: 45911 | AK1: 45912 | AL1: TOTAL SEMANA | AM1: 45915 | AN1: 45916 | AO1: 45917 | AP1: 45918 | AQ1: 45919 | AR1: TOTAL SEMANA | AS1: 45922 | AT1: 45923 | AU1: 45924 | AV1: 45925 | AW1: 45926 | AX1: TOTAL SEMANA | AY1: 45929 | AZ1: 45930 | BA1: 45931 | BB1: 45932 | BC1: 45933 | BD1: TOTAL SEMANA
A2: Desarquivamento de Processos/Documentos - Saída de Guia Fora | B2: 1 | H2: =SUM(C2:G2) -> 0 | N2: =SUM(I2:M2) -> 0 | T2: =SUM(O2:S2) -> 0 | Z2: =SUM(U2:Y2) -> 0 | AF2: =SUM(AA2:AE2) -> 0 | AL2: =SUM(AG2:AK2) -> 0 | AR2: =SUM(AM2:AQ2) -> 0 | AX2: =SUM(AS2:AW2) -> 0 | BD2: =SUM(AY2:BC2) -> 0
A3: Caixas consultadas em pesquisa de desarquivamento | B3: 2 | H3: =SUM(C3:G3) -> 0 | N3: =SUM(I3:M3) -> 0 | O3: 5 | T3: =SUM(O3:S3) -> 5 | Z3: =SUM(U3:Y3) -> 0 | AF3: =SUM(AA3:AE3) -> 0 | AL3: =SUM(AG3:AK3) -> 0 | AR3: =SUM(AM3:AQ3) -> 0 | AX3: =SUM(AS3:AW3) -> 0 | BD3: =SUM(AY3:BC3) -> 0
A4: Retorno de Processos/Documentos Desarquivados | B4: 3 | H4: =SUM(C4:G4) -> 0 | N4: =SUM(I4:M4) -> 0 | T4: =SUM(O4:S4) -> 0 | Z4: =SUM(U4:Y4) -> 0 | AF4: =SUM(AA4:AE4) -> 0 | AL4: =SUM(AG4:AK4) -> 0 | AR4: =SUM(AM4:AQ4) -> 0 | AX4: =SUM(AS4:AW4) -> 0 | BD4: =SUM(AY4:BC4) -> 0
A5: Recebimento de Documentos - Guia de Transferência | B5: 4 | H5: =SUM(C5:G5) -> 0 | N5: =SUM(I5:M5) -> 0 | T5: =SUM(O5:S5) -> 0 | Z5: =SUM(U5:Y5) -> 0 | AF5: =SUM(AA5:AE5) -> 0 | AL5: =SUM(AG5:AK5) -> 0 | AR5: =SUM(AM5:AQ5) -> 0 | AX5: =SUM(AS5:AW5) -> 0 | BD5: =SUM(AY5:BC5) -> 0
A6: Caixas separadas para classificação | B6: 5 | H6: =SUM(C6:G6) -> 0 | N6: =SUM(I6:M6) -> 0 | T6: =SUM(O6:S6) -> 0 | Z6: =SUM(U6:Y6) -> 0 | AF6: =SUM(AA6:AE6) -> 0 | AL6: =SUM(AG6:AK6) -> 0 | AR6: =SUM(AM6:AQ6) -> 0 | AX6: =SUM(AS6:AW6) -> 0 | BD6: =SUM(AY6:BC6) -> 0
A7: Processos/Documentos classificados | B7: 6 | H7: =SUM(C7:G7) -> 0 | N7: =SUM(I7:M7) -> 0 | T7: =SUM(O7:S7) -> 0 | Z7: =SUM(U7:Y7) -> 0 | AF7: =SUM(AA7:AE7) -> 0 | AL7: =SUM(AG7:AK7) -> 0 | AR7: =SUM(AM7:AQ7) -> 0 | AX7: =SUM(AS7:AW7) -> 0 | BD7: =SUM(AY7:BC7) -> 0
A8: Caixas separadas para eliminação | B8: 7 | H8: =SUM(C8:G8) -> 0 | N8: =SUM(I8:M8) -> 0 | T8: =SUM(O8:S8) -> 0 | Z8: =SUM(U8:Y8) -> 0 | AF8: =SUM(AA8:AE8) -> 0 | AL8: =SUM(AG8:AK8) -> 0 | AR8: =SUM(AM8:AQ8) -> 0 | AX8: =SUM(AS8:AW8) -> 0 | BD8: =SUM(AY8:BC8) -> 0
A9: Caixas listadas para eliminação | B9: 8 | H9: =SUM(C9:G9) -> 0 | N9: =SUM(I9:M9) -> 0 | T9: =SUM(O9:S9) -> 0 | Z9: =SUM(U9:Y9) -> 0 | AF9: =SUM(AA9:AE9) -> 0 | AL9: =SUM(AG9:AK9) -> 0 | AR9: =SUM(AM9:AQ9) -> 0 | AX9: =SUM(AS9:AW9) -> 0 | BD9: =SUM(AY9:BC9) -> 0
A10: Processos/Documentos listados para eliminação | B10: 9 | H10: =SUM(C10:G10) -> 0 | N10: =SUM(I10:M10) -> 0 | T10: =SUM(O10:S10) -> 0 | Z10: =SUM(U10:Y10) -> 0 | AF10: =SUM(AA10:AE10) -> 0 | AL10: =SUM(AG10:AK10) -> 0 | AR10: =SUM(AM10:AQ10) -> 0 | AX10: =SUM(AS10:AW10) -> 0 | BD10: =SUM(AY10:BC10) -> 0
A11: Caixas inventariadas | B11: 10 | H11: =SUM(C11:G11) -> 0 | N11: =SUM(I11:M11) -> 0 | T11: =SUM(O11:S11) -> 0 | Z11: =SUM(U11:Y11) -> 0 | AF11: =SUM(AA11:AE11) -> 0 | AL11: =SUM(AG11:AK11) -> 0 | AR11: =SUM(AM11:AQ11) -> 0 | AX11: =SUM(AS11:AW11) -> 0 | BD11: =SUM(AY11:BC11) -> 0
A12: Processos/documentos inventariados | B12: 11 | H12: =SUM(C12:G12) -> 0 | N12: =SUM(I12:M12) -> 0 | T12: =SUM(O12:S12) -> 0 | Z12: =SUM(U12:Y12) -> 0 | AF12: =SUM(AA12:AE12) -> 0 | AL12: =SUM(AG12:AK12) -> 0 | AR12: =SUM(AM12:AQ12) -> 0 | AX12: =SUM(AS12:AW12) -> 0 | BD12: =SUM(AY12:BC12) -> 0
A13: Documentos administrativos produzidos (Despacho, Nota Técnica, minutas diversas) | B13: 12 | H13: =SUM(C13:G13) -> 0 | N13: =SUM(I13:M13) -> 0 | O13: 1 | T13: =SUM(O13:S13) -> 1 | Z13: =SUM(U13:Y13) -> 0 | AF13: =SUM(AA13:AE13) -> 0 | AL13: =SUM(AG13:AK13) -> 0 | AR13: =SUM(AM13:AQ13) -> 0 | AX13: =SUM(AS13:AW13) -> 0 | BD13: =SUM(AY13:BC13) -> 0
A14: Orientação técnica / atendimentos realizados | B14: 13 | H14: =SUM(C14:G14) -> 0 | N14: =SUM(I14:M14) -> 0 | T14: =SUM(O14:S14) -> 0 | Z14: =SUM(U14:Y14) -> 0 | AF14: =SUM(AA14:AE14) -> 0 | AL14: =SUM(AG14:AK14) -> 0 | AR14: =SUM(AM14:AQ14) -> 0 | AX14: =SUM(AS14:AW14) -> 0 | BD14: =SUM(AY14:BC14) -> 0
A15: Caixas remanejadas | B15: 14 | H15: =SUM(C15:G15) -> 0 | N15: =SUM(I15:M15) -> 0 | T15: =SUM(O15:S15) -> 0 | Z15: =SUM(U15:Y15) -> 0 | AF15: =SUM(AA15:AE15) -> 0 | AL15: =SUM(AG15:AK15) -> 0 | AR15: =SUM(AM15:AQ15) -> 0 | AX15: =SUM(AS15:AW15) -> 0 | BD15: =SUM(AY15:BC15) -> 0
A16: Caixas conferidas | B16: 15 | H16: =SUM(C16:G16) -> 0 | N16: =SUM(I16:M16) -> 0 | T16: =SUM(O16:S16) -> 0 | Z16: =SUM(U16:Y16) -> 0 | AF16: =SUM(AA16:AE16) -> 0 | AL16: =SUM(AG16:AK16) -> 0 | AR16: =SUM(AM16:AQ16) -> 0 | AX16: =SUM(AS16:AW16) -> 0 | BD16: =SUM(AY16:BC16) -> 0
A17: OUTRA ATIVIDADE. QUAL? | C17: Procura de caixas para eliminação. | D17: Procura de caixas para eliminação. | E17: Procura de caixas para eliminação. | F17: Palestra no Arquivo Nacional Fomos liberados do Ponto Eletrônico. | G17: Pesquisa e busca pelo processo 71000.004542/2005-12 (SESAN) | I17: Pesquisa e busca pelo processo 71000.004542/2005-12 (SESAN) Não encontrado registro de entrada neste arquivo. | J17: Pesquisa e busca pelo processo 44000.006180/1997-51 | K17: 1. Pesquisa e busca pelo processo 44000.006180/1997-51. 2. Pesquisa e busca pela pasta funcional - DYLENY TEIXEIRA ALVES DA SILVA | L17: Inventário de fotos LBA. | M17: Pesquisa e busca dos cadernos de protocoloda SESAN-Apoio no bloco A | O17: Inventário de fotos LBA. | P17: Inventário de Fotos LBA | Q17: Inventário de Fotos LBA | R17: Inventário de Fotos LBA | S17: Inventário de Fotos LBA | U17: Inventário de fotos LBA. | V17: Inventário de Fotos LBA | W17: Inventário de Fotos LBA | X17: Inventário de Fotos LBA | Y17: Inventário de Fotos LBA | AA17: Inventário de fotos LBA. | AB17: AFASTAMENTO POR MOTIVO DE SAÚDE | AC17: NÃO HOUVE ATIVIDADES COM INVENTÁRIO DE FOTOS: MOTIVOS DE SAÚDE | AD17: NÃO HOUVE ATIVIDADES COM INVENTÁRIO DE FOTOS: MOTIVOS DE SAÚDE | AE17: Inventário de fotos em planilha. | AG17: Inventário de fotos LBA. | AH17: Inventário de fotos LBA. | AI17: Inventário de fotos LBA. | AJ17: Inventário de fotos LBA. | AK17: Inventário de fotos LBA. | AM17: Inventário de Fotos LBA | AN17: Inventário de Fotos LBA | AO17: Inventário de Fotos LBA | AP17: Inventário de Fotos LBA | AQ17: INVETARIO DE SLIDES DA LBA | AS17: INVETARIO DE SLIDES DA LBA | AT17: INVETARIO DE SLIDES DA LBA | AU17: INVETARIO DE SLIDES DA LBA | AV17: RECEBIMENTO DE 140 CAIXAS | AW17: ENTREGANDO AS DOCUMENTAÇÃO DA EMPRESA NOVA | AY17: Conversa entre os terceirizados sobre a demanda da apostila que a Patrícia entregou. Resultado: Microfilmes somente resultado total; Mapas não foi possível devido serem anexos de processos; Fotos conseguiremos dar o resultado; Contagem das caixas total do Acervo conseguiremos. | AZ17: 1. Confraternização: Aniversário 2. Reunião com a chefe Patrícia para tratar dos tópicos da apostila. 3. Entreguei o resultado total de microfilmes e fotos da LBA, que constam nas planilhas, para a Patrícia. | BA17: Conferência caixas do DEFNAS. | BB17: Conferência caixas do DEFNAS. | BC17: 1. Conferência caixas do DEFNAS. 2. Pesquisa e busca por processos DEFNAS.
A18: OBSERVAÇÃO | AH18: PROCURANDO O PROCESSO DA LBA | AI18: PROCURANDO O PROCESSO DA LBA

Sheet Marcos
A1: INDICADORES | C1: 45873 | D1: 45874 | E1: 45875 | F1: 45876 | G1: 45877 | H1: TOTAL SEMANA | I1: 45880 | J1: 45881 | K1: 45882 | L1: 45883 | M1: 45884 | N1: TOTAL SEMANA | O1: 45887 | P1: 45888 | Q1: 45889 | R1: 45890 | S1: 45891 | T1: TOTAL SEMANA | U1: 45894 | V1: 45895 | W1: 45896 | X1: 45897 | Y1: 45898 | Z1: TOTAL SEMANA | AA1: 45901 | AB1: 45902 | AC1: 45903 | AD1: 45904 | AE1: 45905 | AF1: TOTAL SEMANA | AG1: 45908 | AH1: 45909 | AI1: 45910 | AJ1: 45911 | AK1: 45912 | AL1: TOTAL SEMANA | AM1: 45915 | AN1: 45916 | AO1: 45917 | AP1: 45918 | AQ1: 45919 | AR1: TOTAL SEMANA | AS1: 45922 | AT1: 45923 | AU1: 45924 | AV1: 45925 | AW1: 45926 | AX1: TOTAL SEMANA | AY1: 45929 | AZ1: 45930 | BA1: 45931 | BB1: 45932 | BC1: 45933 | BD1: TOTAL SEMANA
A2: Desarquivamento de Processos/Documentos - Saída de Guia Fora | B2: 1 | H2: =SUM(C2:G2) -> 0 | N2: =SUM(I2:M2) -> 0 | T2: =SUM(O2:S2) -> 0 | Z2: =SUM(U2:Y2) -> 0 | AF2: =SUM(AA2:AE2) -> 0 | AL2: =SUM(AG2:AK2) -> 0 | AR2: =SUM(AM2:AQ2) -> 0 | AX2: =SUM(AS2:AW2) -> 0 | BD2: =SUM(AY2:BC2) -> 0
A3: Caixas consultadas em pesquisa de desarquivamento | B3: 2 | H3: =SUM(C3:G3) -> 0 | N3: =SUM(I3:M3) -> 0 | T3: =SUM(O3:S3) -> 0 | Z3: =SUM(U3:Y3) -> 0 | AF3: =SUM(AA3:AE3) -> 0 | AL3: =SUM(AG3:AK3) -> 0 | AR3: =SUM(AM3:AQ3) -> 0 | AX3: =SUM(AS3:AW3) -> 0 | BD3: =SUM(AY3:BC3) -> 0
A4: Retorno de Processos/Documentos Desarquivados | B4: 3 | H4: =SUM(C4:G4) -> 0 | N4: =SUM(I4:M4) -> 0 | T4: =SUM(O4:S4) -> 0 | Z4: =SUM(U4:Y4) -> 0 | AF4: =SUM(AA4:AE4) -> 0 | AL4: =SUM(AG4:AK4) -> 0 | AR4: =SUM(AM4:AQ4) -> 0 | AX4: =SUM(AS4:AW4) -> 0 | BD4: =SUM(AY4:BC4) -> 0
A5: Recebimento de Documentos - Guia de Transferência | B5: 4 | H5: =SUM(C5:G5) -> 0 | N5: =SUM(I5:M5) -> 0 | T5: =SUM(O5:S5) -> 0 | Z5: =SUM(U5:Y5) -> 0 | AF5: =SUM(AA5:AE5) -> 0 | AL5: =SUM(AG5:AK5) -> 0 | AR5: =SUM(AM5:AQ5) -> 0 | AX5: =SUM(AS5:AW5) -> 0 | BD5: =SUM(AY5:BC5) -> 0
A6: Caixas separadas para classificação | B6: 5 | H6: =SUM(C6:G6) -> 0 | N6: =SUM(I6:M6) -> 0 | T6: =SUM(O6:S6) -> 0 | Z6: =SUM(U6:Y6) -> 0 | AF6: =SUM(AA6:AE6) -> 0 | AL6: =SUM(AG6:AK6) -> 0 | AR6: =SUM(AM6:AQ6) -> 0 | AX6: =SUM(AS6:AW6) -> 0 | BD6: =SUM(AY6:BC6) -> 0
A7: Processos/Documentos classificados | B7: 6 | H7: =SUM(C7:G7) -> 0 | N7: =SUM(I7:M7) -> 0 | T7: =SUM(O7:S7) -> 0 | Z7: =SUM(U7:Y7) -> 0 | AF7: =SUM(AA7:AE7) -> 0 | AL7: =SUM(AG7:AK7) -> 0 | AR7: =SUM(AM7:AQ7) -> 0 | AX7: =SUM(AS7:AW7) -> 0 | BD7: =SUM(AY7:BC7) -> 0
A8: Caixas separadas para eliminação | B8: 7 | H8: =SUM(C8:G8) -> 0 | N8: =SUM(I8:M8) -> 0 | T8: =SUM(O8:S8) -> 0 | Z8: =SUM(U8:Y8) -> 0 | AF8: =SUM(AA8:AE8) -> 0 | AL8: =SUM(AG8:AK8) -> 0 | AR8: =SUM(AM8:AQ8) -> 0 | AX8: =SUM(AS8:AW8) -> 0 | BD8: =SUM(AY8:BC8) -> 0
A9: Caixas listadas para eliminação | B9: 8 | H9: =SUM(C9:G9) -> 0 | N9: =SUM(I9:M9) -> 0 | T9: =SUM(O9:S9) -> 0 | Z9: =SUM(U9:Y9) -> 0 | AF9: =SUM(AA9:AE9) -> 0 | AL9: =SUM(AG9:AK9) -> 0 | AR9: =SUM(AM9:AQ9) -> 0 | AX9: =SUM(AS9:AW9) -> 0 | BD9: =SUM(AY9:BC9) -> 0
A10: Processos/Documentos listados para eliminação | B10: 9 | H10: =SUM(C10:G10) -> 0 | N10: =SUM(I10:M10) -> 0 | T10: =SUM(O10:S10) -> 0 | Z10: =SUM(U10:Y10) -> 0 | AF10: =SUM(AA10:AE10) -> 0 | AL10: =SUM(AG10:AK10) -> 0 | AR10: =SUM(AM10:AQ10) -> 0 | AX10: =SUM(AS10:AW10) -> 0 | BD10: =SUM(AY10:BC10) -> 0
A11: Caixas inventariadas | B11: 10 | H11: =SUM(C11:G11) -> 0 | N11: =SUM(I11:M11) -> 0 | T11: =SUM(O11:S11) -> 0 | Z11: =SUM(U11:Y11) -> 0 | AF11: =SUM(AA11:AE11) -> 0 | AL11: =SUM(AG11:AK11) -> 0 | AR11: =SUM(AM11:AQ11) -> 0 | AX11: =SUM(AS11:AW11) -> 0 | BD11: =SUM(AY11:BC11) -> 0
