Workbook

Sheet Marcelo
A1: INDICADORES | C1: 45659 | D1: 45660 | E1: TOTAL SEMANA | F1: 45663 | G1: 45664 | H1: 45665 | I1: 45666 | J1: 45667 | K1: TOTAL SEMANA | L1: 45670 | M1: 45671 | N1: 45672 | O1: 45673 | P1: 45674 | Q1: TOTAL SEMANA | R1: 45675 | S1: 45677 | T1: 45678 | U1: 45679 | V1: 45680 | W1: 45681 | X1: TOTAL SEMANA | Y1: 45684 | Z1: 45685 | AA1: 45686 | AB1: 45687 | AC1: 45688 | AD1: TOTAL SEMANA | AE1: 45691 | AF1: 45692 | AG1: 45693 | AH1: 45694 | AI1: 45695 | AJ1: TOTAL SEMANA | AK1: 45698 | AL1: 45699 | AM1: 45700 | AN1: 45701 | AO1: 45702 | AP1: TOTAL SEMANA | AQ1: 45705 | AR1: 45706 | AS1: 45707 | AT1: 45708 | AU1: 45709 | AV1: TOTAL SEMANA | AW1: 45712 | AX1: 45713 | AY1: 45714 | AZ1: 45715 | BA1: 45716 | BB1: TOTAL SEMANA | BC1: 45721 | BD1: 45722 | BE1: 45723 | BF1: TOTAL SEMANA | BG1: 45726 | BH1: 45727 | BI1: 45728 | BJ1: 45729 | BK1: 45730 | BL1: TOTAL SEMANA | BM1: 45733 | BN1: 45734 | BO1: 45735 | BP1: 45736 | BQ1: 45737 | BR1: TOTAL SEMANA | BS1: 45740 | BT1: 45741 | BU1: 45742 | BV1: 45743 | BW1: 45744 | BX1: TOTAL SEMANA | BY1: 45747 | BZ1: 45748 | CA1: 45749 | CB1: 45750 | CC1: 45751 | CD1: TOTAL SEMANA
A2: Desarquivamento de Processos/Documentos - Saída de Guia Fora | B2: 1
A3: Caixas consultadas em pesquisa de desarquivamento | B3: 2
A4: Retorno de Processos/Documentos Desarquivados | B4: 3
A5: Recebimento de Documentos - Guia de Transferência | B5: 4 | AU5: 1
A6: Caixas separadas para classificação | B6: 5
A7: Processos/Documentos classificados | B7: 6
A8: Caixas separadas para eliminação | B8: 7 | BX8: =SUM(BS8:BW8) -> 0 | CD8: =SUM(BY8:CC8) -> 0
A9: Caixas listadas para eliminação | B9: 8 | BR9: =SUM(BM9:BQ9) -> 0 | BX9: =SUM(BS9:BW9) -> 0 | CD9: =SUM(BY9:CC9) -> 0
A10: Processos/Documentos listados para eliminação | B10: 9 | BR10: =SUM(BM10:BQ10) -> 0 | BX10: =SUM(BS10:BW10) -> 0 | CD10: =SUM(BY10:CC10) -> 0
A11: Caixas inventariadas | B11: 10 | BR11: =SUM(BM11:BQ11) -> 0 | BX11: =SUM(BS11:BW11) -> 0 | CD11: =SUM(BY11:CC11) -> 0
A12: Processos/documentos inventariados | B12: 11
A13: Documentos administrativos produzidos (Despacho, Nota Técnica, minutas diversas) | B13: 12 | D13: 1 | E13: =SUM(C13:D13) -> 1 | F13: 3 | G13: 1 | O13: 1 | T13: 1 | Z13: 2 | AB13: 4 | AC13: 1 | AE13: 1 | AH13: 2 | AI13: 1 | AK13: 1 | AN13: 1 | AQ13: 7 | AR13: 1 | AS13: 1 | AW13: 4 | AY13: 1
A14: Orientação técnica / atendimentos realizados | B14: 13 | E14: =SUM(C14:D14) -> 0 | AK14: 1 | AT14: 1
A15: Caixas remanejadas | B15: 14
A16: Caixas conferidas | B16: 15
A17: OUTRA ATIVIDADE. QUAL?
A18: OBSERVAÇÃO | V18: retirada das divisórias com estantes embutidas da Sala 3.25 (Dnit) | AS18: Reunião com Min da Prev (devolução das cx da Ouvidoria) | AT18: resposta à pesquisadora da LBA por e-mail | AW18: Despacho SEI nº 16595682 feito / Conferência da Guia de Transferência 16582022 | AX18: Inserção da Guia de Transf 16582022 na planilha de controle | BA18: Supervisão da conferênica das caixas da Ouvidoria do MPS | BM18: Elaboração de rotinas de recebimento de Guia de Transf e de retorno de Guia Fora, Conferência de retorno de Guia Fora

Sheet Patrícia
A1: INDICADORES | C1: 45659 | D1: 45660 | E1: TOTAL SEMANA | F1: 45663 | G1: 45664 | H1: 45665 | I1: 45666 | J1: 45667 | K1: TOTAL SEMANA | L1: 45670 | M1: 45671 | N1: 45672 | O1: 45673 | P1: 45674 | Q1: TOTAL SEMANA | R1: 45675 | S1: 45677 | T1: 45678 | U1: 45679 | V1: 45680 | W1: 45681 | X1: TOTAL SEMANA | Y1: 45684 | Z1: 45685 | AA1: 45686 | AB1: 45687 | AC1: 45688 | AD1: TOTAL SEMANA | AE1: 45691 | AF1: 45692 | AG1: 45693 | AH1: 45694 | AI1: 45695 | AJ1: TOTAL SEMANA | AK1: 45698 | AL1: 45699 | AM1: 45700 | AN1: 45701 | AO1: 45702 | AP1: TOTAL SEMANA | AQ1: 45705 | AR1: 45706 | AS1: 45707 | AT1: 45708 | AU1: 45709 | AV1: TOTAL SEMANA | AW1: 45712 | AX1: 45713 | AY1: 45714 | AZ1: 45715 | BA1: 45716 | BB1: TOTAL SEMANA | BC1: 45721 | BD1: 45722 | BE1: 45723 | BF1: TOTAL SEMANA | BG1: 45726 | BH1: 45727 | BI1: 45728 | BJ1: 45729 | BK1: 45730 | BL1: TOTAL SEMANA | BM1: 45733 | BN1: 45734 | BO1: 45735 | BP1: 45736 | BQ1: 45737 | BR1: TOTAL SEMANA | BS1: 45740 | BT1: 45741 | BU1: 45742 | BV1: 45743 | BW1: 45744 | BX1: TOTAL SEMANA | BY1: 45747 | BZ1: 45748 | CA1: 45749 | CB1: 45750 | CC1: 45751 | CD1: TOTAL SEMANA
A2: Desarquivamento de Processos/Documentos - Saída de Guia Fora | B2: 1
A3: Caixas consultadas em pesquisa de desarquivamento | B3: 2
A4: Retorno de Processos/Documentos Desarquivados | B4: 3
A5: Recebimento de Documentos - Guia de Transferência | B5: 4
A6: Caixas separadas para classificação | B6: 5
A7: Processos/Documentos classificados | B7: 6
A8: Caixas separadas para eliminação | B8: 7 | BX8: =SUM(BS8:BW8) -> 0 | CD8: =SUM(BY8:CC8) -> 0
A9: Caixas listadas para eliminação | B9: 8 | BR9: =SUM(BM9:BQ9) -> 0 | BX9: =SUM(BS9:BW9) -> 0 | CD9: =SUM(BY9:CC9) -> 0
A10: Processos/Documentos listados para eliminação | B10: 9 | BR10: =SUM(BM10:BQ10) -> 0 | BX10: =SUM(BS10:BW10) -> 0 | CD10: =SUM(BY10:CC10) -> 0
A11: Caixas inventariadas | B11: 10 | BF11: =SUM(BC11:BE11) -> 0 | BR11: =SUM(BM11:BQ11) -> 0 | BX11: =SUM(BS11:BW11) -> 0 | CD11: =SUM(BY11:CC11) -> 0
A12: Processos/documentos inventariados | B12: 11 | BF12: =SUM(BC12:BE12) -> 0
A13: Documentos administrativos produzidos (Despacho, Nota Técnica, minutas diversas) | B13: 12
A14: Orientação técnica / atendimentos realizados | B14: 13 | AC14: 1 | AD14: =SUM(Y14:AC14) -> 1 | AH14: 1 | AT14: 1
A15: Caixas remanejadas | B15: 14 | BF15: =SUM(BC15:BE15) -> 0
A16: Caixas conferidas | B16: 15
A17: OUTRA ATIVIDADE. QUAL?
A18: OBSERVAÇÃO | AC18: Resposta a demanda de desarquivamento realizada por meio do SEI nº 16489491 | AH18: Resposta a demanda de desarquivamento realizada por meio do SEI nº 16512241 | AS18: Reunião com Min da Prev (devolução das cx da Ouvidoria) | AT18: resposta à pesquisadora da LBA por e-mail

Sheet TOTAL
A1: INDICADORES | B1: Fonte | C1: 02/01 a 03/01/2025 | D1: 06/01 a 10/01/2025 | E1: 13/01 a 17/01/2025 | F1: 20/01/ a 24/01/2025 | G1: 27/01 a 31/01/2025 | H1: 03/02 a 07/02/2025 | I1: 10/02 a 14/02/2025 | J1: 17/02 a 21/02/2025 | K1: 24/02 a 28/02/2025 | L1: 05/03 a 07/03/2025 | M1: 10/03 a 14/03/2025 | N1: 17/03 a 21/03/2025 | O1: 24/03 a 28/03/2025 | P1: 31/03 a 04/04/2025 | Q1: 07/04 a 11/04/2025 | R1: 14/04 a 18/04/2025 | S1: 21/04 a 25/04/2025 | T1: 28/04 a 02/05/2025 | U1: 05/05 a 09/05/2025 | V1: 12/05 a 16/05/2025 | W1: 19/05 a 23/05/2025 | X1: 26/05 a 30/05/2025
A2: Desarquivamento de Processos/Documentos - Saída de Guia Fora | B2: SEI | D2: 2 | E2: 1 | H2: 2 | I2: 1 | J2: 1 | O2: =Marcelo!BX2+Patrícia!BX2+Diego!BX2+Aelton!BX2+Leonam!BX2+Danilo!BX2+Marcos!BX2+Carlos!BX2 -> 0 | P2: =Marcelo!CD2+Patrícia!CD2+Diego!CD2+Aelton!CD2+Leonam!CD2+Danilo!CD2+Marcos!CD2+Carlos!CD2+Alessandro!G2 -> 0 | Q2: =Marcelo!CJ2+Patrícia!CJ2+Diego!CJ2+Aelton!CJ2+Leonam!CJ2+Danilo!CJ2+Marcos!CJ2+Carlos!CJ2+Alessandro!M2 -> 0 | R2: =Marcelo!CP2+Patrícia!CP2+Diego!CP2+Aelton!CP2+Leonam!CP2+Danilo!CP2+Marcos!CP2+Carlos!CP2+Alessandro!S2 -> 3 | S2: =Marcelo!CV2+Patrícia!CV2+Diego!CV2+Aelton!CV2+Leonam!CV2+Danilo!CV2+Marcos!CV2+Carlos!CV2+Alessandro!Y2 -> 0 | T2: =Marcelo!DB2+Patrícia!DB2+Diego!DB2+Aelton!DB2+Leonam!DB2+Danilo!DB2+Marcos!DB2+Carlos!DB2+Alessandro!AE2 -> 1 | U2: 2 | V2: 2 | W2: =Marcelo!DT2+Patrícia!DT2+Diego!DT2+Aelton!DT2+Leonam!DT2+Danilo!DT2+Marcos!DT2+Carlos!DT2+Alessandro!AW2 -> 1 | X2: =Marcelo!DZ2+Patrícia!DZ2+Diego!DZ2+Aelton!DZ2+Leonam!DZ2+Danilo!DZ2+Marcos!DZ2+Carlos!DZ2+Alessandro!BC2 -> 1
A3: Caixas consultadas em pesquisa de desarquivamento | B3: CONTAGEM INDIVIDUAL (das caixas abertas para verificação de conteúdo em contexto de pesquisa para desarquivamento) | C3: =Diego!E3+Aelton!E3+Leonam!E3+Danilo!E3+Marcos!E3 -> 0 | D3: =Diego!K3+Aelton!K3+Leonam!K3+Danilo!K3+Marcos!F3 -> 0 | E3: =Diego!Q3+Aelton!Q3+Leonam!Q3+Danilo!Q3+Marcos!Q3 -> 0 | F3: =Diego!X3+Aelton!X3+Leonam!X3+Danilo!X3+Marcos!X3 -> 0 | G3: =Diego!AD3+Aelton!AD3+Leonam!AD3+Danilo!AD3+Marcos!AD3 -> 0 | H3: =Diego!AJ3+Aelton!AJ3+Leonam!AJ3+Danilo!AJ3+Marcos!AJ3+Carlos!AJ3 -> 3 | I3: =Diego!AP3+Aelton!AP3+Leonam!AP3+Danilo!AP3+Marcos!AP3+Carlos!AP3 -> 4 | J3: =Diego!AV3+Aelton!AV3+Leonam!AV3+Danilo!AV3+Marcos!AV3+Carlos!AV3 -> 0 | K3: =Diego!BB3+Aelton!BB3+Leonam!BB3+Danilo!BB3+Marcos!BB3+Carlos!BB3 -> 0 | L3: =Diego!BF3+Aelton!BF3+Leonam!BF3+Danilo!BF3+Marcos!BF3+Carlos!BF3 -> 0 | N3: =Marcelo!BR3+Patrícia!RM3+Diego!BR3+Aelton!BR3+Leonam!BR3+Danilo!BR3+Marcos!BR3+Carlos!BR3 -> 0 | O3: =Marcelo!BX3+Patrícia!BX3+Diego!BX3+Aelton!BX3+Leonam!BX3+Danilo!BX3+Marcos!BX3+Carlos!BX3 -> 0 | P3: =Marcelo!CD3+Patrícia!CD3+Diego!CD3+Aelton!CD3+Leonam!CD3+Danilo!CD3+Marcos!CD3+Carlos!CD3+Alessandro!G3 -> 37 | Q3: =Marcelo!CJ3+Patrícia!CJ3+Diego!CJ3+Aelton!CJ3+Leonam!CJ3+Danilo!CJ3+Marcos!CJ3+Carlos!CJ3++Alessandro!M3 -> 258 | R3: =Marcelo!CP3+Patrícia!CP3+Diego!CP3+Aelton!CP3+Leonam!CP3+Danilo!CP3+Marcos!CP3+Carlos!CP3+Alessandro!S3 -> 0 | S3: =Marcelo!CV3+Patrícia!CV3+Diego!CV3+Aelton!CV3+Leonam!CV3+Danilo!CV3+Marcos!CV3+Carlos!CV3+Alessandro!Y3 -> 0 | T3: =Marcelo!DB3+Patrícia!DB3+Diego!DB3+Aelton!DB3+Leonam!DB3+Danilo!DB3+Marcos!DB3+Carlos!DB3+Alessandro!AE3 -> 0 | U3: =Marcelo!DH3+Patrícia!DH3+Diego!DH3+Aelton!DH3+Leonam!DH3+Danilo!DH3+Marcos!DH3+Carlos!DH3+Alessandro!AK3 -> 0 | V3: =Marcelo!DN3+Patrícia!DN3+Diego!DN3+Aelton!DN3+Leonam!DN3+Danilo!DN3+Marcos!DN3+Carlos!DN3+Alessandro!AQ3 -> 2 | W3: =Marcelo!DT3+Patrícia!DT3+Diego!DT3+Aelton!DT3+Leonam!DT3+Danilo!DT3+Marcos!DT3+Carlos!DT3+Alessandro!AW3 -> 10 | X3: =Marcelo!DZ3+Patrícia!DZ3+Diego!DZ3+Aelton!DZ3+Leonam!DZ3+Danilo!DZ3+Marcos!DZ3+Carlos!DZ3+Alessandro!BC3 -> 1
A4: Retorno de Processos/Documentos Desarquivados | B4: SEI | D4: 1 | I4: 1 | J4: 1 | O4: =Marcelo!BX4+Patrícia!BX4+Diego!BX4+Aelton!BX4+Leonam!BX4+Danilo!BX4+Marcos!BX4+Carlos!BX4 -> 0 | P4: =Marcelo!CD4+Patrícia!CD4+Diego!CD4+Aelton!CD4+Leonam!CD4+Danilo!CD4+Marcos!CD4+Carlos!CD4+Alessandro!G4 -> 0 | Q4: =Marcelo!CJ4+Patrícia!CJ4+Diego!CJ4+Aelton!CJ4+Leonam!CJ4+Danilo!CJ4+Marcos!CJ4+Carlos!CJ4++Alessandro!M4 -> 0 | R4: =Marcelo!CP4+Patrícia!CP4+Diego!CP4+Aelton!CP4+Leonam!CP4+Danilo!CP4+Marcos!CP4+Carlos!CP4+Alessandro!S4 -> 0 | S4: =Marcelo!CV4+Patrícia!CV4+Diego!CV4+Aelton!CV4+Leonam!CV4+Danilo!CV4+Marcos!CV4+Carlos!CV4+Alessandro!Y4 -> 0 | T4: =Marcelo!DB4+Patrícia!DB4+Diego!DB4+Aelton!DB4+Leonam!DB4+Danilo!DB4+Marcos!DB4+Carlos!DB4+Alessandro!AE4 -> 4 | U4: =Marcelo!DH4+Patrícia!DH4+Diego!DH4+Aelton!DH4+Leonam!DH4+Danilo!DH4+Marcos!DH4+Carlos!DH4+Alessandro!AK4 -> 4 | V4: =Marcelo!DN4+Patrícia!DN4+Diego!DN4+Aelton!DN4+Leonam!DN4+Danilo!DN4+Marcos!DN4+Carlos!DN4+Alessandro!AQ4 -> 0 | W4: =Marcelo!DT4+Patrícia!DT4+Diego!DT4+Aelton!DT4+Leonam!DT4+Danilo!DT4+Marcos!DT4+Carlos!DT4+Alessandro!AW4 -> 2 | X4: =Marcelo!DZ4+Patrícia!DZ4+Diego!DZ4+Aelton!DZ4+Leonam!DZ4+Danilo!DZ4+Marcos!DZ4+Carlos!DZ4+Alessandro!BC4 -> 5
A5: Recebimento de Documentos - Guia de Transferência | B5: SEI | D5: 1 | E5: 1 | I5: 1 | O5: =Marcelo!BX5+Patrícia!BX5+Diego!BX5+Aelton!BX5+Leonam!BX5+Danilo!BX5+Marcos!BX5+Carlos!BX5 -> 0 | P5: =Marcelo!CD5+Patrícia!CD5+Diego!CD5+Aelton!CD5+Leonam!CD5+Danilo!CD5+Marcos!CD5+Carlos!CD5+Alessandro!G5 -> 0 | Q5: =Marcelo!CJ5+Patrícia!CJ5+Diego!CJ5+Aelton!CJ5+Leonam!CJ5+Danilo!CJ5+Marcos!CJ5+Carlos!CJ5++Alessandro!M5 -> 0 | R5: =Marcelo!CP5+Patrícia!CP5+Diego!CP5+Aelton!CP5+Leonam!CP5+Danilo!CP5+Marcos!CP5+Carlos!CP5+Alessandro!S5 -> 0 | S5: =Marcelo!CV5+Patrícia!CV5+Diego!CV5+Aelton!CV5+Leonam!CV5+Danilo!CV5+Marcos!CV5+Carlos!CV5+Alessandro!Y5 -> 0 | T5: =Marcelo!DB5+Patrícia!DB5+Diego!DB5+Aelton!DB5+Leonam!DB5+Danilo!DB5+Marcos!DB5+Carlos!DB5+Alessandro!AE5 -> 0 | U5: =Marcelo!DH5+Patrícia!DH5+Diego!DH5+Aelton!DH5+Leonam!DH5+Danilo!DH5+Marcos!DH5+Carlos!DH5+Alessandro!AK5 -> 1 | V5: =Marcelo!DN5+Patrícia!DN5+Diego!DN5+Aelton!DN5+Leonam!DN5+Danilo!DN5+Marcos!DN5+Carlos!DN5+Alessandro!AQ5 -> 0 | W5: =Marcelo!DT5+Patrícia!DT5+Diego!DT5+Aelton!DT5+Leonam!DT5+Danilo!DT5+Marcos!DT5+Carlos!DT5+Alessandro!AW5 -> 1 | X5: =Marcelo!DZ5+Patrícia!DZ5+Diego!DZ5+Aelton!DZ5+Leonam!DZ5+Danilo!DZ5+Marcos!DZ5+Carlos!DZ5+Alessandro!BC5 -> 0
A6: Caixas separadas para classificação | B6: CONTAGEM INDIVIDUAL (das caixas "puxadas" nas estantes como uma pré-seleção para classificação) | C6: =Diego!E6+Aelton!E6+Leonam!E6+Danilo!E6+Marcos!E6 -> 0 | D6: =Diego!K6+Aelton!K6+Leonam!K6+Danilo!K6+Marcos!F6 -> 0 | E6: =Diego!Q6+Aelton!Q6+Leonam!Q6+Danilo!Q6+Marcos!Q6 -> 0 | F6: =Diego!X6+Aelton!X6+Leonam!X6+Danilo!X6+Marcos!X6 -> 0 | G6: =Diego!AD6+Aelton!AD6+Leonam!AD6+Danilo!AD6+Marcos!AD6 -> 0 | H6: =Diego!AJ6+Aelton!AJ6+Leonam!AJ6+Danilo!AJ6+Marcos!AJ6+Carlos!AJ6 -> 25 | I6: =Diego!AP6+Aelton!AP6+Leonam!AP6+Danilo!AP6+Marcos!AP6+Carlos!AP6 -> 0 | J6: =Diego!AV6+Aelton!AV6+Leonam!AV6+Danilo!AV6+Marcos!AV6+Carlos!AV6 -> 0 | K6: =Diego!BB6+Aelton!BB6+Leonam!BB6+Danilo!BB6+Marcos!BB6+Carlos!BB6 -> 0 | L6: =Diego!BF6+Aelton!BF6+Leonam!BF6+Danilo!BF6+Marcos!BF6+Carlos!BF6 -> 0 | M6: =Diego!BL6+Aelton!BL6+Leonam!BL6+Danilo!BL6+Marcos!BL6+Carlos!BL6 -> 0 | N6: =Marcelo!BR6+Patrícia!RM6+Diego!BR6+Aelton!BR6+Leonam!BR6+Danilo!BR6+Marcos!BR6+Carlos!BR6 -> 0 | O6: =Marcelo!BX6+Patrícia!BX6+Diego!BX6+Aelton!BX6+Leonam!BX6+Danilo!BX6+Marcos!BX6+Carlos!BX6 -> 50 | P6: =Marcelo!CD6+Patrícia!CD6+Diego!CD6+Aelton!CD6+Leonam!CD6+Danilo!CD6+Marcos!CD6+Carlos!CD6+Alessandro!G6 -> 0 | Q6: =Marcelo!CJ6+Patrícia!CJ6+Diego!CJ6+Aelton!CJ6+Leonam!CJ6+Danilo!CJ6+Marcos!CJ6+Carlos!CJ6++Alessandro!M6 -> 14 | R6: =Marcelo!CP6+Patrícia!CP6+Diego!CP6+Aelton!CP6+Leonam!CP6+Danilo!CP6+Marcos!CP6+Carlos!CP6+Alessandro!S6 -> 0 | S6: =Marcelo!CV6+Patrícia!CV6+Diego!CV6+Aelton!CV6+Leonam!CV6+Danilo!CV6+Marcos!CV6+Carlos!CV6+Alessandro!Y6 -> 0 | T6: =Marcelo!DB6+Patrícia!DB6+Diego!DB6+Aelton!DB6+Leonam!DB6+Danilo!DB6+Marcos!DB6+Carlos!DB6+Alessandro!AE6 -> 0 | U6: =Marcelo!DH6+Patrícia!DH6+Diego!DH6+Aelton!DH6+Leonam!DH6+Danilo!DH6+Marcos!DH6+Carlos!DH6+Alessandro!AK6 -> 0 | V6: =Marcelo!DN6+Patrícia!DN6+Diego!DN6+Aelton!DN6+Leonam!DN6+Danilo!DN6+Marcos!DN6+Carlos!DN6+Alessandro!AQ6 -> 0 | W6: =Marcelo!DT6+Patrícia!DT6+Diego!DT6+Aelton!DT6+Leonam!DT6+Danilo!DT6+Marcos!DT6+Carlos!DT6+Alessandro!AW6 -> 0 | X6: =Marcelo!DZ6+Patrícia!DZ6+Diego!DZ6+Aelton!DZ6+Leonam!DZ6+Danilo!DZ6+Marcos!DZ6+Carlos!DZ6+Alessandro!BC6 -> 0
A7: Processos/Documentos classificados | B7: PLANILHA | C7: =Diego!E7+Aelton!E7+Leonam!E7+Danilo!E7+Marcos!E7 -> 0 | D7: =Diego!K7+Aelton!K7+Leonam!K7+Danilo!K7+Marcos!F7 -> 0 | E7: =Diego!Q7+Aelton!Q7+Leonam!Q7+Danilo!Q7+Marcos!Q7 -> 0 | F7: =Diego!X7+Aelton!X7+Leonam!X7+Danilo!X7+Marcos!X7 -> 0 | G7: =Diego!AD7+Aelton!AD7+Leonam!AD7+Danilo!AD7+Marcos!AD7 -> 0 | H7: =Diego!AJ7+Aelton!AJ7+Leonam!AJ7+Danilo!AJ7+Marcos!AJ7+Carlos!AJ7 -> 0 | I7: =Diego!AP7+Aelton!AP7+Leonam!AP7+Danilo!AP7+Marcos!AP7+Carlos!AP7 -> 0 | J7: =Diego!AV7+Aelton!AV7+Leonam!AV7+Danilo!AV7+Marcos!AV7+Carlos!AV7 -> 0 | K7: =Diego!BB7+Aelton!BB7+Leonam!BB7+Danilo!BB7+Marcos!BB7+Carlos!BB7 -> 0 | L7: =Diego!BF7+Aelton!BF7+Leonam!BF7+Danilo!BF7+Marcos!BF7+Carlos!BF7 -> 0 | M7: =Diego!BL7+Aelton!BL7+Leonam!BL7+Danilo!BL7+Marcos!BL7+Carlos!BL7 -> 0 | N7: =Marcelo!BR7+Patrícia!RM7+Diego!BR7+Aelton!BR7+Leonam!BR7+Danilo!BR7+Marcos!BR7+Carlos!BR7 -> 0 | O7: =Marcelo!BX7+Patrícia!BX7+Diego!BX7+Aelton!BX7+Leonam!BX7+Danilo!BX7+Marcos!BX7+Carlos!BX7 -> 405 | P7: =Marcelo!CD7+Patrícia!CD7+Diego!CD7+Aelton!CD7+Leonam!CD7+Danilo!CD7+Marcos!CD7+Carlos!CD7+Alessandro!G7 -> 86 | Q7: =Marcelo!CJ7+Patrícia!CJ7+Diego!CJ7+Aelton!CJ7+Leonam!CJ7+Danilo!CJ7+Marcos!CJ7+Carlos!CJ7++Alessandro!M7 -> 23 | R7: =Marcelo!CP7+Patrícia!CP7+Diego!CP7+Aelton!CP7+Leonam!CP7+Danilo!CP7+Marcos!CP7+Carlos!CP7+Alessandro!S7 -> 13 | S7: =Marcelo!CV7+Patrícia!CV7+Diego!CV7+Aelton!CV7+Leonam!CV7+Danilo!CV7+Marcos!CV7+Carlos!CV7+Alessandro!Y7 -> 0 | T7: =Marcelo!DB7+Patrícia!DB7+Diego!DB7+Aelton!DB7+Leonam!DB7+Danilo!DB7+Marcos!DB7+Carlos!DB7+Alessandro!AE7 -> 0 | U7: =Marcelo!DH7+Patrícia!DH7+Diego!DH7+Aelton!DH7+Leonam!DH7+Danilo!DH7+Marcos!DH7+Carlos!DH7+Alessandro!AK7 -> 0 | V7: =Marcelo!DN7+Patrícia!DN7+Diego!DN7+Aelton!DN7+Leonam!DN7+Danilo!DN7+Marcos!DN7+Carlos!DN7+Alessandro!AQ7 -> 0 | W7: =Marcelo!DT7+Patrícia!DT7+Diego!DT7+Aelton!DT7+Leonam!DT7+Danilo!DT7+Marcos!DT7+Carlos!DT7+Alessandro!AW7 -> 0 | X7: =Marcelo!DZ7+Patrícia!DZ7+Diego!DZ7+Aelton!DZ7+Leonam!DZ7+Danilo!DZ7+Marcos!DZ7+Carlos!DZ7+Alessandro!BC7 -> 88
A8: Caixas separadas para eliminação | B8: CONTAGEM INDIVIDUAL (das caixas "puxadas" nas estantes como uma pré-seleção para eliminação) | C8: =Diego!E8+Aelton!E8+Leonam!E8+Danilo!E8+Marcos!E8 -> 0 | D8: =Diego!K8+Aelton!K8+Leonam!K8+Danilo!K8+Marcos!F8 -> 0 | E8: =Diego!Q8+Aelton!Q8+Leonam!Q8+Danilo!Q8+Marcos!Q8 -> 0 | F8: =Diego!X8+Aelton!X8+Leonam!X8+Danilo!X8+Marcos!X8 -> 75 | G8: =Diego!AD8+Aelton!AD8+Leonam!AD8+Danilo!AD8+Marcos!AD8 -> 37 | H8: =Diego!AJ8+Aelton!AJ8+Leonam!AJ8+Danilo!AJ8+Marcos!AJ8+Carlos!AJ8 -> 22 | I8: =Diego!AP8+Aelton!AP8+Leonam!AP8+Danilo!AP8+Marcos!AP8+Carlos!AP8 -> 0 | J8: =Diego!AV8+Aelton!AV8+Leonam!AV8+Danilo!AV8+Marcos!AV8+Carlos!AV8 -> 119 | K8: =Diego!BB8+Aelton!BB8+Leonam!BB8+Danilo!BB8+Marcos!BB8+Carlos!BB8 -> 91 | L8: =Diego!BF8+Aelton!BF8+Leonam!BF8+Danilo!BF8+Marcos!BF8+Carlos!BF8 -> 60 | M8: =Diego!BL8+Aelton!BL8+Leonam!BL8+Danilo!BL8+Marcos!BL8+Carlos!BL8 -> 79 | N8: =Marcelo!BR8+Patrícia!RM8+Diego!BR8+Aelton!BR8+Leonam!BR8+Danilo!BR8+Marcos!BR8+Carlos!BR8 -> 219 | O8: =Marcelo!BX8+Patrícia!BX8+Diego!BX8+Aelton!BX8+Leonam!BX8+Danilo!BX8+Marcos!BX8+Carlos!BX8 -> 459 | P8: =Marcelo!CD8+Patrícia!CD8+Diego!CD8+Aelton!CD8+Leonam!CD8+Danilo!CD8+Marcos!CD8+Carlos!CD8+Alessandro!G8 -> 226 | Q8: =Marcelo!CJ8+Patrícia!CJ8+Diego!CJ8+Aelton!CJ8+Leonam!CJ8+Danilo!CJ8+Marcos!CJ8+Carlos!CJ8++Alessandro!M8 -> 24 | R8: =Marcelo!CP8+Patrícia!CP8+Diego!CP8+Aelton!CP8+Leonam!CP8+Danilo!CP8+Marcos!CP8+Carlos!CP8+Alessandro!S8 -> 35 | S8: =Marcelo!CV8+Patrícia!CV8+Diego!CV8+Aelton!CV8+Leonam!CV8+Danilo!CV8+Marcos!CV8+Carlos!CV8+Alessandro!Y8 -> 54 | T8: =Marcelo!DB8+Patrícia!DB8+Diego!DB8+Aelton!DB8+Leonam!DB8+Danilo!DB8+Marcos!DB8+Carlos!DB8+Alessandro!AE8 -> 16 | U8: =Marcelo!DH8+Patrícia!DH8+Diego!DH8+Aelton!DH8+Leonam!DH8+Danilo!DH8+Marcos!DH8+Carlos!DH8+Alessandro!AK8 -> 0 | V8: =Marcelo!DN8+Patrícia!DN8+Diego!DN8+Aelton!DN8+Leonam!DN8+Danilo!DN8+Marcos!DN8+Carlos!DN8+Alessandro!AQ8 -> 0 | W8: =Marcelo!DT8+Patrícia!DT8+Diego!DT8+Aelton!DT8+Leonam!DT8+Danilo!DT8+Marcos!DT8+Carlos!DT8+Alessandro!AW8 -> 37 | X8: =Marcelo!DZ8+Patrícia!DZ8+Diego!DZ8+Aelton!DZ8+Leonam!DZ8+Danilo!DZ8+Marcos!DZ8+Carlos!DZ8+Alessandro!BC8 -> 93
A9: Caixas listadas para eliminação | B9: PLANILHA | C9: =Diego!E9+Aelton!E9+Leonam!E9+Danilo!E9+Marcos!E9 -> 0 | D9: =Diego!K9+Aelton!K9+Leonam!K9+Danilo!K9+Marcos!F9 -> 0 | E9: =Diego!Q9+Aelton!Q9+Leonam!Q9+Danilo!Q9+Marcos!Q9 -> 0 | F9: =Diego!X9+Aelton!X9+Leonam!X9+Danilo!X9+Marcos!X9 -> 55 | G9: =Diego!AD9+Aelton!AD9+Leonam!AD9+Danilo!AD9+Marcos!AD9 -> 30 | H9: =Diego!AJ9+Aelton!AJ9+Leonam!AJ9+Danilo!AJ9+Marcos!AJ9+Carlos!AJ9 -> 22 | I9: =Diego!AP9+Aelton!AP9+Leonam!AP9+Danilo!AP9+Marcos!AP9+Carlos!AP9 -> 0 | J9: =Diego!AV9+Aelton!AV9+Leonam!AV9+Danilo!AV9+Marcos!AV9+Carlos!AV9 -> 27 | K9: =Diego!BB9+Aelton!BB9+Leonam!BB9+Danilo!BB9+Marcos!BB9+Carlos!BB9 -> 73 | L9: =Diego!BF9+Aelton!BF9+Leonam!BF9+Danilo!BF9+Marcos!BF9+Carlos!BF9 -> 78 | M9: =Diego!BL9+Aelton!BL9+Leonam!BL9+Danilo!BL9+Marcos!BL9+Carlos!BL9 -> 88 | N9: =Marcelo!BR9+Patrícia!RM9+Diego!BR9+Aelton!BR9+Leonam!BR9+Danilo!BR9+Marcos!BR9+Carlos!BR9 -> 120 | O9: =Marcelo!BX9+Patrícia!BX9+Diego!BX9+Aelton!BX9+Leonam!BX9+Danilo!BX9+Marcos!BX9+Carlos!BX9 -> 100 | P9: =Marcelo!CD9+Patrícia!CD9+Diego!CD9+Aelton!CD9+Leonam!CD9+Danilo!CD9+Marcos!CD9+Carlos!CD9+Alessandro!G9 -> 149 | Q9: =Marcelo!CJ9+Patrícia!CJ9+Diego!CJ9+Aelton!CJ9+Leonam!CJ9+Danilo!CJ9+Marcos!CJ9+Carlos!CJ9++Alessandro!M9 -> 79 | R9: =Marcelo!CP9+Patrícia!CP9+Diego!CP9+Aelton!CP9+Leonam!CP9+Danilo!CP9+Marcos!CP9+Carlos!CP9+Alessandro!S9 -> 44 | S9: =Marcelo!CV9+Patrícia!CV9+Diego!CV9+Aelton!CV9+Leonam!CV9+Danilo!CV9+Marcos!CV9+Carlos!CV9+Alessandro!Y9 -> 12 | T9: =Marcelo!DB9+Patrícia!DB9+Diego!DB9+Aelton!DB9+Leonam!DB9+Danilo!DB9+Marcos!DB9+Carlos!DB9+Alessandro!AE9 -> 55 | U9: =Marcelo!DH9+Patrícia!DH9+Diego!DH9+Aelton!DH9+Leonam!DH9+Danilo!DH9+Marcos!DH9+Carlos!DH9+Alessandro!AK9 -> 32 | V9: =Marcelo!DN9+Patrícia!DN9+Diego!DN9+Aelton!DN9+Leonam!DN9+Danilo!DN9+Marcos!DN9+Carlos!DN9+Alessandro!AQ9 -> 5 | W9: =Marcelo!DT9+Patrícia!DT9+Diego!DT9+Aelton!DT9+Leonam!DT9+Danilo!DT9+Marcos!DT9+Carlos!DT9+Alessandro!AW9 -> 0 | X9: =Marcelo!DZ9+Patrícia!DZ9+Diego!DZ9+Aelton!DZ9+Leonam!DZ9+Danilo!DZ9+Marcos!DZ9+Carlos!DZ9+Alessandro!BC9 -> 11
A10: Processos/Documentos listados para eliminação | B10: PLANILHA | C10: =Diego!E10+Aelton!E10+Leonam!E10+Danilo!E10+Marcos!E10 -> 0 | D10: =Diego!K10+Aelton!K10+Leonam!K10+Danilo!K10+Marcos!F10 -> 0 | E10: =Diego!Q10+Aelton!Q10+Leonam!Q10+Danilo!Q10+Marcos!Q10 -> 0 | F10: =Diego!X10+Aelton!X10+Leonam!X10+Danilo!X10+Marcos!X10 -> 0 | G10: =Diego!AD10+Aelton!AD10+Leonam!AD10+Danilo!AD10+Marcos!AD10 -> 0 | H10: =Diego!AJ10+Aelton!AJ10+Leonam!AJ10+Danilo!AJ10+Marcos!AJ10+Carlos!AJ10 -> 0 | I10: =Diego!AP10+Aelton!AP10+Leonam!AP10+Danilo!AP10+Marcos!AP10+Carlos!AP10 -> 0 | J10: =Diego!AV10+Aelton!AV10+Leonam!AV10+Danilo!AV10+Marcos!AV10+Carlos!AV10 -> 41 | K10: =Diego!BB10+Aelton!BB10+Leonam!BB10+Danilo!BB10+Marcos!BB10+Carlos!BB10 -> 73 | L10: =Diego!BF10+Aelton!BF10+Leonam!BF10+Danilo!BF10+Marcos!BF10+Carlos!BF10 -> 78 | M10: =Diego!BL10+Aelton!BL10+Leonam!BL10+Danilo!BL10+Marcos!BL10+Carlos!BL10 -> 94 | N10: =Marcelo!BR10+Patrícia!RM10+Diego!BR10+Aelton!BR10+Leonam!BR10+Danilo!BR10+Marcos!BR10+Carlos!BR10 -> 165 | O10: =Marcelo!BX10+Patrícia!BX10+Diego!BX10+Aelton!BX10+Leonam!BX10+Danilo!BX10+Marcos!BX10+Carlos!BX10 -> 146 | P10: =Marcelo!CD10+Patrícia!CD10+Diego!CD10+Aelton!CD10+Leonam!CD10+Danilo!CD10+Marcos!CD10+Carlos!CD10+Alessandro!G10 -> 174 | Q10: =Marcelo!CJ10+Patrícia!CJ10+Diego!CJ10+Aelton!CJ10+Leonam!CJ10+Danilo!CJ10+Marcos!CJ10+Carlos!CJ10++Alessandro!M10 -> 139 | R10: =Marcelo!CP10+Patrícia!CP10+Diego!CP10+Aelton!CP10+Leonam!CP10+Danilo!CP10+Marcos!CP10+Carlos!CP10+Alessandro!S10 -> 61 | S10: =Marcelo!CV10+Patrícia!CV10+Diego!CV10+Aelton!CV10+Leonam!CV10+Danilo!CV10+Marcos!CV10+Carlos!CV10+Alessandro!Y10 -> 26 | T10: =Marcelo!DB10+Patrícia!DB10+Diego!DB10+Aelton!DB10+Leonam!DB10+Danilo!DB10+Marcos!DB10+Carlos!DB10+Alessandro!AE10 -> 45 | U10: =Marcelo!DH10+Patrícia!DH10+Diego!DH10+Aelton!DH10+Leonam!DH10+Danilo!DH10+Marcos!DH10+Carlos!DH10+Alessandro!AK10 -> 32 | V10: =Marcelo!DN10+Patrícia!DN10+Diego!DN10+Aelton!DN10+Leonam!DN10+Danilo!DN10+Marcos!DN10+Carlos!DN10+Alessandro!AQ10 -> 523 | W10: =Marcelo!DT10+Patrícia!DT10+Diego!DT10+Aelton!DT10+Leonam!DT10+Danilo!DT10+Marcos!DT10+Carlos!DT10+Alessandro!AW10 -> 0 | X10: =Marcelo!DZ10+Patrícia!DZ10+Diego!DZ10+Aelton!DZ10+Leonam!DZ10+Danilo!DZ10+Marcos!DZ10+Carlos!DZ10+Alessandro!BC10 -> 0
A11: Caixas inventariadas | B11: PLANILHA | C11: =Diego!E11+Aelton!E11+Leonam!E11+Danilo!E11+Marcos!E11 -> 0 | D11: =Diego!K11+Aelton!K11+Leonam!K11+Danilo!K11+Marcos!F11 -> 0 | E11: =Diego!Q11+Aelton!Q11+Leonam!Q11+Danilo!Q11+Marcos!Q11 -> 0 | F11: =Diego!X11+Aelton!X11+Leonam!X11+Danilo!X11+Marcos!X11 -> 70 | G11: =Diego!AD11+Aelton!AD11+Leonam!AD11+Danilo!AD11+Marcos!AD11 -> 9 | H11: =Diego!AJ11+Aelton!AJ11+Leonam!AJ11+Danilo!AJ11+Marcos!AJ11+Carlos!AJ11 -> 21 | I11: =Diego!AP11+Aelton!AP11+Leonam!AP11+Danilo!AP11+Marcos!AP11+Carlos!AP11 -> 60 | J11: =Diego!AV11+Aelton!AV11+Leonam!AV11+Danilo!AV11+Marcos!AV11+Carlos!AV11 -> 30 | K11: =Diego!BB11+Aelton!BB11+Leonam!BB11+Danilo!BB11+Marcos!BB11+Carlos!BB11 -> 40 | L11: =Diego!BF11+Aelton!BF11+Leonam!BF11+Danilo!BF11+Marcos!BF11+Carlos!BF11 -> 16 | M11: =Diego!BL11+Aelton!BL11+Leonam!BL11+Danilo!BL11+Marcos!BL11+Carlos!BL11 -> 12 | N11: =Marcelo!BR11+Patrícia!RM11+Diego!BR11+Aelton!BR11+Leonam!BR11+Danilo!BR11+Marcos!BR11+Carlos!BR11 -> 0 | O11: =Marcelo!BX11+Patrícia!BX11+Diego!BX11+Aelton!BX11+Leonam!BX11+Danilo!BX11+Marcos!BX11+Carlos!BX11 -> 40 | P11: =Marcelo!CD11+Patrícia!CD11+Diego!CD11+Aelton!CD11+Leonam!CD11+Danilo!CD11+Marcos!CD11+Carlos!CD11+Alessandro!G11 -> 71 | Q11: =Marcelo!CJ11+Patrícia!CJ11+Diego!CJ11+Aelton!CJ11+Leonam!CJ11+Danilo!CJ11+Marcos!CJ11+Carlos!CJ11++Alessandro!M11 -> 0 | R11: =Marcelo!CP11+Patrícia!CP11+Diego!CP11+Aelton!CP11+Leonam!CP11+Danilo!CP11+Marcos!CP11+Carlos!CP11+Alessandro!S11 -> 23 | S11: =Marcelo!CV11+Patrícia!CV11+Diego!CV11+Aelton!CV11+Leonam!CV11+Danilo!CV11+Marcos!CV11+Carlos!CV11+Alessandro!Y11 -> 51 | T11: =Marcelo!DB11+Patrícia!DB11+Diego!DB11+Aelton!DB11+Leonam!DB11+Danilo!DB11+Marcos!DB11+Carlos!DB11+Alessandro!AE11 -> 31 | U11: =Marcelo!DH11+Patrícia!DH11+Diego!DH11+Aelton!DH11+Leonam!DH11+Danilo!DH11+Marcos!DH11+Carlos!DH11+Alessandro!AK11 -> 32 | V11: =Marcelo!DN11+Patrícia!DN11+Diego!DN11+Aelton!DN11+Leonam!DN11+Danilo!DN11+Marcos!DN11+Carlos!DN11+Alessandro!AQ11 -> 52 | W11: =Marcelo!DT11+Patrícia!DT11+Diego!DT11+Aelton!DT11+Leonam!DT11+Danilo!DT11+Marcos!DT11+Carlos!DT11+Alessandro!AW11 -> 28 | X11: =Marcelo!DZ11+Patrícia!DZ11+Diego!DZ11+Aelton!DZ11+Leonam!DZ11+Danilo!DZ11+Marcos!DZ11+Carlos!DZ11+Alessandro!BC11 -> 32
A12: Processos/documentos inventariados | B12: PLANILHA | C12: =Diego!E12+Aelton!E12+Leonam!E12+Danilo!E12+Marcos!E12 -> 0 | D12: =Diego!K12+Aelton!K12+Leonam!K12+Danilo!K12+Marcos!F12 -> 0 | E12: =Diego!Q12+Aelton!Q12+Leonam!Q12+Danilo!Q12+Marcos!Q12 -> 0 | F12: =Diego!X12+Aelton!X12+Leonam!X12+Danilo!X12+Marcos!X12 -> 1118 | G12: =Diego!AD12+Aelton!AD12+Leonam!AD12+Danilo!AD12+Marcos!AD12 -> 122 | H12: =Diego!AJ12+Aelton!AJ12+Leonam!AJ12+Danilo!AJ12+Marcos!AJ12+Carlos!AJ12 -> 476 | I12: =Diego!AP12+Aelton!AP12+Leonam!AP12+Danilo!AP12+Marcos!AP12+Carlos!AP12 -> 1108 | J12: =Diego!AV12+Aelton!AV12+Leonam!AV12+Danilo!AV12+Marcos!AV12+Carlos!AV12 -> 579 | K12: =Diego!BB12+Aelton!BB12+Leonam!BB12+Danilo!BB12+Marcos!BB12+Carlos!BB12 -> 624 | L12: =Diego!BF12+Aelton!BF12+Leonam!BF12+Danilo!BF12+Marcos!BF12+Carlos!BF12 -> 193 | M12: =Diego!BL12+Aelton!BL12+Leonam!BL12+Danilo!BL12+Marcos!BL12+Carlos!BL12 -> 199 | N12: =Marcelo!BR12+Patrícia!RM12+Diego!BR12+Aelton!BR12+Leonam!BR12+Danilo!BR12+Marcos!BR12+Carlos!BR12 -> 0 | O12: =Marcelo!BX12+Patrícia!BX12+Diego!BX12+Aelton!BX12+Leonam!BX12+Danilo!BX12+Marcos!BX12+Carlos!BX12 -> 0 | P12: =Marcelo!CD12+Patrícia!CD12+Diego!CD12+Aelton!CD12+Leonam!CD12+Danilo!CD12+Marcos!CD12+Carlos!CD12+Alessandro!G12 -> 273 | Q12: =Marcelo!CJ12+Patrícia!CJ12+Diego!CJ12+Aelton!CJ12+Leonam!CJ12+Danilo!CJ12+Marcos!CJ12+Carlos!CJ12++Alessandro!M12 -> 0 | R12: =Marcelo!CP12+Patrícia!CP12+Diego!CP12+Aelton!CP12+Leonam!CP12+Danilo!CP12+Marcos!CP12+Carlos!CP12+Alessandro!S12 -> 117 | S12: =Marcelo!CV12+Patrícia!CV12+Diego!CV12+Aelton!CV12+Leonam!CV12+Danilo!CV12+Marcos!CV12+Carlos!CV12+Alessandro!Y12 -> 365 | T12: =Marcelo!DB12+Patrícia!DB12+Diego!DB12+Aelton!DB12+Leonam!DB12+Danilo!DB12+Marcos!DB12+Carlos!DB12+Alessandro!AE12 -> 250 | U12: =Marcelo!DH12+Patrícia!DH12+Diego!DH12+Aelton!DH12+Leonam!DH12+Danilo!DH12+Marcos!DH12+Carlos!DH12+Alessandro!AK12 -> 407 | V12: =Marcelo!DN12+Patrícia!DN12+Diego!DN12+Aelton!DN12+Leonam!DN12+Danilo!DN12+Marcos!DN12+Carlos!DN12+Alessandro!AQ12 -> 627 | W12: =Marcelo!DT12+Patrícia!DT12+Diego!DT12+Aelton!DT12+Leonam!DT12+Danilo!DT12+Marcos!DT12+Carlos!DT12+Alessandro!AW12 -> 405 | X12: =Marcelo!DZ12+Patrícia!DZ12+Diego!DZ12+Aelton!DZ12+Leonam!DZ12+Danilo!DZ12+Marcos!DZ12+Carlos!DZ12+Alessandro!BC12 -> 688
A13: Documentos administrativos produzidos (Despacho, Nota Técnica, minutas diversas) | B13: SEI | C13: 1 | D13: 4 | E13: 1 | F13: 1 | G13: 7 | H13: 4 | I13: 2 | J13: 9 | K13: 4 | L13: 44 | M13: 3 | N13: 57 | O13: 7 | P13: 10 | Q13: 2 | R13: =Marcelo!CP13+Patrícia!CP13+Diego!CP13+Aelton!CP13+Leonam!CP13+Danilo!CP13+Marcos!CP13+Carlos!CP13+Alessandro!S13 -> 10 | S13: 4 | T13: =Marcelo!DB13+Patrícia!DB13+Diego!DB13+Aelton!DB13+Leonam!DB13+Danilo!DB13+Marcos!DB13+Carlos!DB13+Alessandro!AE13 -> 1 | U13: 3 | V13: =Marcelo!DN13+Patrícia!DN13+Diego!DN13+Aelton!DN13+Leonam!DN13+Danilo!DN13+Marcos!DN13+Carlos!DN13+Alessandro!AQ13 -> 2 | W13: =Marcelo!DT13+Patrícia!DT13+Diego!DT13+Aelton!DT13+Leonam!DT13+Danilo!DT13+Marcos!DT13+Carlos!DT13+Alessandro!AW13 -> 4 | X13: =Marcelo!DZ13+Patrícia!DZ13+Diego!DZ13+Aelton!DZ13+Leonam!DZ13+Danilo!DZ13+Marcos!DZ13+Carlos!DZ13+Alessandro!BC13 -> 2
A14: Orientação técnica / atendimentos realizados | B14: SEI, E-MAIL, TELEFONE | C14: =Marcelo!E14+Patrícia!E14+Diego!E14+Aelton!E14+Leonam!E14+Danilo!E14+Marcos!E14 -> 0 | D14: =Marcelo!K14+Patrícia!K14+Diego!K14+Aelton!K14+Leonam!K14+Danilo!K14+Marcos!K14 -> 0 | E14: =Marcelo!Q14+Patrícia!Q14+Diego!Q14+Aelton!Q14+Leonam!Q14+Danilo!Q14+Marcos!Q14 -> 0 | F14: =Marcelo!X14+Patrícia!X14+Diego!X14+Aelton!X14+Leonam!X14+Danilo!X14+Marcos!X14 -> 0 | G14: =Marcelo!AD14+Patrícia!AD14+Diego!AD14+Aelton!AD14+Leonam!AD14+Danilo!AD14+Marcos!AD14 -> 1 | H14: =Marcelo!AJ14+Patrícia!AJ14+Diego!AJ14+Aelton!AJ14+Leonam!AJ14+Danilo!AJ14+Marcos!AJ14 -> 0 | I14: =Marcelo!AP14+Patrícia!AP14+Diego!AP14+Aelton!AP14+Leonam!AP14+Danilo!AP14+Marcos!AP14 -> 0 | J14: =Marcelo!AV14+Patrícia!AV14+Diego!AV14+Aelton!AV14+Leonam!AV14+Danilo!AV14+Marcos!AV14 -> 0 | K14: =Marcelo!BB14+Patrícia!B14+Diego!BB14+Aelton!BB14+Leonam!BB14+Danilo!BB14+Marcos!BB14 -> 13 | L14: =Marcelo!BF14+Patrícia!BF14+Diego!BF14+Aelton!BF14+Leonam!BF14+Danilo!BF14+Marcos!BF14 -> 0 | M14: =Marcelo!BL14+Patrícia!BL14+Diego!BL14+Aelton!BL14+Leonam!BL14+Danilo!BL14+Marcos!BL14+Carlos!BL14 -> 0 | N14: =Marcelo!BR14+Patrícia!RM14+Diego!BR14+Aelton!BR14+Leonam!BR14+Danilo!BR14+Marcos!BR14+Carlos!BR14 -> 0 | O14: =Marcelo!BX14+Patrícia!BX14+Diego!BX14+Aelton!BX14+Leonam!BX14+Danilo!BX14+Marcos!BX14+Carlos!BX14 -> 0 | P14: =Marcelo!CD14+Patrícia!CD14+Diego!CD14+Aelton!CD14+Leonam!CD14+Danilo!CD14+Marcos!CD14+Carlos!CD14+Alessandro!G14 -> 0 | Q14: =Marcelo!CJ14+Patrícia!CJ14+Diego!CJ14+Aelton!CJ14+Leonam!CJ14+Danilo!CJ14+Marcos!CJ14+Carlos!CJ14++Alessandro!M14 -> 0 | R14: =Marcelo!CP14+Patrícia!CP14+Diego!CP14+Aelton!CP14+Leonam!CP14+Danilo!CP14+Marcos!CP14+Carlos!CP14+Alessandro!S14 -> 0 | S14: =Marcelo!CV14+Patrícia!CV14+Diego!CV14+Aelton!CV14+Leonam!CV14+Danilo!CV14+Marcos!CV14+Carlos!CV14+Alessandro!Y14 -> 1 | T14: =Marcelo!DB14+Patrícia!DB14+Diego!DB14+Aelton!DB14+Leonam!DB14+Danilo!DB14+Marcos!DB14+Carlos!DB14+Alessandro!AE14 -> 0 | U14: =Marcelo!DH14+Patrícia!DH14+Diego!DH14+Aelton!DH14+Leonam!DH14+Danilo!DH14+Marcos!DH14+Carlos!DH14+Alessandro!AK14 -> 3 | V14: =Marcelo!DN14+Patrícia!DN14+Diego!DN14+Aelton!DN14+Leonam!DN14+Danilo!DN14+Marcos!DN14+Carlos!DN14+Alessandro!AQ14 -> 0 | W14: =Marcelo!DT14+Patrícia!DT14+Diego!DT14+Aelton!DT14+Leonam!DT14+Danilo!DT14+Marcos!DT14+Carlos!DT14+Alessandro!AW14 -> 0 | X14: =Marcelo!DZ14+Patrícia!DZ14+Diego!DZ14+Aelton!DZ14+Leonam!DZ14+Danilo!DZ14+Marcos!DZ14+Carlos!DZ14+Alessandro!BC14 -> 1
A15: Caixas remanejada | B15: CONTAGEM INDIVIDUAL (de caixas deslocadas visando reorganização temporária ou permanente) | C15: =Diego!E15+Aelton!E15+Leonam!E15+Danilo!E15+Marcos!E15 -> 0 | D15: =Diego!K15+Aelton!K15+Leonam!K15+Danilo!K15+Marcos!F15 -> 161 | E15: =Diego!Q15+Aelton!Q15+Leonam!Q15+Danilo!Q15+Marcos!Q15 -> 0 | F15: =Diego!X15+Aelton!X15+Leonam!X15+Danilo!X15+Marcos!X15 -> 1028 | G15: =Diego!AD15+Aelton!AD15+Leonam!AD15+Danilo!AD15+Marcos!AD15 -> 1243 | H15: =Diego!AJ15+Aelton!AJ15+Leonam!AJ15+Danilo!AJ15+Marcos!AJ15+Carlos!AJ15 -> 496 | I15: =Diego!AP15+Aelton!AP15+Leonam!AP15+Danilo!AP15+Marcos!AP15+Carlos!AP15 -> 0 | J15: =Diego!AV15+Aelton!AV15+Leonam!AV15+Danilo!AV15+Marcos!AV15+Carlos!AV15 -> 0 | K15: =Diego!BB15+Aelton!BB15+Leonam!BB15+Danilo!BB15+Marcos!BB15+Carlos!BB15 -> 49 | L15: =Diego!BF15+Aelton!BF15+Leonam!BF15+Danilo!BF15+Marcos!BF15+Carlos!BF15 -> 32 | M15: =Diego!BL15+Aelton!BL15+Leonam!BL15+Danilo!BL15+Marcos!BL15+Carlos!BL15 -> 784 | N15: =Marcelo!BR15+Patrícia!RM15+Diego!BR15+Aelton!BR15+Leonam!BR15+Danilo!BR15+Marcos!BR15+Carlos!BR15 -> 0 | O15: =Marcelo!BX15+Patrícia!BX15+Diego!BX15+Aelton!BX15+Leonam!BX15+Danilo!BX15+Marcos!BX15+Carlos!BX15 -> 0 | P15: =Marcelo!CD15+Patrícia!CD15+Diego!CD15+Aelton!CD15+Leonam!CD15+Danilo!CD15+Marcos!CD15+Carlos!CD15+Alessandro!G15 -> 0 | Q15: =Marcelo!CJ15+Patrícia!CJ15+Diego!CJ15+Aelton!CJ15+Leonam!CJ15+Danilo!CJ15+Marcos!CJ15+Carlos!CJ15++Alessandro!M15 -> 0 | R15: =Marcelo!CP15+Patrícia!CP15+Diego!CP15+Aelton!CP15+Leonam!CP15+Danilo!CP15+Marcos!CP15+Carlos!CP15+Alessandro!S15 -> 0 | S15: =Marcelo!CV15+Patrícia!CV15+Diego!CV15+Aelton!CV15+Leonam!CV15+Danilo!CV15+Marcos!CV15+Carlos!CV15+Alessandro!Y15 -> 0 | T15: =Marcelo!DB15+Patrícia!DB15+Diego!DB15+Aelton!DB15+Leonam!DB15+Danilo!DB15+Marcos!DB15+Carlos!DB15+Alessandro!AE15 -> 0 | U15: =Marcelo!DH15+Patrícia!DH15+Diego!DH15+Aelton!DH15+Leonam!DH15+Danilo!DH15+Marcos!DH15+Carlos!DH15+Alessandro!AK15 -> 784 | V15: =Marcelo!DN15+Patrícia!DN15+Diego!DN15+Aelton!DN15+Leonam!DN15+Danilo!DN15+Marcos!DN15+Carlos!DN15+Alessandro!AQ15 -> 315 | W15: =Marcelo!DT15+Patrícia!DT15+Diego!DT15+Aelton!DT15+Leonam!DT15+Danilo!DT15+Marcos!DT15+Carlos!DT15+Alessandro!AW15 -> 3814 | X15: =Marcelo!DZ15+Patrícia!DZ15+Diego!DZ15+Aelton!DZ15+Leonam!DZ15+Danilo!DZ15+Marcos!DZ15+Carlos!DZ15+Alessandro!BC15 -> 831
A16: Caixas conferidas | B16: CONTAGEM INDIVIDUAL (de caixas para simples conferência de quantitativo ou do conteúdo do espelho em atividades diversas) | C16: =Diego!E16+Aelton!E16+Leonam!E16+Danilo!E16+Marcos!E16 -> 0 | D16: =Diego!K16+Aelton!K16+Leonam!K16+Danilo!K16+Marcos!F16 -> 0 | E16: =Diego!Q16+Aelton!Q16+Leonam!Q16+Danilo!Q16+Marcos!Q16 -> 0 | F16: =Diego!X16+Aelton!X16+Leonam!X16+Danilo!X16+Marcos!X16 -> 0 | G16: =Diego!AD16+Aelton!AD16+Leonam!AD16+Danilo!AD16+Marcos!AD16 -> 0 | H16: =Diego!AJ16+Aelton!AJ16+Leonam!AJ16+Danilo!AJ16+Marcos!AJ16+Carlos!AJ16 -> 0 | I16: =Diego!AP16+Aelton!AP16+Leonam!AP16+Danilo!AP16+Marcos!AP16+Carlos!AP16 -> 0 | J16: =Diego!AV16+Aelton!AV16+Leonam!AV16+Danilo!AV16+Marcos!AV16+Carlos!AV16 -> 0 | K16: =Diego!BB16+Aelton!BB16+Leonam!BB16+Danilo!BB16+Marcos!BB16+Carlos!BB16 -> 520 | L16: =Diego!BF16+Aelton!BF16+Leonam!BF16+Danilo!BF16+Marcos!BF16+Carlos!BF16 -> 0 | M16: =Diego!BL16+Aelton!BL16+Leonam!BL16+Danilo!BL16+Marcos!BL16+Carlos!BL16 -> 1 | N16: =Marcelo!BR16+Patrícia!RM16+Diego!BR16+Aelton!BR16+Leonam!BR16+Danilo!BR16+Marcos!BR16+Carlos!BR16 -> 1184 | O16: =Marcelo!BX16+Patrícia!BX16+Diego!BX16+Aelton!BX16+Leonam!BX16+Danilo!BX16+Marcos!BX16+Carlos!BX16 -> 0 | P16: =Marcelo!CD16+Patrícia!CD16+Diego!CD16+Aelton!CD16+Leonam!CD16+Danilo!CD16+Marcos!CD16+Carlos!CD16+Alessandro!G16 -> 0 | Q16: =Marcelo!CJ16+Patrícia!CJ16+Diego!CJ16+Aelton!CJ16+Leonam!CJ16+Danilo!CJ16+Marcos!CJ16+Carlos!CJ16++Alessandro!M16 -> 0 | R16: =Marcelo!CP16+Patrícia!CP16+Diego!CP16+Aelton!CP16+Leonam!CP16+Danilo!CP16+Marcos!CP16+Carlos!CP16+Alessandro!S16 -> 0 | S16: =Marcelo!CV16+Patrícia!CV16+Diego!CV16+Aelton!CV16+Leonam!CV16+Danilo!CV16+Marcos!CV16+Carlos!CV16+Alessandro!Y16 -> 7 | T16: =Marcelo!DB16+Patrícia!DB16+Diego!DB16+Aelton!DB16+Leonam!DB16+Danilo!DB16+Marcos!DB16+Carlos!DB16+Alessandro!AE16 -> 0 | U16: =Marcelo!DH16+Patrícia!DH16+Diego!DH16+Aelton!DH16+Leonam!DH16+Danilo!DH16+Marcos!DH16+Carlos!DH16+Alessandro!AK16 -> 0 | V16: =Marcelo!DN16+Patrícia!DN16+Diego!DN16+Aelton!DN16+Leonam!DN16+Danilo!DN16+Marcos!DN16+Carlos!DN16+Alessandro!AQ16 -> 67 | W16: =Marcelo!DT16+Patrícia!DT16+Diego!DT16+Aelton!DT16+Leonam!DT16+Danilo!DT16+Marcos!DT16+Carlos!DT16+Alessandro!AW16 -> 0 | X16: =Marcelo!DZ16+Patrícia!DZ16+Diego!DZ16+Aelton!DZ16+Leonam!DZ16+Danilo!DZ16+Marcos!DZ16+Carlos!DZ16+Alessandro!BC16 -> 0
A17: OUTRA ATIVIDADE. QUAL? | F17: Retirada de 3.000 caixas do MESP da Sala G-07 (Bloco A | G17: Pesquisa "solicitacão de retirada de veiculo do patio da Agenda da Previdencia Social de Vitoria da Conquista - BA. | H17: Pesquisa "solicitacão de retirada de veiculo do patio da Agenda da Previdencia Social de Vitoria da Conquista - BA.
A18: OBSERVAÇÃO | M18: Movimentação de 784 caixas do INSS para devolução ao MPS da sala 3.71 para a sala 4.47 (em palete) | U18: Apoio no carregamento e acompanhamento do descarregamento das 784 caixas devolvidas ao Ministério da Previdência Social (MPS).

Sheet Diego
A1: INDICADORES | C1: 45659 | D1: 45660 | E1: TOTAL SEMANA | F1: 45663 | G1: 45664 | H1: 45665 | I1: 45666 | J1: 45667 | K1: TOTAL SEMANA | L1: 45670 | M1: 45671 | N1: 45672 | O1: 45673 | P1: 45674 | Q1: TOTAL SEMANA | R1: 45675 | S1: 45677 | T1: 45678 | U1: 45679 | V1: 45680 | W1: 45681 | X1: TOTAL SEMANA | Y1: 45684 | Z1: 45685 | AA1: 45686 | AB1: 45687 | AC1: 45688 | AD1: TOTAL SEMANA | AE1: 45691 | AF1: 45692 | AG1: 45693 | AH1: 45694 | AI1: 45695 | AJ1: TOTAL SEMANA | AK1: 45698 | AL1: 45699 | AM1: 45700 | AN1: 45701 | AO1: 45702 | AP1: TOTAL SEMANA | AQ1: 45705 | AR1: 45706 | AS1: 45707 | AT1: 45708 | AU1: 45709 | AV1: TOTAL SEMANA | AW1: 45712 | AX1: 45713 | AY1: 45714 | AZ1: 45715 | BA1: 45716 | BB1: TOTAL SEMANA | BC1: 45721 | BD1: 45722 | BE1: 45723 | BF1: TOTAL SEMANA | BG1: 45726 | BH1: 45727 | BI1: 45728 | BJ1: 45729 | BK1: 45730 | BL1: TOTAL SEMANA | BM1: 45733 | BN1: 45734 | BO1: 45735 | BP1: 45736 | BQ1: 45737 | BR1: TOTAL SEMANA | BS1: 45740 | BT1: 45741 | BU1: 45742 | BV1: 45743 | BW1: 45744 | BX1: TOTAL SEMANA | BY1: 45747 | BZ1: 45748 | CA1: 45749 | CB1: 45750 | CC1: 45751 | CD1: TOTAL SEMANA | CE1: 45754 | CF1: 45755 | CG1: 45756 | CH1: 45757 | CI1: 45758 | CJ1: TOTAL SEMANA | CK1: 45761 | CL1: 45762 | CM1: 45763 | CN1: 45764 | CO1: 45765 | CP1: TOTAL SEMANA | CQ1: 45768 | CR1: 45769 | CS1: 45770 | CT1: 45771 | CU1: 45772 | CV1: TOTAL SEMANA | CW1: 45775 | CX1: 45776 | CY1: 45777 | CZ1: 45778 | DA1: 45779 | DB1: TOTAL SEMANA | DC1: 45782 | DD1: 45783 | DE1: 45784 | DF1: 45785 | DG1: 45786 | DH1: TOTAL SEMANA | DI1: 45789 | DJ1: 45790 | DK1: 45791 | DL1: 45792 | DM1: 45793 | DN1: TOTAL SEMANA | DO1: 45796 | DP1: 45797 | DQ1: 45798 | DR1: 45799 | DS1: 45800 | DT1: TOTAL SEMANA | DU1: 45803 | DV1: 45804 | DW1: 45805 | DX1: 45806 | DY1: 45807 | DZ1: TOTAL SEMANA
A2: Desarquivamento de Processos/Documentos - Saída de Guia Fora | B2: 1 | CM2: 3 | CO2: FERIADO | CP2: =SUM(CK2:CO2) -> 3 | CQ2: FERIADO | CV2: =SUM(CQ2:CU2) -> 0 | CZ2: FERIADO | DA2: PONTO FACULTATIVO | DB2: =SUM(CW2:DA2) -> 0 | DH2: =SUM(DC2:DG2) -> 0 | DN2: =SUM(DI2:DM2) -> 0 | DT2: =SUM(DO2:DS2) -> 0 | DZ2: =SUM(DU2:DY2) -> 0
A3: Caixas consultadas em pesquisa de desarquivamento | B3: 2 | AF3: 3 | AJ3: =SUM(AD3:AI3) -> 3 | CP3: =SUM(CK3:CO3) -> 0 | CV3: =SUM(CQ3:CU3) -> 0 | DB3: =SUM(CW3:DA3) -> 0 | DH3: =SUM(DC3:DG3) -> 0 | DN3: =SUM(DI3:DM3) -> 0 | DT3: =SUM(DO3:DS3) -> 0 | DZ3: =SUM(DU3:DY3) -> 0
A4: Retorno de Processos/Documentos Desarquivados | B4: 3 | CP4: =SUM(CK4:CO4) -> 0 | CV4: =SUM(CQ4:CU4) -> 0 | DB4: =SUM(CW4:DA4) -> 0 | DH4: =SUM(DC4:DG4) -> 0 | DN4: =SUM(DI4:DM4) -> 0 | DT4: =SUM(DO4:DS4) -> 0 | DZ4: =SUM(DU4:DY4) -> 0
A5: Recebimento de Documentos - Guia de Transferência | B5: 4 | CP5: =SUM(CK5:CO5) -> 0 | CV5: =SUM(CQ5:CU5) -> 0 | DB5: =SUM(CW5:DA5) -> 0 | DH5: =SUM(DC5:DG5) -> 0 | DN5: =SUM(DI5:DM5) -> 0 | DT5: =SUM(DO5:DS5) -> 0 | DZ5: =SUM(DU5:DY5) -> 0
A6: Caixas separadas para classificação | B6: 5 | BW6: 50 | CP6: =SUM(CK6:CO6) -> 0 | CV6: =SUM(CQ6:CU6) -> 0 | DB6: =SUM(CW6:DA6) -> 0 | DH6: =SUM(DC6:DG6) -> 0 | DN6: =SUM(DI6:DM6) -> 0 | DT6: =SUM(DO6:DS6) -> 0 | DZ6: =SUM(DU6:DY6) -> 0
A7: Processos/Documentos classificados | B7: 6 | CP7: =SUM(CK7:CO7) -> 0 | CV7: =SUM(CQ7:CU7) -> 0 | DB7: =SUM(CW7:DA7) -> 0 | DH7: =SUM(DC7:DG7) -> 0 | DN7: =SUM(DI7:DM7) -> 0 | DT7: =SUM(DO7:DS7) -> 0 | DZ7: =SUM(DU7:DY7) -> 0
A8: Caixas separadas para eliminação | B8: 7 | U8: 25 | X8: =SUM(R8:W8) -> 25 | AR8: 30 | AS8: 25 | AT8: 20 | AU8: 40 | AV8: =SUM(AQ8:AU8) -> 115 | BC8: 12 | BD8: 28 | BE8: 10 | BG8: 79 | BU8: 261 | BV8: 144 | BX8: =SUM(BS8:BW8) -> 405 | BZ8: 86 | CD8: =SUM(BY8:CC8) -> 86 | CI8: 15 | CJ8: =SUM(CE8:CI8) -> 15 | CK8: 11 | CP8: =SUM(CK8:CO8) -> 11 | CV8: =SUM(CQ8:CU8) -> 0 | DB8: =SUM(CW8:DA8) -> 0 | DH8: =SUM(DC8:DG8) -> 0 | DN8: =SUM(DI8:DM8) -> 0 | DR8: 5 | DT8: =SUM(DO8:DS8) -> 5 | DW8: 6 | DX8: 7 | DY8: 18 | DZ8: =SUM(DU8:DY8) -> 31
A9: Caixas listadas para eliminação | B9: 8 | AQ9: 8 | AR9: 4 | AS9: 6 | AT9: 9 | AV9: =SUM(AQ9:AU9) -> 27 | AW9: 12 | AX9: 6 | AY9: 10 | AZ9: 10 | BB9: =SUM(AW9:BA9) -> 38 | BC9: 10 | BD9: 10 | BE9: 10 | BF9: =SUM(BC9:BE9) -> 30 | BG9: 24 | BH9: 15 | BL9: =SUM(BG9:BK9) -> 39 | BR9: =SUM(BM9:BQ9) -> 0 | BX9: =SUM(BS9:BW9) -> 0 | BY9: 20 | CA9: 19 | CD9: =SUM(BY9:CC9) -> 39 | CG9: 15 | CH9: 14 | CI9: 18 | CJ9: =SUM(CE9:CI9) -> 47 | CL9: 10 | CP9: =SUM(CK9:CO9) -> 10 | CV9: =SUM(CQ9:CU9) -> 0 | CX9: 5 | CY9: 4 | DB9: =SUM(CW9:DA9) -> 9 | DH9: =SUM(DC9:DG9) -> 0 | DN9: =SUM(DI9:DM9) -> 0 | DT9: =SUM(DO9:DS9) -> 0 | DZ9: =SUM(DU9:DY9) -> 0
A10: Processos/Documentos listados para eliminação | B10: 9 | AQ10: 12 | AR10: 6 | AS10: 6 | AT10: 12 | AV10: =SUM(AQ10:AU10) -> 36 | AW10: 12 | AX10: 6 | AY10: 10 | AZ10: 10 | BB10: =SUM(AW10:BA10) -> 38 | BC10: 10 | BD10: 10 | BE10: 10 | BF10: =SUM(BC10:BE10) -> 30 | BG10: 24 | BH10: 15 | BL10: =SUM(BG10:BK10) -> 39 | BR10: =SUM(BM10:BQ10) -> 0 | BS10: 14 | BT10: 16 | BX10: =SUM(BS10:BW10) -> 30 | BY10: 19 | CA10: 9 | CB10: 17 | CD10: =SUM(BY10:CC10) -> 45 | CG10: 15 | CH10: 14 | CI10: 18 | CJ10: =SUM(CE10:CI10) -> 47 | CL10: 10 | CP10: =SUM(CK10:CO10) -> 10 | CV10: =SUM(CQ10:CU10) -> 0 | CX10: 5 | CY10: 4 | DB10: =SUM(CW10:DA10) -> 9 | DH10: =SUM(DC10:DG10) -> 0 | DN10: =SUM(DI10:DM10) -> 0 | DT10: =SUM(DO10:DS10) -> 0 | DZ10: =SUM(DU10:DY10) -> 0
A11: Caixas inventariadas | B11: 10 | R11: 11 | S11: 3 | T11: 4 | U11: 4 | V11: 2 | X11: =SUM(R11:W11) -> 24 | AF11: 2 | AG11: 3 | AH11: 4 | AI11: 2 | AJ11: =SUM(AD11:AI11) -> 11 | AK11: 5 | AL11: 5 | AM11: 5 | AN11: 5 | AO11: 5 | AP11: =SUM(AJ11:AO11) -> 36 | AQ11: 5 | AR11: 5 | AV11: =SUM(AQ11:AU11) -> 10 | BL11: =SUM(BG11:BK11) -> 0 | BR11: =SUM(BM11:BQ11) -> 0 | BS11: 15 | BT11: 16 | BX11: =SUM(BS11:BW11) -> 31 | BY11: 14 | CA11: 9 | CB11: 17 | CD11: =SUM(BY11:CC11) -> 40 | CJ11: =SUM(CE11:CI11) -> 0 | CP11: =SUM(CK11:CO11) -> 0 | CR11: 5 | CS11: 4 | CT11: 5 | CU11: 1 | CV11: =SUM(CQ11:CU11) -> 15 | DB11: =SUM(CW11:DA11) -> 0 | DC11: 5 | DD11: 3 | DE11: 3 | DF11: 3 | DG11: 3 | DH11: =SUM(DC11:DG11) -> 17 | DI11: 5 | DJ11: 5 | DK11: 6 | DL11: 6 | DM11: 5 | DN11: =SUM(DI11:DM11) -> 27 | DT11: =SUM(DO11:DS11) -> 0 | DZ11: =SUM(DU11:DY11) -> 0
A12: Processos/documentos inventariados | B12: 11 | R12: 201 | S12: 37 | T12: 61 | U12: 53 | V12: 46 | X12: =SUM(R12:W12) -> 398 | AF12: 67 | AG12: 61 | AH12: 116 | AI12: 33 | AJ12: =SUM(AD12:AI12) -> 277 | AK12: 59 | AL12: 62 | AM12: 53 | AN12: 49 | AO12: 76 | AP12: =SUM(AJ12:AO12) -> 576 | AQ12: 98 | AR12: 99 | AV12: =SUM(AQ12:AU12) -> 197 | CP12: =SUM(CK12:CO12) -> 0 | CR12: 66 | CS12: 66 | CT12: 84 | CU12: 24 | CV12: =SUM(CQ12:CU12) -> 240 | DB12: =SUM(CW12:DA12) -> 0 | DC12: 46 | DD12: 51 | DE12: 30 | DF12: 41 | DG12: 42 | DH12: =SUM(DC12:DG12) -> 210 | DI12: 77 | DJ12: 60 | DK12: 66 | DL12: 85 | DM12: 64 | DN12: =SUM(DI12:DM12) -> 352 | DT12: =SUM(DO12:DS12) -> 0 | DZ12: =SUM(DU12:DY12) -> 0
A13: Documentos administrativos produzidos (Despacho, Nota Técnica, minutas diversas) | B13: 12 | BM13: 14 | BN13: 14 | BO13: 7 | BP13: 5 | BQ13: 1 | BW13: 5 | CN13: 1 | CP13: =SUM(CK13:CO13) -> 1 | CV13: =SUM(CQ13:CU13) -> 0 | DB13: =SUM(CW13:DA13) -> 0 | DH13: =SUM(DC13:DG13) -> 0 | DN13: =SUM(DI13:DM13) -> 0 | DT13: =SUM(DO13:DS13) -> 0 | DU13: 1 | DZ13: =SUM(DU13:DY13) -> 1
A14: Orientação técnica / atendimentos realizados | B14: 13 | CP14: =SUM(CK14:CO14) -> 0 | CV14: =SUM(CQ14:CU14) -> 0 | DB14: =SUM(CW14:DA14) -> 0 | DH14: =SUM(DC14:DG14) -> 0 | DN14: =SUM(DI14:DM14) -> 0 | DT14: =SUM(DO14:DS14) -> 0 | DZ14: =SUM(DU14:DY14) -> 0
A15: Caixas remanejadas | B15: 14 | BJ15: 64 | BK15: 116 | BL15: =SUM(BG15:BK15) -> 180 | CP15: =SUM(CK15:CO15) -> 0 | CV15: =SUM(CQ15:CU15) -> 0 | DB15: =SUM(CW15:DA15) -> 0 | DH15: =SUM(DC15:DG15) -> 0 | DN15: =SUM(DI15:DM15) -> 0 | DO15: 50 | DP15: 64 | DQ15: 102 | DR15: 10 | DS15: 10 | DT15: =SUM(DO15:DS15) -> 236 | DU15: 100 | DV15: 140 | DW15: 6 | DX15: 15 | DY15: 16 | DZ15: =SUM(DU15:DY15) -> 277
A16: Caixas conferidas | B16: 15 | BA16: 260 | CP16: =SUM(CK16:CO16) -> 0 | CV16: =SUM(CQ16:CU16) -> 0 | DB16: =SUM(CW16:DA16) -> 0 | DH16: =SUM(DC16:DG16) -> 0 | DN16: =SUM(DI16:DM16) -> 0 | DT16: =SUM(DO16:DS16) -> 0 | DZ16: =SUM(DU16:DY16) -> 0
A17: OUTRA ATIVIDADE. QUAL? | AR17: Verificação de 30 caixas para eliminação | AS17: Verificação de 25 caixas para eliminação | AT17: Verificação de 20 caixas para eliminação | AU17: Verificação de 40 caixas para eliminação | BA17: Procurar no acervos a caixa do carro da LBA que não foi indentifica na retirada do processo | BE17: movimentação de total de 20 caixas da 4.47 para sala para fazer | BG17: movimentação de 94 caixas para a sala 4.47 e fazendo paletes | BH17: movimentação de 39 caixas para a sala 4.47 e fazendo paletes | BI17: 98 caixas para a sala 4.47 e fazendo paletes | BJ17: fazendo a movimentação e conferencia de 318 caixas do INSS da sala 3.71 para a sala 4.47 e fazendo Paletes | BK17: fazendo a movimentação de 116 caixas do INSS da sala 3.71 para a sala 4.47 e fazendo Paletes | BM17: 3 pesquisas de processos físicos, se retornaram para DIARQ. | BO17: Criação 9 caixa nova. | BQ17: Fazendo 10 espelhos de caixa | BS17: 56 caixas listadas para eliminaçõa. Guarda das caixas feita no dia anterios e separação das caixas para elimi nação nos acervos, sala 3.71 E 4.47 | BT17: 54 caixas listadas para eliminação. Guarda das caixas feita no dia anterios e separação das caixas para elimi nação nos acervos, sala 3.71 E 4.47,3.61 | BZ17: GUARDAMOS 52 CAIXAS | CA17: PESQUIANDO NUP PARA FAZER DESPACHOS | CB17: PESQUISA DO VOLUME 56 DO PROCESSO 71000.003125/2005-52 NO PERIODO MATUTINO | CC17: PROCURANDO CAIXAS PARA ELIMINAÇÃO | CE17: PROCURANDO O PROCESSO nº 23132.000438/95-22 NO BLOCO A | CF17: PROCURANDO O PROCESSO nº 23132.000438/95-22 NO BLOCO A | CG17: PROCURANDO O PROCESSO nº 23132.000438/95-22 NO BLOCO A DE MANHA | CH17: SEPARADO 81 CAIXAS DO MINISTERIO DA JUSTIÇA PRA DEVOLVER | CK17: PROCURANDO CAIXAS PARA ELIMINAÇÃO O DIA TODO, OLHANDO O E-MAIL E O SEI | CL17: RECEBIMENTO DE DOCUMENTO DA SENARC | CM17: Guarda de 21 caixas de eliminação feita no dia anterios levada da sala 3.11 para o acervos 4.47 e feito PALETES | CN17: PROCURANDO CAIXAS PARA ELIMINAÇÃO , OLHAMNDO EMAIL E O SEI | CS17: MEDIÇÃO DO AQUIVO DESLIZANTE E CONTAGEM DOS MODULOS DANIFICADOS | CU17: COLOCADO NA ESTANTE 30 CAIXAS | CW17: EXAME PERIDODICO PELA PARTE DA MANHA | DW17: ANIVESARIO PELA PARTE DA MANHA | DX17: PROCURANDO CAIXAS PARA ELIMINAÇÃO
A18: OBSERVAÇÃO | C18: RECESSO DE ANO NOVO | D18: RECESSO DE ANO NOVO | F18: RECESSO DE ANO NOVO | G18: Retirada de divisoria | H18: Retirada de divisoria | I18: Retirada de divisoria | J18: Retirada de divisoria | L18: Retirada de divisoria | M18: Retirada de divisoria | N18: Retirada de divisoria | O18: Retirada de divisoria | P18: Retirada de divisoria | R18: Inventário caixas "Arquivo Central" | S18: Inventário caixas "Arquivo Central" | T18: Inventário caixas "Arquivo Central" | U18: Inventário caixas "Arquivo Central" | V18: Inventário caixas "Arquivo Central" | AA18: PESQUISA E BUSCA - Solicitacão de retirada de veiculo do patio da Agenda da Previdencia Social de Vitoria da Conquista - BA. | AB18: PESQUISA E BUSCA - Solicitacão de retirada de veiculo do patio da Agenda da Previdencia Social de Vitoria da Conquista - BA. | AC18: PESQUISA E BUSCA - Solicitacão de retirada de veiculo do patio da Agenda da Previdencia Social de Vitoria da Conquista - BA. | AE18: PESQUISA E BUSCA - Solicitacão de retirada de veiculo do patio da Agenda da Previdencia Social de Vitoria da Conquista - BA. | AF18: Inventário caixas "Arquivo Central" | AG18: Inventário caixas "Arquivo Central" | AH18: Inventário caixas "Arquivo Central" | AI18: Inventário caixas "Arquivo Central" | AK18: Inventário caixas "Arquivo Central" | AL18: Inventário caixas "Arquivo Central" | AM18: Inventário caixas "Arquivo Central" | AN18: Inventário caixas "Arquivo Central" | AO18: Inventário caixas "Arquivo Central" | AQ18: Inventário caixas "Arquivo Central" | AS18: Conferência de processos recebidos da DIPRO / Procurando os processo da CEOF | AT18: Conferência de processos recebidos da DIPRO / Guardamos 30 caixas | AU18: Conferência de processos recebidos da DIPRO | AW18: Conferência de processos recebidos da DIPRO | AX18: Guardamos 44 caixas para eliminação | BA18: conferênica das caixas da Ouvidoria do MPS | BE18: movimentação de 150 caixas para a sala 4.47 e fazendo paletes | BG18: a notar o endereço nas caixas e a movimentação total de 107 caixas da 4.47 P/ sala P/ fazer | BI18: feito 11 caixas e espelhos do inss | BJ18: Verificando e Destacando as caixas do ano de 2005 a 2007 para eliminação nas salas 4.47 - 3.25 e 3.60 | BO18: Diminução da produção de Despachos devido ser necessário pesquisa e criação de caixa nova. | BP18: Diminução da produção de Despachos devido ser necessário pesquisa. | BQ18: Diminução da produção de Despachos devido ser necessário pesquisa. | BS18: Procura de 3 caixas nos Paletes na sala 4.47 | CB18: MONTANDO O PALETE DAS CAIXAS 028.11 | CC18: LANCHE NO DNIT A TARDE | CL18: FOTOS DA LBA | CM18: PROCURANDO O PROCESSO DA CGCEB DE 03 VOLUMES | CN18: FEITO PALETES NA 4.47 DE 60 CAIXAS | CO18: FERIADO | CQ18: FERIADO | CS18: ORIENTAÇÃO DE DESARQUIVAMENTO DE PROCESSOS | CU18: ALMOÇO DA EQUIPE | CW18: PROCURANDO CAIXAS PARA ELIMINAÇÃO | CX18: PROCURANDO CAIXAS PARA ELIMINAÇÃO | CY18: PROCURANDO CAIXAS PARA ELIMINAÇÃO | DE18: Pela parte da tarde na sala G07 mais o leandro olhando os arquivos | DG18: Café da manha da cda
BQ19: concluido todos os despachos

Sheet Aelton
A1: INDICADORES | C1: 45659 | D1: 45660 | E1: TOTAL SEMANA | F1: 45663 | G1: 45664 | H1: 45665 | I1: 45666 | J1: 45667 | K1: TOTAL SEMANA | L1: 45670 | M1: 45671 | N1: 45672 | O1: 45673 | P1: 45674 | Q1: TOTAL SEMANA | R1: 45675 | S1: 45677 | T1: 45678 | U1: 45679 | V1: 45680 | W1: 45681 | X1: TOTAL SEMANA | Y1: 45684 | Z1: 45685 | AA1: 45686 | AB1: 45687 | AC1: 45688 | AD1: TOTAL SEMANA | AE1: 45691 | AF1: 45692 | AG1: 45693 | AH1: 45694 | AI1: 45695 | AJ1: TOTAL SEMANA | AK1: 45698 | AL1: 45699 | AM1: 45700 | AN1: 45701 | AO1: 45702 | AP1: TOTAL SEMANA | AQ1: 45705 | AR1: 45706 | AS1: 45707 | AT1: 45708 | AU1: 45709 | AV1: TOTAL SEMANA | AW1: 45712 | AX1: 45713 | AY1: 45714 | AZ1: 45715 | BA1: 45716 | BB1: TOTAL SEMANA | BC1: 45721 | BD1: 45722 | BE1: 45723 | BF1: TOTAL SEMANA | BG1: 45726 | BH1: 45727 | BI1: 45728 | BJ1: 45729 | BK1: 45730 | BL1: TOTAL SEMANA | BM1: 45733 | BN1: 45734 | BO1: 45735 | BP1: 45736 | BQ1: 45737 | BR1: TOTAL SEMANA | BS1: 45740 | BT1: 45741 | BU1: 45742 | BV1: 45743 | BW1: 45744 | BX1: TOTAL SEMANA | BY1: 45747 | BZ1: 45748 | CA1: 45749 | CB1: 45750 | CC1: 45751 | CD1: TOTAL SEMANA | CE1: 45754 | CF1: 45755 | CG1: 45756 | CH1: 45757 | CI1: 45758 | CJ1: TOTAL SEMANA | CK1: 45761 | CL1: 45762 | CM1: 45763 | CN1: 45764 | CO1: 45765 | CP1: TOTAL SEMANA | CQ1: 45768 | CR1: 45769 | CS1: 45770 | CT1: 45771 | CU1: 45772 | CV1: TOTAL SEMANA | CW1: 45775 | CX1: 45776 | CY1: 45777 | CZ1: 45778 | DA1: 45779 | DB1: TOTAL SEMANA | DC1: 45782 | DD1: 45783 | DE1: 45784 | DF1: 45785 | DG1: 45786 | DH1: TOTAL SEMANA | DI1: 45789 | DJ1: 45790 | DK1: 45791 | DL1: 45792 | DM1: 45793 | DN1: TOTAL SEMANA | DO1: 45796 | DP1: 45797 | DQ1: 45798 | DR1: 45799 | DS1: 45800 | DT1: TOTAL SEMANA | DU1: 45803 | DV1: 45804 | DW1: 45805 | DX1: 45806 | DY1: 45807 | DZ1: TOTAL SEMANA
A2: Desarquivamento de Processos/Documentos - Saída de Guia Fora | B2: 1 | G2: 7 | P2: 1 | AH2: 3 | AI2: 19 | BC2: 2 | BH2: 1 | BW2: 2 | CL2: 2 | CM2: 1 | CO2: FERIADO | CQ2: FERIADO | CY2: 1 | CZ2: FERIADO | DA2: Ponto Facultativo | DB2: =SUM(CW2:DA2) -> 1 | DE2: 1 | DH2: =SUM(DC2:DG2) -> 1 | DZ2: =SUM(DU2:DY2) -> 0
A3: Caixas consultadas em pesquisa de desarquivamento | B3: 2 | AE3: 2 | AF3: 2 | AG3: 2 | BA3: 2 | BS3: 1 | BU3: 1 | BV3: 2 | BW3: 4 | BZ3: 4 | CE3: 20 | CF3: 18 | CG3: 19 | CH3: 19 | CI3: 29 | CJ3: =SUM(CE3:CI3) -> 105 | DB3: =SUM(CW3:DA3) -> 0 | DH3: =SUM(DC3:DG3) -> 0 | DZ3: =SUM(DU3:DY3) -> 0
A4: Retorno de Processos/Documentos Desarquivados | B4: 3 | F4: 15 | AZ4: 6 | BJ4: 1 | BZ4: 1 | CA4: 3 | CB4: 2 | CM4: 7 | CT4: 5 | CU4: 10 | CY4: 4 | DB4: =SUM(CW4:DA4) -> 4 | DG4: 2 | DH4: =SUM(DC4:DG4) -> 2 | DZ4: =SUM(DU4:DY4) -> 0
A5: Recebimento de Documentos - Guia de Transferência | B5: 4 | D5: 4 | H5: 3 | J5: 1 | L5: 8 | M5: 1 | N5: 1 | S5: 4 | Y5: 1 | Z5: 1 | AI5: 1 | AN5: 1 | CN5: 2 | DH5: =SUM(DC5:DG5) -> 0 | DZ5: =SUM(DU5:DY5) -> 0
A6: Caixas separadas para classificação | B6: 5 | DH6: =SUM(DC6:DG6) -> 0 | DZ6: =SUM(DU6:DY6) -> 0
A7: Processos/Documentos classificados | B7: 6 | DH7: =SUM(DC7:DG7) -> 0 | DZ7: =SUM(DU7:DY7) -> 0
A8: Caixas separadas para eliminação | B8: 7 | W8: 107 | AQ8: 25 | BX8: =SUM(BS8:BW8) -> 0 | CD8: =SUM(BY8:CC8) -> 0 | CP8: =SUM(CK8:CO8) -> 0 | CV8: =SUM(CQ8:CU8) -> 0 | DB8: =SUM(CW8:DA8) -> 0 | DH8: =SUM(DC8:DG8) -> 0 | DN8: =SUM(DI8:DM8) -> 0 | DP8: 4 | DQ8: 4 | DT8: =SUM(DO8:DS8) -> 8 | DZ8: =SUM(DU8:DY8) -> 0
A9: Caixas listadas para eliminação | B9: 8 | BR9: =SUM(BM9:BQ9) -> 0 | BX9: =SUM(BS9:BW9) -> 0 | CD9: =SUM(BY9:CC9) -> 0 | CP9: =SUM(CK9:CO9) -> 0 | CV9: =SUM(CQ9:CU9) -> 0 | DB9: =SUM(CW9:DA9) -> 0 | DH9: =SUM(DC9:DG9) -> 0 | DN9: =SUM(DI9:DM9) -> 0 | DT9: =SUM(DO9:DS9) -> 0 | DW9: 6 | DX9: 4 | DY9: 1 | DZ9: =SUM(DU9:DY9) -> 11
A10: Processos/Documentos listados para eliminação | B10: 9 | BR10: =SUM(BM10:BQ10) -> 0 | BX10: =SUM(BS10:BW10) -> 0 | CD10: =SUM(BY10:CC10) -> 0 | CP10: =SUM(CK10:CO10) -> 0 | CV10: =SUM(CQ10:CU10) -> 0 | DB10: =SUM(CW10:DA10) -> 0 | DH10: =SUM(DC10:DG10) -> 0 | DN10: =SUM(DI10:DM10) -> 0 | DT10: =SUM(DO10:DS10) -> 0 | DZ10: =SUM(DU10:DY10) -> 0
A11: Caixas inventariadas | B11: 10 | BR11: =SUM(BM11:BQ11) -> 0 | BX11: =SUM(BS11:BW11) -> 0 | CD11: =SUM(BY11:CC11) -> 0 | CP11: =SUM(CK11:CO11) -> 0 | CV11: =SUM(CQ11:CU11) -> 0 | DB11: =SUM(CW11:DA11) -> 0 | DH11: =SUM(DC11:DG11) -> 0 | DI11: 5 | DJ11: 5 | DK11: 5 | DL11: 5 | DM11: 5 | DN11: =SUM(DI11:DM11) -> 25 | DO11: 3 | DR11: 5 | DS11: 5 | DT11: =SUM(DO11:DS11) -> 13 | DZ11: =SUM(DU11:DY11) -> 0
A12: Processos/documentos inventariados | B12: 11 | CK12: 11 | DH12: =SUM(DC12:DG12) -> 0 | DI12: 48 | DJ12: 49 | DK12: 54 | DL12: 66 | DM12: 58 | DN12: =SUM(DI12:DM12) -> 275 | DO12: 29 | DR12: 69 | DS12: 82 | DT12: =SUM(DO12:DS12) -> 180 | DZ12: =SUM(DU12:DY12) -> 0
A13: Documentos administrativos produzidos (Despacho, Nota Técnica, minutas diversas) | B13: 12 | F13: 1 | P13: 1 | BD13: 2 | BF13: =SUM(BC13:BE13) -> 2 | BJ13: 1 | BM13: 12 | BN13: 12 | BO13: 7 | BP13: 3 | BQ13: 3 | BT13: 1 | BY13: 3 | BZ13: 1 | CA13: 2 | CB13: 4 | CD13: =SUM(BY13:CC13) -> 10 | CJ13: =SUM(CE13:CI13) -> 0 | CM13: 9 | CP13: =SUM(CK13:CO13) -> 9 | CR13: 2 | CS13: 4 | CV13: =SUM(CQ13:CU13) -> 6 | CY13: 1 | DB13: =SUM(CW13:DA13) -> 1 | DF13: 1 | DH13: =SUM(DC13:DG13) -> 1 | DN13: =SUM(DI13:DM13) -> 0 | DT13: =SUM(DO13:DS13) -> 0 | DZ13: =SUM(DU13:DY13) -> 0
A14: Orientação técnica / atendimentos realizados | B14: 13 | G14: 1 | BN14: 1 | BU14: 1 | CW14: 1 | DC14: 2 | DD14: 1 | DH14: =SUM(DC14:DG14) -> 3 | DZ14: =SUM(DU14:DY14) -> 0
A15: Caixas remanejadas | B15: 14 | I15: 161 | K15: =SUM(F15:J15) -> 161 | S15: 120 | T15: 583 | X15: =SUM(R15:W15) -> 703 | BJ15: 64 | BK15: 116 | BL15: =SUM(BG15:BK15) -> 180 | DF15: 784 | DH15: =SUM(DC15:DG15) -> 784 | DU15: 100 | DV15: 140 | DZ15: =SUM(DU15:DY15) -> 240
A16: Caixas conferidas | B16: 15 | J16: 13 | BA16: 260 | BB16: =SUM(AW16:BA16) -> 260 | DH16: =SUM(DC16:DG16) -> 0 | DP16: 1439 | DQ16: 1439 | DZ16: =SUM(DU16:DY16) -> 0
