Workbook

Sheet GLOSSÁRIO
A1: INDICADORES | B1: FONTE
A2: Desarquivamento de Processos/Documentos - Saída de Guia Fora | B2: SEI (Depachos ou Ofícios assinados na unidade Diarq)
A3: Caixas consultadas em pesquisa de desarquivamento | B3: CONTAGEM INDIVIDUAL (Caixas abertas para verificação de conteúdo em contexto de pesquisa para desarquivamento)
A4: Retorno de Processos/Documentos Desarquivados | B4: SEI (Depachos ou Ofícios assinados na unidade Diarq)
A5: Recebimento de Documentos - Guia de Transferência | B5: SEI (Depachos ou Ofícios assinados na unidade Diarq)
A6: Caixas separadas para classificação | B6: CONTAGEM INDIVIDUAL (Caixas "puxadas" nas estantes como uma pré-seleção para classificação)
A7: Processos/Documentos classificados | B7: PLANILHA
A8: Caixas separadas para eliminação | B8: CONTAGEM INDIVIDUAL (Caixas "puxadas" nas estantes como uma pré-seleção para eliminação)
A9: Caixas listadas para eliminação | B9: PLANILHA
A10: Processos/Documentos listados para eliminação | B10: PLANILHA
A11: Caixas inventariadas | B11: PLANILHA
A12: Processos/documentos inventariados | B12: PLANILHA
... A16: Caixas conferidas | B16: CONTAGEM INDIVIDUAL (Caixas consultadas para simples 'conferência de quantitativo' ou do 'conteúdo do espelho' em atividades diversas)

Sheet Patrícia
A1: INDICADORES | C1: 45662 | D1: 45663 | E1: 45664 | F1: 45665 | G1: 45666 | H1: TOTAL SEMANA | I1: 45669 | J1: 45670 | K1: 45671 | L1: 45672 | M1: 45673 | N1: TOTAL SEMANA | O1: 45676 | P1: 45677 | Q1: 45678 | R1: 45679 | S1: 45680 | T1: TOTAL SEMANA | U1: 45683 | V1: 45684 | W1: 45685 | X1: 45686 | Y1: 45687 | Z1: TOTAL SEMANA | AA1: 45690 | AB1: 45691 | AC1: 45692 | AD1: 45693 | AE1: 45694 | AF1: TOTAL SEMANA | AG1: 45697 | AH1: 45698 | AI1: 45699 | AJ1: 45700 | AK1: 45701 | AL1: TOTAL SEMANA | AM1: 45704 | AN1: 45705 | AO1: 45706 | AP1: 45707 | AQ1: 45708 | AR1: TOTAL SEMANA | AS1: 45711 | AT1: 45712 | AU1: 45713 | AV1: 45714 | AW1: 45715 | AX1: TOTAL SEMANA
A2: Documentos administrativos produzidos (Despacho, Nota Técnica, minutas diversas) | B2: 1 | H2: =SUM(C2:G2) -> 0 | N2: =SUM(I2:M2) -> 0 | T2: =SUM(O2:S2) -> 0 | Z2: =SUM(U2:Y2) -> 0 | AF2: =SUM(AA2:AE2) -> 0 | AL2: =SUM(AG2:AK2) -> 0 | AR2: =SUM(AM2:AQ2) -> 0 | AX2: =SUM(AS2:AW2) -> 0
A3: Orientação técnica / atendimentos realizados | B3: 2 | H3: =SUM(C3:G3) -> 0 | N3: =SUM(I3:M3) -> 0 | T3: =SUM(O3:S3) -> 0 | Z3: =SUM(U3:Y3) -> 0 | AF3: =SUM(AA3:AE3) -> 0 | AL3: =SUM(AG3:AK3) -> 0 | AR3: =SUM(AM3:AQ3) -> 0 | AX3: =SUM(AS3:AW3) -> 0
A4: OUTRA ATIVIDADE. QUAL?
A5: OBSERVAÇÃO

Sheet Leonardo
A1: INDICADORES | C1: 45662 | D1: 45663 | E1: 45664 | F1: 45665 | G1: 45666 | H1: TOTAL SEMANA | I1: 45669 | J1: 45670 | K1: 45671 | L1: 45672 | M1: 45673 | N1: TOTAL SEMANA | O1: 45676 | P1: 45677 | Q1: 45678 | R1: 45679 | S1: 45680 | T1: TOTAL SEMANA | U1: 45683 | V1: 45684 | W1: 45685 | X1: 45686 | Y1: 45687 | Z1: TOTAL SEMANA | AA1: 45690 | AB1: 45691 | AC1: 45692 | AD1: 45693 | AE1: 45694 | AF1: TOTAL SEMANA | AG1: 45697 | AH1: 45698 | AI1: 45699 | AJ1: 45700 | AK1: 45701 | AL1: TOTAL SEMANA | AM1: 45704 | AN1: 45705 | AO1: 45706 | AP1: 45707 | AQ1: 45708 | AR1: TOTAL SEMANA | AS1: 45711 | AT1: 45712 | AU1: 45713 | AV1: 45714 | AW1: 45715 | AX1: TOTAL SEMANA
A2: Documentos administrativos produzidos (Despacho, Nota Técnica, minutas diversas) | B2: 1 | H2: =SUM(C2:G2) -> 0 | N2: =SUM(I2:M2) -> 0 | T2: =SUM(O2:S2) -> 0 | Z2: =SUM(U2:Y2) -> 0 | AF2: =SUM(AA2:AE2) -> 0 | AL2: =SUM(AG2:AK2) -> 0 | AR2: =SUM(AM2:AQ2) -> 0 | AX2: =SUM(AS2:AW2) -> 0
A3: Orientação técnica / atendimentos realizados | B3: 2 | H3: =SUM(C3:G3) -> 0 | N3: =SUM(I3:M3) -> 0 | T3: =SUM(O3:S3) -> 0 | Z3: =SUM(U3:Y3) -> 0 | AF3: =SUM(AA3:AE3) -> 0 | AL3: =SUM(AG3:AK3) -> 0 | AR3: =SUM(AM3:AQ3) -> 0 | AX3: =SUM(AS3:AW3) -> 0
A4: OUTRA ATIVIDADE. QUAL?
A5: OBSERVAÇÃO

Sheet TOTAL
A1: INDICADORES | B1: Fonte | C1: 05//01 a 09/01/2026 | D1: 12//01 a 16/01/2026 | E1: 19/01 a 23/01/2026 | F1: 26/01 a 30/01/2026 | G1: 02/02 a 06/02/2026 | H1: 09/02 a 13/02/2026 | I1: 16/02 a 20/02/2026 | J1: 23/02 a 27/02/2026
A2: Desarquivamento de Processos/Documentos - Saída de Guia Fora | B2: SEI | C2: =Diego!H2+Aelton!H2+Leonam!H2+Danilo!H2+Marcos!H2+Alessandro!H2 -> 2 | D2: 1 | E2: =Diego!T2+Aelton!T2+Leonam!T2+Danilo!T2+Marcos!T2+Alessandro!T2 -> 1 | F2: =Diego!Z2+Aelton!Z2+Leonam!Z2+Danilo!Z2+Marcos!Z2+Alessandro!Z2 -> 9 | G2: =Diego!AF2+Aelton!AF2+Leonam!AF2+Danilo!AF2+Marcos!AF2+Alessandro!AF2 -> 0 | H2: =Diego!AL2+Aelton!AL2+Leonam!AL2+Danilo!AL2+Marcos!AL2+Alessandro!AL2 -> 12 | I2: =Diego!AR2+Aelton!AR2+Leonam!AR2+Danilo!AR2+Marcos!AR2+Alessandro!AR2 -> 2 | J2: =Diego!AX2+Aelton!AX2+Leonam!AX2+Danilo!AX2+Marcos!AX2+Alessandro!AX2 -> 0
A3: Caixas consultadas em pesquisa de desarquivamento | B3: CONTAGEM INDIVIDUAL (das caixas abertas para verificação de conteúdo em contexto de pesquisa para desarquivamento) | C3: =Diego!H3+Aelton!H3+Leonam!H3+Danilo!H3+Marcos!H3+Alessandro!H3 -> 0 | D3: 55 | E3: =Diego!T3+Aelton!T3+Leonam!T3+Danilo!T3+Marcos!T3+Alessandro!T3 -> 0 | F3: =Diego!Z3+Aelton!Z3+Leonam!Z3+Danilo!Z3+Marcos!Z3+Alessandro!Z3 -> 8 | G3: =Diego!AF3+Aelton!AF3+Leonam!AF3+Danilo!AF3+Marcos!AF3+Alessandro!AF3 -> 4 | H3: =Diego!AL3+Aelton!AL3+Leonam!AL3+Danilo!AL3+Marcos!AL3+Alessandro!AL3 -> 0 | I3: =Diego!AR3+Aelton!AR3+Leonam!AR3+Danilo!AR3+Marcos!AR3+Alessandro!AR3 -> 4 | J3: =Diego!AX3+Aelton!AX3+Leonam!AX3+Danilo!AX3+Marcos!AX3+Alessandro!AX3 -> 0
A4: Retorno de Processos/Documentos Desarquivados | B4: SEI | C4: =Diego!H4+Aelton!H4+Leonam!H4+Danilo!H4+Marcos!H4+Alessandro!H4 -> 0 | D4: =Diego!N4+Aelton!N4+Leonam!N4+Danilo!N4+Marcos!N4+Alessandro!N4 -> 5 | E4: =Diego!T4+Aelton!T4+Leonam!T4+Danilo!T4+Marcos!T4+Alessandro!T4 -> 0 | F4: =Diego!Z4+Aelton!Z4+Leonam!Z4+Danilo!Z4+Marcos!Z4+Alessandro!Z4 -> 22 | G4: =Diego!AF4+Aelton!AF4+Leonam!AF4+Danilo!AF4+Marcos!AF4+Alessandro!AF4 -> 0 | H4: =Diego!AL4+Aelton!AL4+Leonam!AL4+Danilo!AL4+Marcos!AL4+Alessandro!AL4 -> 12 | I4: =Diego!AR4+Aelton!AR4+Leonam!AR4+Danilo!AR4+Marcos!AR4+Alessandro!AR4 -> 0 | J4: =Diego!AX4+Aelton!AX4+Leonam!AX4+Danilo!AX4+Marcos!AX4+Alessandro!AX4 -> 8
A5: Recebimento de Documentos - Guia de Transferência | B5: SEI | C5: =Diego!H5+Aelton!H5+Leonam!H5+Danilo!H5+Marcos!H5+Alessandro!H5 -> 28 | D5: =Diego!N5+Aelton!N5+Leonam!N5+Danilo!N5+Marcos!N5+Alessandro!N5 -> 0 | E5: =Diego!T5+Aelton!T5+Leonam!T5+Danilo!T5+Marcos!T5+Alessandro!T5 -> 0 | F5: =Diego!Z5+Aelton!Z5+Leonam!Z5+Danilo!Z5+Marcos!Z5+Alessandro!Z5 -> 0 | G5: =Diego!AF5+Aelton!AF5+Leonam!AF5+Danilo!AF5+Marcos!AF5+Alessandro!AF5 -> 0 | H5: =Diego!AL5+Aelton!AL5+Leonam!AL5+Danilo!AL5+Marcos!AL5+Alessandro!AL5 -> 0 | I5: =Diego!AR5+Aelton!AR5+Leonam!AR5+Danilo!AR5+Marcos!AR5+Alessandro!AR5 -> 0 | J5: =Diego!AX5+Aelton!AX5+Leonam!AX5+Danilo!AX5+Marcos!AX5+Alessandro!AX5 -> 1
A6: Caixas separadas para classificação | B6: CONTAGEM INDIVIDUAL (das caixas "puxadas" nas estantes como uma pré-seleção para classificação) | C6: =Diego!H6+Aelton!H6+Leonam!H6+Danilo!H6+Marcos!H6+Alessandro!H6 -> 0 | D6: =Diego!N6+Aelton!N6+Leonam!N6+Danilo!N6+Marcos!N6+Alessandro!N6 -> 0 | E6: =Diego!T6+Aelton!T6+Leonam!T6+Danilo!T6+Marcos!T6+Alessandro!T6 -> 0 | F6: =Diego!Z6+Aelton!Z6+Leonam!Z6+Danilo!Z6+Marcos!Z6+Alessandro!Z6 -> 0 | G6: =Diego!AF6+Aelton!AF6+Leonam!AF6+Danilo!AF6+Marcos!AF6+Alessandro!AF6 -> 0 | H6: =Diego!AL6+Aelton!AL6+Leonam!AL6+Danilo!AL6+Marcos!AL6+Alessandro!AL6 -> 0 | I6: =Diego!AR6+Aelton!AR6+Leonam!AR6+Danilo!AR6+Marcos!AR6+Alessandro!AR6 -> 0 | J6: =Diego!AX6+Aelton!AX6+Leonam!AX6+Danilo!AX6+Marcos!AX6+Alessandro!AX6 -> 0
A7: Processos/Documentos classificados | B7: PLANILHA | C7: =Diego!H7+Aelton!H7+Leonam!H7+Danilo!H7+Marcos!H7+Alessandro!H7 -> 0 | D7: =Diego!N7+Aelton!N7+Leonam!N7+Danilo!N7+Marcos!N7+Alessandro!N7 -> 0 | E7: =Diego!T7+Aelton!T7+Leonam!T7+Danilo!T7+Marcos!T7+Alessandro!T7 -> 0 | F7: =Diego!Z7+Aelton!Z7+Leonam!Z7+Danilo!Z7+Marcos!Z7+Alessandro!Z7 -> 0 | G7: =Diego!AF7+Aelton!AF7+Leonam!AF7+Danilo!AF7+Marcos!AF7+Alessandro!AF7 -> 0 | H7: =Diego!AL7+Aelton!AL7+Leonam!AL7+Danilo!AL7+Marcos!AL7+Alessandro!AL7 -> 0 | I7: =Diego!AR7+Aelton!AR7+Leonam!AR7+Danilo!AR7+Marcos!AR7+Alessandro!AR7 -> 0 | J7: =Diego!AX7+Aelton!AX7+Leonam!AX7+Danilo!AX7+Marcos!AX7+Alessandro!AX7 -> 0
A8: Caixas separadas para eliminação | B8: CONTAGEM INDIVIDUAL (das caixas "puxadas" nas estantes como uma pré-seleção para eliminação) | C8: =Diego!H8+Aelton!H8+Leonam!H8+Danilo!H8+Marcos!H8+Alessandro!H8 -> 0 | D8: =Diego!N8+Aelton!N8+Leonam!N8+Danilo!N8+Marcos!N8+Alessandro!N8 -> 0 | E8: =Diego!T8+Aelton!T8+Leonam!T8+Danilo!T8+Marcos!T8+Alessandro!T8 -> 0 | F8: =Diego!Z8+Aelton!Z8+Leonam!Z8+Danilo!Z8+Marcos!Z8+Alessandro!Z8 -> 0 | G8: =Diego!AF8+Aelton!AF8+Leonam!AF8+Danilo!AF8+Marcos!AF8+Alessandro!AF8 -> 0 | H8: =Diego!AL8+Aelton!AL8+Leonam!AL8+Danilo!AL8+Marcos!AL8+Alessandro!AL8 -> 0 | I8: =Diego!AR8+Aelton!AR8+Leonam!AR8+Danilo!AR8+Marcos!AR8+Alessandro!AR8 -> 0 | J8: =Diego!AX8+Aelton!AX8+Leonam!AX8+Danilo!AX8+Marcos!AX8+Alessandro!AX8 -> 0
A9: Caixas listadas para eliminação | B9: PLANILHA | C9: =Diego!H9+Aelton!H9+Leonam!H9+Danilo!H9+Marcos!H9+Alessandro!H9 -> 0 | D9: =Diego!N9+Aelton!N9+Leonam!N9+Danilo!N9+Marcos!N9+Alessandro!N9 -> 0 | E9: =Diego!T9+Aelton!T9+Leonam!T9+Danilo!T9+Marcos!T9+Alessandro!T9 -> 0 | F9: =Diego!Z9+Aelton!Z9+Leonam!Z9+Danilo!Z9+Marcos!Z9+Alessandro!Z9 -> 0 | G9: =Diego!AF9+Aelton!AF9+Leonam!AF9+Danilo!AF9+Marcos!AF9+Alessandro!AF9 -> 0 | H9: =Diego!AL9+Aelton!AL9+Leonam!AL9+Danilo!AL9+Marcos!AL9+Alessandro!AL9 -> 0 | I9: =Diego!AR9+Aelton!AR9+Leonam!AR9+Danilo!AR9+Marcos!AR9+Alessandro!AR9 -> 0 | J9: =Diego!AX9+Aelton!AX9+Leonam!AX9+Danilo!AX9+Marcos!AX9+Alessandro!AX9 -> 0
A10: Processos/Documentos listados para eliminação | B10: PLANILHA | C10: =Diego!H10+Aelton!H10+Leonam!H10+Danilo!H10+Marcos!H10+Alessandro!H10 -> 0 | D10: =Diego!N10+Aelton!N10+Leonam!N10+Danilo!N10+Marcos!N10+Alessandro!N10 -> 0 | E10: =Diego!T10+Aelton!T10+Leonam!T10+Danilo!T10+Marcos!T10+Alessandro!T10 -> 0 | F10: =Diego!Z10+Aelton!Z10+Leonam!Z10+Danilo!Z10+Marcos!Z10+Alessandro!Z10 -> 0 | G10: =Diego!AF10+Aelton!AF10+Leonam!AF10+Danilo!AF10+Marcos!AF10+Alessandro!AF10 -> 0 | H10: =Diego!AL10+Aelton!AL10+Leonam!AL10+Danilo!AL10+Marcos!AL10+Alessandro!AL10 -> 0 | I10: =Diego!AR10+Aelton!AR10+Leonam!AR10+Danilo!AR10+Marcos!AR10+Alessandro!AR10 -> 0 | J10: =Diego!AX10+Aelton!AX10+Leonam!AX10+Danilo!AX10+Marcos!AX10+Alessandro!AX10 -> 0
A11: Caixas inventariadas | B11: PLANILHA | C11: =Diego!H11+Aelton!H11+Leonam!H11+Danilo!H11+Marcos!H11+Alessandro!H11 -> 0 | D11: =Diego!N11+Aelton!N11+Leonam!N11+Danilo!N11+Marcos!N11+Alessandro!N11 -> 0 | E11: =Diego!T11+Aelton!T11+Leonam!T11+Danilo!T11+Marcos!T11+Alessandro!T11 -> 0 | F11: =Diego!Z11+Aelton!Z11+Leonam!Z11+Danilo!Z11+Marcos!Z11+Alessandro!Z11 -> 0 | G11: =Diego!AF11+Aelton!AF11+Leonam!AF11+Danilo!AF11+Marcos!AF11+Alessandro!AF11 -> 0 | H11: =Diego!AL11+Aelton!AL11+Leonam!AL11+Danilo!AL11+Marcos!AL11+Alessandro!AL11 -> 0 | I11: =Diego!AR11+Aelton!AR11+Leonam!AR11+Danilo!AR11+Marcos!AR11+Alessandro!AR11 -> 0 | J11: =Diego!AX11+Aelton!AX11+Leonam!AX11+Danilo!AX11+Marcos!AX11+Alessandro!AX11 -> 0
A12: Processos/documentos inventariados | B12: PLANILHA | C12: =Diego!H12+Aelton!H12+Leonam!H12+Danilo!H12+Marcos!H12+Alessandro!H12 -> 0 | D12: =Diego!N12+Aelton!N12+Leonam!N12+Danilo!N12+Marcos!N12+Alessandro!N12 -> 0 | E12: =Diego!T12+Aelton!T12+Leonam!T12+Danilo!T12+Marcos!T12+Alessandro!T12 -> 0 | F12: =Diego!Z12+Aelton!Z12+Leonam!Z12+Danilo!Z12+Marcos!Z12+Alessandro!Z12 -> 0 | G12: =Diego!AF12+Aelton!AF12+Leonam!AF12+Danilo!AF12+Marcos!AF12+Alessandro!AF12 -> 0 | H12: =Diego!AL12+Aelton!AL12+Leonam!AL12+Danilo!AL12+Marcos!AL12+Alessandro!AL12 -> 0 | I12: =Diego!AR12+Aelton!AR12+Leonam!AR12+Danilo!AR12+Marcos!AR12+Alessandro!AR12 -> 0 | J12: =Diego!AX12+Aelton!AX12+Leonam!AX12+Danilo!AX12+Marcos!AX12+Alessandro!AX12 -> 0
A13: Documentos administrativos produzidos (Despacho, Nota Técnica, minutas diversas) | B13: SEI | C13: =Diego!H13+Aelton!H13+Leonam!H13+Danilo!H13+Marcos!H13+Alessandro!H13+Patrícia!H2+Leonardo!H2 -> 4 | D13: =Diego!N13+Aelton!N13+Leonam!N13+Danilo!N13+Marcos!N13+Alessandro!N13+Patrícia!N2+Leonardo!N2 -> 7 | E13: =Diego!T13+Aelton!T13+Leonam!T13+Danilo!T13+Marcos!T13+Alessandro!T13+Patrícia!T2+Leonardo!T2 -> 2 | F13: =Diego!Z13+Aelton!Z13+Leonam!Z13+Danilo!Z13+Marcos!Z13+Alessandro!Z13+Patrícia!Z2+Leonardo!Z2 -> 11 | G13: =Diego!AF13+Aelton!AF13+Leonam!AF13+Danilo!AF13+Marcos!AF13+Alessandro!AF13+Patrícia!AF2+Leonardo!AF2 -> 6 | H13: =Diego!AL13+Aelton!AL13+Leonam!AL13+Danilo!AL13+Marcos!AL13+Alessandro!AL13+Patrícia!AL2+Leonardo!AL2 -> 10 | I13: =Diego!AR13+Aelton!AR13+Leonam!AR13+Danilo!AR13+Marcos!AR13+Alessandro!AR13+Patrícia!AR2+Leonardo!AR2 -> 1 | J13: =Diego!AX13+Aelton!AX13+Leonam!AX13+Danilo!AX13+Marcos!AX13+Alessandro!AX13+Patrícia!AX2+Leonardo!AX2 -> 6
A14: Orientação técnica / atendimentos realizados | B14: SEI, E-MAIL, TELEFONE | C14: =Diego!H14+Aelton!H14+Leonam!H14+Danilo!H14+Marcos!H14+Alessandro!H14+Patrícia!H3+Leonardo!H3 -> 0 | D14: =Diego!N14+Aelton!N14+Leonam!N14+Danilo!N14+Marcos!N14+Alessandro!N14+Patrícia!N3+Leonardo!N3 -> 2 | E14: =Diego!T14+Aelton!T14+Leonam!T14+Danilo!T14+Marcos!T14+Alessandro!T14+Patrícia!T3+Leonardo!T3 -> 2 | F14: =Diego!Z14+Aelton!Z14+Leonam!Z14+Danilo!Z14+Marcos!Z14+Alessandro!Z14+Patrícia!Z3+Leonardo!Z3 -> 0 | G14: =Diego!AF14+Aelton!AF14+Leonam!AF14+Danilo!AF14+Marcos!AF14+Alessandro!AF14+Patrícia!AF3+Leonardo!AF3 -> 0 | H14: =Diego!AL14+Aelton!AL14+Leonam!AL14+Danilo!AL14+Marcos!AL14+Alessandro!AL14+Patrícia!AL3+Leonardo!AL3 -> 0 | I14: =Diego!AR14+Aelton!AR14+Leonam!AR14+Danilo!AR14+Marcos!AR14+Alessandro!AR14+Patrícia!AR3+Leonardo!AR3 -> 0 | J14: =Diego!AX14+Aelton!AX14+Leonam!AX14+Danilo!AX14+Marcos!AX14+Alessandro!AX14+Patrícia!AX3+Leonardo!AX3 -> 0
A15: Caixas remanejadas | B15: CONTAGEM INDIVIDUAL (de caixas deslocadas visando reorganização temporária ou permanente) | C15: =Diego!H15+Aelton!H15+Leonam!H15+Danilo!H15+Marcos!H15+Alessandro!H15 -> 447 | D15: 70 | E15: =Diego!T15+Aelton!T15+Leonam!T15+Danilo!T15+Marcos!T15+Alessandro!T15 -> 0 | F15: =Diego!Z15+Aelton!Z15+Leonam!Z15+Danilo!Z15+Marcos!Z15+Alessandro!Z15 -> 364 | G15: =Diego!AF15+Aelton!AF15+Leonam!AF15+Danilo!AF15+Marcos!AF15+Alessandro!AF15 -> 980 | H15: =Diego!AL15+Aelton!AL15+Leonam!AL15+Danilo!AL15+Marcos!AL15+Alessandro!AL15 -> 280 | I15: =Diego!AR15+Aelton!AR15+Leonam!AR15+Danilo!AR15+Marcos!AR15+Alessandro!AR15 -> 770 | J15: =Diego!AX15+Aelton!AX15+Leonam!AX15+Danilo!AX15+Marcos!AX15+Alessandro!AX15 -> 280
A16: Caixas conferidas | B16: CONTAGEM INDIVIDUAL (de caixas para simples conferência de quantitativo ou do conteúdo do espelho em atividades diversas) | C16: =Diego!H16+Aelton!H16+Leonam!H16+Danilo!H16+Marcos!H16+Alessandro!H16 -> 22 | D16: =Diego!N16+Aelton!N16+Leonam!N16+Danilo!N16+Marcos!N16+Alessandro!N16 -> 10 | E16: =Diego!T16+Aelton!T16+Leonam!T16+Danilo!T16+Marcos!T16+Alessandro!T16 -> 0 | F16: =Diego!Z16+Aelton!Z16+Leonam!Z16+Danilo!Z16+Marcos!Z16+Alessandro!Z16 -> 37 | G16: =Diego!AF16+Aelton!AF16+Leonam!AF16+Danilo!AF16+Marcos!AF16+Alessandro!AF16 -> 0 | H16: =Diego!AL16+Aelton!AL16+Leonam!AL16+Danilo!AL16+Marcos!AL16+Alessandro!AL16 -> 0 | I16: =Diego!AR16+Aelton!AR16+Leonam!AR16+Danilo!AR16+Marcos!AR16+Alessandro!AR16 -> 35 | J16: =Diego!AX16+Aelton!AX16+Leonam!AX16+Danilo!AX16+Marcos!AX16+Alessandro!AX16 -> 22
A17: Caixas substituídas(trocadas) | B17: Substituição de caixas degradadas por novas | C17: =Diego!H17+Aelton!H17+Leonam!H17+Danilo!H17+Marcos!H17+Alessandro!H17 -> 170 | D17: =Diego!N17+Aelton!N17+Leonam!N17+Danilo!N17+Marcos!N17+Alessandro!N17 -> 176 | E17: =Diego!T17+Aelton!T17+Leonam!T17+Danilo!T17+Marcos!T17+Alessandro!T17 -> 240 | F17: =Diego!Z17+Aelton!Z17+Leonam!Z17+Danilo!Z17+Marcos!Z17+Alessandro!Z17 -> 293 | G17: =Diego!AF17+Aelton!AF17+Leonam!AF17+Danilo!AF17+Marcos!AF17+Alessandro!AF17 -> 30 | H17: =Diego!AL17+Aelton!AL17+Leonam!AL17+Danilo!AL17+Marcos!AL17+Alessandro!AL17 -> 28 | I17: =Diego!AR17+Aelton!AR17+Leonam!AR17+Danilo!AR17+Marcos!AR17+Alessandro!AR17 -> 0 | J17: =Diego!AX17+Aelton!AX17+Leonam!AX17+Danilo!AX17+Marcos!AX17+Alessandro!AX17 -> 46
A18: OUTRA ATIVIDADE. QUAL?
A19: OBSERVAÇÃO

Sheet Diego
A1: INDICADORES | C1: 45662 | D1: 45663 | E1: 45664 | F1: 45665 | G1: 45666 | H1: TOTAL SEMANA | I1: 45669 | J1: 45670 | K1: 45671 | L1: 45672 | M1: 45673 | N1: TOTAL SEMANA | O1: 45676 | P1: 45677 | Q1: 45678 | R1: 45679 | S1: 45680 | T1: TOTAL SEMANA | U1: 45683 | V1: 45684 | W1: 45685 | X1: 45686 | Y1: 45687 | Z1: TOTAL SEMANA | AA1: 45690 | AB1: 45691 | AC1: 45692 | AD1: 45693 | AE1: 45694 | AF1: TOTAL SEMANA | AG1: 45697 | AH1: 45698 | AI1: 45699 | AJ1: 45700 | AK1: 45701 | AL1: TOTAL SEMANA | AM1: 45704 | AN1: 45705 | AO1: 45706 | AP1: 45707 | AQ1: 45708 | AR1: TOTAL SEMANA | AS1: 45711 | AT1: 45712 | AU1: 45713 | AV1: 45714 | AW1: 45715 | AX1: TOTAL SEMANA
A2: Desarquivamento de Processos/Documentos - Saída de Guia Fora | B2: 1 | F2: 1 | H2: =SUM(C2:G2) -> 1 | N2: =SUM(I2:M2) -> 0 | O2: 1 | T2: =SUM(O2:S2) -> 1 | X2: 5 | Y2: 1 | Z2: =SUM(U2:Y2) -> 6 | AF2: =SUM(AA2:AE2) -> 0 | AK2: 4 | AL2: =SUM(AG2:AK2) -> 4 | AM2: RECESSO | AN2: CARNAVAL | AR2: =SUM(AM2:AQ2) -> 0 | AX2: =SUM(AS2:AW2) -> 0
A3: Caixas consultadas em pesquisa de desarquivamento | B3: 2 | H3: =SUM(C3:G3) -> 0 | N3: =SUM(I3:M3) -> 0 | T3: =SUM(O3:S3) -> 0 | Y3: 3 | Z3: =SUM(U3:Y3) -> 3 | AF3: =SUM(AA3:AE3) -> 0 | AL3: =SUM(AG3:AK3) -> 0 | AM3: RECESSO | AN3: CARNAVAL | AP3: 2 | AR3: =SUM(AM3:AQ3) -> 2 | AX3: =SUM(AS3:AW3) -> 0
A4: Retorno de Processos/Documentos Desarquivados | B4: 3 | H4: =SUM(C4:G4) -> 0 | K4: 1 | N4: =SUM(I4:M4) -> 1 | T4: =SUM(O4:S4) -> 0 | U4: 1 | Z4: =SUM(U4:Y4) -> 1 | AF4: =SUM(AA4:AE4) -> 0 | AL4: =SUM(AG4:AK4) -> 0 | AM4: RECESSO | AN4: CARNAVAL | AR4: =SUM(AM4:AQ4) -> 0 | AX4: =SUM(AS4:AW4) -> 0
A5: Recebimento de Documentos - Guia de Transferência | B5: 4 | C5: 1 | G5: 1 | H5: =SUM(C5:G5) -> 2 | N5: =SUM(I5:M5) -> 0 | T5: =SUM(O5:S5) -> 0 | Z5: =SUM(U5:Y5) -> 0 | AF5: =SUM(AA5:AE5) -> 0 | AL5: =SUM(AG5:AK5) -> 0 | AM5: RECESSO | AN5: CARNAVAL | AR5: =SUM(AM5:AQ5) -> 0 | AX5: =SUM(AS5:AW5) -> 0
A6: Caixas separadas para classificação | B6: 5 | H6: =SUM(C6:G6) -> 0 | N6: =SUM(I6:M6) -> 0 | T6: =SUM(O6:S6) -> 0 | Z6: =SUM(U6:Y6) -> 0 | AF6: =SUM(AA6:AE6) -> 0 | AL6: =SUM(AG6:AK6) -> 0 | AM6: RECESSO | AN6: CARNAVAL | AR6: =SUM(AM6:AQ6) -> 0 | AX6: =SUM(AS6:AW6) -> 0
A7: Processos/Documentos classificados | B7: 6 | H7: =SUM(C7:G7) -> 0 | N7: =SUM(I7:M7) -> 0 | T7: =SUM(O7:S7) -> 0 | Z7: =SUM(U7:Y7) -> 0 | AF7: =SUM(AA7:AE7) -> 0 | AL7: =SUM(AG7:AK7) -> 0 | AM7: RECESSO | AN7: CARNAVAL | AR7: =SUM(AM7:AQ7) -> 0 | AX7: =SUM(AS7:AW7) -> 0
A8: Caixas separadas para eliminação | B8: 7 | H8: =SUM(C8:G8) -> 0 | N8: =SUM(I8:M8) -> 0 | T8: =SUM(O8:S8) -> 0 | Z8: =SUM(U8:Y8) -> 0 | AF8: =SUM(AA8:AE8) -> 0 | AL8: =SUM(AG8:AK8) -> 0 | AM8: RECESSO | AN8: CARNAVAL | AR8: =SUM(AM8:AQ8) -> 0 | AX8: =SUM(AS8:AW8) -> 0
A9: Caixas listadas para eliminação | B9: 8 | H9: =SUM(C9:G9) -> 0 | N9: =SUM(I9:M9) -> 0 | T9: =SUM(O9:S9) -> 0 | Z9: =SUM(U9:Y9) -> 0 | AF9: =SUM(AA9:AE9) -> 0 | AL9: =SUM(AG9:AK9) -> 0 | AM9: RECESSO | AN9: CARNAVAL | AR9: =SUM(AM9:AQ9) -> 0 | AX9: =SUM(AS9:AW9) -> 0
A10: Processos/Documentos listados para eliminação | B10: 9 | H10: =SUM(C10:G10) -> 0 | N10: =SUM(I10:M10) -> 0 | T10: =SUM(O10:S10) -> 0 | Z10: =SUM(U10:Y10) -> 0 | AF10: =SUM(AA10:AE10) -> 0 | AL10: =SUM(AG10:AK10) -> 0 | AM10: RECESSO | AN10: CARNAVAL | AR10: =SUM(AM10:AQ10) -> 0 | AX10: =SUM(AS10:AW10) -> 0
A11: Caixas inventariadas | B11: 10 | H11: =SUM(C11:G11) -> 0 | N11: =SUM(I11:M11) -> 0 | T11: =SUM(O11:S11) -> 0 | Z11: =SUM(U11:Y11) -> 0 | AF11: =SUM(AA11:AE11) -> 0 | AL11: =SUM(AG11:AK11) -> 0 | AM11: RECESSO | AN11: CARNAVAL | AR11: =SUM(AM11:AQ11) -> 0 | AX11: =SUM(AS11:AW11) -> 0
A12: Processos/documentos inventariados | B12: 11 | H12: =SUM(C12:G12) -> 0 | N12: =SUM(I12:M12) -> 0 | T12: =SUM(O12:S12) -> 0 | Z12: =SUM(U12:Y12) -> 0 | AF12: =SUM(AA12:AE12) -> 0 | AL12: =SUM(AG12:AK12) -> 0 | AM12: RECESSO | AN12: CARNAVAL | AR12: =SUM(AM12:AQ12) -> 0 | AX12: =SUM(AS12:AW12) -> 0
A13: Documentos administrativos produzidos (Despacho, Nota Técnica, minutas diversas) | B13: 12 | D13: 2 | H13: =SUM(C13:G13) -> 2 | I13: 1 | K13: 1 | L13: 1 | N13: =SUM(I13:M13) -> 3 | O13: 1 | T13: =SUM(O13:S13) -> 1 | U13: 1 | Y13: 1 | Z13: =SUM(U13:Y13) -> 2 | AF13: =SUM(AA13:AE13) -> 0 | AL13: =SUM(AG13:AK13) -> 0 | AM13: RECESSO | AN13: CARNAVAL | AR13: =SUM(AM13:AQ13) -> 0 | AX13: =SUM(AS13:AW13) -> 0
A14: Orientação técnica / atendimentos realizados | B14: 13 | H14: =SUM(C14:G14) -> 0 | I14: 1 | N14: =SUM(I14:M14) -> 1 | P14: 1 | T14: =SUM(O14:S14) -> 1 | Z14: =SUM(U14:Y14) -> 0 | AF14: =SUM(AA14:AE14) -> 0 | AL14: =SUM(AG14:AK14) -> 0 | AM14: RECESSO | AN14: CARNAVAL | AR14: =SUM(AM14:AQ14) -> 0 | AX14: =SUM(AS14:AW14) -> 0
A15: Caixas remanejadas | B15: 14 | F15: 149 | H15: =SUM(C15:G15) -> 149 | L15: 70 | N15: =SUM(I15:M15) -> 70 | T15: =SUM(O15:S15) -> 0 | U15: 70 | Y15: 14 | Z15: =SUM(U15:Y15) -> 84 | AB15: 70 | AC15: 70 | AF15: =SUM(AA15:AE15) -> 140 | AH15: 70 | AI15: 70 | AL15: =SUM(AG15:AK15) -> 140 | AM15: RECESSO | AN15: CARNAVAL | AP15: 140 | AR15: =SUM(AM15:AQ15) -> 140 | AU15: 70 | AX15: =SUM(AS15:AW15) -> 70
A16: Caixas conferidas | B16: 15 | C16: 2 | G16: 9 | H16: =SUM(C16:G16) -> 11 | N16: =SUM(I16:M16) -> 0 | T16: =SUM(O16:S16) -> 0 | W16: 10 | X16: 10 | Z16: =SUM(U16:Y16) -> 20 | AF16: =SUM(AA16:AE16) -> 0 | AL16: =SUM(AG16:AK16) -> 0 | AM16: RECESSO | AN16: CARNAVAL | AR16: =SUM(AM16:AQ16) -> 0 | AX16: =SUM(AS16:AW16) -> 0
A17: Caixas substituídas(trocadas) | B17: 16 | C17: 10 | D17: 10 | E17: 10 | H17: =SUM(C17:G17) -> 30 | I17: 10 | J17: 10 | K17: 10 | M17: 10 | N17: =SUM(I17:M17) -> 40 | O17: 5 | P17: 6 | Q17: 10 | R17: 10 | S17: 8 | T17: =SUM(O17:S17) -> 39 | Z17: =SUM(U17:Y17) -> 0 | AF17: =SUM(AA17:AE17) -> 0 | AL17: =SUM(AG17:AK17) -> 0 | AM17: RECESSO | AN17: CARNAVAL | AR17: =SUM(AM17:AQ17) -> 0 | AX17: =SUM(AS17:AW17) -> 0
A18: OUTRA ATIVIDADE. QUAL? | C18: 1. Conferência 2 Guias de Transferência. | D18: TROCA DE CAIXAS | E18: TROCA DE CAIXAS | F18: 1. Desarquivamento de 70 caixas do DEFNAS e Recebimento de 79. | G18: Conferência Guia de Transferência. | I18: TROCA DE CAIXAS | J18: TROCA DE CAIXAS | K18: TROCA DE CAIXAS | L18: ARQUIVAMENTO DE 70 CAIXAS | M18: TROCA DE CAIXAS | O18: TROCA DE CAIXAS | P18: TROCA DE CAIXAS | Q18: TROCA DE CAIXAS | R18: TROCA DE CAIXAS | S18: TROCA DE CAIXAS | V18: RECEBIMENTO DE 70 CAIXAS DA CGPC | AA18: Reunião pela parte da manha | AB18: RECEBIMENTO DE 70 CAIXAS DA CGPC | AC18: CARREGANDO 70 CAIXAS PARA CGPC | AD18: TROCANDO ESPELHO DE CAIXAS | AE18: TROCANDO ESPELHO DE CAIXAS | AG18: FAZENDO ESPELHOS NOVOS DAS CAIXAS DA CGPC | AH18: trocando caixas | AI18: trocando caixas | AJ18: trocando caixas | AK18: trocando caixas | AO18: recebendo pedido de processos | AQ18: CONFERENCIA DE CAIXAS DA CGPC | AS18: CONFERENCIA DE CAIXAS DA CGPC | AT18: CONFERENCIA DE CAIXAS DA CGPC | AU18: GUARDANDO AS 70 CAIXAS
A19: OBSERVAÇÃO | C19: OLHANDO OS PEDIDOS DE PROCESSO NO SEI | D19: OLHANDO OS PEDIDOS DE PROCESSO NO SEI | E19: OLHANDO OS PEDIDOS DE PROCESSO NO SEI | F19: OLHANDO OS PEDIDOS DE PROCESSO NO SEI | G19: OLHANDO OS PEDIDOS DE PROCESSO NO SEI | I19: OLHANDO OS PEDIDOS DE PROCESSO NO SEI | J19: OLHANDO OS PEDIDOS DE PROCESSO NO SEI | K19: FAZENDO PESQUISA DE PROCESSOS | L19: OLHANDO OS PEDIDOS DE PROCESSO NO SEI | M19: OLHANDO OS PEDIDOS DE PROCESSO NO SEI | P19: FAZENDO ESPELHOS | Q19: FAZENDO ESPELHOS | R19: FAZENDO ESPELHOS | S19: FAZENDO ESPELHOS | V19: ENVIANDO 70 CAIXAS PARA O MONTES | W19: CONFERENCIA DE 10 CAIXAS DA CGPC | X19: CONFERENCIA DE 10 CAIXAS DA CGPC | AA19: Reunião pela parte da tarde | AC19: DESCARREGANDO 70 CAIXAS DA CGPC | AD19: TROCANDO ESPELHO DE CAIXAS | AE19: TROCANDO ESPELHO DE CAIXAS
V20: ENVIANDO 104 PROCESSOS PARA BLOCO A

Sheet Aelton
A1: INDICADORES | C1: 45662 | D1: 45663 | E1: 45664 | F1: 45665 | G1: 45666 | H1: TOTAL SEMANA | I1: 45669 | J1: 45670 | K1: 45671 | L1: 45672 | M1: 45673 | N1: TOTAL SEMANA | O1: 45676 | P1: 45677 | Q1: 45678 | R1: 45679 | S1: 45680 | T1: TOTAL SEMANA | U1: 45683 | V1: 45684 | W1: 45685 | X1: 45686 | Y1: 45687 | Z1: TOTAL SEMANA | AA1: 45690 | AB1: 45691 | AC1: 45692 | AD1: 45693 | AE1: 45694 | AF1: TOTAL SEMANA | AG1: 45697 | AH1: 45698 | AI1: 45699 | AJ1: 45700 | AK1: 45701 | AL1: TOTAL SEMANA | AM1: 45704 | AN1: 45705 | AO1: 45706 | AP1: 45707 | AQ1: 45708 | AR1: TOTAL SEMANA | AS1: 45711 | AT1: 45712 | AU1: 45713 | AV1: 45714 | AW1: 45715 | AX1: TOTAL SEMANA
A2: Desarquivamento de Processos/Documentos - Saída de Guia Fora | B2: 1 | F2: 1 | H2: =SUM(C2:G2) -> 1 | K2: 1 | N2: =SUM(I2:M2) -> 1 | T2: =SUM(O2:S2) -> 0 | V2: 2 | Z2: =SUM(U2:Y2) -> 2 | AF2: =SUM(AA2:AE2) -> 0 | AG2: 1 | AJ2: 6 | AL2: =SUM(AG2:AK2) -> 7 | AO2: 1 | AP2: 1 | AR2: =SUM(AM2:AQ2) -> 2 | AX2: =SUM(AS2:AW2) -> 0
A3: Caixas consultadas em pesquisa de desarquivamento | B3: 2 | H3: =SUM(C3:G3) -> 0 | N3: =SUM(I3:M3) -> 0 | T3: =SUM(O3:S3) -> 0 | Z3: =SUM(U3:Y3) -> 0 | AF3: =SUM(AA3:AE3) -> 0 | AL3: =SUM(AG3:AK3) -> 0 | AR3: =SUM(AM3:AQ3) -> 0 | AX3: =SUM(AS3:AW3) -> 0
A4: Retorno de Processos/Documentos Desarquivados | B4: 3 | H4: =SUM(C4:G4) -> 0 | I4: 1 | L4: 1 | M4: 2 | N4: =SUM(I4:M4) -> 4 | T4: =SUM(O4:S4) -> 0 | Z4: =SUM(U4:Y4) -> 0 | AF4: =SUM(AA4:AE4) -> 0 | AH4: 4 | AI4: 4 | AL4: =SUM(AG4:AK4) -> 8 | AR4: =SUM(AM4:AQ4) -> 0 | AU4: 1 | AV4: 5 | AX4: =SUM(AS4:AW4) -> 6
A5: Recebimento de Documentos - Guia de Transferência | B5: 4 | C5: 1 | G5: 1 | H5: =SUM(C5:G5) -> 2 | N5: =SUM(I5:M5) -> 0 | T5: =SUM(O5:S5) -> 0 | Z5: =SUM(U5:Y5) -> 0 | AF5: =SUM(AA5:AE5) -> 0 | AL5: =SUM(AG5:AK5) -> 0 | AR5: =SUM(AM5:AQ5) -> 0 | AX5: =SUM(AS5:AW5) -> 0
A6: Caixas separadas para classificação | B6: 5 | H6: =SUM(C6:G6) -> 0 | N6: =SUM(I6:M6) -> 0 | T6: =SUM(O6:S6) -> 0 | Z6: =SUM(U6:Y6) -> 0 | AF6: =SUM(AA6:AE6) -> 0 | AL6: =SUM(AG6:AK6) -> 0 | AR6: =SUM(AM6:AQ6) -> 0 | AX6: =SUM(AS6:AW6) -> 0
A7: Processos/Documentos classificados | B7: 6 | H7: =SUM(C7:G7) -> 0 | N7: =SUM(I7:M7) -> 0 | T7: =SUM(O7:S7) -> 0 | Z7: =SUM(U7:Y7) -> 0 | AF7: =SUM(AA7:AE7) -> 0 | AL7: =SUM(AG7:AK7) -> 0 | AR7: =SUM(AM7:AQ7) -> 0 | AX7: =SUM(AS7:AW7) -> 0
A8: Caixas separadas para eliminação | B8: 7 | H8: =SUM(C8:G8) -> 0 | N8: =SUM(I8:M8) -> 0 | T8: =SUM(O8:S8) -> 0 | Z8: =SUM(U8:Y8) -> 0 | AF8: =SUM(AA8:AE8) -> 0 | AL8: =SUM(AG8:AK8) -> 0 | AR8: =SUM(AM8:AQ8) -> 0 | AX8: =SUM(AS8:AW8) -> 0
A9: Caixas listadas para eliminação | B9: 8 | H9: =SUM(C9:G9) -> 0 | N9: =SUM(I9:M9) -> 0 | T9: =SUM(O9:S9) -> 0 | Z9: =SUM(U9:Y9) -> 0 | AF9: =SUM(AA9:AE9) -> 0 | AL9: =SUM(AG9:AK9) -> 0 | AR9: =SUM(AM9:AQ9) -> 0 | AX9: =SUM(AS9:AW9) -> 0
A10: Processos/Documentos listados para eliminação | B10: 9 | H10: =SUM(C10:G10) -> 0 | N10: =SUM(I10:M10) -> 0 | T10: =SUM(O10:S10) -> 0 | Z10: =SUM(U10:Y10) -> 0 | AF10: =SUM(AA10:AE10) -> 0 | AL10: =SUM(AG10:AK10) -> 0 | AR10: =SUM(AM10:AQ10) -> 0 | AX10: =SUM(AS10:AW10) -> 0
A11: Caixas inventariadas | B11: 10 | H11: =SUM(C11:G11) -> 0 | N11: =SUM(I11:M11) -> 0 | T11: =SUM(O11:S11) -> 0 | Z11: =SUM(U11:Y11) -> 0 | AF11: =SUM(AA11:AE11) -> 0 | AL11: =SUM(AG11:AK11) -> 0 | AR11: =SUM(AM11:AQ11) -> 0 | AX11: =SUM(AS11:AW11) -> 0
A12: Processos/documentos inventariados | B12: 11 | H12: =SUM(C12:G12) -> 0 | N12: =SUM(I12:M12) -> 0 | T12: =SUM(O12:S12) -> 0 | Z12: =SUM(U12:Y12) -> 0 | AF12: =SUM(AA12:AE12) -> 0 | AL12: =SUM(AG12:AK12) -> 0 | AR12: =SUM(AM12:AQ12) -> 0 | AX12: =SUM(AS12:AW12) -> 0
A13: Documentos administrativos produzidos (Despacho, Nota Técnica, minutas diversas) | B13: 12 | D13: 2 | H13: =SUM(C13:G13) -> 2 | J13: 2 | K13: 1 | L13: 1 | N13: =SUM(I13:M13) -> 4 | O13: 1 | T13: =SUM(O13:S13) -> 1 | U13: 2 | X13: 2 | Y13: 2 | Z13: =SUM(U13:Y13) -> 6 | AB13: 1 | AD13: 2 | AF13: =SUM(AA13:AE13) -> 3 | AG13: 1 | AH13: 1 | AI13: 2 | AJ13: 1 | AK13: 1 | AL13: =SUM(AG13:AK13) -> 6 | AO13: 1 | AR13: =SUM(AM13:AQ13) -> 1 | AS13: 1 | AU13: 2 | AV13: 3 | AX13: =SUM(AS13:AW13) -> 6
A14: Orientação técnica / atendimentos realizados | B14: 13 | H14: =SUM(C14:G14) -> 0 | M14: 1 | N14: =SUM(I14:M14) -> 1 | O14: 1 | T14: =SUM(O14:S14) -> 1 | Z14: =SUM(U14:Y14) -> 0 | AF14: =SUM(AA14:AE14) -> 0 | AL14: =SUM(AG14:AK14) -> 0 | AR14: =SUM(AM14:AQ14) -> 0 | AX14: =SUM(AS14:AW14) -> 0
A15: Caixas remanejadas | B15: 14 | F15: 149 | H15: =SUM(C15:G15) -> 149 | L15: 70 | N15: =SUM(I15:M15) -> 70 | T15: =SUM(O15:S15) -> 0 | U15: 70 | V15: 140 | Z15: =SUM(U15:Y15) -> 210 | AA15: 70 | AC15: 140 | AF15: =SUM(AA15:AE15) -> 210 | AL15: =SUM(AG15:AK15) -> 0 | AP15: 140 | AR15: =SUM(AM15:AQ15) -> 140 | AU15: 70 | AX15: =SUM(AS15:AW15) -> 70
A16: Caixas conferidas | B16: 15 | C16: 2 | G16: 9 | H16: =SUM(C16:G16) -> 11 | J16: 10 | N16: =SUM(I16:M16) -> 10 | T16: =SUM(O16:S16) -> 0 | W16: 10 | X16: 5 | Y16: 2 | Z16: =SUM(U16:Y16) -> 17 | AF16: =SUM(AA16:AE16) -> 0 | AL16: =SUM(AG16:AK16) -> 0 | AQ16: 6 | AR16: =SUM(AM16:AQ16) -> 6 | AS16: 5 | AX16: =SUM(AS16:AW16) -> 5
A17: Caixas substituídas(trocadas) | B17: 16 | C17: 5 | D17: 10 | E17: 10 | H17: =SUM(C17:G17) -> 25 | N17: =SUM(I17:M17) -> 0 | O17: 10 | P17: 10 | Q17: 10 | R17: 10 | S17: 10 | T17: =SUM(O17:S17) -> 50 | Z17: =SUM(U17:Y17) -> 0 | AB17: 10 | AF17: =SUM(AA17:AE17) -> 10 | AK17: 7 | AL17: =SUM(AG17:AK17) -> 7 | AR17: =SUM(AM17:AQ17) -> 0 | AT17: 5 | AX17: =SUM(AS17:AW17) -> 5
A18: OUTRA ATIVIDADE. QUAL? | C18: 1. Conferência 2 Guias de Transferência. | D18: 1. Documento produzido: Folha de Ponto e Termo de Cancelamento. | F18: 1. Desarquivamento de 70 caixas do DEFNAS e Recebimento de 79. | G18: Conferência Guia de Transferência. | I18: 1. Alimentação planilha Guias de Transferência. | J18: 1. Conferência 10 caixas DEFNAS. 2. Pesquisa de processos - solictação do e-mail da CONJUR: 44000.001801/2007-42 44006.002300/2001-38 44006.0047/2000-21 | K18: 1. Pesquisa e busca processo 58000.002183/2009-24 | L18: 1. Arquivamento e movimentação 70 caixas da DEFNAS. | M18: 1. Orientação a CGP/MESP para Arquivamento, via telefone. | O18: Troca de caixa e espelho. Total 10 caixas. | P18: Troca de caixa e espelho. Total 10 caixas. | Q18: Troca de caixa e espelho. Total 10 caixas. | R18: Troca de caixa e espelho. Total 10 caixas. | S18: Troca de caixa e espelho. Total 10 caixas. | U18: Preparação do envio das 70 caixas para o DEFNAS. | V18: 1. Desarquivamento 70 caixas do DEFNAS. 2. Recebimento: 70 caixas do DEFNAS. | W18: 1. Conferência 10 caixas da DEFNAS. 2. Pesquisa e busca processo 58000.003896/2007-43. | X18: 1. Conferência 5 caixas da DEFNAS. | Y18: 1. Documento produzido: Orientação para arquivamento para o kalleber.santos da COSEG. 2. Documento produzido: planilha CGLA 71000.006023/2026-13. 3. Conferência 2 caixas da DEFNAS. | AA18: 1. Guarda das 70 caixas do DEFNAS. 2. Reunião: Apresentação do novo chefe (Leonardo) do Arquivo. | AC18: 1. Desarquivamento 70 caixas do DEFNAS. 2. Recebimento: 70 caixas do DEFNAS. 3. Reunião sobre reforma da nossa sala 24.32 e não ter home office, trabalhar presencial. | AD18: Pesquisa e busca por pasta funcional Albano Soares Martins Junior | AE18: Pesquisa e busca por pasta funcional Albano Soares Martins Junior | AG18: 1. Pesquisa e busca por pasta funcional Albano Soares Martins Junior. 2. Desarquivamento processo de nomeação de Albano Soares Martins Junior. | AH18: Arquivamento de Pastas Funcionais e documentos de Dyleny Teixeira Alves da Silva. | AI18: Arquivamento de Pasta funcionais e 1 processo de Mariana Aparecida Lima Neves e Marcos Roberto dos Santos Barbosa. | AM18: Ponto Facultativo Carnaval | AN18: Feriado de Carnaval | AO18: 1. Pesquisa e busca processo 71001.057163/2008-68 | AP18: 1. Desarquivamento 70 caixas do DEFNAS. Caixas: 3251 a 3320. 2. Recebimento: 70 caixas do DEFNAS. Caixas: 3181 a 3250. | AQ18: Conferência 6 caixas da DEFNAS. | AS18: 1. Conferência 5 caixas da DEFNAS. 2. Pesquisa localização processos: 44006.004706/2000-21 - Encontrada a caixa. 44006.002300/2001-39 44000.001801/2007-42 | AT18: 1. Troca de caixa e espelho. Total 5 caixas. 2. Pesquisa localização processos: 44006.004706/2000-21 - Encontrada a caixa. 44006.002300/2001-39 44000.001801/2007-42 | AU18: Arquivamento de 70 caixas do DEFNAS | AV18: 1. Arquivamento processoS da SESAN. 2. Pesquisa localização de 14 processos vindo da DIPRO mais 1 CD. Os processos são cópias, ver se existe o original. | AW18: 1. Pesquisa localização processos: 44006.004706/2000-21 - Encontrada a caixa. 44006.002300/2001-39 44000.001801/2007-42 2. Pesquisa localização de 14 processos vindo da DIPRO mais 1 CD. Os processos são cópias, ver se existe o original.
A19: OBSERVAÇÃO

Sheet Leonam
A1: INDICADORES | C1: 45662 | D1: 45663 | E1: 45664 | F1: 45665 | G1: 45666 | H1: TOTAL SEMANA | I1: 45669 | J1: 45670 | K1: 45671 | L1: 45672 | M1: 45673 | N1: TOTAL SEMANA | O1: 45676 | P1: 45677 | Q1: 45678 | R1: 45679 | S1: 45680 | T1: TOTAL SEMANA | U1: 45683 | V1: 45684 | W1: 45685 | X1: 45686 | Y1: 45687 | Z1: TOTAL SEMANA | AA1: 45690 | AB1: 45691 | AC1: 45692 | AD1: 45693 | AE1: 45694 | AF1: TOTAL SEMANA | AG1: 45697 | AH1: 45698 | AI1: 45699 | AJ1: 45700 | AK1: 45701 | AL1: TOTAL SEMANA | AM1: 45704 | AN1: 45705 | AO1: 45706 | AP1: 45707 | AQ1: 45708 | AR1: TOTAL SEMANA | AS1: 45711 | AT1: 45712 | AU1: 45713 | AV1: 45714 | AW1: 45715 | AX1: TOTAL SEMANA
A2: Desarquivamento de Processos/Documentos - Saída de Guia Fora | B2: 1 | H2: =SUM(C2:G2) -> 0 | K2: 1 | N2: =SUM(I2:M2) -> 1 | T2: =SUM(O2:S2) -> 0 | Z2: =SUM(U2:Y2) -> 0 | AF2: =SUM(AA2:AE2) -> 0 | AG2: 1 | AL2: =SUM(AG2:AK2) -> 1 | AM2: RECESSO | AN2: CARNAVAL | AR2: =SUM(AM2:AQ2) -> 0 | AX2: =SUM(AS2:AW2) -> 0
A3: Caixas consultadas em pesquisa de desarquivamento | B3: 2 | H3: =SUM(C3:G3) -> 0 | K3: 55 | N3: =SUM(I3:M3) -> 55 | T3: =SUM(O3:S3) -> 0 | Z3: =SUM(U3:Y3) -> 0 | AF3: =SUM(AA3:AE3) -> 0 | AL3: =SUM(AG3:AK3) -> 0 | AM3: RECESSO | AN3: CARNAVAL | AR3: =SUM(AM3:AQ3) -> 0 | AX3: =SUM(AS3:AW3) -> 0
A4: Retorno de Processos/Documentos Desarquivados | B4: 3 | H4: =SUM(C4:G4) -> 0 | N4: =SUM(I4:M4) -> 0 | T4: =SUM(O4:S4) -> 0 | Z4: =SUM(U4:Y4) -> 0 | AF4: =SUM(AA4:AE4) -> 0 | AH4: 2 | AI4: 2 | AL4: =SUM(AG4:AK4) -> 4 | AM4: RECESSO | AN4: CARNAVAL | AR4: =SUM(AM4:AQ4) -> 0 | AX4: =SUM(AS4:AW4) -> 0
A5: Recebimento de Documentos - Guia de Transferência | B5: 4 | G5: 12 | H5: =SUM(C5:G5) -> 12 | N5: =SUM(I5:M5) -> 0 | T5: =SUM(O5:S5) -> 0 | Z5: =SUM(U5:Y5) -> 0 | AF5: =SUM(AA5:AE5) -> 0 | AL5: =SUM(AG5:AK5) -> 0 | AM5: RECESSO | AN5: CARNAVAL | AR5: =SUM(AM5:AQ5) -> 0 | AX5: =SUM(AS5:AW5) -> 0
A6: Caixas separadas para classificação | B6: 5 | H6: =SUM(C6:G6) -> 0 | N6: =SUM(I6:M6) -> 0 | T6: =SUM(O6:S6) -> 0 | Z6: =SUM(U6:Y6) -> 0 | AF6: =SUM(AA6:AE6) -> 0 | AL6: =SUM(AG6:AK6) -> 0 | AM6: RECESSO | AN6: CARNAVAL | AR6: =SUM(AM6:AQ6) -> 0 | AX6: =SUM(AS6:AW6) -> 0
A7: Processos/Documentos classificados | B7: 6 | H7: =SUM(C7:G7) -> 0 | N7: =SUM(I7:M7) -> 0 | T7: =SUM(O7:S7) -> 0 | Z7: =SUM(U7:Y7) -> 0 | AF7: =SUM(AA7:AE7) -> 0 | AL7: =SUM(AG7:AK7) -> 0 | AM7: RECESSO | AN7: CARNAVAL | AR7: =SUM(AM7:AQ7) -> 0 | AX7: =SUM(AS7:AW7) -> 0
A8: Caixas separadas para eliminação | B8: 7 | H8: =SUM(C8:G8) -> 0 | N8: =SUM(I8:M8) -> 0 | T8: =SUM(O8:S8) -> 0 | Z8: =SUM(U8:Y8) -> 0 | AF8: =SUM(AA8:AE8) -> 0 | AL8: =SUM(AG8:AK8) -> 0 | AM8: RECESSO | AN8: CARNAVAL | AR8: =SUM(AM8:AQ8) -> 0 | AX8: =SUM(AS8:AW8) -> 0
A9: Caixas listadas para eliminação | B9: 8 | H9: =SUM(C9:G9) -> 0 | N9: =SUM(I9:M9) -> 0 | T9: =SUM(O9:S9) -> 0 | Z9: =SUM(U9:Y9) -> 0 | AF9: =SUM(AA9:AE9) -> 0 | AL9: =SUM(AG9:AK9) -> 0 | AM9: RECESSO | AN9: CARNAVAL | AR9: =SUM(AM9:AQ9) -> 0 | AX9: =SUM(AS9:AW9) -> 0
A10: Processos/Documentos listados para eliminação | B10: 9 | H10: =SUM(C10:G10) -> 0 | N10: =SUM(I10:M10) -> 0 | T10: =SUM(O10:S10) -> 0 | Z10: =SUM(U10:Y10) -> 0 | AF10: =SUM(AA10:AE10) -> 0 | AL10: =SUM(AG10:AK10) -> 0 | AM10: RECESSO | AN10: CARNAVAL | AR10: =SUM(AM10:AQ10) -> 0 | AX10: =SUM(AS10:AW10) -> 0
A11: Caixas inventariadas | B11: 10 | H11: =SUM(C11:G11) -> 0 | N11: =SUM(I11:M11) -> 0 | T11: =SUM(O11:S11) -> 0 | Z11: =SUM(U11:Y11) -> 0 | AF11: =SUM(AA11:AE11) -> 0 | AL11: =SUM(AG11:AK11) -> 0 | AM11: RECESSO | AN11: CARNAVAL | AR11: =SUM(AM11:AQ11) -> 0 | AX11: =SUM(AS11:AW11) -> 0
A12: Processos/documentos inventariados | B12: 11 | H12: =SUM(C12:G12) -> 0 | N12: =SUM(I12:M12) -> 0 | T12: =SUM(O12:S12) -> 0 | Z12: =SUM(U12:Y12) -> 0 | AF12: =SUM(AA12:AE12) -> 0 | AL12: =SUM(AG12:AK12) -> 0 | AM12: RECESSO | AN12: CARNAVAL | AR12: =SUM(AM12:AQ12) -> 0 | AX12: =SUM(AS12:AW12) -> 0
A13: Documentos administrativos produzidos (Despacho, Nota Técnica, minutas diversas) | B13: 12 | H13: =SUM(C13:G13) -> 0 | N13: =SUM(I13:M13) -> 0 | T13: =SUM(O13:S13) -> 0 | Z13: =SUM(U13:Y13) -> 0 | AB13: 1 | AD13: 2 | AF13: =SUM(AA13:AE13) -> 3 | AL13: =SUM(AG13:AK13) -> 0 | AM13: RECESSO | AN13: CARNAVAL | AR13: =SUM(AM13:AQ13) -> 0 | AX13: =SUM(AS13:AW13) -> 0
A14: Orientação técnica / atendimentos realizados | B14: 13 | H14: =SUM(C14:G14) -> 0 | N14: =SUM(I14:M14) -> 0 | T14: =SUM(O14:S14) -> 0 | Z14: =SUM(U14:Y14) -> 0 | AF14: =SUM(AA14:AE14) -> 0 | AL14: =SUM(AG14:AK14) -> 0 | AM14: RECESSO | AN14: CARNAVAL | AR14: =SUM(AM14:AQ14) -> 0 | AX14: =SUM(AS14:AW14) -> 0
A15: Caixas remanejadas | B15: 14 | H15: =SUM(C15:G15) -> 0 | N15: =SUM(I15:M15) -> 0 | T15: =SUM(O15:S15) -> 0 | V15: 70 | Z15: =SUM(U15:Y15) -> 70 | AA15: 70 | AC15: 140 | AF15: =SUM(AA15:AE15) -> 210 | AL15: =SUM(AG15:AK15) -> 0 | AM15: RECESSO | AN15: CARNAVAL | AP15: 140 | AR15: =SUM(AM15:AQ15) -> 140 | AX15: =SUM(AS15:AW15) -> 0
A16: Caixas conferidas | B16: 15 | H16: =SUM(C16:G16) -> 0 | N16: =SUM(I16:M16) -> 0 | T16: =SUM(O16:S16) -> 0 | Z16: =SUM(U16:Y16) -> 0 | AF16: =SUM(AA16:AE16) -> 0 | AL16: =SUM(AG16:AK16) -> 0 | AM16: RECESSO | AN16: CARNAVAL | AQ16: 8 | AR16: =SUM(AM16:AQ16) -> 8 | AX16: =SUM(AS16:AW16) -> 0
A17: Caixas substituídas(trocadas) | B17: 16 | C17: 10 | D17: 10 | E17: 10 | F17: 5 | H17: =SUM(C17:G17) -> 35 | I17: 10 | J17: 10 | K17: 6 | M17: 10 | N17: =SUM(I17:M17) -> 36 | O17: 10 | P17: 10 | Q17: 10 | R17: 10 | S17: 10 | T17: =SUM(O17:S17) -> 50 | Z17: =SUM(U17:Y17) -> 0 | AB17: 10 | AF17: =SUM(AA17:AE17) -> 10 | AL17: =SUM(AG17:AK17) -> 0 | AM17: RECESSO | AN17: CARNAVAL | AR17: =SUM(AM17:AQ17) -> 0 | AX17: =SUM(AS17:AW17) -> 0
A18: OUTRA ATIVIDADE. QUAL? | C18: TROCANDO CAIXAS E OS ESPELHOS | D18: TROCANDO CAIXAS E OS ESPELHOS | E18: TROCANDO CAIXAS E OS ESPELHOS | F18: TROCA DE CAIXAS E ESPELHOS | G18: CONFERÊNCIA DE 12 CAIXAS CGPCO | I18: TROCANDO CAIXAS E OS ESPELHOS | J18: TROCANDO CAIXAS E OS ESPELHOS | K18: TROCANDO CAIXAS E OS ESPELHOS | L18: MONITORAMENTO DA LIMPEZA DA SALA G15 (BL A) | M18: TROCANDO CAIXAS E OS ESPELHOS | O18: TROCANDO CAIXAS E OS ESPELHOS | P18: TROCANDO CAIXAS E OS ESPELHOS | Q18: TROCANDO CAIXAS E OS ESPELHOS | R18: TROCANDO CAIXAS E OS ESPELHOS | S18: TROCANDO CAIXAS E OS ESPELHOS | U18: TROCA DE CAIXAS | V18: 1 - RECEBIMENTO DE 70 CAIXAS DA CGPC 2 - ENVIANDO 70 CAIXAS PARA O MONTES | W18: CONFERÊNCIA DE CAIXAS DFSNAS | X18: CONFERÊNCIA DE CAIXAS DFSNAS | Y18: MONITORAMENTO DA LIMPEZA DA SALA G15/ G7 (BL A) | AA18: Reunião pela parte da manha | AC18: 1. Desarquivamento 70 caixas do DEFNAS. 2. Recebimento: 70 caixas do DEFNAS. 3. Reunião sobre reforma da nossa sala 24.32 e não ter home office, trabalhar presencial. | AD18: Pesquisa e busca por pasta funcional Albano Soares Martins Junior | AE18: Pesquisa e busca por pasta funcional Albano Soares Martins Junior | AG18: entrega da pasta funcional Albano Soares Martins Junior | AH18: arquivamento de pasta funcionais | AI18: arquivamento de pasta funcionais | AJ18: TROCANDO CAIXAS E OS ESPELHOS | AK18: TROCANDO CAIXAS E OS ESPELHOS | AO18: ATESTADO | AP18: RECEBIMENTO DE 70 CAIXAS DA CGPC E ENVIO DE 70 CAIXAS DA CGPC | AQ18: CONFERENCIA DE CAIXAS DA CGPC
A19: OBSERVAÇÃO | F19: RECEBIMENTO DE 70 CAIXAS CGPCO | K19: PESQUISA E DESARQUIVAMENTO DO PROCESSO 58000.002183/2009-24 NO BLOCO 'A' | L19: RECEBIMENTO DE PROCESSO (BL A) | V19: ENVIANDO 104 PROCESSOS PARA BLOCO A | Y19: ARQUIVANDO PROCESSO DE 104 VOLUMES NO BLOCO A | AA19: Reunião pela parte da tarde

Sheet Danilo
A1: INDICADORES | C1: 45662 | D1: 45663 | E1: 45664 | F1: 45665 | G1: 45666 | H1: TOTAL SEMANA | I1: 45669 | J1: 45670 | K1: 45671 | L1: 45672 | M1: 45673 | N1: TOTAL SEMANA | O1: 45676 | P1: 45677 | Q1: 45678 | R1: 45679 | S1: 45680 | T1: TOTAL SEMANA | U1: 45683 | V1: 45684 | W1: 45685 | X1: 45686 | Y1: 45687 | Z1: TOTAL SEMANA | AA1: 45690 | AB1: 45691 | AC1: 45692 | AD1: 45693 | AE1: 45694 | AF1: TOTAL SEMANA | AG1: 45697 | AH1: 45698 | AI1: 45699 | AJ1: 45700 | AK1: 45701 | AL1: TOTAL SEMANA | AM1: 45704 | AN1: 45705 | AO1: 45706 | AP1: 45707 | AQ1: 45708 | AR1: TOTAL SEMANA | AS1: 45711 | AT1: 45712 | AU1: 45713 | AV1: 45714 | AW1: 45715 | AX1: TOTAL SEMANA
A2: Desarquivamento de Processos/Documentos - Saída de Guia Fora | B2: 1 | H2: =SUM(C2:G2) -> 0 | K2: 1 | N2: =SUM(I2:M2) -> 1 | T2: =SUM(O2:S2) -> 0 | W2: 1 | Z2: =SUM(U2:Y2) -> 1 | AF2: =SUM(AA2:AE2) -> 0 | AL2: =SUM(AG2:AK2) -> 0 | AM2: RECESSO | AN2: CARNAVAL | AR2: =SUM(AM2:AQ2) -> 0 | AX2: =SUM(AS2:AW2) -> 0
A3: Caixas consultadas em pesquisa de desarquivamento | B3: 2 | H3: =SUM(C3:G3) -> 0 | K3: 55 | N3: =SUM(I3:M3) -> 55 | T3: =SUM(O3:S3) -> 0 | U3: 5 | Z3: =SUM(U3:Y3) -> 5 | AD3: 4 | AF3: =SUM(AA3:AE3) -> 4 | AL3: =SUM(AG3:AK3) -> 0 | AM3: RECESSO | AN3: CARNAVAL | AR3: =SUM(AM3:AQ3) -> 0 | AX3: =SUM(AS3:AW3) -> 0
A4: Retorno de Processos/Documentos Desarquivados | B4: 3 | H4: =SUM(C4:G4) -> 0 | N4: =SUM(I4:M4) -> 0 | T4: =SUM(O4:S4) -> 0 | V4: 1 | X4: 8 | Y4: 12 | Z4: =SUM(U4:Y4) -> 21 | AF4: =SUM(AA4:AE4) -> 0 | AL4: =SUM(AG4:AK4) -> 0 | AM4: RECESSO | AN4: CARNAVAL | AR4: =SUM(AM4:AQ4) -> 0 | AV4: 2 | AX4: =SUM(AS4:AW4) -> 2
A5: Recebimento de Documentos - Guia de Transferência | B5: 4 | G5: 12 | H5: =SUM(C5:G5) -> 12 | N5: =SUM(I5:M5) -> 0 | T5: =SUM(O5:S5) -> 0 | Z5: =SUM(U5:Y5) -> 0 | AF5: =SUM(AA5:AE5) -> 0 | AL5: =SUM(AG5:AK5) -> 0 | AM5: RECESSO | AN5: CARNAVAL | AR5: =SUM(AM5:AQ5) -> 0 | AV5: 1 | AX5: =SUM(AS5:AW5) -> 1
A6: Caixas separadas para classificação | B6: 5 | H6: =SUM(C6:G6) -> 0 | N6: =SUM(I6:M6) -> 0 | T6: =SUM(O6:S6) -> 0 | Z6: =SUM(U6:Y6) -> 0 | AF6: =SUM(AA6:AE6) -> 0 | AL6: =SUM(AG6:AK6) -> 0 | AM6: RECESSO | AN6: CARNAVAL | AR6: =SUM(AM6:AQ6) -> 0 | AX6: =SUM(AS6:AW6) -> 0
A7: Processos/Documentos classificados | B7: 6 | H7: =SUM(C7:G7) -> 0 | N7: =SUM(I7:M7) -> 0 | T7: =SUM(O7:S7) -> 0 | Z7: =SUM(U7:Y7) -> 0 | AF7: =SUM(AA7:AE7) -> 0 | AL7: =SUM(AG7:AK7) -> 0 | AM7: RECESSO | AN7: CARNAVAL | AR7: =SUM(AM7:AQ7) -> 0 | AX7: =SUM(AS7:AW7) -> 0
A8: Caixas separadas para eliminação | B8: 7 | H8: =SUM(C8:G8) -> 0 | N8: =SUM(I8:M8) -> 0 | T8: =SUM(O8:S8) -> 0 | Z8: =SUM(U8:Y8) -> 0 | AF8: =SUM(AA8:AE8) -> 0 | AL8: =SUM(AG8:AK8) -> 0 | AM8: RECESSO | AN8: CARNAVAL | AR8: =SUM(AM8:AQ8) -> 0 | AX8: =SUM(AS8:AW8) -> 0
A9: Caixas listadas para eliminação | B9: 8 | H9: =SUM(C9:G9) -> 0 | N9: =SUM(I9:M9) -> 0 | T9: =SUM(O9:S9) -> 0 | Z9: =SUM(U9:Y9) -> 0 | AF9: =SUM(AA9:AE9) -> 0 | AL9: =SUM(AG9:AK9) -> 0 | AM9: RECESSO | AN9: CARNAVAL | AR9: =SUM(AM9:AQ9) -> 0 | AX9: =SUM(AS9:AW9) -> 0
A10: Processos/Documentos listados para eliminação | B10: 9 | H10: =SUM(C10:G10) -> 0 | N10: =SUM(I10:M10) -> 0 | T10: =SUM(O10:S10) -> 0 | Z10: =SUM(U10:Y10) -> 0 | AF10: =SUM(AA10:AE10) -> 0 | AL10: =SUM(AG10:AK10) -> 0 | AM10: RECESSO | AN10: CARNAVAL | AR10: =SUM(AM10:AQ10) -> 0 | AX10: =SUM(AS10:AW10) -> 0
A11: Caixas inventariadas | B11: 10 | H11: =SUM(C11:G11) -> 0 | N11: =SUM(I11:M11) -> 0 | T11: =SUM(O11:S11) -> 0 | Z11: =SUM(U11:Y11) -> 0 | AF11: =SUM(AA11:AE11) -> 0 | AL11: =SUM(AG11:AK11) -> 0 | AM11: RECESSO | AN11: CARNAVAL | AR11: =SUM(AM11:AQ11) -> 0 | AX11: =SUM(AS11:AW11) -> 0
A12: Processos/documentos inventariados | B12: 11 | H12: =SUM(C12:G12) -> 0 | N12: =SUM(I12:M12) -> 0 | T12: =SUM(O12:S12) -> 0 | Z12: =SUM(U12:Y12) -> 0 | AF12: =SUM(AA12:AE12) -> 0 | AL12: =SUM(AG12:AK12) -> 0 | AM12: RECESSO | AN12: CARNAVAL | AR12: =SUM(AM12:AQ12) -> 0 | AX12: =SUM(AS12:AW12) -> 0
A13: Documentos administrativos produzidos (Despacho, Nota Técnica, minutas diversas) | B13: 12 | H13: =SUM(C13:G13) -> 0 | N13: =SUM(I13:M13) -> 0 | T13: =SUM(O13:S13) -> 0 | W13: 3 | Z13: =SUM(U13:Y13) -> 3 | AF13: =SUM(AA13:AE13) -> 0 | AG13: 2 | AH13: 2 | AL13: =SUM(AG13:AK13) -> 4 | AM13: RECESSO | AN13: CARNAVAL | AR13: =SUM(AM13:AQ13) -> 0 | AX13: =SUM(AS13:AW13) -> 0
A14: Orientação técnica / atendimentos realizados | B14: 13 | H14: =SUM(C14:G14) -> 0 | N14: =SUM(I14:M14) -> 0 | T14: =SUM(O14:S14) -> 0 | Z14: =SUM(U14:Y14) -> 0 | AF14: =SUM(AA14:AE14) -> 0 | AL14: =SUM(AG14:AK14) -> 0 | AM14: RECESSO | AN14: CARNAVAL | AR14: =SUM(AM14:AQ14) -> 0 | AX14: =SUM(AS14:AW14) -> 0
A15: Caixas remanejadas | B15: 14 | H15: =SUM(C15:G15) -> 0 | N15: =SUM(I15:M15) -> 0 | T15: =SUM(O15:S15) -> 0 | Z15: =SUM(U15:Y15) -> 0 | AA15: 70 | AC15: 140 | AF15: =SUM(AA15:AE15) -> 210 | AL15: =SUM(AG15:AK15) -> 0 | AM15: RECESSO | AN15: CARNAVAL | AP15: 140 | AR15: =SUM(AM15:AQ15) -> 140 | AU15: 70 | AX15: =SUM(AS15:AW15) -> 70
A16: Caixas conferidas | B16: 15 | H16: =SUM(C16:G16) -> 0 | N16: =SUM(I16:M16) -> 0 | T16: =SUM(O16:S16) -> 0 | Z16: =SUM(U16:Y16) -> 0 | AF16: =SUM(AA16:AE16) -> 0 | AL16: =SUM(AG16:AK16) -> 0 | AM16: RECESSO | AN16: CARNAVAL | AQ16: 8 | AR16: =SUM(AM16:AQ16) -> 8 | AS16: 5 | AX16: =SUM(AS16:AW16) -> 5
A17: Caixas substituídas(trocadas) | B17: 16 | E17: 10 | F17: 10 | H17: =SUM(C17:G17) -> 20 | I17: 12 | J17: 10 | K17: 10 | M17: 12 | N17: =SUM(I17:M17) -> 44 | O17: 5 | P17: 5 | Q17: 5 | R17: 5 | S17: 5 | T17: =SUM(O17:S17) -> 25 | Z17: =SUM(U17:Y17) -> 0 | AB17: 10 | AF17: =SUM(AA17:AE17) -> 10 | AI17: 7 | AJ17: 7 | AK17: 7 | AL17: =SUM(AG17:AK17) -> 21 | AM17: RECESSO | AN17: CARNAVAL | AR17: =SUM(AM17:AQ17) -> 0 | AT17: 5 | AV17: 3 | AW17: 7 | AX17: =SUM(AS17:AW17) -> 15
A18: OUTRA ATIVIDADE. QUAL? | C18: AUSENCIA JUSTIFICADA | D18: AUSENCIA JUSTIFICADA | E18: TROCA DE CAIXAS E ESPELHOS | F18: TROCA DE CAIXAS E ESPELHOS | G18: CONFERÊNCIA DE 12 CAIXAS CGPCO | I18: TROCA DE CAIXAS E ESPELHOS | J18: TROCA DE CAIXAS E ESPELHOS | K18: TROCA DE CAIXAS E ESPELHOS | L18: MONITORAMENTO DA LIMPEZA DA SALA G15/ G7 (BL A) | M18: TROCA DE CAIXAS E ESPELHOS | O18: TROCA DE CAIXAS E ESPELHOS | P18: TROCA DE CAIXAS E ESPELHOS | Q18: TROCA DE CAIXAS E ESPELHOS | R18: TROCA DE CAIXAS E ESPELHOS | S18: TROCA DE CAIXAS E ESPELHOS | U18: Vistórias das salas G15/G7/G17 BLOCO A. Pesquisando desarquivamento | V18: Informações prestadas dos dislizantes bloco A. Recebimento de 104 volumes no BLOCO A | X18: Caixas separadas, referente aos 104 volumes.Entrega de 07 volumes na dipro para digitalizar | Y18: Caixas separadas, referente aos 104 volumes | AA18: Reunião pela parte da manha | AC18: 1. Desarquivamento 70 caixas do DEFNAS. 2. Recebimento: 70 caixas do DEFNAS. 3. Reunião sobre reforma da nossa sala 24.32 e não ter home office, trabalhar presencial. | AD18: Pesquisa e busca por pasta funcional Albano Soares Martins Junior | AE18: Pesquisa e busca por pasta funcional Albano Soares Martins Junior | AH18: arquivamento de pasta funcionais | AI18: 1.arquivamento de pasta funcionais. 2.TROCANDO CAIXAS E OS ESPELHOS | AJ18: TROCANDO CAIXAS E OS ESPELHOS | AK18: TROCANDO CAIXAS E OS ESPELHOS | AO18: recebendo pedido de processos | AP18: RECEBIMENTO DE 70 CAIXAS DA CGPC E ENVIO DE 70 CAIXAS DA CGPC | AQ18: CONFERENCIA DE CAIXAS DA CGPC | AS18: 1. Conferência 5 caixas da DEFNAS. | AT18: 1. Troca de caixa e espelho. Total 5 caixas. | AU18: Arquivamento de 70 caixas do DEFNAS | AV18: 1. Troa de caixas e espelhos 2.ARQUIVAMENTO DE PROCESSO BLOCO A 7 VOLUMES.RECEBIMENTO DE 01 PASTA FUNCIONAL BL A | AW18: Troca de caixas e espelho
A19: OBSERVAÇÃO | F19: RECEBIMENTO DE 70 CAIXAS CGPCO | K19: PESQUISA E DESARQUIVAMENTO DO PROCESSO 58000.002183/2009-24 NO BLOCO 'A' | L19: RECEBIMENTO DE PROCESSO (BL A)

Sheet Marcos
A1: INDICADORES | C1: 45662 | D1: 45663 | E1: 45664 | F1: 45665 | G1: 45666 | H1: TOTAL SEMANA | I1: 45669 | J1: 45670 | K1: 45671 | L1: 45672 | M1: 45673 | N1: TOTAL SEMANA | O1: 45676 | P1: 45677 | Q1: 45678 | R1: 45679 | S1: 45680 | T1: TOTAL SEMANA | U1: 45683 | V1: 45684 | W1: 45685 | X1: 45686 | Y1: 45687 | Z1: TOTAL SEMANA | AA1: 45690 | AB1: 45691 | AC1: 45692 | AD1: 45693 | AE1: 45694 | AF1: TOTAL SEMANA | AG1: 45697 | AH1: 45698 | AI1: 45699 | AJ1: 45700 | AK1: 45701 | AL1: TOTAL SEMANA | AM1: 45704 | AN1: 45705 | AO1: 45706 | AP1: 45707 | AQ1: 45708 | AR1: TOTAL SEMANA | AS1: 45711 | AT1: 45712 | AU1: 45713 | AV1: 45714 | AW1: 45715 | AX1: TOTAL SEMANA
A2: Desarquivamento de Processos/Documentos - Saída de Guia Fora | B2: 1 | H2: =SUM(C2:G2) -> 0 | N2: =SUM(I2:M2) -> 0 | T2: =SUM(O2:S2) -> 0 | Z2: =SUM(U2:Y2) -> 0 | AF2: =SUM(AA2:AE2) -> 0 | AL2: =SUM(AG2:AK2) -> 0 | AM2: RECESSO | AN2: CARNAVAL | AR2: =SUM(AM2:AQ2) -> 0 | AX2: =SUM(AS2:AW2) -> 0
A3: Caixas consultadas em pesquisa de desarquivamento | B3: 2 | H3: =SUM(C3:G3) -> 0 | N3: =SUM(I3:M3) -> 0 | T3: =SUM(O3:S3) -> 0 | Z3: =SUM(U3:Y3) -> 0 | AF3: =SUM(AA3:AE3) -> 0 | AL3: =SUM(AG3:AK3) -> 0 | AM3: RECESSO | AN3: CARNAVAL | AP3: 2 | AR3: =SUM(AM3:AQ3) -> 2 | AX3: =SUM(AS3:AW3) -> 0
A4: Retorno de Processos/Documentos Desarquivados | B4: 3 | H4: =SUM(C4:G4) -> 0 | N4: =SUM(I4:M4) -> 0 | T4: =SUM(O4:S4) -> 0 | Z4: =SUM(U4:Y4) -> 0 | AF4: =SUM(AA4:AE4) -> 0 | AL4: =SUM(AG4:AK4) -> 0 | AM4: RECESSO | AN4: CARNAVAL | AR4: =SUM(AM4:AQ4) -> 0 | AX4: =SUM(AS4:AW4) -> 0
A5: Recebimento de Documentos - Guia de Transferência | B5: 4 | H5: =SUM(C5:G5) -> 0 | N5: =SUM(I5:M5) -> 0 | T5: =SUM(O5:S5) -> 0 | Z5: =SUM(U5:Y5) -> 0 | AF5: =SUM(AA5:AE5) -> 0 | AL5: =SUM(AG5:AK5) -> 0 | AM5: RECESSO | AN5: CARNAVAL | AR5: =SUM(AM5:AQ5) -> 0 | AX5: =SUM(AS5:AW5) -> 0
A6: Caixas separadas para classificação | B6: 5 | H6: =SUM(C6:G6) -> 0 | N6: =SUM(I6:M6) -> 0 | T6: =SUM(O6:S6) -> 0 | Z6: =SUM(U6:Y6) -> 0 | AF6: =SUM(AA6:AE6) -> 0 | AL6: =SUM(AG6:AK6) -> 0 | AM6: RECESSO | AN6: CARNAVAL | AR6: =SUM(AM6:AQ6) -> 0 | AX6: =SUM(AS6:AW6) -> 0
A7: Processos/Documentos classificados | B7: 6 | H7: =SUM(C7:G7) -> 0 | N7: =SUM(I7:M7) -> 0 | T7: =SUM(O7:S7) -> 0 | Z7: =SUM(U7:Y7) -> 0 | AF7: =SUM(AA7:AE7) -> 0 | AL7: =SUM(AG7:AK7) -> 0 | AM7: RECESSO | AN7: CARNAVAL | AR7: =SUM(AM7:AQ7) -> 0 | AX7: =SUM(AS7:AW7) -> 0
A8: Caixas separadas para eliminação | B8: 7 | H8: =SUM(C8:G8) -> 0 | N8: =SUM(I8:M8) -> 0 | T8: =SUM(O8:S8) -> 0 | Z8: =SUM(U8:Y8) -> 0 | AF8: =SUM(AA8:AE8) -> 0 | AL8: =SUM(AG8:AK8) -> 0 | AM8: RECESSO | AN8: CARNAVAL | AR8: =SUM(AM8:AQ8) -> 0 | AX8: =SUM(AS8:AW8) -> 0
A9: Caixas listadas para eliminação | B9: 8 | H9: =SUM(C9:G9) -> 0 | N9: =SUM(I9:M9) -> 0 | T9: =SUM(O9:S9) -> 0 | Z9: =SUM(U9:Y9) -> 0 | AF9: =SUM(AA9:AE9) -> 0 | AL9: =SUM(AG9:AK9) -> 0 | AM9: RECESSO | AN9: CARNAVAL | AR9: =SUM(AM9:AQ9) -> 0 | AX9: =SUM(AS9:AW9) -> 0
A10: Processos/Documentos listados para eliminação | B10: 9 | H10: =SUM(C10:G10) -> 0 | N10: =SUM(I10:M10) -> 0 | T10: =SUM(O10:S10) -> 0 | Z10: =SUM(U10:Y10) -> 0 | AF10: =SUM(AA10:AE10) -> 0 | AL10: =SUM(AG10:AK10) -> 0 | AM10: RECESSO | AN10: CARNAVAL | AR10: =SUM(AM10:AQ10) -> 0 | AX10: =SUM(AS10:AW10) -> 0
A11: Caixas inventariadas | B11: 10 | H11: =SUM(C11:G11) -> 0 | N11: =SUM(I11:M11) -> 0 | T11: =SUM(O11:S11) -> 0 | Z11: =SUM(U11:Y11) -> 0 | AF11: =SUM(AA11:AE11) -> 0 | AL11: =SUM(AG11:AK11) -> 0 | AM11: RECESSO | AN11: CARNAVAL | AR11: =SUM(AM11:AQ11) -> 0 | AX11: =SUM(AS11:AW11) -> 0
A12: Processos/documentos inventariados | B12: 11 | H12: =SUM(C12:G12) -> 0 | N12: =SUM(I12:M12) -> 0 | T12: =SUM(O12:S12) -> 0 | Z12: =SUM(U12:Y12) -> 0 | AF12: =SUM(AA12:AE12) -> 0 | AL12: =SUM(AG12:AK12) -> 0 | AM12: RECESSO | AN12: CARNAVAL | AR12: =SUM(AM12:AQ12) -> 0 | AX12: =SUM(AS12:AW12) -> 0
A13: Documentos administrativos produzidos (Despacho, Nota Técnica, minutas diversas) | B13: 12 | H13: =SUM(C13:G13) -> 0 | N13: =SUM(I13:M13) -> 0 | T13: =SUM(O13:S13) -> 0 | Z13: =SUM(U13:Y13) -> 0 | AF13: =SUM(AA13:AE13) -> 0 | AL13: =SUM(AG13:AK13) -> 0 | AM13: RECESSO | AN13: CARNAVAL | AR13: =SUM(AM13:AQ13) -> 0 | AX13: =SUM(AS13:AW13) -> 0
A14: Orientação técnica / atendimentos realizados | B14: 13 | H14: =SUM(C14:G14) -> 0 | N14: =SUM(I14:M14) -> 0 | T14: =SUM(O14:S14) -> 0 | Z14: =SUM(U14:Y14) -> 0 | AF14: =SUM(AA14:AE14) -> 0 | AL14: =SUM(AG14:AK14) -> 0 | AM14: RECESSO | AN14: CARNAVAL | AR14: =SUM(AM14:AQ14) -> 0 | AX14: =SUM(AS14:AW14) -> 0
A15: Caixas remanejadas | B15: 14 | F15: 149 | H15: =SUM(C15:G15) -> 149 | L15: 70 | N15: =SUM(I15:M15) -> 70 | T15: =SUM(O15:S15) -> 0 | Z15: =SUM(U15:Y15) -> 0 | AB15: 70 | AC15: 70 | AF15: =SUM(AA15:AE15) -> 140 | AH15: 70 | AI15: 70 | AL15: =SUM(AG15:AK15) -> 140 | AM15: RECESSO | AN15: CARNAVAL | AP15: 140 | AR15: =SUM(AM15:AQ15) -> 140 | AT15: 70 | AX15: =SUM(AS15:AW15) -> 70
A16: Caixas conferidas | B16: 15 | H16: =SUM(C16:G16) -> 0 | N16: =SUM(I16:M16) -> 0 | T16: =SUM(O16:S16) -> 0 | Z16: =SUM(U16:Y16) -> 0 | AF16: =SUM(AA16:AE16) -> 0 | AL16: =SUM(AG16:AK16) -> 0 | AM16: RECESSO | AN16: CARNAVAL | AQ16: 8 | AR16: =SUM(AM16:AQ16) -> 8 | AS16: 7 | AX16: =SUM(AS16:AW16) -> 7
A17: Caixas substituídas(trocadas) | B17: 16 | C17: 15 | D17: 14 | E17: 17 | G17: 14 | H17: =SUM(C17:G17) -> 60 | I17: 15 | J17: 12 | K17: 14 | M17: 15 | N17: =SUM(I17:M17) -> 56 | O17: 17 | P17: 14 | Q17: 14 | R17: 15 | S17: 16 | T17: =SUM(O17:S17) -> 76 | U17: 15 | V17: 244 | W17: 10 | Y17: 9 | Z17: =SUM(U17:Y17) -> 278 | AF17: =SUM(AA17:AE17) -> 0 | AL17: =SUM(AG17:AK17) -> 0 | AM17: RECESSO | AN17: CARNAVAL | AR17: =SUM(AM17:AQ17) -> 0 | AU17: 8 | AV17: 10 | AW17: 8 | AX17: =SUM(AS17:AW17) -> 26
A18: OUTRA ATIVIDADE. QUAL? | C18: TROCA DE CAIXAS | D18: TROCA DE CAIXAS | E18: TROCA DE CAIXAS | F18: 1. Desarquivamento de 70 caixas do DEFNAS e Recebimento de 79. | G18: TROCA DE CAIXAS | I18: TROCA DE CAIXAS | J18: TROCA DE CAIXAS | K18: TROCA DE CAIXAS | L18: ARQUIVAMENTO DE 70 CAIXAS | M18: TROCA DE CAIXAS | O18: TROCA DE CAIXAS | P18: TROCA DE CAIXAS | Q18: TROCA DE CAIXAS | R18: TROCA DE CAIXAS | S18: TROCA DE CAIXAS | U18: TROCA DE CAIXAS | V18: RECEBIMENTO DE 70 CAIXAS DA CGPC | W18: CONFERÊNCIA DE CAIXAS DFSNAS | X18: CONFERÊNCIA DE CAIXAS DFSNAS | Y18: TROCA DE CAIXAS | AA18: Reunião pela parte da manha | AB18: RECEBIMENTO DE 70 CAIXAS DA CGPC | AC18: CARREGANDO 70 CAIXAS PARA CGPC | AD18: TROCANDO ESPELHO DE CAIXAS | AE18: TROCANDO ESPELHO DE CAIXAS | AG18: FAZENDO ESPELHOS NOVOS DAS CAIXAS DA CGPC | AH18: trocando caixas | AI18: trocando caixas | AJ18: trocando caixas | AK18: trocando caixas | AO18: recebendo pedido de processos | AP18: RECEBIMENTO DE 70 CAIXAS DA CGPC E ENVIO DE 70 CAIXAS DA CGPC | AQ18: CONFERENCIA DE CAIXAS DA CGPC | AS18: CONFERENCIA DE CAIXAS DA CGPC | AT18: ARQUIVAMENTO DE CAIXAS CGPC | AU18: TROCANDO CAIXAS | AV18: TROCANDO CAIXAS | AW18: TROCANDO CAIXAS
A19: OBSERVAÇÃO | V19: ENVIANDO 70 CAIXAS PARA O MONTES | AA19: Reunião pela parte da tarde | AC19: DESCARREGANDO 70 CAIXAS DA CGPC | AD19: TROCANDO ESPELHO DE CAIXAS | AE19: TROCANDO ESPELHO DE CAIXAS
V20: ENVIANDO 104 PROCESSOS PARA BLOCO A

Sheet Alessandro
A1: INDICADORES | C1: 45662 | D1: 45663 | E1: 45664 | F1: 45665 | G1: 45666 | H1: TOTAL SEMANA | I1: 45669 | J1: 45670 | K1: 45671 | L1: 45672 | M1: 45673 | N1: TOTAL SEMANA | O1: 45676 | P1: 45677 | Q1: 45678 | R1: 45679 | S1: 45680 | T1: TOTAL SEMANA | U1: 45683 | V1: 45684 | W1: 45685 | X1: 45686 | Y1: 45687 | Z1: TOTAL SEMANA | AA1: 45690 | AB1: 45691 | AC1: 45692 | AD1: 45693 | AE1: 45694 | AF1: TOTAL SEMANA | AG1: 45697 | AH1: 45698 | AI1: 45699 | AJ1: 45700 | AK1: 45701 | AL1: TOTAL SEMANA | AM1: 45704 | AN1: 45705 | AO1: 45706 | AP1: 45707 | AQ1: 45708 | AR1: TOTAL SEMANA | AS1: 45711 | AT1: 45712 | AU1: 45713 | AV1: 45714 | AW1: 45715 | AX1: TOTAL SEMANA
A2: Desarquivamento de Processos/Documentos - Saída de Guia Fora | B2: 1 | H2: =SUM(C2:G2) -> 0 | N2: =SUM(I2:M2) -> 0 | T2: =SUM(O2:S2) -> 0 | Z2: =SUM(U2:Y2) -> 0 | AF2: =SUM(AA2:AE2) -> 0 | AL2: =SUM(AG2:AK2) -> 0 | AM2: RECESSO | AN2: CARNAVAL | AR2: =SUM(AM2:AQ2) -> 0 | AX2: =SUM(AS2:AW2) -> 0
A3: Caixas consultadas em pesquisa de desarquivamento | B3: 2 | H3: =SUM(C3:G3) -> 0 | N3: =SUM(I3:M3) -> 0 | T3: =SUM(O3:S3) -> 0 | Z3: =SUM(U3:Y3) -> 0 | AF3: =SUM(AA3:AE3) -> 0 | AL3: =SUM(AG3:AK3) -> 0 | AM3: RECESSO | AN3: CARNAVAL | AR3: =SUM(AM3:AQ3) -> 0 | AX3: =SUM(AS3:AW3) -> 0
A4: Retorno de Processos/Documentos Desarquivados | B4: 3 | H4: =SUM(C4:G4) -> 0 | N4: =SUM(I4:M4) -> 0 | T4: =SUM(O4:S4) -> 0 | Z4: =SUM(U4:Y4) -> 0 | AF4: =SUM(AA4:AE4) -> 0 | AL4: =SUM(AG4:AK4) -> 0 | AM4: RECESSO | AN4: CARNAVAL | AR4: =SUM(AM4:AQ4) -> 0 | AX4: =SUM(AS4:AW4) -> 0
A5: Recebimento de Documentos - Guia de Transferência | B5: 4 | H5: =SUM(C5:G5) -> 0 | N5: =SUM(I5:M5) -> 0 | T5: =SUM(O5:S5) -> 0 | Z5: =SUM(U5:Y5) -> 0 | AF5: =SUM(AA5:AE5) -> 0 | AL5: =SUM(AG5:AK5) -> 0 | AM5: RECESSO | AN5: CARNAVAL | AR5: =SUM(AM5:AQ5) -> 0 | AX5: =SUM(AS5:AW5) -> 0
A6: Caixas separadas para classificação | B6: 5 | H6: =SUM(C6:G6) -> 0 | N6: =SUM(I6:M6) -> 0 | T6: =SUM(O6:S6) -> 0 | Z6: =SUM(U6:Y6) -> 0 | AF6: =SUM(AA6:AE6) -> 0 | AL6: =SUM(AG6:AK6) -> 0 | AM6: RECESSO | AN6: CARNAVAL | AR6: =SUM(AM6:AQ6) -> 0 | AX6: =SUM(AS6:AW6) -> 0
A7: Processos/Documentos classificados | B7: 6 | H7: =SUM(C7:G7) -> 0 | N7: =SUM(I7:M7) -> 0 | T7: =SUM(O7:S7) -> 0 | Z7: =SUM(U7:Y7) -> 0 | AF7: =SUM(AA7:AE7) -> 0 | AL7: =SUM(AG7:AK7) -> 0 | AM7: RECESSO | AN7: CARNAVAL | AR7: =SUM(AM7:AQ7) -> 0 | AX7: =SUM(AS7:AW7) -> 0
A8: Caixas separadas para eliminação | B8: 7 | H8: =SUM(C8:G8) -> 0 | N8: =SUM(I8:M8) -> 0 | T8: =SUM(O8:S8) -> 0 | Z8: =SUM(U8:Y8) -> 0 | AF8: =SUM(AA8:AE8) -> 0 | AL8: =SUM(AG8:AK8) -> 0 | AM8: RECESSO | AN8: CARNAVAL | AR8: =SUM(AM8:AQ8) -> 0 | AX8: =SUM(AS8:AW8) -> 0
A9: Caixas listadas para eliminação | B9: 8 | H9: =SUM(C9:G9) -> 0 | N9: =SUM(I9:M9) -> 0 | T9: =SUM(O9:S9) -> 0 | Z9: =SUM(U9:Y9) -> 0 | AF9: =SUM(AA9:AE9) -> 0 | AL9: =SUM(AG9:AK9) -> 0 | AM9: RECESSO | AN9: CARNAVAL | AR9: =SUM(AM9:AQ9) -> 0 | AX9: =SUM(AS9:AW9) -> 0
A10: Processos/Documentos listados para eliminação | B10: 9 | H10: =SUM(C10:G10) -> 0 | N10: =SUM(I10:M10) -> 0 | T10: =SUM(O10:S10) -> 0 | Z10: =SUM(U10:Y10) -> 0 | AF10: =SUM(AA10:AE10) -> 0 | AL10: =SUM(AG10:AK10) -> 0 | AM10: RECESSO | AN10: CARNAVAL | AR10: =SUM(AM10:AQ10) -> 0 | AX10: =SUM(AS10:AW10) -> 0
A11: Caixas inventariadas | B11: 10 | H11: =SUM(C11:G11) -> 0 | N11: =SUM(I11:M11) -> 0 | T11: =SUM(O11:S11) -> 0 | Z11: =SUM(U11:Y11) -> 0 | AF11: =SUM(AA11:AE11) -> 0 | AL11: =SUM(AG11:AK11) -> 0 | AM11: RECESSO | AN11: CARNAVAL | AR11: =SUM(AM11:AQ11) -> 0 | AX11: =SUM(AS11:AW11) -> 0
A12: Processos/documentos inventariados | B12: 11 | H12: =SUM(C12:G12) -> 0 | N12: =SUM(I12:M12) -> 0 | T12: =SUM(O12:S12) -> 0 | Z12: =SUM(U12:Y12) -> 0 | AF12: =SUM(AA12:AE12) -> 0 | AL12: =SUM(AG12:AK12) -> 0 | AM12: RECESSO | AN12: CARNAVAL | AR12: =SUM(AM12:AQ12) -> 0 | AX12: =SUM(AS12:AW12) -> 0
A13: Documentos administrativos produzidos (Despacho, Nota Técnica, minutas diversas) | B13: 12 | H13: =SUM(C13:G13) -> 0 | N13: =SUM(I13:M13) -> 0 | T13: =SUM(O13:S13) -> 0 | Z13: =SUM(U13:Y13) -> 0 | AF13: =SUM(AA13:AE13) -> 0 | AL13: =SUM(AG13:AK13) -> 0 | AM13: RECESSO | AN13: CARNAVAL | AR13: =SUM(AM13:AQ13) -> 0 | AX13: =SUM(AS13:AW13) -> 0
A14: Orientação técnica / atendimentos realizados | B14: 13 | H14: =SUM(C14:G14) -> 0 | N14: =SUM(I14:M14) -> 0 | T14: =SUM(O14:S14) -> 0 | Z14: =SUM(U14:Y14) -> 0 | AF14: =SUM(AA14:AE14) -> 0 | AL14: =SUM(AG14:AK14) -> 0 | AM14: RECESSO | AN14: CARNAVAL | AR14: =SUM(AM14:AQ14) -> 0 | AX14: =SUM(AS14:AW14) -> 0
A15: Caixas remanejadas | B15: 14 | H15: =SUM(C15:G15) -> 0 | N15: =SUM(I15:M15) -> 0 | T15: =SUM(O15:S15) -> 0 | Z15: =SUM(U15:Y15) -> 0 | AC15: 70 | AF15: =SUM(AA15:AE15) -> 70 | AL15: =SUM(AG15:AK15) -> 0 | AM15: RECESSO | AN15: CARNAVAL | AP15: 70 | AR15: =SUM(AM15:AQ15) -> 70 | AX15: =SUM(AS15:AW15) -> 0
