Workbook

Sheet GLOSSÁRIO
A1: INDICADORES | B1: FONTE
A2: Desarquivamento de Processos/Documentos - Saída de Guia Fora | B2: SEI (Depachos ou Ofícios assinados na unidade Diarq)
A3: Caixas consultadas em pesquisa de desarquivamento | B3: CONTAGEM INDIVIDUAL (Caixas abertas para verificação de conteúdo em contexto de pesquisa para desarquivamento)
A4: Retorno de Processos/Documentos Desarquivados | B4: SEI (Depachos ou Ofícios assinados na unidade Diarq)
A5: Recebimento de Documentos - Guia de Transferência | B5: SEI (Depachos ou Ofícios assinados na unidade Diarq)
A6: Caixas separadas para classificação | B6: CONTAGEM INDIVIDUAL (Caixas "puxadas" nas estantes como uma pré-seleção para classificação)
A7: Processos/Documentos classificados | B7: PLANILHA
A8: Caixas separadas para eliminação | B8: CONTAGEM INDIVIDUAL (Caixas "puxadas" nas estantes como uma pré-seleção para eliminação)
A9: Caixas listadas para eliminação | B9: PLANILHA
A10: Processos/Documentos listados para eliminação | B10: PLANILHA
A11: Caixas inventariadas | B11: PLANILHA
A12: Processos/documentos inventariados | B12: PLANILHA
... A16: Caixas conferidas | B16: CONTAGEM INDIVIDUAL (Caixas consultadas para simples 'conferência de quantitativo' ou do 'conteúdo do espelho' em atividades diversas)

Sheet Patrícia
A1: INDICADORES | C1: 46083 | D1: 46084 | E1: 46085 | F1: 46086 | G1: 46087 | H1: TOTAL SEMANA | I1: 46090 | J1: 46091 | K1: 46092 | L1: 46093 | M1: 46094 | N1: TOTAL SEMANA | O1: 46097 | P1: 46098 | Q1: 46099 | R1: 46100 | S1: 46101 | T1: TOTAL SEMANA | U1: 46104 | V1: 46105 | W1: 46106 | X1: 46107 | Y1: 46108 | Z1: TOTAL SEMANA | AA1: 46111 | AB1: 46112 | AC1: 46113 | AD1: 46114 | AE1: 46115 | AF1: TOTAL SEMANA | AG1: 46118 | AH1: 46119 | AI1: 46120 | AJ1: 46121 | AK1: 46122 | AL1: TOTAL SEMANA | AM1: 46125 | AN1: 46126 | AO1: 46127 | AP1: 46128 | AQ1: 46129 | AR1: TOTAL SEMANA | AS1: 46132 | AT1: 46133 | AU1: 46134 | AV1: 46135 | AW1: 46136 | AX1: TOTAL SEMANA | AY1: 46139 | AZ1: 46140 | BA1: 46141 | BB1: 46142 | BC1: 46143 | BD1: TOTAL SEMANA
A2: Documentos administrativos produzidos (Despacho, Nota Técnica, minutas diversas) | B2: 1 | H2: =SUM(C2:G2) -> 0 | N2: =SUM(I2:M2) -> 0 | T2: =SUM(O2:S2) -> 0 | Z2: =SUM(U2:Y2) -> 0 | AF2: =SUM(AA2:AE2) -> 0 | AL2: =SUM(AG2:AK2) -> 0 | AR2: =SUM(AM2:AQ2) -> 0 | AX2: =SUM(AS2:AW2) -> 0 | BD2: =SUM(AY2:BC2) -> 0
A3: Orientação técnica / atendimentos realizados | B3: 2 | H3: =SUM(C3:G3) -> 0 | N3: =SUM(I3:M3) -> 0 | T3: =SUM(O3:S3) -> 0 | Z3: =SUM(U3:Y3) -> 0 | AF3: =SUM(AA3:AE3) -> 0 | AL3: =SUM(AG3:AK3) -> 0 | AR3: =SUM(AM3:AQ3) -> 0 | AX3: =SUM(AS3:AW3) -> 0 | BD3: =SUM(AY3:BC3) -> 0
A4: OUTRA ATIVIDADE. QUAL?
A5: OBSERVAÇÃO

Sheet Leonardo
A1: INDICADORES | C1: 46083 | D1: 46084 | E1: 46085 | F1: 46086 | G1: 46087 | H1: TOTAL SEMANA | I1: 46090 | J1: 46091 | K1: 46092 | L1: 46093 | M1: 46094 | N1: TOTAL SEMANA | O1: 46097 | P1: 46098 | Q1: 46099 | R1: 46100 | S1: 46101 | T1: TOTAL SEMANA | U1: 46104 | V1: 46105 | W1: 46106 | X1: 46107 | Y1: 46108 | Z1: TOTAL SEMANA | AA1: 46111 | AB1: 46112 | AC1: 46113 | AD1: 46114 | AE1: 46115 | AF1: TOTAL SEMANA | AG1: 46118 | AH1: 46119 | AI1: 46120 | AJ1: 46121 | AK1: 46122 | AL1: TOTAL SEMANA | AM1: 46125 | AN1: 46126 | AO1: 46127 | AP1: 46128 | AQ1: 46129 | AR1: TOTAL SEMANA | AS1: 46132 | AT1: 46133 | AU1: 46134 | AV1: 46135 | AW1: 46136 | AX1: TOTAL SEMANA | AY1: 46139 | AZ1: 46140 | BA1: 46141 | BB1: 46142 | BC1: 46143 | BD1: TOTAL SEMANA
A2: Documentos administrativos produzidos (Despacho, Nota Técnica, minutas diversas) | B2: 1 | H2: =SUM(C2:G2) -> 0 | N2: =SUM(I2:M2) -> 0 | T2: =SUM(O2:S2) -> 0 | Z2: =SUM(U2:Y2) -> 0 | AF2: =SUM(AA2:AE2) -> 0 | AL2: =SUM(AG2:AK2) -> 0 | AR2: =SUM(AM2:AQ2) -> 0 | AX2: =SUM(AS2:AW2) -> 0 | BD2: =SUM(AY2:BC2) -> 0
A3: Orientação técnica / atendimentos realizados | B3: 2 | H3: =SUM(C3:G3) -> 0 | N3: =SUM(I3:M3) -> 0 | T3: =SUM(O3:S3) -> 0 | Z3: =SUM(U3:Y3) -> 0 | AF3: =SUM(AA3:AE3) -> 0 | AL3: =SUM(AG3:AK3) -> 0 | AR3: =SUM(AM3:AQ3) -> 0 | AX3: =SUM(AS3:AW3) -> 0 | BD3: =SUM(AY3:BC3) -> 0
A4: OUTRA ATIVIDADE. QUAL?
A5: OBSERVAÇÃO

Sheet TOTAL
A1: INDICADORES | B1: Fonte | C1: 02/03 a 06/03/2026 | D1: 09/03 a 13/03/2026 | E1: 16/03 a 20/03/2026 | F1: 23/03 a 27/03/2026 | G1: 30/03 a 03/04/2026 | H1: 06/04 a 10/04/2026 | I1: 13/04 a 17/04/2026 | J1: 20/04 a 24/04/2026 | K1: 27/04 a 31/04/2026
A2: Desarquivamento de Processos/Documentos - Saída de Guia Fora | B2: SEI | C2: =Diego!H2+Aelton!H2+Leonam!H2+Danilo!H2+Marcos!H2+Alessandro!H2 -> 0 | D2: =Diego!N2+Aelton!N2+Leonam!N2+Danilo!N2+Marcos!N2+Alessandro!AL2+Carlos!N2 -> 1 | E2: =Diego!T2+Aelton!T2+Leonam!T2+Danilo!T2+Marcos!T2+Alessandro!T2 -> 1 | F2: =Diego!Z2+Aelton!Z2+Leonam!Z2+Danilo!Z2+Marcos!Z2+Alessandro!Z2 -> 0 | G2: =Diego!AF2+Aelton!AF2+Leonam!AF2+Danilo!AF2+Marcos!AF2+Alessandro!AF2 -> 24 | H2: =Diego!AL2+Aelton!AL2+Leonam!AL2+Danilo!AL2+Marcos!AL2+Alessandro!AL2 -> 3 | I2: =Diego!AR2+Aelton!AR2+Leonam!AR2+Danilo!AR2+Marcos!AR2+Alessandro!AR2 -> 0 | J2: =Diego!AX2+Aelton!AX2+Leonam!AX2+Danilo!AX2+Marcos!AX2+Alessandro!AX2 -> 0 | K2: =Diego!BD2+Aelton!BD2+Leonam!BD2+Danilo!BD2+Marcos!BD2+Alessandro!BD2+Carlos!BD2 -> 0
A3: Caixas consultadas em pesquisa de desarquivamento | B3: CONTAGEM INDIVIDUAL (das caixas abertas para verificação de conteúdo em contexto de pesquisa para desarquivamento) | C3: =Diego!H3+Aelton!H3+Leonam!H3+Danilo!H3+Marcos!H3+Alessandro!H3 -> 0 | D3: =Diego!N3+Aelton!N3+Leonam!N3+Danilo!N3+Marcos!N3+Alessandro!AL3+Carlos!N3 -> 6 | E3: =Diego!T3+Aelton!T3+Leonam!T3+Danilo!T3+Marcos!T3+Alessandro!T3 -> 0 | F3: =Diego!Z3+Aelton!Z3+Leonam!Z3+Danilo!Z3+Marcos!Z3+Alessandro!Z3 -> 0 | G3: =Diego!AF3+Aelton!AF3+Leonam!AF3+Danilo!AF3+Marcos!AF3+Alessandro!AF3 -> 3 | H3: =Diego!AL3+Aelton!AL3+Leonam!AL3+Danilo!AL3+Marcos!AL3+Alessandro!AL3 -> 6 | I3: =Diego!AR3+Aelton!AR3+Leonam!AR3+Danilo!AR3+Marcos!AR3+Alessandro!AR3 -> 0 | J3: =Diego!AX3+Aelton!AX3+Leonam!AX3+Danilo!AX3+Marcos!AX3+Alessandro!AX3 -> 0 | K3: =Diego!BD3+Aelton!BD3+Leonam!BD3+Danilo!BD3+Marcos!BD3+Alessandro!BD3+Carlos!BD3 -> 0
A4: Retorno de Processos/Documentos Desarquivados | B4: SEI | C4: =Diego!H4+Aelton!H4+Leonam!H4+Danilo!H4+Marcos!H4+Alessandro!H4 -> 1 | D4: =Diego!N4+Aelton!N4+Leonam!N4+Danilo!N4+Marcos!N4+Alessandro!N4 -> 0 | E4: =Diego!T4+Aelton!T4+Leonam!T4+Danilo!T4+Marcos!T4+Alessandro!T4 -> 27 | F4: =Diego!Z4+Aelton!Z4+Leonam!Z4+Danilo!Z4+Marcos!Z4+Alessandro!Z4 -> 7 | G4: =Diego!AF4+Aelton!AF4+Leonam!AF4+Danilo!AF4+Marcos!AF4+Alessandro!AF4 -> 0 | H4: =Diego!AL4+Aelton!AL4+Leonam!AL4+Danilo!AL4+Marcos!AL4+Alessandro!AL4 -> 0 | I4: =Diego!AR4+Aelton!AR4+Leonam!AR4+Danilo!AR4+Marcos!AR4+Alessandro!AR4 -> 26 | J4: =Diego!AX4+Aelton!AX4+Leonam!AX4+Danilo!AX4+Marcos!AX4+Alessandro!AX4 -> 0 | K4: =Diego!BD4+Aelton!BD4+Leonam!BD4+Danilo!BD4+Marcos!BD4+Alessandro!BD4+Carlos!BD4 -> 0
A5: Recebimento de Documentos - Guia de Transferência | B5: SEI | C5: =Diego!H5+Aelton!H5+Leonam!H5+Danilo!H5+Marcos!H5+Alessandro!H5 -> 0 | D5: =Diego!N5+Aelton!N5+Leonam!N5+Danilo!N5+Marcos!N5+Alessandro!N5 -> 0 | E5: =Diego!T5+Aelton!T5+Leonam!T5+Danilo!T5+Marcos!T5+Alessandro!T5 -> 0 | F5: =Diego!Z5+Aelton!Z5+Leonam!Z5+Danilo!Z5+Marcos!Z5+Alessandro!Z5 -> 0 | G5: =Diego!AF5+Aelton!AF5+Leonam!AF5+Danilo!AF5+Marcos!AF5+Alessandro!AF5 -> 0 | H5: =Diego!AL5+Aelton!AL5+Leonam!AL5+Danilo!AL5+Marcos!AL5+Alessandro!AL5 -> 0 | I5: =Diego!AR5+Aelton!AR5+Leonam!AR5+Danilo!AR5+Marcos!AR5+Alessandro!AR5 -> 0 | J5: =Diego!AX5+Aelton!AX5+Leonam!AX5+Danilo!AX5+Marcos!AX5+Alessandro!AX5 -> 0 | K5: =Diego!BD5+Aelton!BD5+Leonam!BD5+Danilo!BD5+Marcos!BD5+Alessandro!BD5+Carlos!BD5 -> 0
A6: Caixas separadas para classificação | B6: CONTAGEM INDIVIDUAL (das caixas "puxadas" nas estantes como uma pré-seleção para classificação) | C6: =Diego!H6+Aelton!H6+Leonam!H6+Danilo!H6+Marcos!H6+Alessandro!H6 -> 0 | D6: =Diego!N6+Aelton!N6+Leonam!N6+Danilo!N6+Marcos!N6+Alessandro!N6 -> 0 | E6: =Diego!T6+Aelton!T6+Leonam!T6+Danilo!T6+Marcos!T6+Alessandro!T6 -> 0 | F6: =Diego!Z6+Aelton!Z6+Leonam!Z6+Danilo!Z6+Marcos!Z6+Alessandro!Z6 -> 0 | G6: =Diego!AF6+Aelton!AF6+Leonam!AF6+Danilo!AF6+Marcos!AF6+Alessandro!AF6 -> 0 | H6: =Diego!AL6+Aelton!AL6+Leonam!AL6+Danilo!AL6+Marcos!AL6+Alessandro!AL6 -> 0 | I6: =Diego!AR6+Aelton!AR6+Leonam!AR6+Danilo!AR6+Marcos!AR6+Alessandro!AR6 -> 0 | J6: =Diego!AX6+Aelton!AX6+Leonam!AX6+Danilo!AX6+Marcos!AX6+Alessandro!AX6 -> 0 | K6: =Diego!BD6+Aelton!BD6+Leonam!BD6+Danilo!BD6+Marcos!BD6+Alessandro!BD6+Carlos!BD6 -> 0
A7: Processos/Documentos classificados | B7: PLANILHA | C7: =Diego!H7+Aelton!H7+Leonam!H7+Danilo!H7+Marcos!H7+Alessandro!H7 -> 0 | D7: =Diego!N7+Aelton!N7+Leonam!N7+Danilo!N7+Marcos!N7+Alessandro!N7 -> 0 | E7: =Diego!T7+Aelton!T7+Leonam!T7+Danilo!T7+Marcos!T7+Alessandro!T7 -> 0 | F7: =Diego!Z7+Aelton!Z7+Leonam!Z7+Danilo!Z7+Marcos!Z7+Alessandro!Z7 -> 0 | G7: =Diego!AF7+Aelton!AF7+Leonam!AF7+Danilo!AF7+Marcos!AF7+Alessandro!AF7 -> 0 | H7: =Diego!AL7+Aelton!AL7+Leonam!AL7+Danilo!AL7+Marcos!AL7+Alessandro!AL7 -> 0 | I7: =Diego!AR7+Aelton!AR7+Leonam!AR7+Danilo!AR7+Marcos!AR7+Alessandro!AR7 -> 0 | J7: =Diego!AX7+Aelton!AX7+Leonam!AX7+Danilo!AX7+Marcos!AX7+Alessandro!AX7 -> 0 | K7: =Diego!BD7+Aelton!BD7+Leonam!BD7+Danilo!BD7+Marcos!BD7+Alessandro!BD7+Carlos!BD7 -> 0
A8: Caixas separadas para eliminação | B8: CONTAGEM INDIVIDUAL (das caixas "puxadas" nas estantes como uma pré-seleção para eliminação) | C8: =Diego!H8+Aelton!H8+Leonam!H8+Danilo!H8+Marcos!H8+Alessandro!H8 -> 0 | D8: =Diego!N8+Aelton!N8+Leonam!N8+Danilo!N8+Marcos!N8+Alessandro!N8 -> 0 | E8: =Diego!T8+Aelton!T8+Leonam!T8+Danilo!T8+Marcos!T8+Alessandro!T8 -> 24 | F8: =Diego!Z8+Aelton!Z8+Leonam!Z8+Danilo!Z8+Marcos!Z8+Alessandro!Z8 -> 0 | G8: =Diego!AF8+Aelton!AF8+Leonam!AF8+Danilo!AF8+Marcos!AF8+Alessandro!AF8 -> 0 | H8: =Diego!AL8+Aelton!AL8+Leonam!AL8+Danilo!AL8+Marcos!AL8+Alessandro!AL8 -> 0 | I8: =Diego!AR8+Aelton!AR8+Leonam!AR8+Danilo!AR8+Marcos!AR8+Alessandro!AR8 -> 0 | J8: =Diego!AX8+Aelton!AX8+Leonam!AX8+Danilo!AX8+Marcos!AX8+Alessandro!AX8 -> 0 | K8: =Diego!BD8+Aelton!BD8+Leonam!BD8+Danilo!BD8+Marcos!BD8+Alessandro!BD8+Carlos!BD8 -> 0
A9: Caixas listadas para eliminação | B9: PLANILHA | C9: =Diego!H9+Aelton!H9+Leonam!H9+Danilo!H9+Marcos!H9+Alessandro!H9 -> 0 | D9: =Diego!N9+Aelton!N9+Leonam!N9+Danilo!N9+Marcos!N9+Alessandro!N9 -> 0 | E9: =Diego!T9+Aelton!T9+Leonam!T9+Danilo!T9+Marcos!T9+Alessandro!T9 -> 77 | F9: =Diego!Z9+Aelton!Z9+Leonam!Z9+Danilo!Z9+Marcos!Z9+Alessandro!Z9 -> 0 | G9: =Diego!AF9+Aelton!AF9+Leonam!AF9+Danilo!AF9+Marcos!AF9+Alessandro!AF9 -> 0 | H9: =Diego!AL9+Aelton!AL9+Leonam!AL9+Danilo!AL9+Marcos!AL9+Alessandro!AL9 -> 0 | I9: =Diego!AR9+Aelton!AR9+Leonam!AR9+Danilo!AR9+Marcos!AR9+Alessandro!AR9 -> 0 | J9: =Diego!AX9+Aelton!AX9+Leonam!AX9+Danilo!AX9+Marcos!AX9+Alessandro!AX9 -> 0 | K9: =Diego!BD9+Aelton!BD9+Leonam!BD9+Danilo!BD9+Marcos!BD9+Alessandro!BD9+Carlos!BD9 -> 0
A10: Processos/Documentos listados para eliminação | B10: PLANILHA | C10: =Diego!H10+Aelton!H10+Leonam!H10+Danilo!H10+Marcos!H10+Alessandro!H10 -> 0 | D10: =Diego!N10+Aelton!N10+Leonam!N10+Danilo!N10+Marcos!N10+Alessandro!N10 -> 0 | E10: =Diego!T10+Aelton!T10+Leonam!T10+Danilo!T10+Marcos!T10+Alessandro!T10 -> 40 | F10: =Diego!Z10+Aelton!Z10+Leonam!Z10+Danilo!Z10+Marcos!Z10+Alessandro!Z10 -> 0 | G10: =Diego!AF10+Aelton!AF10+Leonam!AF10+Danilo!AF10+Marcos!AF10+Alessandro!AF10 -> 0 | H10: =Diego!AL10+Aelton!AL10+Leonam!AL10+Danilo!AL10+Marcos!AL10+Alessandro!AL10 -> 0 | I10: =Diego!AR10+Aelton!AR10+Leonam!AR10+Danilo!AR10+Marcos!AR10+Alessandro!AR10 -> 0 | J10: =Diego!AX10+Aelton!AX10+Leonam!AX10+Danilo!AX10+Marcos!AX10+Alessandro!AX10 -> 0 | K10: =Diego!BD10+Aelton!BD10+Leonam!BD10+Danilo!BD10+Marcos!BD10+Alessandro!BD10+Carlos!BD10 -> 0
A11: Caixas inventariadas | B11: PLANILHA | C11: =Diego!H11+Aelton!H11+Leonam!H11+Danilo!H11+Marcos!H11+Alessandro!H11 -> 0 | D11: =Diego!N11+Aelton!N11+Leonam!N11+Danilo!N11+Marcos!N11+Alessandro!N11 -> 0 | E11: =Diego!T11+Aelton!T11+Leonam!T11+Danilo!T11+Marcos!T11+Alessandro!T11 -> 69 | F11: =Diego!Z11+Aelton!Z11+Leonam!Z11+Danilo!Z11+Marcos!Z11+Alessandro!Z11 -> 2 | G11: =Diego!AF11+Aelton!AF11+Leonam!AF11+Danilo!AF11+Marcos!AF11+Alessandro!AF11+Carlos!AF11 -> 26 | H11: =Diego!AL11+Aelton!AL11+Leonam!AL11+Danilo!AL11+Marcos!AL11+Alessandro!AL11+Carlos!AL11 -> 131 | I11: =Diego!AR11+Aelton!AR11+Leonam!AR11+Danilo!AR11+Marcos!AR11+Alessandro!AR11+Carlos!AR11 -> 84 | J11: =Diego!AX11+Aelton!AX11+Leonam!AX11+Danilo!AX11+Marcos!AX11+Alessandro!AX11+Carlos!AX11 -> 68 | K11: =Diego!BD11+Aelton!BD11+Leonam!BD11+Danilo!BD11+Marcos!BD11+Alessandro!BD11+Carlos!BD11 -> 36
A12: Processos/documentos inventariados | B12: PLANILHA | C12: =Diego!H12+Aelton!H12+Leonam!H12+Danilo!H12+Marcos!H12+Alessandro!H12 -> 0 | D12: =Diego!N12+Aelton!N12+Leonam!N12+Danilo!N12+Marcos!N12+Alessandro!N12 -> 0 | E12: =Diego!T12+Aelton!T12+Leonam!T12+Danilo!T12+Marcos!T12+Alessandro!T12 -> 0 | F12: =Diego!Z12+Aelton!Z12+Leonam!Z12+Danilo!Z12+Marcos!Z12+Alessandro!Z12 -> 0 | G12: =Diego!AF12+Aelton!AF12+Leonam!AF12+Danilo!AF12+Marcos!AF12+Alessandro!AF12+Carlos!AF12 -> 98 | H12: =Diego!AL12+Aelton!AL12+Leonam!AL12+Danilo!AL12+Marcos!AL12+Alessandro!AL12+Carlos!AL12 -> 873 | I12: =Diego!AR12+Aelton!AR12+Leonam!AR12+Danilo!AR12+Marcos!AR12+Alessandro!AR12+Carlos!AR12 -> 551 | J12: =Diego!AX12+Aelton!AX12+Leonam!AX12+Danilo!AX12+Marcos!AX12+Alessandro!AX12+Carlos!AX12 -> 409 | K12: =Diego!BD12+Aelton!BD12+Leonam!BD12+Danilo!BD12+Marcos!BD12+Alessandro!BD12+Carlos!BD12 -> 211
A13: Documentos administrativos produzidos (Despacho, Nota Técnica, minutas diversas) | B13: SEI | C13: =Diego!H13+Aelton!H13+Leonam!H13+Danilo!H13+Marcos!H13+Alessandro!H13+Patrícia!H2+Leonardo!H2 -> 3 | D13: =Diego!N13+Aelton!N13+Leonam!N13+Danilo!N13+Marcos!N13+Alessandro!N13+Patrícia!N2+Leonardo!N2 -> 0 | E13: =Diego!T13+Aelton!T13+Leonam!T13+Danilo!T13+Marcos!T13+Alessandro!T13+Patrícia!T2+Leonardo!T2 -> 1 | F13: =Diego!Z13+Aelton!Z13+Leonam!Z13+Danilo!Z13+Marcos!Z13+Alessandro!Z13+Patrícia!Z2+Leonardo!Z2 -> 1 | G13: =Diego!AF13+Aelton!AF13+Leonam!AF13+Danilo!AF13+Marcos!AF13+Alessandro!AF13+Patrícia!AF2+Leonardo!AF2 -> 1 | H13: =Diego!AL13+Aelton!AL13+Leonam!AL13+Danilo!AL13+Marcos!AL13+Alessandro!AL13+Patrícia!AL2+Leonardo!AL2 -> 3 | I13: =Diego!AR13+Aelton!AR13+Leonam!AR13+Danilo!AR13+Marcos!AR13+Alessandro!AR13+Patrícia!AR2+Leonardo!AR2 -> 1 | J13: =Diego!AX13+Aelton!AX13+Leonam!AX13+Danilo!AX13+Marcos!AX13+Alessandro!AX13+Patrícia!AX2+Leonardo!AX2 -> 0 | K13: =Diego!BD13+Aelton!BD13+Leonam!BD13+Danilo!BD13+Marcos!BD13+Alessandro!BD13+Carlos!BD13 -> 0
A14: Orientação técnica / atendimentos realizados | B14: SEI, E-MAIL, TELEFONE | C14: =Diego!H14+Aelton!H14+Leonam!H14+Danilo!H14+Marcos!H14+Alessandro!H14+Patrícia!H3+Leonardo!H3 -> 0 | D14: =Diego!N14+Aelton!N14+Leonam!N14+Danilo!N14+Marcos!N14+Alessandro!N14+Patrícia!N3+Leonardo!N3 -> 0 | E14: =Diego!T14+Aelton!T14+Leonam!T14+Danilo!T14+Marcos!T14+Alessandro!T14+Patrícia!T3+Leonardo!T3 -> 0 | F14: =Diego!Z14+Aelton!Z14+Leonam!Z14+Danilo!Z14+Marcos!Z14+Alessandro!Z14+Patrícia!Z3+Leonardo!Z3 -> 0 | G14: =Diego!AF14+Aelton!AF14+Leonam!AF14+Danilo!AF14+Marcos!AF14+Alessandro!AF14+Patrícia!AF3+Leonardo!AF3 -> 0 | H14: =Diego!AL14+Aelton!AL14+Leonam!AL14+Danilo!AL14+Marcos!AL14+Alessandro!AL14+Patrícia!AL3+Leonardo!AL3 -> 0 | I14: =Diego!AR14+Aelton!AR14+Leonam!AR14+Danilo!AR14+Marcos!AR14+Alessandro!AR14+Patrícia!AR3+Leonardo!AR3 -> 1 | J14: =Diego!AX14+Aelton!AX14+Leonam!AX14+Danilo!AX14+Marcos!AX14+Alessandro!AX14+Patrícia!AX3+Leonardo!AX3 -> 0 | K14: =Diego!BD14+Aelton!BD14+Leonam!BD14+Danilo!BD14+Marcos!BD14+Alessandro!BD14+Carlos!BD14 -> 0
A15: Caixas remanejadas | B15: CONTAGEM INDIVIDUAL (de caixas deslocadas visando reorganização temporária ou permanente) | C15: =Diego!H15+Aelton!H15+Leonam!H15+Danilo!H15+Marcos!H15+Alessandro!H15 -> 0 | D15: =Diego!N15+Aelton!N15+Leonam!N15+Danilo!N15+Marcos!N15+Alessandro!N15+Carlos!N15 -> 0 | E15: =Diego!T15+Aelton!T15+Leonam!T15+Danilo!T15+Marcos!T15+Alessandro!T15 -> 562 | F15: =Diego!Z15+Aelton!Z15+Leonam!Z15+Danilo!Z15+Marcos!Z15+Alessandro!Z15 -> 52 | G15: =Diego!AF15+Aelton!AF15+Leonam!AF15+Danilo!AF15+Marcos!AF15+Alessandro!AF15 -> 72 | H15: =Diego!AL15+Aelton!AL15+Leonam!AL15+Danilo!AL15+Marcos!AL15+Alessandro!AL15 -> 301 | I15: =Diego!AR15+Aelton!AR15+Leonam!AR15+Danilo!AR15+Marcos!AR15+Alessandro!AR15 -> 135 | J15: =Diego!AX15+Aelton!AX15+Leonam!AX15+Danilo!AX15+Marcos!AX15+Alessandro!AX15 -> 350 | K15: =Diego!BD15+Aelton!BD15+Leonam!BD15+Danilo!BD15+Marcos!BD15+Alessandro!BD15+Carlos!BD15 -> 482
A16: Caixas conferidas | B16: CONTAGEM INDIVIDUAL (de caixas para simples conferência de quantitativo ou do conteúdo do espelho em atividades diversas) | C16: =Diego!H16+Aelton!H16+Leonam!H16+Danilo!H16+Marcos!H16+Alessandro!H16 -> 0 | D16: =Diego!N16+Aelton!N16+Leonam!N16+Danilo!N16+Marcos!N16+Alessandro!N16 -> 0 | E16: =Diego!T16+Aelton!T16+Leonam!T16+Danilo!T16+Marcos!T16+Alessandro!T16 -> 0 | F16: =Diego!Z16+Aelton!Z16+Leonam!Z16+Danilo!Z16+Marcos!Z16+Alessandro!Z16 -> 0 | G16: =Diego!AF16+Aelton!AF16+Leonam!AF16+Danilo!AF16+Marcos!AF16+Alessandro!AF16 -> 0 | H16: =Diego!AL16+Aelton!AL16+Leonam!AL16+Danilo!AL16+Marcos!AL16+Alessandro!AL16 -> 0 | I16: =Diego!AR16+Aelton!AR16+Leonam!AR16+Danilo!AR16+Marcos!AR16+Alessandro!AR16 -> 0 | J16: =Diego!AX16+Aelton!AX16+Leonam!AX16+Danilo!AX16+Marcos!AX16+Alessandro!AX16 -> 0 | K16: =Diego!BD16+Aelton!BD16+Leonam!BD16+Danilo!BD16+Marcos!BD16+Alessandro!BD16+Carlos!BD16 -> 36
A17: Caixas substituídas(trocadas) | B17: Substituição de caixas degradadas por novas | C17: =Diego!H17+Aelton!H17+Leonam!H17+Danilo!H17+Marcos!H17+Alessandro!H17 -> 190 | D17: =Diego!N17+Aelton!N17+Leonam!N17+Danilo!N17+Marcos!N17+Alessandro!N17 -> 143 | E17: =Diego!T17+Aelton!T17+Leonam!T17+Danilo!T17+Marcos!T17+Alessandro!T17 -> 0 | F17: =Diego!Z17+Aelton!Z17+Leonam!Z17+Danilo!Z17+Marcos!Z17+Alessandro!Z17 -> 0 | G17: =Diego!AF17+Aelton!AF17+Leonam!AF17+Danilo!AF17+Marcos!AF17+Alessandro!AF17 -> 0 | H17: =Diego!AL17+Aelton!AL17+Leonam!AL17+Danilo!AL17+Marcos!AL17+Alessandro!AL17 -> 0 | I17: =Diego!AR17+Aelton!AR17+Leonam!AR17+Danilo!AR17+Marcos!AR17+Alessandro!AR17 -> 3 | J17: =Diego!AX17+Aelton!AX17+Leonam!AX17+Danilo!AX17+Marcos!AX17+Alessandro!AX17 -> 0 | K17: =Diego!BD17+Aelton!BD17+Leonam!BD17+Danilo!BD17+Marcos!BD17+Alessandro!BD17+Carlos!BD17 -> 0
A18: OUTRA ATIVIDADE. QUAL?
A19: OBSERVAÇÃO

Sheet Diego
A1: INDICADORES | C1: 46083 | D1: 46084 | E1: 46085 | F1: 46086 | G1: 46087 | H1: TOTAL SEMANA | I1: 46090 | J1: 46091 | K1: 46092 | L1: 46093 | M1: 46094 | N1: TOTAL SEMANA | O1: 46097 | P1: 46098 | Q1: 46099 | R1: 46100 | S1: 46101 | T1: TOTAL SEMANA | U1: 46104 | V1: 46105 | W1: 46106 | X1: 46107 | Y1: 46108 | Z1: TOTAL SEMANA | AA1: 46111 | AB1: 46112 | AC1: 46113 | AD1: 46114 | AE1: 46115 | AF1: TOTAL SEMANA | AG1: 46118 | AH1: 46119 | AI1: 46120 | AJ1: 46121 | AK1: 46122 | AL1: TOTAL SEMANA | AM1: 46125 | AN1: 46126 | AO1: 46127 | AP1: 46128 | AQ1: 46129 | AR1: TOTAL SEMANA | AS1: 46132 | AT1: 46133 | AU1: 46134 | AV1: 46135 | AW1: 46136 | AX1: TOTAL SEMANA | AY1: 46139 | AZ1: 46140 | BA1: 46141 | BB1: 46142 | BC1: 46143 | BD1: TOTAL SEMANA
A2: Desarquivamento de Processos/Documentos - Saída de Guia Fora | B2: 1 | H2: =SUM(C2:G2) -> 0 | N2: =SUM(I2:M2) -> 0 | T2: =SUM(O2:S2) -> 0 | Z2: =SUM(U2:Y2) -> 0 | AF2: =SUM(AA2:AE2) -> 0 | AL2: =SUM(AG2:AK2) -> 0 | AR2: =SUM(AM2:AQ2) -> 0 | AX2: =SUM(AS2:AW2) -> 0 | BC2: FERIADO | BD2: =SUM(AY2:BC2) -> 0
A3: Caixas consultadas em pesquisa de desarquivamento | B3: 2 | H3: =SUM(C3:G3) -> 0 | N3: =SUM(I3:M3) -> 0 | T3: =SUM(O3:S3) -> 0 | Z3: =SUM(U3:Y3) -> 0 | AF3: =SUM(AA3:AE3) -> 0 | AL3: =SUM(AG3:AK3) -> 0 | AR3: =SUM(AM3:AQ3) -> 0 | AX3: =SUM(AS3:AW3) -> 0 | BC3: FERIADO | BD3: =SUM(AY3:BC3) -> 0
A4: Retorno de Processos/Documentos Desarquivados | B4: 3 | H4: =SUM(C4:G4) -> 0 | N4: =SUM(I4:M4) -> 0 | Q4: 22 | T4: =SUM(O4:S4) -> 22 | Z4: =SUM(U4:Y4) -> 0 | AF4: =SUM(AA4:AE4) -> 0 | AL4: =SUM(AG4:AK4) -> 0 | AN4: 13 | AR4: =SUM(AM4:AQ4) -> 13 | AX4: =SUM(AS4:AW4) -> 0 | BC4: FERIADO | BD4: =SUM(AY4:BC4) -> 0
A5: Recebimento de Documentos - Guia de Transferência | B5: 4 | H5: =SUM(C5:G5) -> 0 | N5: =SUM(I5:M5) -> 0 | T5: =SUM(O5:S5) -> 0 | Z5: =SUM(U5:Y5) -> 0 | AF5: =SUM(AA5:AE5) -> 0 | AL5: =SUM(AG5:AK5) -> 0 | AR5: =SUM(AM5:AQ5) -> 0 | AX5: =SUM(AS5:AW5) -> 0 | BC5: FERIADO | BD5: =SUM(AY5:BC5) -> 0
A6: Caixas separadas para classificação | B6: 5 | H6: =SUM(C6:G6) -> 0 | N6: =SUM(I6:M6) -> 0 | T6: =SUM(O6:S6) -> 0 | Z6: =SUM(U6:Y6) -> 0 | AF6: =SUM(AA6:AE6) -> 0 | AL6: =SUM(AG6:AK6) -> 0 | AR6: =SUM(AM6:AQ6) -> 0 | AX6: =SUM(AS6:AW6) -> 0 | BC6: FERIADO | BD6: =SUM(AY6:BC6) -> 0
A7: Processos/Documentos classificados | B7: 6 | H7: =SUM(C7:G7) -> 0 | N7: =SUM(I7:M7) -> 0 | T7: =SUM(O7:S7) -> 0 | Z7: =SUM(U7:Y7) -> 0 | AF7: =SUM(AA7:AE7) -> 0 | AL7: =SUM(AG7:AK7) -> 0 | AR7: =SUM(AM7:AQ7) -> 0 | AX7: =SUM(AS7:AW7) -> 0 | BC7: FERIADO | BD7: =SUM(AY7:BC7) -> 0
A8: Caixas separadas para eliminação | B8: 7 | H8: =SUM(C8:G8) -> 0 | N8: =SUM(I8:M8) -> 0 | T8: =SUM(O8:S8) -> 0 | Z8: =SUM(U8:Y8) -> 0 | AF8: =SUM(AA8:AE8) -> 0 | AL8: =SUM(AG8:AK8) -> 0 | AR8: =SUM(AM8:AQ8) -> 0 | AX8: =SUM(AS8:AW8) -> 0 | BC8: FERIADO | BD8: =SUM(AY8:BC8) -> 0
A9: Caixas listadas para eliminação | B9: 8 | H9: =SUM(C9:G9) -> 0 | N9: =SUM(I9:M9) -> 0 | T9: =SUM(O9:S9) -> 0 | Z9: =SUM(U9:Y9) -> 0 | AF9: =SUM(AA9:AE9) -> 0 | AL9: =SUM(AG9:AK9) -> 0 | AR9: =SUM(AM9:AQ9) -> 0 | AX9: =SUM(AS9:AW9) -> 0 | BC9: FERIADO | BD9: =SUM(AY9:BC9) -> 0
A10: Processos/Documentos listados para eliminação | B10: 9 | H10: =SUM(C10:G10) -> 0 | N10: =SUM(I10:M10) -> 0 | T10: =SUM(O10:S10) -> 0 | Z10: =SUM(U10:Y10) -> 0 | AF10: =SUM(AA10:AE10) -> 0 | AL10: =SUM(AG10:AK10) -> 0 | AR10: =SUM(AM10:AQ10) -> 0 | AX10: =SUM(AS10:AW10) -> 0 | BC10: FERIADO | BD10: =SUM(AY10:BC10) -> 0
A11: Caixas inventariadas | B11: 10 | H11: =SUM(C11:G11) -> 0 | N11: =SUM(I11:M11) -> 0 | O11: 8 | P11: 6 | T11: =SUM(O11:S11) -> 14 | Z11: =SUM(U11:Y11) -> 0 | AE11: 7 | AF11: =SUM(AA11:AE11) -> 7 | AG11: 2 | AH11: 1 | AI11: 7 | AJ11: 7 | AL11: =SUM(AG11:AK11) -> 17 | AR11: =SUM(AM11:AQ11) -> 0 | AX11: =SUM(AS11:AW11) -> 0 | BC11: FERIADO | BD11: =SUM(AY11:BC11) -> 0
A12: Processos/documentos inventariados | B12: 11 | H12: =SUM(C12:G12) -> 0 | N12: =SUM(I12:M12) -> 0 | T12: =SUM(O12:S12) -> 0 | Z12: =SUM(U12:Y12) -> 0 | AF12: =SUM(AA12:AE12) -> 0 | AG12: 26 | AH12: 8 | AI12: 54 | AJ12: 56 | AL12: =SUM(AG12:AK12) -> 144 | AR12: =SUM(AM12:AQ12) -> 0 | AX12: =SUM(AS12:AW12) -> 0 | BC12: FERIADO | BD12: =SUM(AY12:BC12) -> 0
A13: Documentos administrativos produzidos (Despacho, Nota Técnica, minutas diversas) | B13: 12 | H13: =SUM(C13:G13) -> 0 | N13: =SUM(I13:M13) -> 0 | T13: =SUM(O13:S13) -> 0 | Z13: =SUM(U13:Y13) -> 0 | AC13: 1 | AF13: =SUM(AA13:AE13) -> 1 | AL13: =SUM(AG13:AK13) -> 0 | AN13: 1 | AR13: =SUM(AM13:AQ13) -> 1 | AX13: =SUM(AS13:AW13) -> 0 | BC13: FERIADO | BD13: =SUM(AY13:BC13) -> 0
A14: Orientação técnica / atendimentos realizados | B14: 13 | H14: =SUM(C14:G14) -> 0 | N14: =SUM(I14:M14) -> 0 | T14: =SUM(O14:S14) -> 0 | Z14: =SUM(U14:Y14) -> 0 | AF14: =SUM(AA14:AE14) -> 0 | AL14: =SUM(AG14:AK14) -> 0 | AR14: =SUM(AM14:AQ14) -> 0 | AX14: =SUM(AS14:AW14) -> 0 | BC14: FERIADO | BD14: =SUM(AY14:BC14) -> 0
A15: Caixas remanejadas | B15: 14 | H15: =SUM(C15:G15) -> 0 | N15: =SUM(I15:M15) -> 0 | O15: 49 | P15: 50 | Q15: 26 | R15: 50 | T15: =SUM(O15:S15) -> 175 | Z15: =SUM(U15:Y15) -> 0 | AA15: 10 | AB15: 10 | AF15: =SUM(AA15:AE15) -> 20 | AL15: =SUM(AG15:AK15) -> 0 | AN15: 42 | AR15: =SUM(AM15:AQ15) -> 42 | AX15: =SUM(AS15:AW15) -> 0 | BC15: FERIADO | BD15: =SUM(AY15:BC15) -> 0
A16: Caixas conferidas | B16: 15 | H16: =SUM(C16:G16) -> 0 | N16: =SUM(I16:M16) -> 0 | T16: =SUM(O16:S16) -> 0 | Z16: =SUM(U16:Y16) -> 0 | AF16: =SUM(AA16:AE16) -> 0 | AL16: =SUM(AG16:AK16) -> 0 | AR16: =SUM(AM16:AQ16) -> 0 | AX16: =SUM(AS16:AW16) -> 0 | BC16: FERIADO | BD16: =SUM(AY16:BC16) -> 0
A17: Caixas substituídas(trocadas) | B17: 16 | C17: 10 | D17: 10 | E17: 10 | F17: 10 | G17: 10 | H17: =SUM(C17:G17) -> 50 | K17: 10 | L17: 10 | M17: 10 | N17: =SUM(I17:M17) -> 30 | T17: =SUM(O17:S17) -> 0 | Z17: =SUM(U17:Y17) -> 0 | AF17: =SUM(AA17:AE17) -> 0 | AL17: =SUM(AG17:AK17) -> 0 | AR17: =SUM(AM17:AQ17) -> 0 | AX17: =SUM(AS17:AW17) -> 0 | BC17: FERIADO | BD17: =SUM(AY17:BC17) -> 0
A18: OUTRA ATIVIDADE. QUAL? | C18: trocando as caixas | D18: trocando as caixas | E18: trocando as caixas | F18: trocando as caixas | G18: trocando as caixas | I18: Reunião com pedro | J18: Orientação do serviço pela parte da manha | K18: trocando as caixas | L18: trocando as caixas | M18: trocando as caixas | Q18: arquivamento de processos | S18: Pesquisa e busca Documentos referente ao Plano de Saúde de servidores. | U18: Pesquisa e busca Documentos referente ao Plano de Saúde de servidores. | V18: Pesquisa e busca Documentos referente ao Plano de Saúde de servidores. | W18: Pesquisa e busca Documentos referente ao Plano de Saúde de servidores. | X18: ATESTADO | Y18: ATESTADO | AA18: PEGANDO AS PASTAS FUNCIONAIS | AB18: PEGANDO AS PASTAS FUNCIONAIS | AC18: PEGANDO AS PASTAS FUNCIONAIS | AD18: Desarquivadas 23 pastas funcionais. | AE18: Inventário de caixas da CGCEB | AG18: Inventário de caixas da CGCEB | AH18: Inventário de caixas da CGCEB | AI18: Inventário de caixas da CGCEB | AJ18: Inventário de caixas da CGCEB | AK18: Inventário de caixas da CGCEB | AM18: PROCURANDO CAIXAS DA CGCEB | AN18: GUARDADANDO PROCESSOS CGRH | AO18: Pesquisa e busca processo 23132.000438/95-22, convênio nº 214/95, SIAFI nº 138116, Fundação de Desporto e Lazer de Mato Grosso | AP18: Pesquisa e busca processo 23132.000438/95-22, convênio nº 214/95, SIAFI nº 138116, Fundação de Desporto e Lazer de Mato Grosso | AQ18: Pesquisa e busca processo 23132.000438/95-22, convênio nº 214/95, SIAFI nº 138116, Fundação de Desporto e Lazer de Mato Grosso | AS18: PONTO FACULTATIVO | AT18: FERIADO (Aniversário de Brasília) | AU18: Pesquisa e busca processo 23132.000438/95-22, convênio nº 214/95, SIAFI nº 138116, Fundação de Desporto e Lazer de Mato Grosso | AV18: Pesquisa e busca processo 23132.000438/95-22, convênio nº 214/95, SIAFI nº 138116, Fundação de Desporto e Lazer de Mato Grosso | AW18: Pesquisa e busca processo 23132.000438/95-22, convênio nº 214/95, SIAFI nº 138116, Fundação de Desporto e Lazer de Mato Grosso | AY18: Pesquisa e busca processo 23132.000438/95-22, convênio nº 214/95, SIAFI nº 138116, Fundação de Desporto e Lazer de Mato Grosso | AZ18: Pesquisa e busca processo 23132.000438/95-22, convênio nº 214/95, SIAFI nº 138116, Fundação de Desporto e Lazer de Mato Grosso | BA18: Pesquisa e busca processo 23132.000438/95-22, convênio nº 214/95, SIAFI nº 138116, Fundação de Desporto e Lazer de Mato Grosso | BB18: Pesquisa e busca processo 23132.000438/95-22, convênio nº 214/95, SIAFI nº 138116, Fundação de Desporto e Lazer de Mato Grosso
A19: OBSERVAÇÃO | D19: procurando caixas da cgeof/senarc | E19: procurando caixas da cgeof/senarc | F19: procurando caixas da cgeof/senarc | J19: Reunião da equipe pela parte da tarde | Q19: procurando caixas , organizando os pedidos do sei,pegando numeração de caixas dos processos | R19: Pesquisa e busca Documentos referente ao Plano de Saúde de servidores. | AA19: Pesquisa e busca Documentos referente ao Plano de Saúde de servidores. | AB19: Pesquisa e busca Documentos referente ao Plano de Saúde de servidores. | AG19: GUARDANDO AS CAIXAS DA CGCEB | AH19: PROCURANDO PASTAS FUNCIONAIS | AK19: GUARDADANDO PROCESSOS CGCEB | AO19: GUARDADANDO PROCESSOS CGCEB
Q20: orientação sobre as caixas de eliminação

Sheet Aelton
A1: INDICADORES | C1: 46083 | D1: 46084 | E1: 46085 | F1: 46086 | G1: 46087 | H1: TOTAL SEMANA | I1: 46090 | J1: 46091 | K1: 46092 | L1: 46093 | M1: 46094 | N1: TOTAL SEMANA | O1: 46097 | P1: 46098 | Q1: 46099 | R1: 46100 | S1: 46101 | T1: TOTAL SEMANA | U1: 46104 | V1: 46105 | W1: 46106 | X1: 46107 | Y1: 46108 | Z1: TOTAL SEMANA | AA1: 46111 | AB1: 46112 | AC1: 46113 | AD1: 46114 | AE1: 46115 | AF1: TOTAL SEMANA | AG1: 46118 | AH1: 46119 | AI1: 46120 | AJ1: 46121 | AK1: 46122 | AL1: TOTAL SEMANA | AM1: 46125 | AN1: 46126 | AO1: 46127 | AP1: 46128 | AQ1: 46129 | AR1: TOTAL SEMANA | AS1: 46132 | AT1: 46133 | AU1: 46134 | AV1: 46135 | AW1: 46136 | AX1: TOTAL SEMANA | AY1: 46139 | AZ1: 46140 | BA1: 46141 | BB1: 46142 | BC1: 46143 | BD1: TOTAL SEMANA
A2: Desarquivamento de Processos/Documentos - Saída de Guia Fora | B2: 1 | H2: =SUM(C2:G2) -> 0 | N2: =SUM(I2:M2) -> 0 | P2: 1 | T2: =SUM(O2:S2) -> 1 | Z2: =SUM(U2:Y2) -> 0 | AD2: 23 | AF2: =SUM(AA2:AE2) -> 23 | AL2: =SUM(AG2:AK2) -> 0 | AR2: =SUM(AM2:AQ2) -> 0 | AX2: =SUM(AS2:AW2) -> 0 | BC2: FERIADO | BD2: =SUM(AY2:BC2) -> 0
A3: Caixas consultadas em pesquisa de desarquivamento | B3: 2 | H3: =SUM(C3:G3) -> 0 | N3: =SUM(I3:M3) -> 0 | T3: =SUM(O3:S3) -> 0 | Z3: =SUM(U3:Y3) -> 0 | AF3: =SUM(AA3:AE3) -> 0 | AL3: =SUM(AG3:AK3) -> 0 | AR3: =SUM(AM3:AQ3) -> 0 | AX3: =SUM(AS3:AW3) -> 0 | BC3: FERIADO | BD3: =SUM(AY3:BC3) -> 0
A4: Retorno de Processos/Documentos Desarquivados | B4: 3 | E4: 1 | H4: =SUM(C4:G4) -> 1 | N4: =SUM(I4:M4) -> 0 | T4: =SUM(O4:S4) -> 0 | V4: 7 | Z4: =SUM(U4:Y4) -> 7 | AF4: =SUM(AA4:AE4) -> 0 | AL4: =SUM(AG4:AK4) -> 0 | AR4: =SUM(AM4:AQ4) -> 0 | AX4: =SUM(AS4:AW4) -> 0 | BC4: FERIADO | BD4: =SUM(AY4:BC4) -> 0
A5: Recebimento de Documentos - Guia de Transferência | B5: 4 | H5: =SUM(C5:G5) -> 0 | N5: =SUM(I5:M5) -> 0 | T5: =SUM(O5:S5) -> 0 | Z5: =SUM(U5:Y5) -> 0 | AF5: =SUM(AA5:AE5) -> 0 | AL5: =SUM(AG5:AK5) -> 0 | AR5: =SUM(AM5:AQ5) -> 0 | AX5: =SUM(AS5:AW5) -> 0 | BC5: FERIADO | BD5: =SUM(AY5:BC5) -> 0
A6: Caixas separadas para classificação | B6: 5 | H6: =SUM(C6:G6) -> 0 | N6: =SUM(I6:M6) -> 0 | T6: =SUM(O6:S6) -> 0 | Z6: =SUM(U6:Y6) -> 0 | AF6: =SUM(AA6:AE6) -> 0 | AL6: =SUM(AG6:AK6) -> 0 | AR6: =SUM(AM6:AQ6) -> 0 | AX6: =SUM(AS6:AW6) -> 0 | BC6: FERIADO | BD6: =SUM(AY6:BC6) -> 0
A7: Processos/Documentos classificados | B7: 6 | H7: =SUM(C7:G7) -> 0 | N7: =SUM(I7:M7) -> 0 | T7: =SUM(O7:S7) -> 0 | Z7: =SUM(U7:Y7) -> 0 | AF7: =SUM(AA7:AE7) -> 0 | AL7: =SUM(AG7:AK7) -> 0 | AR7: =SUM(AM7:AQ7) -> 0 | AX7: =SUM(AS7:AW7) -> 0 | BC7: FERIADO | BD7: =SUM(AY7:BC7) -> 0
A8: Caixas separadas para eliminação | B8: 7 | H8: =SUM(C8:G8) -> 0 | N8: =SUM(I8:M8) -> 0 | T8: =SUM(O8:S8) -> 0 | Z8: =SUM(U8:Y8) -> 0 | AF8: =SUM(AA8:AE8) -> 0 | AL8: =SUM(AG8:AK8) -> 0 | AR8: =SUM(AM8:AQ8) -> 0 | AX8: =SUM(AS8:AW8) -> 0 | BC8: FERIADO | BD8: =SUM(AY8:BC8) -> 0
A9: Caixas listadas para eliminação | B9: 8 | H9: =SUM(C9:G9) -> 0 | N9: =SUM(I9:M9) -> 0 | T9: =SUM(O9:S9) -> 0 | Z9: =SUM(U9:Y9) -> 0 | AF9: =SUM(AA9:AE9) -> 0 | AL9: =SUM(AG9:AK9) -> 0 | AR9: =SUM(AM9:AQ9) -> 0 | AX9: =SUM(AS9:AW9) -> 0 | BC9: FERIADO | BD9: =SUM(AY9:BC9) -> 0
A10: Processos/Documentos listados para eliminação | B10: 9 | H10: =SUM(C10:G10) -> 0 | N10: =SUM(I10:M10) -> 0 | T10: =SUM(O10:S10) -> 0 | Z10: =SUM(U10:Y10) -> 0 | AF10: =SUM(AA10:AE10) -> 0 | AL10: =SUM(AG10:AK10) -> 0 | AR10: =SUM(AM10:AQ10) -> 0 | AX10: =SUM(AS10:AW10) -> 0 | BC10: FERIADO | BD10: =SUM(AY10:BC10) -> 0
A11: Caixas inventariadas | B11: 10 | H11: =SUM(C11:G11) -> 0 | N11: =SUM(I11:M11) -> 0 | O11: 7 | P11: 7 | Q11: 4 | R11: 7 | T11: =SUM(O11:S11) -> 25 | Z11: =SUM(U11:Y11) -> 0 | AE11: 8 | AF11: =SUM(AA11:AE11) -> 8 | AI11: 8 | AJ11: 6 | AL11: =SUM(AG11:AK11) -> 14 | AM11: 6 | AR11: =SUM(AM11:AQ11) -> 6 | AX11: =SUM(AS11:AW11) -> 0 | BC11: FERIADO | BD11: =SUM(AY11:BC11) -> 0
A12: Processos/documentos inventariados | B12: 11 | H12: =SUM(C12:G12) -> 0 | N12: =SUM(I12:M12) -> 0 | T12: =SUM(O12:S12) -> 0 | Z12: =SUM(U12:Y12) -> 0 | AD12: 44 | AF12: =SUM(AA12:AE12) -> 44 | AI12: 60 | AJ12: 39 | AL12: =SUM(AG12:AK12) -> 99 | AM12: 27 | AR12: =SUM(AM12:AQ12) -> 27 | AX12: =SUM(AS12:AW12) -> 0 | BC12: FERIADO | BD12: =SUM(AY12:BC12) -> 0
A13: Documentos administrativos produzidos (Despacho, Nota Técnica, minutas diversas) | B13: 12 | E13: 1 | G13: 1 | H13: =SUM(C13:G13) -> 2 | N13: =SUM(I13:M13) -> 0 | Q13: 1 | T13: =SUM(O13:S13) -> 1 | V13: 1 | Z13: =SUM(U13:Y13) -> 1 | AF13: =SUM(AA13:AE13) -> 0 | AL13: =SUM(AG13:AK13) -> 0 | AR13: =SUM(AM13:AQ13) -> 0 | AX13: =SUM(AS13:AW13) -> 0 | BC13: FERIADO | BD13: =SUM(AY13:BC13) -> 0
A14: Orientação técnica / atendimentos realizados | B14: 13 | H14: =SUM(C14:G14) -> 0 | N14: =SUM(I14:M14) -> 0 | T14: =SUM(O14:S14) -> 0 | Z14: =SUM(U14:Y14) -> 0 | AF14: =SUM(AA14:AE14) -> 0 | AL14: =SUM(AG14:AK14) -> 0 | AR14: =SUM(AM14:AQ14) -> 0 | AX14: =SUM(AS14:AW14) -> 0 | BC14: FERIADO | BD14: =SUM(AY14:BC14) -> 0
A15: Caixas remanejadas | B15: 14 | H15: =SUM(C15:G15) -> 0 | N15: =SUM(I15:M15) -> 0 | O15: 49 | P15: 50 | Q15: 26 | R15: 50 | T15: =SUM(O15:S15) -> 175 | Z15: =SUM(U15:Y15) -> 0 | AF15: =SUM(AA15:AE15) -> 0 | AL15: =SUM(AG15:AK15) -> 0 | AN15: 92 | AR15: =SUM(AM15:AQ15) -> 92 | AX15: =SUM(AS15:AW15) -> 0 | BC15: FERIADO | BD15: =SUM(AY15:BC15) -> 0
A16: Caixas conferidas | B16: 15 | H16: =SUM(C16:G16) -> 0 | N16: =SUM(I16:M16) -> 0 | T16: =SUM(O16:S16) -> 0 | Z16: =SUM(U16:Y16) -> 0 | AF16: =SUM(AA16:AE16) -> 0 | AL16: =SUM(AG16:AK16) -> 0 | AR16: =SUM(AM16:AQ16) -> 0 | AX16: =SUM(AS16:AW16) -> 0 | BC16: FERIADO | BD16: =SUM(AY16:BC16) -> 0
A17: Caixas substituídas(trocadas) | B17: 16 | F17: 5 | H17: =SUM(C17:G17) -> 5 | K17: 5 | L17: 7 | M17: 10 | N17: =SUM(I17:M17) -> 22 | T17: =SUM(O17:S17) -> 0 | Z17: =SUM(U17:Y17) -> 0 | AF17: =SUM(AA17:AE17) -> 0 | AL17: =SUM(AG17:AK17) -> 0 | AR17: =SUM(AM17:AQ17) -> 0 | AX17: =SUM(AS17:AW17) -> 0 | BC17: FERIADO | BD17: =SUM(AY17:BC17) -> 0
A18: OUTRA ATIVIDADE. QUAL? | C18: Pesquisa localização de 14 processos vindo da DIPRO mais 1 CD. Os processos são cópias, ver se existe o original. | D18: Pesquisa localização de 14 processos vindo da DIPRO mais 1 CD. Os processos são cópias, ver se existe o original. | E18: Pesquisa localização de 14 processos vindo da DIPRO mais 1 CD. Os processos são cópias, ver se existe o original. Todos os processos cópias, verificamos e existe o original, somente o CD que não possui caixa. Estes processos cópias foram triturados à pedido da chefe Patrícia. | F18: 1. Troca de caixa e espelho. Total 5 caixas. 2. Pesquisa sobre se realmente 3 demandas foram finalizadas. | G18: Relatório - Planilha Controle Desarquivamento e Arquivamento. | I18: 1. Pela manhã, aguardando reunião com a chefe Patrícia e Leonardo. Reunião cancelada. 2. À tarde reunião com Pedro da CGLA. Reunião sobre o sistema CGLA. Obs.: Mas como iniciou perto de 16h eu tive que ir embora pegar minha filha. | J18: 1. Pela manhã, aguardando reunião com a chefe Patrícia e Leonardo. Reunião cancelada. 2. À tarde, reunião com a chefe Patrícia e Leonardo. | K18: 1. Troca de caixa e espelho. Total 5 caixas. 2. À tarde fui para o Bloco A, com o a Alessandro, para realocar uma caixa do Esporte que estava na G-15. Processo no SEI foi finalizado com Despacho com a localização correta. | L18: Troca de caixa e espelho. Total 7 caixas. | M18: Troca de caixa e espelho. Total 10 caixas. | O18: Inventário - 7 caixas | P18: Inventário - 7 caixas | Q18: Inventário - 4 caixas | R18: Inventário - 7 caixas | S18: Pesquisa e busca Documentos referente ao Plano de Saúde de servidores. | U18: Pesquisa e busca Documentos referente ao Plano de Saúde de servidores. | V18: 1. Arquivamento DEFNAS. 2. Pesquisa e busca Documentos referente ao Plano de Saúde de servidores. | W18: Pesquisa e busca Documentos referente ao Plano de Saúde de servidores. | X18: Pesquisa e busca Documentos referente ao Plano de Saúde de servidores. | Y18: Contagem caixas da LBA - Bloco A sala G-15. Total: 2.157 caixas. | AA18: Pesquisa e busca Documentos referente ao Plano de Saúde de servidores. | AB18: Pesquisa e busca Documentos referente ao Plano de Saúde de servidores. | AC18: Pesquisa e busca Documentos referente ao Plano de Saúde de servidores. | AD18: Desarquivadas 23 pastas funcionais. | AE18: Inventário de caixas da CGCEB | AG18: 1. Busca pelas caixas da CGCEB e acompanhamento dos carregadores. 2. Pesquisa e busca pastas funcionais COAP. | AH18: Pesquisa e busca pastas funcionais COAP. | AI18: Inventário de caixas CGCEB Total: 8 caixas e 60 processos | AJ18: Inventário de caixas CGCEB Total: 6 caixas e 39 processos | AK18: Atestado Médico | AM18: Inventário de caixas CGCEB Total: 6 caixas e 27 processos | AN18: Procurando e movimentando caixas da CGCEB 92 caixas. | AO18: Pesquisa e busca processo 23132.000438/95-22, convênio nº 214/95, SIAFI nº 138116, Fundação de Desporto e Lazer de Mato Grosso | AP18: Pesquisa e busca processo 23132.000438/95-22, convênio nº 214/95, SIAFI nº 138116, Fundação de Desporto e Lazer de Mato Grosso | AQ18: Pesquisa e busca processo 23132.000438/95-22, convênio nº 214/95, SIAFI nº 138116, Fundação de Desporto e Lazer de Mato Grosso | AS18: PONTO FACULTATIVO | AT18: FERIADO (Aniversário de Brasília) | AU18: Pesquisa e busca processo 23132.000438/95-22, convênio nº 214/95, SIAFI nº 138116, Fundação de Desporto e Lazer de Mato Grosso | AV18: Pesquisa e busca processo 23132.000438/95-22, convênio nº 214/95, SIAFI nº 138116, Fundação de Desporto e Lazer de Mato Grosso | AW18: Pesquisa e busca processo 23132.000438/95-22, convênio nº 214/95, SIAFI nº 138116, Fundação de Desporto e Lazer de Mato Grosso | AY18: Pesquisa e busca processo 23132.000438/95-22, convênio nº 214/95, SIAFI nº 138116, Fundação de Desporto e Lazer de Mato Grosso | AZ18: Pesquisa e busca processo 23132.000438/95-22, convênio nº 214/95, SIAFI nº 138116, Fundação de Desporto e Lazer de Mato Grosso | BA18: Pesquisa e busca processo 23132.000438/95-22, convênio nº 214/95, SIAFI nº 138116, Fundação de Desporto e Lazer de Mato Grosso | BB18: Pesquisa e busca processo 23132.000438/95-22, convênio nº 214/95, SIAFI nº 138116, Fundação de Desporto e Lazer de Mato Grosso
A19: OBSERVAÇÃO

Sheet Leonam
A1: INDICADORES | C1: 46083 | D1: 46084 | E1: 46085 | F1: 46086 | G1: 46087 | H1: TOTAL SEMANA | I1: 46090 | J1: 46091 | K1: 46092 | L1: 46093 | M1: 46094 | N1: TOTAL SEMANA | O1: 46097 | P1: 46098 | Q1: 46099 | R1: 46100 | S1: 46101 | T1: TOTAL SEMANA | U1: 46104 | V1: 46105 | W1: 46106 | X1: 46107 | Y1: 46108 | Z1: TOTAL SEMANA | AA1: 46111 | AB1: 46112 | AC1: 46113 | AD1: 46114 | AE1: 46115 | AF1: TOTAL SEMANA | AG1: 46118 | AH1: 46119 | AI1: 46120 | AJ1: 46121 | AK1: 46122 | AL1: TOTAL SEMANA | AM1: 46125 | AN1: 46126 | AO1: 46127 | AP1: 46128 | AQ1: 46129 | AR1: TOTAL SEMANA | AS1: 46132 | AT1: 46133 | AU1: 46134 | AV1: 46135 | AW1: 46136 | AX1: TOTAL SEMANA | AY1: 46139 | AZ1: 46140 | BA1: 46141 | BB1: 46142 | BC1: 46143 | BD1: TOTAL SEMANA
A2: Desarquivamento de Processos/Documentos - Saída de Guia Fora | B2: 1 | H2: =SUM(C2:G2) -> 0 | N2: =SUM(I2:M2) -> 0 | T2: =SUM(O2:S2) -> 0 | Z2: =SUM(U2:Y2) -> 0 | AF2: =SUM(AA2:AE2) -> 0 | AL2: =SUM(AG2:AK2) -> 0 | AR2: =SUM(AM2:AQ2) -> 0 | AS2: RECESSO | AT2: FERIADO | AX2: =SUM(AS2:AW2) -> 0 | AY2: Atestado | AZ2: Atestado | BA2: Atestado | BB2: Atestado | BC2: FERIADO | BD2: =SUM(AY2:BC2) -> 0
A3: Caixas consultadas em pesquisa de desarquivamento | B3: 2 | H3: =SUM(C3:G3) -> 0 | N3: =SUM(I3:M3) -> 0 | T3: =SUM(O3:S3) -> 0 | Z3: =SUM(U3:Y3) -> 0 | AF3: =SUM(AA3:AE3) -> 0 | AL3: =SUM(AG3:AK3) -> 0 | AR3: =SUM(AM3:AQ3) -> 0 | AS3: RECESSO | AT3: FERIADO | AX3: =SUM(AS3:AW3) -> 0 | AY3: Atestado | AZ3: Atestado | BA3: Atestado | BB3: Atestado | BC3: FERIADO | BD3: =SUM(AY3:BC3) -> 0
A4: Retorno de Processos/Documentos Desarquivados | B4: 3 | H4: =SUM(C4:G4) -> 0 | N4: =SUM(I4:M4) -> 0 | P4: 5 | T4: =SUM(O4:S4) -> 5 | Z4: =SUM(U4:Y4) -> 0 | AF4: =SUM(AA4:AE4) -> 0 | AL4: =SUM(AG4:AK4) -> 0 | AR4: =SUM(AM4:AQ4) -> 0 | AS4: RECESSO | AT4: FERIADO | AX4: =SUM(AS4:AW4) -> 0 | AY4: Atestado | AZ4: Atestado | BA4: Atestado | BB4: Atestado | BC4: FERIADO | BD4: =SUM(AY4:BC4) -> 0
A5: Recebimento de Documentos - Guia de Transferência | B5: 4 | H5: =SUM(C5:G5) -> 0 | N5: =SUM(I5:M5) -> 0 | T5: =SUM(O5:S5) -> 0 | Z5: =SUM(U5:Y5) -> 0 | AF5: =SUM(AA5:AE5) -> 0 | AL5: =SUM(AG5:AK5) -> 0 | AR5: =SUM(AM5:AQ5) -> 0 | AS5: RECESSO | AT5: FERIADO | AX5: =SUM(AS5:AW5) -> 0 | AY5: Atestado | AZ5: Atestado | BA5: Atestado | BB5: Atestado | BC5: FERIADO | BD5: =SUM(AY5:BC5) -> 0
A6: Caixas separadas para classificação | B6: 5 | H6: =SUM(C6:G6) -> 0 | N6: =SUM(I6:M6) -> 0 | T6: =SUM(O6:S6) -> 0 | Z6: =SUM(U6:Y6) -> 0 | AF6: =SUM(AA6:AE6) -> 0 | AL6: =SUM(AG6:AK6) -> 0 | AR6: =SUM(AM6:AQ6) -> 0 | AS6: RECESSO | AT6: FERIADO | AX6: =SUM(AS6:AW6) -> 0 | AY6: Atestado | AZ6: Atestado | BA6: Atestado | BB6: Atestado | BC6: FERIADO | BD6: =SUM(AY6:BC6) -> 0
A7: Processos/Documentos classificados | B7: 6 | H7: =SUM(C7:G7) -> 0 | N7: =SUM(I7:M7) -> 0 | T7: =SUM(O7:S7) -> 0 | Z7: =SUM(U7:Y7) -> 0 | AF7: =SUM(AA7:AE7) -> 0 | AL7: =SUM(AG7:AK7) -> 0 | AR7: =SUM(AM7:AQ7) -> 0 | AS7: RECESSO | AT7: FERIADO | AX7: =SUM(AS7:AW7) -> 0 | AY7: Atestado | AZ7: Atestado | BA7: Atestado | BB7: Atestado | BC7: FERIADO | BD7: =SUM(AY7:BC7) -> 0
A8: Caixas separadas para eliminação | B8: 7 | H8: =SUM(C8:G8) -> 0 | N8: =SUM(I8:M8) -> 0 | P8: 11 | Q8: 6 | R8: 7 | T8: =SUM(O8:S8) -> 24 | Z8: =SUM(U8:Y8) -> 0 | AF8: =SUM(AA8:AE8) -> 0 | AL8: =SUM(AG8:AK8) -> 0 | AR8: =SUM(AM8:AQ8) -> 0 | AS8: RECESSO | AT8: FERIADO | AX8: =SUM(AS8:AW8) -> 0 | AY8: Atestado | AZ8: Atestado | BA8: Atestado | BB8: Atestado | BC8: FERIADO | BD8: =SUM(AY8:BC8) -> 0
A9: Caixas listadas para eliminação | B9: 8 | H9: =SUM(C9:G9) -> 0 | N9: =SUM(I9:M9) -> 0 | O9: 7 | P9: 7 | Q9: 4 | R9: 7 | T9: =SUM(O9:S9) -> 25 | Z9: =SUM(U9:Y9) -> 0 | AF9: =SUM(AA9:AE9) -> 0 | AL9: =SUM(AG9:AK9) -> 0 | AR9: =SUM(AM9:AQ9) -> 0 | AS9: RECESSO | AT9: FERIADO | AX9: =SUM(AS9:AW9) -> 0 | AY9: Atestado | AZ9: Atestado | BA9: Atestado | BB9: Atestado | BC9: FERIADO | BD9: =SUM(AY9:BC9) -> 0
A10: Processos/Documentos listados para eliminação | B10: 9 | H10: =SUM(C10:G10) -> 0 | N10: =SUM(I10:M10) -> 0 | P10: 16 | Q10: 8 | R10: 16 | T10: =SUM(O10:S10) -> 40 | Z10: =SUM(U10:Y10) -> 0 | AF10: =SUM(AA10:AE10) -> 0 | AL10: =SUM(AG10:AK10) -> 0 | AR10: =SUM(AM10:AQ10) -> 0 | AS10: RECESSO | AT10: FERIADO | AX10: =SUM(AS10:AW10) -> 0 | AY10: Atestado | AZ10: Atestado | BA10: Atestado | BB10: Atestado | BC10: FERIADO | BD10: =SUM(AY10:BC10) -> 0
A11: Caixas inventariadas | B11: 10 | H11: =SUM(C11:G11) -> 0 | N11: =SUM(I11:M11) -> 0 | T11: =SUM(O11:S11) -> 0 | Z11: =SUM(U11:Y11) -> 0 | AF11: =SUM(AA11:AE11) -> 0 | AL11: =SUM(AG11:AK11) -> 0 | AR11: =SUM(AM11:AQ11) -> 0 | AS11: RECESSO | AT11: FERIADO | AX11: =SUM(AS11:AW11) -> 0 | AY11: Atestado | AZ11: Atestado | BA11: Atestado | BB11: Atestado | BC11: FERIADO | BD11: =SUM(AY11:BC11) -> 0
A12: Processos/documentos inventariados | B12: 11 | H12: =SUM(C12:G12) -> 0 | N12: =SUM(I12:M12) -> 0 | T12: =SUM(O12:S12) -> 0 | Z12: =SUM(U12:Y12) -> 0 | AF12: =SUM(AA12:AE12) -> 0 | AL12: =SUM(AG12:AK12) -> 0 | AR12: =SUM(AM12:AQ12) -> 0 | AS12: RECESSO | AT12: FERIADO | AX12: =SUM(AS12:AW12) -> 0 | AY12: Atestado | AZ12: Atestado | BA12: Atestado | BB12: Atestado | BC12: FERIADO | BD12: =SUM(AY12:BC12) -> 0
A13: Documentos administrativos produzidos (Despacho, Nota Técnica, minutas diversas) | B13: 12 | H13: =SUM(C13:G13) -> 0 | N13: =SUM(I13:M13) -> 0 | T13: =SUM(O13:S13) -> 0 | Z13: =SUM(U13:Y13) -> 0 | AF13: =SUM(AA13:AE13) -> 0 | AL13: =SUM(AG13:AK13) -> 0 | AR13: =SUM(AM13:AQ13) -> 0 | AS13: RECESSO | AT13: FERIADO | AX13: =SUM(AS13:AW13) -> 0 | AY13: Atestado | AZ13: Atestado | BA13: Atestado | BB13: Atestado | BC13: FERIADO | BD13: =SUM(AY13:BC13) -> 0
A14: Orientação técnica / atendimentos realizados | B14: 13 | H14: =SUM(C14:G14) -> 0 | N14: =SUM(I14:M14) -> 0 | T14: =SUM(O14:S14) -> 0 | Z14: =SUM(U14:Y14) -> 0 | AF14: =SUM(AA14:AE14) -> 0 | AL14: =SUM(AG14:AK14) -> 0 | AR14: =SUM(AM14:AQ14) -> 0 | AS14: RECESSO | AT14: FERIADO | AX14: =SUM(AS14:AW14) -> 0 | AY14: Atestado | AZ14: Atestado | BA14: Atestado | BB14: Atestado | BC14: FERIADO | BD14: =SUM(AY14:BC14) -> 0
A15: Caixas remanejadas | B15: 14 | H15: =SUM(C15:G15) -> 0 | N15: =SUM(I15:M15) -> 0 | O15: 10 | P15: 11 | Q15: 6 | R15: 10 | T15: =SUM(O15:S15) -> 37 | Z15: =SUM(U15:Y15) -> 0 | AF15: =SUM(AA15:AE15) -> 0 | AL15: =SUM(AG15:AK15) -> 0 | AR15: =SUM(AM15:AQ15) -> 0 | AS15: RECESSO | AT15: FERIADO | AX15: =SUM(AS15:AW15) -> 0 | AY15: Atestado | AZ15: Atestado | BA15: Atestado | BB15: Atestado | BC15: FERIADO | BD15: =SUM(AY15:BC15) -> 0
A16: Caixas conferidas | B16: 15 | H16: =SUM(C16:G16) -> 0 | N16: =SUM(I16:M16) -> 0 | T16: =SUM(O16:S16) -> 0 | Z16: =SUM(U16:Y16) -> 0 | AF16: =SUM(AA16:AE16) -> 0 | AL16: =SUM(AG16:AK16) -> 0 | AR16: =SUM(AM16:AQ16) -> 0 | AS16: RECESSO | AT16: FERIADO | AX16: =SUM(AS16:AW16) -> 0 | AY16: Atestado | AZ16: Atestado | BA16: Atestado | BB16: Atestado | BC16: FERIADO | BD16: =SUM(AY16:BC16) -> 0
A17: Caixas substituídas(trocadas) | B17: 16 | C17: 10 | D17: 10 | E17: 10 | F17: 10 | G17: 10 | H17: =SUM(C17:G17) -> 50 | I17: 5 | J17: 5 | K17: 10 | L17: 10 | N17: =SUM(I17:M17) -> 30 | T17: =SUM(O17:S17) -> 0 | Z17: =SUM(U17:Y17) -> 0 | AF17: =SUM(AA17:AE17) -> 0 | AL17: =SUM(AG17:AK17) -> 0 | AR17: =SUM(AM17:AQ17) -> 0 | AS17: RECESSO | AT17: FERIADO | AX17: =SUM(AS17:AW17) -> 0 | AY17: Atestado | AZ17: Atestado | BA17: Atestado | BB17: Atestado | BC17: FERIADO | BD17: =SUM(AY17:BC17) -> 0
A18: OUTRA ATIVIDADE. QUAL? | C18: trocando as caixas | D18: trocando as caixas | E18: trocando as caixas | F18: trocando as caixas | G18: trocando as caixas | I18: reunião com o Pedro | J18: reunião de equipe | K18: trocando as caixas | L18: trocando as caixas | Q18: descendo e subindo caixas do 1 subsolo para o 2 andar | R18: descendo e subindo caixas do 1 subsolo para o 2 andar | U18: MEXENDO NO NOVO SISTEMA | V18: MEXENDO NO NOVO SISTEMA | W18: ATESTADO | X18: MEXENDO NO NOVO SISTEMA | Y18: MEXENDO NO NOVO SISTEMA | AA18: MEXENDO NO NOVO SISTEMA | AB18: MEXENDO NO NOVO SISTEMA | AC18: MEXENDO NO NOVO SISTEMA | AD18: MEXENDO NO NOVO SISTEMA | AE18: MEXENDO NO NOVO SISTEMA | AG18: MEXENDO NO NOVO SISTEMA | AH18: MEXENDO NO NOVO SISTEMA | AI18: MEXENDO NO NOVO SISTEMA | AJ18: MEXENDO NO NOVO SISTEMA | AK18: MEXENDO NO NOVO SISTEMA
A19: OBSERVAÇÃO | D19: procurando caixas da cgeof/senarc | E19: procurando caixas da cgeof/senarc | F19: ajudando o Danilo em um despacho de arquivamento | G19: almoço em comemoração ao aniversario da Patricia, e fomo liberados mais cedo | I19: trocando as caixas | Q19: ajudando no despacho do processo 71000.009222/2026-83

Sheet Danilo
A1: INDICADORES | C1: 46083 | D1: 46084 | E1: 46085 | F1: 46086 | G1: 46087 | H1: TOTAL SEMANA | I1: 46090 | J1: 46091 | K1: 46092 | L1: 46093 | M1: 46094 | N1: TOTAL SEMANA | O1: 46097 | P1: 46098 | Q1: 46099 | R1: 46100 | S1: 46101 | T1: TOTAL SEMANA | U1: 46104 | V1: 46105 | W1: 46106 | X1: 46107 | Y1: 46108 | Z1: TOTAL SEMANA | AA1: 46111 | AB1: 46112 | AC1: 46113 | AD1: 46114 | AE1: 46115 | AF1: TOTAL SEMANA | AG1: 46118 | AH1: 46119 | AI1: 46120 | AJ1: 46121 | AK1: 46122 | AL1: TOTAL SEMANA | AM1: 46125 | AN1: 46126 | AO1: 46127 | AP1: 46128 | AQ1: 46129 | AR1: TOTAL SEMANA | AS1: 46132 | AT1: 46133 | AU1: 46134 | AV1: 46135 | AW1: 46136 | AX1: TOTAL SEMANA | AY1: 46139 | AZ1: 46140 | BA1: 46141 | BB1: 46142 | BC1: 46143 | BD1: TOTAL SEMANA
A2: Desarquivamento de Processos/Documentos - Saída de Guia Fora | B2: 1 | H2: =SUM(C2:G2) -> 0 | N2: =SUM(I2:M2) -> 0 | T2: =SUM(O2:S2) -> 0 | Z2: =SUM(U2:Y2) -> 0 | AF2: =SUM(AA2:AE2) -> 0 | AK2: 2 | AL2: =SUM(AG2:AK2) -> 2 | AR2: =SUM(AM2:AQ2) -> 0 | AS2: RECESSO | AT2: FERIADO | AX2: =SUM(AS2:AW2) -> 0 | BD2: =SUM(AY2:BC2) -> 0
A3: Caixas consultadas em pesquisa de desarquivamento | B3: 2 | H3: =SUM(C3:G3) -> 0 | N3: =SUM(I3:M3) -> 0 | T3: =SUM(O3:S3) -> 0 | Z3: =SUM(U3:Y3) -> 0 | AF3: =SUM(AA3:AE3) -> 0 | AL3: =SUM(AG3:AK3) -> 0 | AR3: =SUM(AM3:AQ3) -> 0 | AS3: RECESSO | AT3: FERIADO | AX3: =SUM(AS3:AW3) -> 0 | BD3: =SUM(AY3:BC3) -> 0
A4: Retorno de Processos/Documentos Desarquivados | B4: 3 | H4: =SUM(C4:G4) -> 0 | N4: =SUM(I4:M4) -> 0 | T4: =SUM(O4:S4) -> 0 | Z4: =SUM(U4:Y4) -> 0 | AF4: =SUM(AA4:AE4) -> 0 | AL4: =SUM(AG4:AK4) -> 0 | AR4: =SUM(AM4:AQ4) -> 0 | AS4: RECESSO | AT4: FERIADO | AX4: =SUM(AS4:AW4) -> 0 | BD4: =SUM(AY4:BC4) -> 0
A5: Recebimento de Documentos - Guia de Transferência | B5: 4 | H5: =SUM(C5:G5) -> 0 | N5: =SUM(I5:M5) -> 0 | T5: =SUM(O5:S5) -> 0 | Z5: =SUM(U5:Y5) -> 0 | AF5: =SUM(AA5:AE5) -> 0 | AL5: =SUM(AG5:AK5) -> 0 | AR5: =SUM(AM5:AQ5) -> 0 | AS5: RECESSO | AT5: FERIADO | AX5: =SUM(AS5:AW5) -> 0 | BD5: =SUM(AY5:BC5) -> 0
A6: Caixas separadas para classificação | B6: 5 | H6: =SUM(C6:G6) -> 0 | N6: =SUM(I6:M6) -> 0 | T6: =SUM(O6:S6) -> 0 | Z6: =SUM(U6:Y6) -> 0 | AF6: =SUM(AA6:AE6) -> 0 | AL6: =SUM(AG6:AK6) -> 0 | AR6: =SUM(AM6:AQ6) -> 0 | AS6: RECESSO | AT6: FERIADO | AX6: =SUM(AS6:AW6) -> 0 | BD6: =SUM(AY6:BC6) -> 0
A7: Processos/Documentos classificados | B7: 6 | H7: =SUM(C7:G7) -> 0 | N7: =SUM(I7:M7) -> 0 | T7: =SUM(O7:S7) -> 0 | Z7: =SUM(U7:Y7) -> 0 | AF7: =SUM(AA7:AE7) -> 0 | AL7: =SUM(AG7:AK7) -> 0 | AR7: =SUM(AM7:AQ7) -> 0 | AS7: RECESSO | AT7: FERIADO | AX7: =SUM(AS7:AW7) -> 0 | BD7: =SUM(AY7:BC7) -> 0
A8: Caixas separadas para eliminação | B8: 7 | H8: =SUM(C8:G8) -> 0 | N8: =SUM(I8:M8) -> 0 | T8: =SUM(O8:S8) -> 0 | Z8: =SUM(U8:Y8) -> 0 | AF8: =SUM(AA8:AE8) -> 0 | AL8: =SUM(AG8:AK8) -> 0 | AR8: =SUM(AM8:AQ8) -> 0 | AS8: RECESSO | AT8: FERIADO | AX8: =SUM(AS8:AW8) -> 0 | BD8: =SUM(AY8:BC8) -> 0
A9: Caixas listadas para eliminação | B9: 8 | H9: =SUM(C9:G9) -> 0 | N9: =SUM(I9:M9) -> 0 | O9: 7 | P9: 7 | Q9: 5 | R9: 7 | T9: =SUM(O9:S9) -> 26 | Z9: =SUM(U9:Y9) -> 0 | AF9: =SUM(AA9:AE9) -> 0 | AL9: =SUM(AG9:AK9) -> 0 | AR9: =SUM(AM9:AQ9) -> 0 | AS9: RECESSO | AT9: FERIADO | AX9: =SUM(AS9:AW9) -> 0 | BD9: =SUM(AY9:BC9) -> 0
A10: Processos/Documentos listados para eliminação | B10: 9 | H10: =SUM(C10:G10) -> 0 | N10: =SUM(I10:M10) -> 0 | T10: =SUM(O10:S10) -> 0 | Z10: =SUM(U10:Y10) -> 0 | AF10: =SUM(AA10:AE10) -> 0 | AL10: =SUM(AG10:AK10) -> 0 | AR10: =SUM(AM10:AQ10) -> 0 | AS10: RECESSO | AT10: FERIADO | AX10: =SUM(AS10:AW10) -> 0 | BD10: =SUM(AY10:BC10) -> 0
A11: Caixas inventariadas | B11: 10 | H11: =SUM(C11:G11) -> 0 | N11: =SUM(I11:M11) -> 0 | T11: =SUM(O11:S11) -> 0 | Z11: =SUM(U11:Y11) -> 0 | AF11: =SUM(AA11:AE11) -> 0 | AH11: 9 | AI11: 8 | AJ11: 7 | AL11: =SUM(AG11:AK11) -> 24 | AM11: 3 | AO11: 2 | AP11: 3 | AQ11: 5 | AR11: =SUM(AM11:AQ11) -> 13 | AS11: RECESSO | AT11: FERIADO | AV11: 7 | AW11: 5 | AX11: =SUM(AS11:AW11) -> 12 | BD11: =SUM(AY11:BC11) -> 0
A12: Processos/documentos inventariados | B12: 11 | H12: =SUM(C12:G12) -> 0 | N12: =SUM(I12:M12) -> 0 | T12: =SUM(O12:S12) -> 0 | Z12: =SUM(U12:Y12) -> 0 | AF12: =SUM(AA12:AE12) -> 0 | AH12: 59 | AI12: 53 | AJ12: 53 | AL12: =SUM(AG12:AK12) -> 165 | AM12: 22 | AO12: 8 | AP12: 17 | AQ12: 43 | AR12: =SUM(AM12:AQ12) -> 90 | AS12: RECESSO | AT12: FERIADO | AV12: 43 | AW12: 29 | AX12: =SUM(AS12:AW12) -> 72 | BD12: =SUM(AY12:BC12) -> 0
A13: Documentos administrativos produzidos (Despacho, Nota Técnica, minutas diversas) | B13: 12 | F13: 1 | H13: =SUM(C13:G13) -> 1 | N13: =SUM(I13:M13) -> 0 | T13: =SUM(O13:S13) -> 0 | Z13: =SUM(U13:Y13) -> 0 | AF13: =SUM(AA13:AE13) -> 0 | AK13: 1 | AL13: =SUM(AG13:AK13) -> 1 | AR13: =SUM(AM13:AQ13) -> 0 | AS13: RECESSO | AT13: FERIADO | AX13: =SUM(AS13:AW13) -> 0 | BD13: =SUM(AY13:BC13) -> 0
A14: Orientação técnica / atendimentos realizados | B14: 13 | H14: =SUM(C14:G14) -> 0 | N14: =SUM(I14:M14) -> 0 | T14: =SUM(O14:S14) -> 0 | Z14: =SUM(U14:Y14) -> 0 | AF14: =SUM(AA14:AE14) -> 0 | AL14: =SUM(AG14:AK14) -> 0 | AN14: 1 | AR14: =SUM(AM14:AQ14) -> 1 | AS14: RECESSO | AT14: FERIADO | AX14: =SUM(AS14:AW14) -> 0 | BD14: =SUM(AY14:BC14) -> 0
A15: Caixas remanejadas | B15: 14 | H15: =SUM(C15:G15) -> 0 | N15: =SUM(I15:M15) -> 0 | T15: =SUM(O15:S15) -> 0 | Z15: =SUM(U15:Y15) -> 0 | AF15: =SUM(AA15:AE15) -> 0 | AL15: =SUM(AG15:AK15) -> 0 | AR15: =SUM(AM15:AQ15) -> 0 | AS15: RECESSO | AT15: FERIADO | AU15: 175 | AX15: =SUM(AS15:AW15) -> 175 | BA15: 173 | BB15: 48 | BD15: =SUM(AY15:BC15) -> 221
A16: Caixas conferidas | B16: 15 | H16: =SUM(C16:G16) -> 0 | N16: =SUM(I16:M16) -> 0 | T16: =SUM(O16:S16) -> 0 | Z16: =SUM(U16:Y16) -> 0 | AF16: =SUM(AA16:AE16) -> 0 | AL16: =SUM(AG16:AK16) -> 0 | AR16: =SUM(AM16:AQ16) -> 0 | AS16: RECESSO | AT16: FERIADO | AX16: =SUM(AS16:AW16) -> 0 | AY16: 10 | AZ16: 10 | BD16: =SUM(AY16:BC16) -> 20
A17: Caixas substituídas(trocadas) | B17: 16 | C17: 10 | D17: 10 | E17: 10 | F17: 10 | G17: 10 | H17: =SUM(C17:G17) -> 50 | I17: 3 | J17: 4 | K17: 7 | L17: 7 | M17: 7 | N17: =SUM(I17:M17) -> 28 | T17: =SUM(O17:S17) -> 0 | Z17: =SUM(U17:Y17) -> 0 | AF17: =SUM(AA17:AE17) -> 0 | AL17: =SUM(AG17:AK17) -> 0 | AR17: =SUM(AM17:AQ17) -> 0 | AS17: RECESSO | AT17: FERIADO | AX17: =SUM(AS17:AW17) -> 0 | BD17: =SUM(AY17:BC17) -> 0
A18: OUTRA ATIVIDADE. QUAL? | C18: trocando as caixas | D18: trocando as caixas | E18: trocando as caixas | F18: trocando as caixas | G18: trocando as caixas | I18: reunião com o Pedro | J18: reunião de equipe | K18: trocando as caixas e espelho | L18: trocando as caixas e espelho | M18: trocando as caixas e espelho | U18: Pesquisa e busca Documentos referente ao Plano de Saúde de servidores. | V18: 1. Arquivamento DEFNAS. 2. Pesquisa e busca Documentos referente ao Plano de Saúde de servidores. | W18: Pesquisa e busca Documentos referente ao Plano de Saúde de servidores. | X18: Pesquisa e busca Documentos referente ao Plano de Saúde de servidores. | Y18: Pesquisa e busca Documentos referente ao Plano de Saúde de servidores. | AA18: Pesquisa e busca Documentos referente ao Plano de Saúde de servidores. | AB18: Pesquisa e busca Documentos referente ao Plano de Saúde de servidores. | AC18: Pesquisa e busca Documentos referente ao Plano de Saúde de servidores. | AD18: Desarquivadas 23 pastas funcionais. | AE18: AJUSTE DO SISTEMA DE GESTAÇÃO DO ARQUIVO DA DIARQ | AG18: AJUTE NO SISTEMA DE GESTÃO DE DOCUMENTOS | AK18: ATENDENDO A DEMANDA SEI NUP Nº 71000.027931/2026-41 | AM18: ORGANIZAÇÃO DAS CAIXAS INVENTARIADAS. | AN18: ELABORAÇÃO DO DESPACHO 37 (SEI N 18519857) | AO18: AUXILIANDO NO SISTEMA DE UNIFICADO DE ARQUIVAMENTO | AP18: RESOLVENDO ASSUNTOS PESSOAIS DURANTE O DIA | AY18: RECEBIMENTO DE 70 CAIXAS SNAS. | BA18: ARMAZENTO DE 173 CAIXAS SL. 3.71 | BB18: ARMAZENAMENTO 48 CAIXAS SL 3.25 | BC18: FERIADO
A19: OBSERVAÇÃO | D19: procurando caixas da cgeof/senarc | E19: procurando caixas da cgeof/senarc | F19: despacho de arquivamento | G19: almoço em comemoração ao aniversario da Patricia, e fomo liberados mais cedo | I19: trocando as caixas e espelho | J19: trocando as caixas e espelho | S19: Pequisa e desarquivamento de 31 pastas funcionais 71000.022140/2026-24 | AU19: REMANEJAMENTO DE 175 CAIXAS, TENDO EM VISTA DO ENVIO DE APENAS UM CARREGADOR PELO SETOR RESPONSAVEL

Sheet Marcos
A1: INDICADORES | C1: 46083 | D1: 46084 | E1: 46085 | F1: 46086 | G1: 46087 | H1: TOTAL SEMANA | I1: 46090 | J1: 46091 | K1: 46092 | L1: 46093 | M1: 46094 | N1: TOTAL SEMANA | O1: 46097 | P1: 46098 | Q1: 46099 | R1: 46100 | S1: 46101 | T1: TOTAL SEMANA | U1: 46104 | V1: 46105 | W1: 46106 | X1: 46107 | Y1: 46108 | Z1: TOTAL SEMANA | AA1: 46111 | AB1: 46112 | AC1: 46113 | AD1: 46114 | AE1: 46115 | AF1: TOTAL SEMANA | AG1: 46118 | AH1: 46119 | AI1: 46120 | AJ1: 46121 | AK1: 46122 | AL1: TOTAL SEMANA | AM1: 46125 | AN1: 46126 | AO1: 46127 | AP1: 46128 | AQ1: 46129 | AR1: TOTAL SEMANA | AS1: 46132 | AT1: 46133 | AU1: 46134 | AV1: 46135 | AW1: 46136 | AX1: TOTAL SEMANA | AY1: 46139 | AZ1: 46140 | BA1: 46141 | BB1: 46142 | BC1: 46143 | BD1: TOTAL SEMANA
A2: Desarquivamento de Processos/Documentos - Saída de Guia Fora | B2: 1 | H2: =SUM(C2:G2) -> 0 | N2: =SUM(I2:M2) -> 0 | T2: =SUM(O2:S2) -> 0 | Z2: =SUM(U2:Y2) -> 0 | AF2: =SUM(AA2:AE2) -> 0 | AL2: =SUM(AG2:AK2) -> 0 | AR2: =SUM(AM2:AQ2) -> 0 | AS2: RECESSO | AT2: FERIADO | AX2: =SUM(AS2:AW2) -> 0 | BD2: =SUM(AY2:BC2) -> 0
A3: Caixas consultadas em pesquisa de desarquivamento | B3: 2 | H3: =SUM(C3:G3) -> 0 | N3: =SUM(I3:M3) -> 0 | T3: =SUM(O3:S3) -> 0 | Z3: =SUM(U3:Y3) -> 0 | AF3: =SUM(AA3:AE3) -> 0 | AL3: =SUM(AG3:AK3) -> 0 | AR3: =SUM(AM3:AQ3) -> 0 | AS3: RECESSO | AT3: FERIADO | AX3: =SUM(AS3:AW3) -> 0 | BD3: =SUM(AY3:BC3) -> 0
A4: Retorno de Processos/Documentos Desarquivados | B4: 3 | H4: =SUM(C4:G4) -> 0 | N4: =SUM(I4:M4) -> 0 | T4: =SUM(O4:S4) -> 0 | Z4: =SUM(U4:Y4) -> 0 | AF4: =SUM(AA4:AE4) -> 0 | AL4: =SUM(AG4:AK4) -> 0 | AN4: 13 | AR4: =SUM(AM4:AQ4) -> 13 | AS4: RECESSO | AT4: FERIADO | AX4: =SUM(AS4:AW4) -> 0 | BD4: =SUM(AY4:BC4) -> 0
A5: Recebimento de Documentos - Guia de Transferência | B5: 4 | H5: =SUM(C5:G5) -> 0 | N5: =SUM(I5:M5) -> 0 | T5: =SUM(O5:S5) -> 0 | Z5: =SUM(U5:Y5) -> 0 | AF5: =SUM(AA5:AE5) -> 0 | AL5: =SUM(AG5:AK5) -> 0 | AR5: =SUM(AM5:AQ5) -> 0 | AS5: RECESSO | AT5: FERIADO | AX5: =SUM(AS5:AW5) -> 0 | BD5: =SUM(AY5:BC5) -> 0
A6: Caixas separadas para classificação | B6: 5 | H6: =SUM(C6:G6) -> 0 | N6: =SUM(I6:M6) -> 0 | T6: =SUM(O6:S6) -> 0 | Z6: =SUM(U6:Y6) -> 0 | AF6: =SUM(AA6:AE6) -> 0 | AL6: =SUM(AG6:AK6) -> 0 | AR6: =SUM(AM6:AQ6) -> 0 | AS6: RECESSO | AT6: FERIADO | AX6: =SUM(AS6:AW6) -> 0 | BD6: =SUM(AY6:BC6) -> 0
A7: Processos/Documentos classificados | B7: 6 | H7: =SUM(C7:G7) -> 0 | N7: =SUM(I7:M7) -> 0 | T7: =SUM(O7:S7) -> 0 | Z7: =SUM(U7:Y7) -> 0 | AF7: =SUM(AA7:AE7) -> 0 | AL7: =SUM(AG7:AK7) -> 0 | AR7: =SUM(AM7:AQ7) -> 0 | AS7: RECESSO | AT7: FERIADO | AX7: =SUM(AS7:AW7) -> 0 | BD7: =SUM(AY7:BC7) -> 0
A8: Caixas separadas para eliminação | B8: 7 | H8: =SUM(C8:G8) -> 0 | N8: =SUM(I8:M8) -> 0 | T8: =SUM(O8:S8) -> 0 | Z8: =SUM(U8:Y8) -> 0 | AF8: =SUM(AA8:AE8) -> 0 | AL8: =SUM(AG8:AK8) -> 0 | AR8: =SUM(AM8:AQ8) -> 0 | AS8: RECESSO | AT8: FERIADO | AX8: =SUM(AS8:AW8) -> 0 | BD8: =SUM(AY8:BC8) -> 0
A9: Caixas listadas para eliminação | B9: 8 | H9: =SUM(C9:G9) -> 0 | N9: =SUM(I9:M9) -> 0 | O9: 7 | P9: 8 | Q9: 4 | R9: 7 | T9: =SUM(O9:S9) -> 26 | Z9: =SUM(U9:Y9) -> 0 | AF9: =SUM(AA9:AE9) -> 0 | AL9: =SUM(AG9:AK9) -> 0 | AR9: =SUM(AM9:AQ9) -> 0 | AS9: RECESSO | AT9: FERIADO | AX9: =SUM(AS9:AW9) -> 0 | BD9: =SUM(AY9:BC9) -> 0
A10: Processos/Documentos listados para eliminação | B10: 9 | H10: =SUM(C10:G10) -> 0 | N10: =SUM(I10:M10) -> 0 | T10: =SUM(O10:S10) -> 0 | Z10: =SUM(U10:Y10) -> 0 | AF10: =SUM(AA10:AE10) -> 0 | AL10: =SUM(AG10:AK10) -> 0 | AR10: =SUM(AM10:AQ10) -> 0 | AS10: RECESSO | AT10: FERIADO | AX10: =SUM(AS10:AW10) -> 0 | BD10: =SUM(AY10:BC10) -> 0
A11: Caixas inventariadas | B11: 10 | H11: =SUM(C11:G11) -> 0 | N11: =SUM(I11:M11) -> 0 | T11: =SUM(O11:S11) -> 0 | Z11: =SUM(U11:Y11) -> 0 | AD11: 8 | AF11: =SUM(AA11:AE11) -> 8 | AG11: 3 | AH11: 7 | AI11: 8 | AJ11: 6 | AL11: =SUM(AG11:AK11) -> 24 | AM11: 8 | AO11: 7 | AP11: 6 | AR11: =SUM(AM11:AQ11) -> 21 | AS11: RECESSO | AT11: FERIADO | AU11: 2 | AV11: 9 | AW11: 6 | AX11: =SUM(AS11:AW11) -> 17 | AY11: 8 | AZ11: 5 | BB11: 1 | BD11: =SUM(AY11:BC11) -> 14
A12: Processos/documentos inventariados | B12: 11 | H12: =SUM(C12:G12) -> 0 | N12: =SUM(I12:M12) -> 0 | T12: =SUM(O12:S12) -> 0 | Z12: =SUM(U12:Y12) -> 0 | AD12: 37 | AF12: =SUM(AA12:AE12) -> 37 | AG12: 24 | AH12: 62 | AI12: 45 | AJ12: 49 | AL12: =SUM(AG12:AK12) -> 180 | AM12: 41 | AO12: 43 | AP12: 45 | AR12: =SUM(AM12:AQ12) -> 129 | AS12: RECESSO | AT12: FERIADO | AU12: 15 | AV12: 46 | AW12: 35 | AX12: =SUM(AS12:AW12) -> 96 | AY12: 44 | AZ12: 27 | BB12: 5 | BD12: =SUM(AY12:BC12) -> 76
A13: Documentos administrativos produzidos (Despacho, Nota Técnica, minutas diversas) | B13: 12 | H13: =SUM(C13:G13) -> 0 | N13: =SUM(I13:M13) -> 0 | T13: =SUM(O13:S13) -> 0 | Z13: =SUM(U13:Y13) -> 0 | AF13: =SUM(AA13:AE13) -> 0 | AL13: =SUM(AG13:AK13) -> 0 | AR13: =SUM(AM13:AQ13) -> 0 | AS13: RECESSO | AT13: FERIADO | AX13: =SUM(AS13:AW13) -> 0 | BD13: =SUM(AY13:BC13) -> 0
A14: Orientação técnica / atendimentos realizados | B14: 13 | H14: =SUM(C14:G14) -> 0 | N14: =SUM(I14:M14) -> 0 | T14: =SUM(O14:S14) -> 0 | Z14: =SUM(U14:Y14) -> 0 | AF14: =SUM(AA14:AE14) -> 0 | AL14: =SUM(AG14:AK14) -> 0 | AR14: =SUM(AM14:AQ14) -> 0 | AS14: RECESSO | AT14: FERIADO | AX14: =SUM(AS14:AW14) -> 0 | BD14: =SUM(AY14:BC14) -> 0
