Workbook

Sheet GLOSSÁRIO
A1: INDICADORES | B1: FONTE
A2: Desarquivamento de Processos/Documentos - Saída de Guia Fora | B2: SEI (Depachos ou Ofícios assinados na unidade Diarq)
A3: Caixas consultadas em pesquisa de desarquivamento | B3: CONTAGEM INDIVIDUAL (Caixas abertas para verificação de conteúdo em contexto de pesquisa para desarquivamento)
A4: Retorno de Processos/Documentos Desarquivados | B4: SEI (Depachos ou Ofícios assinados na unidade Diarq)
A5: Recebimento de Documentos - Guia de Transferência | B5: SEI (Depachos ou Ofícios assinados na unidade Diarq)
A6: Caixas separadas para classificação | B6: CONTAGEM INDIVIDUAL (Caixas "puxadas" nas estantes como uma pré-seleção para classificação)
A7: Processos/Documentos classificados | B7: PLANILHA
A8: Caixas separadas para eliminação | B8: CONTAGEM INDIVIDUAL (Caixas "puxadas" nas estantes como uma pré-seleção para eliminação)
A9: Caixas listadas para eliminação | B9: PLANILHA
A10: Processos/Documentos listados para eliminação | B10: PLANILHA
A11: Caixas inventariadas | B11: PLANILHA
A12: Processos/documentos inventariados | B12: PLANILHA
... A16: Caixas conferidas | B16: CONTAGEM INDIVIDUAL (Caixas consultadas para simples 'conferência de quantitativo' ou do 'conteúdo do espelho' em atividades diversas)

Sheet Patrícia
A1: INDICADORES | C1: 45810 | D1: 45811 | E1: 45812 | F1: 45813 | G1: 45814 | H1: TOTAL SEMANA | I1: 45817 | J1: 45818 | K1: 45819 | L1: 45820 | M1: 45821 | N1: TOTAL SEMANA | O1: 45824 | P1: 45825 | Q1: 45826 | R1: 45827 | S1: 45828 | T1: TOTAL SEMANA | U1: 45831 | V1: 45832 | W1: 45833 | X1: 45834 | Y1: 45835 | Z1: TOTAL SEMANA | AA1: 45838 | AB1: 45839 | AC1: 45840 | AD1: 45841 | AE1: 45842 | AF1: TOTAL SEMANA | AG1: 45845 | AH1: 45846 | AI1: 45847 | AJ1: 45848 | AK1: 45849 | AL1: TOTAL SEMANA | AM1: 45852 | AN1: 45853 | AO1: 45854 | AP1: 45855 | AQ1: 45856 | AR1: TOTAL SEMANA | AS1: 45859 | AT1: 45860 | AU1: 45861 | AV1: 45862 | AW1: 45863 | AX1: TOTAL SEMANA | AY1: 45866 | AZ1: 45867 | BA1: 45868 | BB1: 45869 | BC1: 45870 | BD1: TOTAL SEMANA
A2: Desarquivamento de Processos/Documentos - Saída de Guia Fora | B2: 1 | H2: =SUM(C2:G2) -> 0 | N2: =SUM(I2:M2) -> 0 | T2: =SUM(O2:S2) -> 0 | Z2: =SUM(U2:Y2) -> 0 | AF2: =SUM(AA2:AE2) -> 0 | AL2: =SUM(AG2:AK2) -> 0 | AR2: =SUM(AM2:AQ2) -> 0 | AX2: =SUM(AS2:AW2) -> 0 | BD2: =SUM(AY2:BC2) -> 0
A3: Caixas consultadas em pesquisa de desarquivamento | B3: 2 | H3: =SUM(C3:G3) -> 0 | N3: =SUM(I3:M3) -> 0 | T3: =SUM(O3:S3) -> 0 | Z3: =SUM(U3:Y3) -> 0 | AF3: =SUM(AA3:AE3) -> 0 | AL3: =SUM(AG3:AK3) -> 0 | AR3: =SUM(AM3:AQ3) -> 0 | AX3: =SUM(AS3:AW3) -> 0 | BD3: =SUM(AY3:BC3) -> 0
A4: Retorno de Processos/Documentos Desarquivados | B4: 3 | H4: =SUM(C4:G4) -> 0 | N4: =SUM(I4:M4) -> 0 | T4: =SUM(O4:S4) -> 0 | Z4: =SUM(U4:Y4) -> 0 | AF4: =SUM(AA4:AE4) -> 0 | AL4: =SUM(AG4:AK4) -> 0 | AR4: =SUM(AM4:AQ4) -> 0 | AX4: =SUM(AS4:AW4) -> 0 | BD4: =SUM(AY4:BC4) -> 0
A5: Recebimento de Documentos - Guia de Transferência | B5: 4 | H5: =SUM(C5:G5) -> 0 | N5: =SUM(I5:M5) -> 0 | T5: =SUM(O5:S5) -> 0 | Z5: =SUM(U5:Y5) -> 0 | AF5: =SUM(AA5:AE5) -> 0 | AL5: =SUM(AG5:AK5) -> 0 | AR5: =SUM(AM5:AQ5) -> 0 | AX5: =SUM(AS5:AW5) -> 0 | BD5: =SUM(AY5:BC5) -> 0
A6: Caixas separadas para classificação | B6: 5 | H6: =SUM(C6:G6) -> 0 | N6: =SUM(I6:M6) -> 0 | T6: =SUM(O6:S6) -> 0 | Z6: =SUM(U6:Y6) -> 0 | AF6: =SUM(AA6:AE6) -> 0 | AL6: =SUM(AG6:AK6) -> 0 | AR6: =SUM(AM6:AQ6) -> 0 | AX6: =SUM(AS6:AW6) -> 0 | BD6: =SUM(AY6:BC6) -> 0
A7: Processos/Documentos classificados | B7: 6 | H7: =SUM(C7:G7) -> 0 | N7: =SUM(I7:M7) -> 0 | T7: =SUM(O7:S7) -> 0 | Z7: =SUM(U7:Y7) -> 0 | AF7: =SUM(AA7:AE7) -> 0 | AL7: =SUM(AG7:AK7) -> 0 | AR7: =SUM(AM7:AQ7) -> 0 | AX7: =SUM(AS7:AW7) -> 0 | BD7: =SUM(AY7:BC7) -> 0
A8: Caixas separadas para eliminação | B8: 7 | H8: =SUM(C8:G8) -> 0 | N8: =SUM(I8:M8) -> 0 | T8: =SUM(O8:S8) -> 0 | Z8: =SUM(U8:Y8) -> 0 | AF8: =SUM(AA8:AE8) -> 0 | AL8: =SUM(AG8:AK8) -> 0 | AR8: =SUM(AM8:AQ8) -> 0 | AX8: =SUM(AS8:AW8) -> 0 | BD8: =SUM(AY8:BC8) -> 0
A9: Caixas listadas para eliminação | B9: 8 | H9: =SUM(C9:G9) -> 0 | N9: =SUM(I9:M9) -> 0 | T9: =SUM(O9:S9) -> 0 | Z9: =SUM(U9:Y9) -> 0 | AF9: =SUM(AA9:AE9) -> 0 | AL9: =SUM(AG9:AK9) -> 0 | AR9: =SUM(AM9:AQ9) -> 0 | AX9: =SUM(AS9:AW9) -> 0 | BD9: =SUM(AY9:BC9) -> 0
A10: Processos/Documentos listados para eliminação | B10: 9 | H10: =SUM(C10:G10) -> 0 | N10: =SUM(I10:M10) -> 0 | T10: =SUM(O10:S10) -> 0 | Z10: =SUM(U10:Y10) -> 0 | AF10: =SUM(AA10:AE10) -> 0 | AL10: =SUM(AG10:AK10) -> 0 | AR10: =SUM(AM10:AQ10) -> 0 | AX10: =SUM(AS10:AW10) -> 0 | BD10: =SUM(AY10:BC10) -> 0
A11: Caixas inventariadas | B11: 10 | H11: =SUM(C11:G11) -> 0 | N11: =SUM(I11:M11) -> 0 | T11: =SUM(O11:S11) -> 0 | Z11: =SUM(U11:Y11) -> 0 | AF11: =SUM(AA11:AE11) -> 0 | AL11: =SUM(AG11:AK11) -> 0 | AR11: =SUM(AM11:AQ11) -> 0 | AX11: =SUM(AS11:AW11) -> 0 | BD11: =SUM(AY11:BC11) -> 0
A12: Processos/documentos inventariados | B12: 11 | H12: =SUM(C12:G12) -> 0 | N12: =SUM(I12:M12) -> 0 | T12: =SUM(O12:S12) -> 0 | Z12: =SUM(U12:Y12) -> 0 | AF12: =SUM(AA12:AE12) -> 0 | AL12: =SUM(AG12:AK12) -> 0 | AR12: =SUM(AM12:AQ12) -> 0 | AX12: =SUM(AS12:AW12) -> 0 | BD12: =SUM(AY12:BC12) -> 0
A13: Documentos administrativos produzidos (Despacho, Nota Técnica, minutas diversas) | B13: 12 | H13: =SUM(C13:G13) -> 0 | J13: 1 | M13: 1 | N13: =SUM(I13:M13) -> 2 | P13: 1 | T13: =SUM(O13:S13) -> 1 | U13: 1 | V13: 1 | Z13: =SUM(U13:Y13) -> 2 | AA13: 1 | AC13: 1 | AF13: =SUM(AA13:AE13) -> 2 | AL13: =SUM(AG13:AK13) -> 0 | AR13: =SUM(AM13:AQ13) -> 0 | AX13: =SUM(AS13:AW13) -> 0 | BD13: =SUM(AY13:BC13) -> 0
A14: Orientação técnica / atendimentos realizados | B14: 13 | H14: =SUM(C14:G14) -> 0 | N14: =SUM(I14:M14) -> 0 | T14: =SUM(O14:S14) -> 0 | Z14: =SUM(U14:Y14) -> 0 | AF14: =SUM(AA14:AE14) -> 0 | AL14: =SUM(AG14:AK14) -> 0 | AR14: =SUM(AM14:AQ14) -> 0 | AX14: =SUM(AS14:AW14) -> 0 | BD14: =SUM(AY14:BC14) -> 0
A15: Caixas remanejadas | B15: 14 | H15: =SUM(C15:G15) -> 0 | N15: =SUM(I15:M15) -> 0 | T15: =SUM(O15:S15) -> 0 | Z15: =SUM(U15:Y15) -> 0 | AF15: =SUM(AA15:AE15) -> 0 | AL15: =SUM(AG15:AK15) -> 0 | AR15: =SUM(AM15:AQ15) -> 0 | AX15: =SUM(AS15:AW15) -> 0 | BD15: =SUM(AY15:BC15) -> 0
A16: Caixas conferidas | B16: 15 | H16: =SUM(C16:G16) -> 0 | N16: =SUM(I16:M16) -> 0 | T16: =SUM(O16:S16) -> 0 | Z16: =SUM(U16:Y16) -> 0 | AF16: =SUM(AA16:AE16) -> 0 | AL16: =SUM(AG16:AK16) -> 0 | AR16: =SUM(AM16:AQ16) -> 0 | AX16: =SUM(AS16:AW16) -> 0 | BD16: =SUM(AY16:BC16) -> 0
A17: OUTRA ATIVIDADE. QUAL?
A18: OBSERVAÇÃO

Sheet Marcelo
A1: INDICADORES | C1: 45810 | D1: 45811 | E1: 45812 | F1: 45813 | G1: 45814 | H1: TOTAL SEMANA | I1: 45817 | J1: 45818 | K1: 45819 | L1: 45820 | M1: 45821 | N1: TOTAL SEMANA | O1: 45824 | P1: 45825 | Q1: 45826 | R1: 45827 | S1: 45828 | T1: TOTAL SEMANA | U1: 45831 | V1: 45832 | W1: 45833 | X1: 45834 | Y1: 45835 | Z1: TOTAL SEMANA | AA1: 45838 | AB1: 45839 | AC1: 45840 | AD1: 45841 | AE1: 45842 | AF1: TOTAL SEMANA | AG1: 45845 | AH1: 45846 | AI1: 45847 | AJ1: 45848 | AK1: 45849 | AL1: TOTAL SEMANA | AM1: 45852 | AN1: 45853 | AO1: 45854 | AP1: 45855 | AQ1: 45856 | AR1: TOTAL SEMANA | AS1: 45859 | AT1: 45860 | AU1: 45861 | AV1: 45862 | AW1: 45863 | AX1: TOTAL SEMANA | AY1: 45866 | AZ1: 45867 | BA1: 45868 | BB1: 45869 | BC1: 45870 | BD1: TOTAL SEMANA
A2: Desarquivamento de Processos/Documentos - Saída de Guia Fora | B2: 1 | H2: =SUM(C2:G2) -> 0 | N2: =SUM(I2:M2) -> 0 | T2: =SUM(O2:S2) -> 0 | Z2: =SUM(U2:Y2) -> 0 | AF2: =SUM(AA2:AE2) -> 0 | AL2: =SUM(AG2:AK2) -> 0 | AR2: =SUM(AM2:AQ2) -> 0 | AX2: =SUM(AS2:AW2) -> 0 | BD2: =SUM(AY2:BC2) -> 0
A3: Caixas consultadas em pesquisa de desarquivamento | B3: 2 | H3: =SUM(C3:G3) -> 0 | N3: =SUM(I3:M3) -> 0 | T3: =SUM(O3:S3) -> 0 | Z3: =SUM(U3:Y3) -> 0 | AF3: =SUM(AA3:AE3) -> 0 | AL3: =SUM(AG3:AK3) -> 0 | AR3: =SUM(AM3:AQ3) -> 0 | AX3: =SUM(AS3:AW3) -> 0 | BD3: =SUM(AY3:BC3) -> 0
A4: Retorno de Processos/Documentos Desarquivados | B4: 3 | H4: =SUM(C4:G4) -> 0 | N4: =SUM(I4:M4) -> 0 | T4: =SUM(O4:S4) -> 0 | Z4: =SUM(U4:Y4) -> 0 | AF4: =SUM(AA4:AE4) -> 0 | AL4: =SUM(AG4:AK4) -> 0 | AR4: =SUM(AM4:AQ4) -> 0 | AX4: =SUM(AS4:AW4) -> 0 | BD4: =SUM(AY4:BC4) -> 0
A5: Recebimento de Documentos - Guia de Transferência | B5: 4 | H5: =SUM(C5:G5) -> 0 | N5: =SUM(I5:M5) -> 0 | T5: =SUM(O5:S5) -> 0 | Z5: =SUM(U5:Y5) -> 0 | AF5: =SUM(AA5:AE5) -> 0 | AL5: =SUM(AG5:AK5) -> 0 | AR5: =SUM(AM5:AQ5) -> 0 | AX5: =SUM(AS5:AW5) -> 0 | BD5: =SUM(AY5:BC5) -> 0
A6: Caixas separadas para classificação | B6: 5 | H6: =SUM(C6:G6) -> 0 | N6: =SUM(I6:M6) -> 0 | T6: =SUM(O6:S6) -> 0 | Z6: =SUM(U6:Y6) -> 0 | AF6: =SUM(AA6:AE6) -> 0 | AL6: =SUM(AG6:AK6) -> 0 | AR6: =SUM(AM6:AQ6) -> 0 | AX6: =SUM(AS6:AW6) -> 0 | BD6: =SUM(AY6:BC6) -> 0
A7: Processos/Documentos classificados | B7: 6 | H7: =SUM(C7:G7) -> 0 | N7: =SUM(I7:M7) -> 0 | T7: =SUM(O7:S7) -> 0 | Z7: =SUM(U7:Y7) -> 0 | AF7: =SUM(AA7:AE7) -> 0 | AL7: =SUM(AG7:AK7) -> 0 | AR7: =SUM(AM7:AQ7) -> 0 | AX7: =SUM(AS7:AW7) -> 0 | BD7: =SUM(AY7:BC7) -> 0
A8: Caixas separadas para eliminação | B8: 7 | H8: =SUM(C8:G8) -> 0 | N8: =SUM(I8:M8) -> 0 | T8: =SUM(O8:S8) -> 0 | Z8: =SUM(U8:Y8) -> 0 | AF8: =SUM(AA8:AE8) -> 0 | AL8: =SUM(AG8:AK8) -> 0 | AR8: =SUM(AM8:AQ8) -> 0 | AX8: =SUM(AS8:AW8) -> 0 | BD8: =SUM(AY8:BC8) -> 0
A9: Caixas listadas para eliminação | B9: 8 | H9: =SUM(C9:G9) -> 0 | N9: =SUM(I9:M9) -> 0 | T9: =SUM(O9:S9) -> 0 | Z9: =SUM(U9:Y9) -> 0 | AF9: =SUM(AA9:AE9) -> 0 | AL9: =SUM(AG9:AK9) -> 0 | AR9: =SUM(AM9:AQ9) -> 0 | AX9: =SUM(AS9:AW9) -> 0 | BD9: =SUM(AY9:BC9) -> 0
A10: Processos/Documentos listados para eliminação | B10: 9 | H10: =SUM(C10:G10) -> 0 | N10: =SUM(I10:M10) -> 0 | T10: =SUM(O10:S10) -> 0 | Z10: =SUM(U10:Y10) -> 0 | AF10: =SUM(AA10:AE10) -> 0 | AL10: =SUM(AG10:AK10) -> 0 | AR10: =SUM(AM10:AQ10) -> 0 | AX10: =SUM(AS10:AW10) -> 0 | BD10: =SUM(AY10:BC10) -> 0
A11: Caixas inventariadas | B11: 10 | H11: =SUM(C11:G11) -> 0 | N11: =SUM(I11:M11) -> 0 | T11: =SUM(O11:S11) -> 0 | Z11: =SUM(U11:Y11) -> 0 | AF11: =SUM(AA11:AE11) -> 0 | AL11: =SUM(AG11:AK11) -> 0 | AR11: =SUM(AM11:AQ11) -> 0 | AX11: =SUM(AS11:AW11) -> 0 | BD11: =SUM(AY11:BC11) -> 0
A12: Processos/documentos inventariados | B12: 11 | H12: =SUM(C12:G12) -> 0 | N12: =SUM(I12:M12) -> 0 | T12: =SUM(O12:S12) -> 0 | Z12: =SUM(U12:Y12) -> 0 | AF12: =SUM(AA12:AE12) -> 0 | AL12: =SUM(AG12:AK12) -> 0 | AR12: =SUM(AM12:AQ12) -> 0 | AX12: =SUM(AS12:AW12) -> 0 | BD12: =SUM(AY12:BC12) -> 0
A13: Documentos administrativos produzidos (Despacho, Nota Técnica, minutas diversas) | B13: 12 | H13: =SUM(C13:G13) -> 0 | N13: =SUM(I13:M13) -> 0 | T13: =SUM(O13:S13) -> 0 | Z13: =SUM(U13:Y13) -> 0 | AF13: =SUM(AA13:AE13) -> 0 | AL13: =SUM(AG13:AK13) -> 0 | AR13: =SUM(AM13:AQ13) -> 0 | AX13: =SUM(AS13:AW13) -> 0 | BD13: =SUM(AY13:BC13) -> 0
... A16: Caixas conferidas | B16: 15 | H16: =SUM(C16:G16) -> 0 | N16: =SUM(I16:M16) -> 0 | T16: =SUM(O16:S16) -> 0 | Z16: =SUM(U16:Y16) -> 0 | AF16: =SUM(AA16:AE16) -> 0 | AL16: =SUM(AG16:AK16) -> 0 | AR16: =SUM(AM16:AQ16) -> 0 | AX16: =SUM(AS16:AW16) -> 0 | BD16: =SUM(AY16:BC16) -> 0
A17: OUTRA ATIVIDADE. QUAL?
A18: OBSERVAÇÃO

Sheet TOTAL
A1: INDICADORES | B1: Fonte | C1: 06/10 a 10/10/2025 | D1: 13/10 a 17/10/2025 | E1: 20/10 a 24/10/2025 | F1: 27/10 a 31/10/2025 | G1: 03/11 a 07/11/2025 | H1: 10/11 a 14/11/2025 | I1: 17/11 a 21/11/2025 | J1: 24/11 a 28/11/2025 | K1: 01/12 a 05/12/2025 | L1: 08/12 a 12/12/2025 | M1: 15/12 a 19/12/2025 | N1: 22/12 a 26/12/2025 | O1: 29/12 a 02/01/2026
A2: Desarquivamento de Processos/Documentos - Saída de Guia Fora | B2: SEI | C2: =Diego!H2+Aelton!H2+Leonam!H2+Danilo!H2+Marcos!H2+Alessandro!H2+Carlos!H2 -> 1 | D2: =Diego!N2+Aelton!N2+Leonam!N2+Danilo!N2+Marcos!N2+Carlos!N2+Alessandro!N2 -> 0 | E2: =Diego!T2+Aelton!T2+Leonam!T2+Danilo!T2+Marcos!T2+Carlos!T2+Alessandro!T2 -> 34 | F2: =Diego!Z2+Aelton!Z2+Leonam!Z2+Danilo!Z2+Marcos!Z2+Carlos!Z2+Alessandro!Z2 -> 0 | G2: =Diego!AF2+Aelton!AF2+Leonam!AF2+Danilo!AF2+Marcos!AF2+Carlos!AF2+Alessandro!AF2 -> 8 | H2: =Diego!AL2+Aelton!AL2+Leonam!AL2+Danilo!AL2+Marcos!AL2+Carlos!AL2+Alessandro!AL2 -> 95 | I2: =Diego!AR2+Aelton!AR2+Leonam!AR2+Danilo!AR2+Marcos!AR2+Carlos!AR2+Alessandro!AR2 -> 14 | J2: =Diego!AX2+Aelton!AX2+Leonam!AX2+Danilo!AX2+Marcos!AX2+Carlos!AX2+Alessandro!AX2 -> 0 | K2: =Diego!BD2+Aelton!BD2+Leonam!BD2+Danilo!BD2+Marcos!BD2+Carlos!BD2+Alessandro!BD2 -> 0 | L2: =Diego!BJ2+Aelton!BJ2+Leonam!BJ2+Danilo!BJ2+Marcos!BJ2+Carlos!BJ2+Alessandro!BJ2 -> 0 | M2: =Diego!BP2+Aelton!BP2+Leonam!BP2+Danilo!BP2+Marcos!BP2+Carlos!BP2+Alessandro!BP2 -> 0 | N2: =Diego!BV2+Aelton!BV2+Leonam!BV2+Danilo!BV2+Marcos!BV2+Carlos!BV2+Alessandro!BV2 -> 0 | O2: =Diego!CB2+Aelton!CB2+Leonam!CB2+Danilo!CBH2+Marcos!CBH2+Carlos!CB2+Alessandro!CB2 -> 1
A3: Caixas consultadas em pesquisa de desarquivamento | B3: CONTAGEM INDIVIDUAL (das caixas abertas para verificação de conteúdo em contexto de pesquisa para desarquivamento) | C3: =Diego!H3+Aelton!AF3+Leonam!H3+Danilo!H3+Marcos!H3+Alessandro!H3+Carlos!H3 -> 0 | D3: =Diego!N3+Aelton!N3+Leonam!N3+Danilo!N3+Marcos!N3+Carlos!N3+Alessandro!N3 -> 0 | E3: =Diego!T3+Aelton!T3+Leonam!T3+Danilo!T3+Marcos!T3+Carlos!T3+Alessandro!T3 -> 0 | F3: =Diego!Z3+Aelton!Z3+Leonam!Z3+Danilo!Z3+Marcos!Z3+Carlos!Z3+Alessandro!Z3 -> 0 | G3: =Diego!AF3+Aelton!AF3+Leonam!AF3+Danilo!AF3+Marcos!AF3+Carlos!AF3+Alessandro!AF3 -> 10 | H3: =Diego!AL3+Aelton!AL3+Leonam!AL3+Danilo!AL3+Marcos!AL3+Carlos!AL3+Alessandro!AL3 -> 45 | I3: =Diego!AR3+Aelton!AR3+Leonam!AR3+Danilo!AR3+Marcos!AR3+Carlos!AR3+Alessandro!AR3 -> 0 | J3: =Diego!AX3+Aelton!AX3+Leonam!AX3+Danilo!AX3+Marcos!AX3+Carlos!AX3+Alessandro!AX3 -> 2 | K3: =Diego!BD3+Aelton!BD3+Leonam!BD3+Danilo!BD3+Marcos!BD3+Carlos!BD3+Alessandro!BD3 -> 0 | L3: =Diego!BJ3+Aelton!BJ3+Leonam!BJ3+Danilo!BJ3+Marcos!BJ3+Carlos!BJ3+Alessandro!BJ3 -> 0 | M3: =Diego!BP3+Aelton!BP3+Leonam!BP3+Danilo!BP3+Marcos!BP3+Carlos!BP3+Alessandro!BP3 -> 0 | N3: =Diego!BV3+Aelton!BV3+Leonam!BV3+Danilo!BV3+Marcos!BV3+Carlos!BV3+Alessandro!BV3 -> 0 | O3: =Diego!CB3+Aelton!CB3+Leonam!CB3+Danilo!CBH3+Marcos!CBH3+Carlos!CB3+Alessandro!CB3 -> 0
A4: Retorno de Processos/Documentos Desarquivados | B4: SEI | C4: =Diego!H4+Aelton!AF4+Leonam!H4+Danilo!H4+Marcos!H4+Alessandro!H4+Carlos!H4 -> 20 | D4: =Diego!N4+Aelton!N4+Leonam!N4+Danilo!N4+Marcos!N4+Carlos!N4+Alessandro!N4 -> 0 | E4: =Diego!T4+Aelton!T4+Leonam!T4+Danilo!T4+Marcos!T4+Carlos!T4+Alessandro!T4 -> 0 | F4: =Diego!Z4+Aelton!Z4+Leonam!Z4+Danilo!Z4+Marcos!Z4+Carlos!Z4+Alessandro!Z4 -> 176 | G4: =Diego!AF4+Aelton!AF4+Leonam!AF4+Danilo!AF4+Marcos!AF4+Carlos!AF4+Alessandro!AF4 -> 35 | H4: =Diego!AL4+Aelton!AL4+Leonam!AL4+Danilo!AL4+Marcos!AL4+Carlos!AL4+Alessandro!AL4 -> 3 | I4: =Diego!AR4+Aelton!AR4+Leonam!AR4+Danilo!AR4+Marcos!AR4+Carlos!AR4+Alessandro!AR4 -> 50 | J4: =Diego!AX4+Aelton!AX4+Leonam!AX4+Danilo!AX4+Marcos!AX4+Carlos!AX4+Alessandro!AX4 -> 2 | K4: =Diego!BD4+Aelton!BD4+Leonam!BD4+Danilo!BD4+Marcos!BD4+Carlos!BD4+Alessandro!BD4 -> 0 | L4: =Diego!BJ4+Aelton!BJ4+Leonam!BJ4+Danilo!BJ4+Marcos!BJ4+Carlos!BJ4+Alessandro!BJ4 -> 0 | M4: =Diego!BP4+Aelton!BP4+Leonam!BP4+Danilo!BP4+Marcos!BP4+Carlos!BP4+Alessandro!BP4 -> 0 | N4: =Diego!BV4+Aelton!BV4+Leonam!BV4+Danilo!BV4+Marcos!BV4+Carlos!BV4+Alessandro!BV4 -> 0 | O4: =Diego!CB4+Aelton!CB4+Leonam!CB4+Danilo!CBH4+Marcos!CBH4+Carlos!CB4+Alessandro!CB4 -> 0
A5: Recebimento de Documentos - Guia de Transferência | B5: SEI | C5: =Diego!H5+Aelton!AF5+Leonam!H5+Danilo!H5+Marcos!H5+Alessandro!H5+Carlos!H5 -> 0 | D5: =Diego!N5+Aelton!N5+Leonam!N5+Danilo!N5+Marcos!N5+Carlos!N5+Alessandro!N5 -> 0 | E5: =Diego!T5+Aelton!T5+Leonam!T5+Danilo!T5+Marcos!T5+Carlos!T5+Alessandro!T5 -> 0 | F5: =Diego!Z5+Aelton!Z5+Leonam!Z5+Danilo!Z5+Marcos!Z5+Carlos!Z5+Alessandro!Z5 -> 0 | G5: =Diego!AF5+Aelton!AF5+Leonam!AF5+Danilo!AF5+Marcos!AF5+Carlos!AF5+Alessandro!AF5 -> 0 | H5: =Diego!AL5+Aelton!AL5+Leonam!AL5+Danilo!AL5+Marcos!AL5+Carlos!AL5+Alessandro!AL5 -> 0 | I5: =Diego!AR5+Aelton!AR5+Leonam!AR5+Danilo!AR5+Marcos!AR5+Carlos!AR5+Alessandro!AR5 -> 26 | J5: =Diego!AX5+Aelton!AX5+Leonam!AX5+Danilo!AX5+Marcos!AX5+Carlos!AX5+Alessandro!AX5 -> 0 | K5: =Diego!BD5+Aelton!BD5+Leonam!BD5+Danilo!BD5+Marcos!BD5+Carlos!BD5+Alessandro!BD5 -> 0 | L5: =Diego!BJ5+Aelton!BJ5+Leonam!BJ5+Danilo!BJ5+Marcos!BJ5+Carlos!BJ5+Alessandro!BJ5 -> 0 | M5: =Diego!BP5+Aelton!BP5+Leonam!BP5+Danilo!BP5+Marcos!BP5+Carlos!BP5+Alessandro!BP5 -> 1 | N5: =Diego!BV5+Aelton!BV5+Leonam!BV5+Danilo!BV5+Marcos!BV5+Carlos!BV5+Alessandro!BV5 -> 0 | O5: =Diego!CB5+Aelton!CB5+Leonam!CB5+Danilo!CBH5+Marcos!CBH5+Carlos!CB5+Alessandro!CB5 -> 0
A6: Caixas separadas para classificação | B6: CONTAGEM INDIVIDUAL (das caixas "puxadas" nas estantes como uma pré-seleção para classificação) | C6: =Diego!H6+Aelton!AF6+Leonam!H6+Danilo!H6+Marcos!H6+Alessandro!H6+Carlos!H6 -> 0 | D6: =Diego!N6+Aelton!N6+Leonam!N6+Danilo!N6+Marcos!N6+Carlos!N6+Alessandro!N6 -> 0 | E6: =Diego!T6+Aelton!T6+Leonam!T6+Danilo!T6+Marcos!T6+Carlos!T6+Alessandro!T6 -> 0 | F6: =Diego!Z6+Aelton!Z6+Leonam!Z6+Danilo!Z6+Marcos!Z6+Carlos!Z6+Alessandro!Z6 -> 0 | G6: =Diego!AF6+Aelton!AF6+Leonam!AF6+Danilo!AF6+Marcos!AF6+Carlos!AF6+Alessandro!AF6 -> 0 | H6: =Diego!AL6+Aelton!AL6+Leonam!AL6+Danilo!AL6+Marcos!AL6+Carlos!AL6+Alessandro!AL6 -> 0 | I6: =Diego!AR6+Aelton!AR6+Leonam!AR6+Danilo!AR6+Marcos!AR6+Carlos!AR6+Alessandro!AR6 -> 0 | J6: =Diego!AX6+Aelton!AX6+Leonam!AX6+Danilo!AX6+Marcos!AX6+Carlos!AX6+Alessandro!AX6 -> 0 | K6: =Diego!BD6+Aelton!BD6+Leonam!BD6+Danilo!BD6+Marcos!BD6+Carlos!BD6+Alessandro!BD6 -> 0 | L6: =Diego!BJ6+Aelton!BJ6+Leonam!BJ6+Danilo!BJ6+Marcos!BJ6+Carlos!BJ6+Alessandro!BJ6 -> 0 | M6: =Diego!BP6+Aelton!BP6+Leonam!BP6+Danilo!BP6+Marcos!BP6+Carlos!BP6+Alessandro!BP6 -> 0 | N6: =Diego!BV6+Aelton!BV6+Leonam!BV6+Danilo!BV6+Marcos!BV6+Carlos!BV6+Alessandro!BV6 -> 0 | O6: =Diego!CB6+Aelton!CB6+Leonam!CB6+Danilo!CBH6+Marcos!CBH6+Carlos!CB6+Alessandro!CB6 -> 0
A7: Processos/Documentos classificados | B7: PLANILHA | C7: =Diego!H7+Aelton!AF7+Leonam!H7+Danilo!H7+Marcos!H7+Alessandro!H7+Carlos!H7 -> 0 | D7: =Diego!N7+Aelton!N7+Leonam!N7+Danilo!N7+Marcos!N7+Carlos!N7+Alessandro!N7 -> 0 | E7: =Diego!T7+Aelton!T7+Leonam!T7+Danilo!T7+Marcos!T7+Carlos!T7+Alessandro!T7 -> 0 | F7: =Diego!Z7+Aelton!Z7+Leonam!Z7+Danilo!Z7+Marcos!Z7+Carlos!Z7+Alessandro!Z7 -> 0 | G7: =Diego!AF7+Aelton!AF7+Leonam!AF7+Danilo!AF7+Marcos!AF7+Carlos!AF7+Alessandro!AF7 -> 0 | H7: =Diego!AL7+Aelton!AL7+Leonam!AL7+Danilo!AL7+Marcos!AL7+Carlos!AL7+Alessandro!AL7 -> 0 | I7: =Diego!AR7+Aelton!AR7+Leonam!AR7+Danilo!AR7+Marcos!AR7+Carlos!AR7+Alessandro!AR7 -> 0 | J7: =Diego!AX7+Aelton!AX7+Leonam!AX7+Danilo!AX7+Marcos!AX7+Carlos!AX7+Alessandro!AX7 -> 0 | K7: =Diego!BD7+Aelton!BD7+Leonam!BD7+Danilo!BD7+Marcos!BD7+Carlos!BD7+Alessandro!BD7 -> 0 | L7: =Diego!BJ7+Aelton!BJ7+Leonam!BJ7+Danilo!BJ7+Marcos!BJ7+Carlos!BJ7+Alessandro!BJ7 -> 0 | M7: =Diego!BP7+Aelton!BP7+Leonam!BP7+Danilo!BP7+Marcos!BP7+Carlos!BP7+Alessandro!BP7 -> 0 | N7: =Diego!BV7+Aelton!BV7+Leonam!BV7+Danilo!BV7+Marcos!BV7+Carlos!BV7+Alessandro!BV7 -> 0 | O7: =Diego!CB7+Aelton!CB7+Leonam!CB7+Danilo!CBH7+Marcos!CBH7+Carlos!CB7+Alessandro!CB7 -> 0
A8: Caixas separadas para eliminação | B8: CONTAGEM INDIVIDUAL (das caixas "puxadas" nas estantes como uma pré-seleção para eliminação) | C8: =Diego!H8+Aelton!AF8+Leonam!H8+Danilo!H8+Marcos!H8+Alessandro!H8+Carlos!H8 -> 0 | D8: =Diego!N8+Aelton!N8+Leonam!N8+Danilo!N8+Marcos!N8+Carlos!N8+Alessandro!N8 -> 0 | E8: =Diego!T8+Aelton!T8+Leonam!T8+Danilo!T8+Marcos!T8+Carlos!T8+Alessandro!T8 -> 0 | F8: =Diego!Z8+Aelton!Z8+Leonam!Z8+Danilo!Z8+Marcos!Z8+Carlos!Z8+Alessandro!Z8 -> 0 | G8: =Diego!AF8+Aelton!AF8+Leonam!AF8+Danilo!AF8+Marcos!AF8+Carlos!AF8+Alessandro!AF8 -> 0 | H8: =Diego!AL8+Aelton!AL8+Leonam!AL8+Danilo!AL8+Marcos!AL8+Carlos!AL8+Alessandro!AL8 -> 0 | I8: =Diego!AR8+Aelton!AR8+Leonam!AR8+Danilo!AR8+Marcos!AR8+Carlos!AR8+Alessandro!AR8 -> 0 | J8: =Diego!AX8+Aelton!AX8+Leonam!AX8+Danilo!AX8+Marcos!AX8+Carlos!AX8+Alessandro!AX8 -> 0 | K8: =Diego!BD8+Aelton!BD8+Leonam!BD8+Danilo!BD8+Marcos!BD8+Carlos!BD8+Alessandro!BD8 -> 0 | L8: =Diego!BJ8+Aelton!BJ8+Leonam!BJ8+Danilo!BJ8+Marcos!BJ8+Carlos!BJ8+Alessandro!BJ8 -> 0 | M8: =Diego!BP8+Aelton!BP8+Leonam!BP8+Danilo!BP8+Marcos!BP8+Carlos!BP8+Alessandro!BP8 -> 0 | N8: =Diego!BV8+Aelton!BV8+Leonam!BV8+Danilo!BV8+Marcos!BV8+Carlos!BV8+Alessandro!BV8 -> 0 | O8: =Diego!CB8+Aelton!CB8+Leonam!CB8+Danilo!CBH8+Marcos!CBH8+Carlos!CB8+Alessandro!CB8 -> 0
A9: Caixas listadas para eliminação | B9: PLANILHA | C9: =Diego!H9+Aelton!AF9+Leonam!H9+Danilo!H9+Marcos!H9+Alessandro!H9+Carlos!H9 -> 0 | D9: =Diego!N9+Aelton!N9+Leonam!N9+Danilo!N9+Marcos!N9+Carlos!N9+Alessandro!N9 -> 0 | E9: =Diego!T9+Aelton!T9+Leonam!T9+Danilo!T9+Marcos!T9+Carlos!T9+Alessandro!T9 -> 0 | F9: =Diego!Z9+Aelton!Z9+Leonam!Z9+Danilo!Z9+Marcos!Z9+Carlos!Z9+Alessandro!Z9 -> 0 | G9: =Diego!AF9+Aelton!AF9+Leonam!AF9+Danilo!AF9+Marcos!AF9+Carlos!AF9+Alessandro!AF9 -> 0 | H9: =Diego!AL9+Aelton!AL9+Leonam!AL9+Danilo!AL9+Marcos!AL9+Carlos!AL9+Alessandro!AL9 -> 0 | I9: =Diego!AR9+Aelton!AR9+Leonam!AR9+Danilo!AR9+Marcos!AR9+Carlos!AR9+Alessandro!AR9 -> 0 | J9: =Diego!AX9+Aelton!AX9+Leonam!AX9+Danilo!AX9+Marcos!AX9+Carlos!AX9+Alessandro!AX9 -> 0 | K9: =Diego!BD9+Aelton!BD9+Leonam!BD9+Danilo!BD9+Marcos!BD9+Carlos!BD9+Alessandro!BD9 -> 0 | L9: =Diego!BJ9+Aelton!BJ9+Leonam!BJ9+Danilo!BJ9+Marcos!BJ9+Carlos!BJ9+Alessandro!BJ9 -> 0 | M9: =Diego!BP9+Aelton!BP9+Leonam!BP9+Danilo!BP9+Marcos!BP9+Carlos!BP9+Alessandro!BP9 -> 0 | N9: =Diego!BV9+Aelton!BV9+Leonam!BV9+Danilo!BV9+Marcos!BV9+Carlos!BV9+Alessandro!BV9 -> 0 | O9: =Diego!CB9+Aelton!CB9+Leonam!CB9+Danilo!CBH9+Marcos!CBH9+Carlos!CB9+Alessandro!CB9 -> 0
A10: Processos/Documentos listados para eliminação | B10: PLANILHA | C10: =Diego!H10+Aelton!AF10+Leonam!H10+Danilo!H10+Marcos!H10+Alessandro!H10+Carlos!H10 -> 0 | D10: =Diego!N10+Aelton!N10+Leonam!N10+Danilo!N10+Marcos!N10+Carlos!N10+Alessandro!N10 -> 0 | E10: =Diego!T10+Aelton!T10+Leonam!T10+Danilo!T10+Marcos!T10+Carlos!T10+Alessandro!T10 -> 0 | F10: =Diego!Z10+Aelton!Z10+Leonam!Z10+Danilo!Z10+Marcos!Z10+Carlos!Z10+Alessandro!Z10 -> 0 | G10: =Diego!AF10+Aelton!AF10+Leonam!AF10+Danilo!AF10+Marcos!AF10+Carlos!AF10+Alessandro!AF10 -> 0 | H10: =Diego!AL10+Aelton!AL10+Leonam!AL10+Danilo!AL10+Marcos!AL10+Carlos!AL10+Alessandro!AL10 -> 0 | I10: =Diego!AR10+Aelton!AR10+Leonam!AR10+Danilo!AR10+Marcos!AR10+Carlos!AR10+Alessandro!AR10 -> 0 | J10: =Diego!AX10+Aelton!AX10+Leonam!AX10+Danilo!AX10+Marcos!AX10+Carlos!AX10+Alessandro!AX10 -> 0 | K10: =Diego!BD10+Aelton!BD10+Leonam!BD10+Danilo!BD10+Marcos!BD10+Carlos!BD10+Alessandro!BD10 -> 0 | L10: =Diego!BJ10+Aelton!BJ10+Leonam!BJ10+Danilo!BJ10+Marcos!BJ10+Carlos!BJ10+Alessandro!BJ10 -> 0 | M10: =Diego!BP10+Aelton!BP10+Leonam!BP10+Danilo!BP10+Marcos!BP10+Carlos!BP10+Alessandro!BP10 -> 0 | N10: =Diego!BV10+Aelton!BV10+Leonam!BV10+Danilo!BV10+Marcos!BV10+Carlos!BV10+Alessandro!BV10 -> 0 | O10: =Diego!CB10+Aelton!CB10+Leonam!CB10+Danilo!CBH10+Marcos!CBH10+Carlos!CB10+Alessandro!CB10 -> 0
A11: Caixas inventariadas | B11: PLANILHA | C11: =Diego!H11+Aelton!AF11+Leonam!H11+Danilo!H11+Marcos!H11+Alessandro!H11+Carlos!H11 -> 0 | D11: =Diego!N11+Aelton!N11+Leonam!N11+Danilo!N11+Marcos!N11+Carlos!N11+Alessandro!N11 -> 0 | E11: =Diego!T11+Aelton!T11+Leonam!T11+Danilo!T11+Marcos!T11+Carlos!T11+Alessandro!T11 -> 0 | F11: =Diego!Z11+Aelton!Z11+Leonam!Z11+Danilo!Z11+Marcos!Z11+Carlos!Z11+Alessandro!Z11 -> 0 | G11: =Diego!AF11+Aelton!AF11+Leonam!AF11+Danilo!AF11+Marcos!AF11+Carlos!AF11+Alessandro!AF11 -> 0 | H11: =Diego!AL11+Aelton!AL11+Leonam!AL11+Danilo!AL11+Marcos!AL11+Carlos!AL11+Alessandro!AL11 -> 0 | I11: =Diego!AR11+Aelton!AR11+Leonam!AR11+Danilo!AR11+Marcos!AR11+Carlos!AR11+Alessandro!AR11 -> 0 | J11: =Diego!AX11+Aelton!AX11+Leonam!AX11+Danilo!AX11+Marcos!AX11+Carlos!AX11+Alessandro!AX11 -> 0 | K11: =Diego!BD11+Aelton!BD11+Leonam!BD11+Danilo!BD11+Marcos!BD11+Carlos!BD11+Alessandro!BD11 -> 0 | L11: =Diego!BJ11+Aelton!BJ11+Leonam!BJ11+Danilo!BJ11+Marcos!BJ11+Carlos!BJ11+Alessandro!BJ11 -> 0 | M11: =Diego!BP11+Aelton!BP11+Leonam!BP11+Danilo!BP11+Marcos!BP11+Carlos!BP11+Alessandro!BP11 -> 0 | N11: =Diego!BV11+Aelton!BV11+Leonam!BV11+Danilo!BV11+Marcos!BV11+Carlos!BV11+Alessandro!BV11 -> 0 | O11: =Diego!CB11+Aelton!CB11+Leonam!CB11+Danilo!CBH11+Marcos!CBH11+Carlos!CB11+Alessandro!CB11 -> 0
A12: Processos/documentos inventariados | B12: PLANILHA | C12: =Diego!H12+Aelton!AF12+Leonam!H12+Danilo!H12+Marcos!H12+Alessandro!H12+Carlos!H12 -> 0 | D12: =Diego!N12+Aelton!N12+Leonam!N12+Danilo!N12+Marcos!N12+Carlos!N12+Alessandro!N12 -> 0 | E12: =Diego!T12+Aelton!T12+Leonam!T12+Danilo!T12+Marcos!T12+Carlos!T12+Alessandro!T12 -> 0 | F12: =Diego!Z12+Aelton!Z12+Leonam!Z12+Danilo!Z12+Marcos!Z12+Carlos!Z12+Alessandro!Z12 -> 0 | G12: =Diego!AF12+Aelton!AF12+Leonam!AF12+Danilo!AF12+Marcos!AF12+Carlos!AF12+Alessandro!AF12 -> 0 | H12: =Diego!AL12+Aelton!AL12+Leonam!AL12+Danilo!AL12+Marcos!AL12+Carlos!AL12+Alessandro!AL12 -> 0 | I12: =Diego!AR12+Aelton!AR12+Leonam!AR12+Danilo!AR12+Marcos!AR12+Carlos!AR12+Alessandro!AR12 -> 0 | J12: =Diego!AX12+Aelton!AX12+Leonam!AX12+Danilo!AX12+Marcos!AX12+Carlos!AX12+Alessandro!AX12 -> 0 | K12: =Diego!BD12+Aelton!BD12+Leonam!BD12+Danilo!BD12+Marcos!BD12+Carlos!BD12+Alessandro!BD12 -> 0 | L12: =Diego!BJ12+Aelton!BJ12+Leonam!BJ12+Danilo!BJ12+Marcos!BJ12+Carlos!BJ12+Alessandro!BJ12 -> 0 | M12: =Diego!BP12+Aelton!BP12+Leonam!BP12+Danilo!BP12+Marcos!BP12+Carlos!BP12+Alessandro!BP12 -> 0 | N12: =Diego!BV12+Aelton!BV12+Leonam!BV12+Danilo!BV12+Marcos!BV12+Carlos!BV12+Alessandro!BV12 -> 0 | O12: =Diego!CB12+Aelton!CB12+Leonam!CB12+Danilo!CBH12+Marcos!CBH12+Carlos!CB12+Alessandro!CB12 -> 0
A13: Documentos administrativos produzidos (Despacho, Nota Técnica, minutas diversas) | B13: SEI | C13: =Diego!H13+Aelton!H13 -> 3 | D13: =Diego!N13+Aelton!N13+Leonam!N13+Danilo!N13+Marcos!N13+Alessandro!N13+Carlos!N13 -> 3 | E13: =Diego!T13+Aelton!T13+Leonam!T13+Danilo!T13+Marcos!T13+Alessandro!T13+Carlos!T13 -> 2 | F13: =Diego!Z13+Aelton!Z13+Leonam!Z13+Danilo!Z13+Marcos!Z13+Carlos!Z13+Alessandro!Z13 -> 5 | G13: =Diego!AF13+Aelton!AF13+Leonam!AF13+Danilo!AF13+Marcos!AF13+Carlos!AF13+Alessandro!AF13 -> 9 | H13: =Diego!AL13+Aelton!AL13+Leonam!AL13+Danilo!AL13+Marcos!AL13+Carlos!AL13+Alessandro!AL13 -> 3 | I13: =Diego!AR13+Aelton!AR13+Leonam!AR13+Danilo!AR13+Marcos!AR13+Carlos!AR13+Alessandro!AR13 -> 6 | J13: =Diego!AX13+Aelton!AX13+Leonam!AX13+Danilo!AX13+Marcos!AX13+Carlos!AX13+Alessandro!AX13 -> 4 | K13: =Diego!BD13+Aelton!BD13+Leonam!BD13+Danilo!BD13+Marcos!BD13+Carlos!BD13+Alessandro!BD13 -> 2 | L13: =Diego!BJ13+Aelton!BJ13+Leonam!BJ13+Danilo!BJ13+Marcos!BJ13+Carlos!BJ13+Alessandro!BJ13 -> 3 | M13: =Diego!BP13+Aelton!BP13+Leonam!BP13+Danilo!BP13+Marcos!BP13+Carlos!BP13+Alessandro!BP13 -> 4 | N13: =Diego!BV13+Aelton!BV13+Leonam!BV13+Danilo!BV13+Marcos!BV13+Carlos!BV13+Alessandro!BV13 -> 0 | O13: =Diego!CB13+Aelton!CB13+Leonam!CB13+Danilo!CBH13+Marcos!CBH13+Carlos!CB13+Alessandro!CB13 -> 1
A14: Orientação técnica / atendimentos realizados | B14: SEI, E-MAIL, TELEFONE | C14: =Diego!H14+Aelton!AF14+Leonam!H14+Danilo!H14+Marcos!H14+Alessandro!H14+Carlos!H14 -> 0 | D14: =Diego!N14+Aelton!N14+Leonam!N14+Danilo!N14+Marcos!N14+Carlos!N14+Alessandro!N14 -> 0 | E14: =Diego!T14+Aelton!T14+Leonam!T14+Danilo!T14+Marcos!T14+Carlos!T14+Alessandro!T14 -> 1 | F14: =Diego!Z14+Aelton!Z14+Leonam!Z14+Danilo!Z14+Marcos!Z14+Carlos!Z14+Alessandro!Z14 -> 1 | G14: =Diego!AF14+Aelton!AF14+Leonam!AF14+Danilo!AF14+Marcos!AF14+Carlos!AF14+Alessandro!AF14 -> 0 | H14: =Diego!AL14+Aelton!AL14+Leonam!AL14+Danilo!AL14+Marcos!AL14+Carlos!AL14+Alessandro!AL14 -> 0 | I14: =Diego!AR14+Aelton!AR14+Leonam!AR14+Danilo!AR14+Marcos!AR14+Carlos!AR14+Alessandro!AR14 -> 2 | J14: =Diego!AX14+Aelton!AX14+Leonam!AX14+Danilo!AX14+Marcos!AX14+Carlos!AX14+Alessandro!AX14 -> 0 | K14: =Diego!BD14+Aelton!BD14+Leonam!BD14+Danilo!BD14+Marcos!BD14+Carlos!BD14+Alessandro!BD14 -> 0 | L14: =Diego!BJ14+Aelton!BJ14+Leonam!BJ14+Danilo!BJ14+Marcos!BJ14+Carlos!BJ14+Alessandro!BJ14 -> 0 | M14: =Diego!BP14+Aelton!BP14+Leonam!BP14+Danilo!BP14+Marcos!BP14+Carlos!BP14+Alessandro!BP14 -> 1 | N14: =Diego!BV14+Aelton!BV14+Leonam!BV14+Danilo!BV14+Marcos!BV14+Carlos!BV14+Alessandro!BV14 -> 0 | O14: =Diego!CB14+Aelton!CB14+Leonam!CB14+Danilo!CBH14+Marcos!CBH14+Carlos!CB14+Alessandro!CB14 -> 0
A15: Caixas remanejadas | B15: CONTAGEM INDIVIDUAL (de caixas deslocadas visando reorganização temporária ou permanente) | C15: =Diego!H15+Aelton!H15+Leonam!H15+Danilo!H15+Marcos!H15+Alessandro!H15+Carlos!H15 -> 0 | D15: =Diego!N15+Aelton!N15+Leonam!N15+Danilo!N15+Marcos!N15+Alessandro!N15+Carlos!N15 -> 70 | E15: =Diego!T15+Aelton!T15+Leonam!T15+Danilo!T15+Marcos!T15+Alessandro!T15+Carlos!T15 -> 0 | F15: =Diego!Z15+Aelton!Z15+Leonam!Z15+Danilo!Z15+Marcos!Z15+Carlos!Z15+Alessandro!Z15 -> 0 | G15: =Diego!AF15+Aelton!AF15+Leonam!AF15+Danilo!AF15+Marcos!AF15+Carlos!AF15+Alessandro!AF15 -> 0 | H15: =Diego!AL15+Aelton!AL15+Leonam!AL15+Danilo!AL15+Marcos!AL15+Carlos!AL15+Alessandro!AL15 -> 230 | I15: =Diego!AR15+Aelton!AR15+Leonam!AR15+Danilo!AR15+Marcos!AR15+Carlos!AR15+Alessandro!AR15 -> 460 | J15: =Diego!AX15+Aelton!AX15+Leonam!AX15+Danilo!AX15+Marcos!AX15+Carlos!AX15+Alessandro!AX15 -> 0 | K15: =Diego!BD15+Aelton!BD15+Leonam!BD15+Danilo!BD15+Marcos!BD15+Carlos!BD15+Alessandro!BD15 -> 80 | L15: =Diego!BJ15+Aelton!BJ15+Leonam!BJ15+Danilo!BJ15+Marcos!BJ15+Carlos!BJ15+Alessandro!BJ15 -> 28 | M15: =Diego!BP15+Aelton!BP15+Leonam!BP15+Danilo!BP15+Marcos!BP15+Carlos!BP15+Alessandro!BP15 -> 8 | N15: =Diego!BV15+Aelton!BV15+Leonam!BV15+Danilo!BV15+Marcos!BV15+Carlos!BV15+Alessandro!BV15 -> 0 | O15: =Diego!CB15+Aelton!CB15+Leonam!CB15+Danilo!CBH15+Marcos!CBH15+Carlos!CB15+Alessandro!CB15 -> 24
A16: Caixas conferidas | B16: CONTAGEM INDIVIDUAL (de caixas para simples conferência de quantitativo ou do conteúdo do espelho em atividades diversas) | C16: =Diego!H16+Aelton!H16+Leonam!H16+Danilo!H16+Marcos!H16+Alessandro!H16+Carlos!H16 -> 10 | D16: =Diego!N16+Aelton!N16+Leonam!N16+Danilo!N16+Marcos!N16+Alessandro!N16+Carlos!N16 -> 2443 | E16: =Diego!T16+Aelton!T16+Leonam!T16+Danilo!T16+Marcos!T16+Alessandro!T16+Carlos!T16 -> 2871 | F16: =Diego!Z16+Aelton!Z16+Leonam!Z16+Danilo!Z16+Marcos!Z16+Carlos!Z16+Alessandro!Z16 -> 0 | G16: =Diego!AF16+Aelton!AF16+Leonam!AF16+Danilo!AF16+Marcos!AF16+Carlos!AF16+Alessandro!AF16 -> 0 | H16: =Diego!AL16+Aelton!AL16+Leonam!AL16+Danilo!AL16+Marcos!AL16+Carlos!AL16+Alessandro!AL16 -> 0 | I16: =Diego!AR16+Aelton!AR16+Leonam!AR16+Danilo!AR16+Marcos!AR16+Carlos!AR16+Alessandro!AR16 -> 0 | J16: =Diego!AX16+Aelton!AX16+Leonam!AX16+Danilo!AX16+Marcos!AX16+Carlos!AX16+Alessandro!AX16 -> 60 | K16: =Diego!BD16+Aelton!BD16+Leonam!BD16+Danilo!BD16+Marcos!BD16+Carlos!BD16+Alessandro!BD16 -> 0 | L16: =Diego!BJ16+Aelton!BJ16+Leonam!BJ16+Danilo!BJ16+Marcos!BJ16+Carlos!BJ16+Alessandro!BJ16 -> 3 | M16: =Diego!BP16+Aelton!BP16+Leonam!BP16+Danilo!BP16+Marcos!BP16+Carlos!BP16+Alessandro!BP16 -> 25 | N16: =Diego!BV16+Aelton!BV16+Leonam!BV16+Danilo!BV16+Marcos!BV16+Carlos!BV16+Alessandro!BV16 -> 0 | O16: =Diego!CB16+Aelton!CB16+Leonam!CB16+Danilo!CBH16+Marcos!CBH16+Carlos!CB16+Alessandro!CB16 -> 0
A17: Caixas substituídas(trocadas) | B17: Substituição de caixas degradadas por novas | C17: =Diego!H17+Aelton!H17+Leonam!H17+Danilo!H17+Marcos!H17+Alessandro!H17 -> 0 | D17: =Diego!N17+Aelton!N17+Leonam!N17+Danilo!N17+Marcos!N17+Alessandro!N17+Carlos!N17 -> 0 | E17: =Diego!T17+Aelton!T17+Leonam!T17+Danilo!T17+Marcos!T17+Alessandro!T17+Carlos!T17 -> 0 | F17: =Diego!Z17+Aelton!Z17+Leonam!Z17+Danilo!Z17+Marcos!Z17+Alessandro!Z17+Carlos!Z17 -> 125 | G17: =Diego!AF17+Aelton!AF17+Leonam!AF17+Danilo!AF17+Marcos!AF17+Alessandro!AF17+Carlos!AF17 -> 70 | H17: =Diego!AL17+Aelton!AL17+Leonam!AL17+Danilo!AL17+Marcos!AL17+Alessandro!AL17+Carlos!AL17 -> 139 | I17: =Diego!AR17+Aelton!AR17+Leonam!AR17+Danilo!AR17+Marcos!AR17+Alessandro!AR17+Carlos!AR17 -> 0 | J17: =Diego!AX17+Aelton!AX17+Leonam!AX17+Danilo!AX17+Marcos!AX17+Alessandro!AX17+Carlos!AX17 -> 235 | K17: =Diego!BD17+Aelton!BD17+Leonam!BD17+Danilo!BD17+Marcos!BD17+Alessandro!BD17+Carlos!BD17 -> 196 | L17: =Diego!BJ17+Aelton!BJ17+Leonam!BJ17+Danilo!BJ17+Marcos!BJ17+Alessandro!BJ17+Carlos!BJ17 -> 153 | M17: =Diego!BP17+Aelton!BP17+Leonam!BP17+Danilo!BP17+Marcos!BP17+Alessandro!BP17+Carlos!BP17 -> 234 | N17: =Diego!BV17+Aelton!BV17+Leonam!BV17+Danilo!BV17+Marcos!BV17+Alessandro!BV17+Carlos!BV17 -> 71 | O17: =Diego!CB17+Aelton!CB17+Leonam!CB17+Danilo!CB17+Marcos!CB17+Alessandro!CB17+Carlos!CB17 -> 65
A18: OUTRA ATIVIDADE. QUAL? | C18: Levantamento patrimonial anual das salas 1º subsolo DNIT (1.20, 3.25, 3.60, 3.47, 3.11) | D18: Pesquisa e busca por processo do MESP (104 volumes) | E18: Pesquisa e busca por processo do MESP (104 volumes) | F18: 1. Troca/substituição de caixas 2. Guarda/devolução de processos MESP 3. Conferência de patrimônio salas 1S3.25 e 1S1.20 | G18: 1.Troca/substituição de caixas 2. Vistoria arquivo Bloco A, para verificação de vazamentos e frestas/buracos 3. Visita técnica de equipe do Arquivo Nacional | H18: 1. Troca/substituição de caixas 2. Confecção de espelhos para caixas | I18: 1. Leitura de módulo 15 da sala 3.71 2. Limpeza no arquivo do Bloco A, sala G-15 | J18: 1. Troca/substituição de caixas 2. Confecção de espelhos para caixas 3. Reunião com chefe Patrícia, sobre demandas 107 volumes MESP (2 volumes faltantes) | K18: 1. Troca/substituição de caixas 2. Confecção de espelhos para caixas 3. Levantamento dos metros lineares dos deslizantes localizados no Bloco A - G-15 4. Acompanhamento de limpeza das estantes do acervo Bloco A, sala G-07 | L18: 1. Troca/substituição de caixas 2. Confecção de espelhos para caixas 3. Levantamento dos metros lineares dos deslizantes localizado no Bloco A - G-15 4. Acompanhamento da limpeza das estantes da sala G-07, Bloco A | M18: 1. Troca/substituição de caixas 2. Confecção de espelhos para caixas | N18: 1. Troca/substituição de caixas 2. Confecção de espelhos para caixas | O18: 1. Troca/substituição de caixas 2. Confecção de espelhos para caixas
A19: OBSERVAÇÃO

Sheet Diego
A1: INDICADORES | C1: 45936 | D1: 45937 | E1: 45938 | F1: 45939 | G1: 45940 | H1: TOTAL SEMANA | I1: 45943 | J1: 45944 | K1: 45945 | L1: 45946 | M1: 45947 | N1: TOTAL SEMANA | O1: 45950 | P1: 45951 | Q1: 45952 | R1: 45953 | S1: 45954 | T1: TOTAL SEMANA | U1: 45957 | V1: 45958 | W1: 45959 | X1: 45960 | Y1: 45961 | Z1: TOTAL SEMANA | AA1: 45964 | AB1: 45965 | AC1: 45966 | AD1: 45967 | AE1: 45968 | AF1: TOTAL SEMANA | AG1: 45971 | AH1: 45972 | AI1: 45973 | AJ1: 45974 | AK1: 45975 | AL1: TOTAL SEMANA | AM1: 45978 | AN1: 45979 | AO1: 45980 | AP1: 45981 | AQ1: 45982 | AR1: TOTAL SEMANA | AS1: 45985 | AT1: 45986 | AU1: 45987 | AV1: 45988 | AW1: 45989 | AX1: TOTAL SEMANA | AY1: 45992 | AZ1: 45993 | BA1: 45994 | BB1: 45995 | BC1: 45996 | BD1: TOTAL SEMANA | BE1: 45999 | BF1: 46000 | BG1: 46001 | BH1: 46002 | BI1: 46003 | BJ1: TOTAL SEMANA | BK1: 46006 | BL1: 46007 | BM1: 46008 | BN1: 46009 | BO1: 46010 | BP1: TOTAL SEMANA | BQ1: 46013 | BR1: 46014 | BS1: 46015 | BT1: 46016 | BU1: 46017 | BV1: TOTAL SEMANA | BW1: 46020 | BX1: 46021 | BY1: 46022 | BZ1: 46023 | CA1: 46024 | CB1: TOTAL SEMANA
A2: Desarquivamento de Processos/Documentos - Saída de Guia Fora | B2: 1 | H2: =SUM(C2:G2) -> 0 | N2: =SUM(I2:M2) -> 0 | T2: =SUM(O2:S2) -> 0 | U2: FERIADO | Z2: =SUM(U2:Y2) -> 0 | AF2: =SUM(AA2:AE2) -> 0 | AK2: 35 | AL2: =SUM(AG2:AK2) -> 35 | AR2: =SUM(AM2:AQ2) -> 0 | AX2: =SUM(AS2:AW2) -> 0 | BD2: =SUM(AY2:BC2) -> 0 | BJ2: =SUM(BE2:BI2) -> 0 | BP2: =SUM(BK2:BO2) -> 0 | BT2: FERIADO | BV2: =SUM(BQ2:BU2) -> 0 | BW2: RECESSO | BX2: RECESSO | BY2: RECESSO | BZ2: FERIADO | CA2: RECESSO | CB2: =SUM(BW2:CA2) -> 0
A3: Caixas consultadas em pesquisa de desarquivamento | B3: 2 | H3: =SUM(C3:G3) -> 0 | N3: =SUM(I3:M3) -> 0 | T3: =SUM(O3:S3) -> 0 | U3: FERIADO | Z3: =SUM(U3:Y3) -> 0 | AB3: 1 | AF3: =SUM(AA3:AE3) -> 1 | AL3: =SUM(AG3:AK3) -> 0 | AR3: =SUM(AM3:AQ3) -> 0 | AS3: 1 | AV3: 1 | AX3: =SUM(AS3:AW3) -> 2 | BD3: =SUM(AY3:BC3) -> 0 | BJ3: =SUM(BE3:BI3) -> 0 | BP3: =SUM(BK3:BO3) -> 0 | BT3: FERIADO | BV3: =SUM(BQ3:BU3) -> 0 | BW3: RECESSO | BX3: RECESSO | BY3: RECESSO | BZ3: FERIADO | CA3: RECESSO | CB3: =SUM(BW3:CA3) -> 0
A4: Retorno de Processos/Documentos Desarquivados | B4: 3 | H4: =SUM(C4:G4) -> 0 | N4: =SUM(I4:M4) -> 0 | T4: =SUM(O4:S4) -> 0 | U4: FERIADO | W4: 8 | Z4: =SUM(U4:Y4) -> 8 | AF4: =SUM(AA4:AE4) -> 0 | AL4: =SUM(AG4:AK4) -> 0 | AR4: =SUM(AM4:AQ4) -> 0 | AV4: 1 | AX4: =SUM(AS4:AW4) -> 1 | BD4: =SUM(AY4:BC4) -> 0 | BJ4: =SUM(BE4:BI4) -> 0 | BP4: =SUM(BK4:BO4) -> 0 | BT4: FERIADO | BV4: =SUM(BQ4:BU4) -> 0 | BW4: RECESSO | BX4: RECESSO | BY4: RECESSO | BZ4: FERIADO | CA4: RECESSO | CB4: =SUM(BW4:CA4) -> 0
A5: Recebimento de Documentos - Guia de Transferência | B5: 4 | H5: =SUM(C5:G5) -> 0 | N5: =SUM(I5:M5) -> 0 | T5: =SUM(O5:S5) -> 0 | U5: FERIADO | Z5: =SUM(U5:Y5) -> 0 | AF5: =SUM(AA5:AE5) -> 0 | AL5: =SUM(AG5:AK5) -> 0 | AR5: =SUM(AM5:AQ5) -> 0 | AX5: =SUM(AS5:AW5) -> 0 | BD5: =SUM(AY5:BC5) -> 0 | BJ5: =SUM(BE5:BI5) -> 0 | BP5: =SUM(BK5:BO5) -> 0 | BT5: FERIADO | BV5: =SUM(BQ5:BU5) -> 0 | BW5: RECESSO | BX5: RECESSO | BY5: RECESSO | BZ5: FERIADO | CA5: RECESSO | CB5: =SUM(BW5:CA5) -> 0
A6: Caixas separadas para classificação | B6: 5 | H6: =SUM(C6:G6) -> 0 | N6: =SUM(I6:M6) -> 0 | T6: =SUM(O6:S6) -> 0 | U6: FERIADO | Z6: =SUM(U6:Y6) -> 0 | AF6: =SUM(AA6:AE6) -> 0 | AL6: =SUM(AG6:AK6) -> 0 | AR6: =SUM(AM6:AQ6) -> 0 | AX6: =SUM(AS6:AW6) -> 0 | BD6: =SUM(AY6:BC6) -> 0 | BJ6: =SUM(BE6:BI6) -> 0 | BP6: =SUM(BK6:BO6) -> 0 | BT6: FERIADO | BV6: =SUM(BQ6:BU6) -> 0 | BW6: RECESSO | BX6: RECESSO | BY6: RECESSO | BZ6: FERIADO | CA6: RECESSO | CB6: =SUM(BW6:CA6) -> 0
A7: Processos/Documentos classificados | B7: 6 | H7: =SUM(C7:G7) -> 0 | N7: =SUM(I7:M7) -> 0 | T7: =SUM(O7:S7) -> 0 | U7: FERIADO | Z7: =SUM(U7:Y7) -> 0 | AF7: =SUM(AA7:AE7) -> 0 | AL7: =SUM(AG7:AK7) -> 0 | AR7: =SUM(AM7:AQ7) -> 0 | AX7: =SUM(AS7:AW7) -> 0 | BD7: =SUM(AY7:BC7) -> 0 | BJ7: =SUM(BE7:BI7) -> 0 | BP7: =SUM(BK7:BO7) -> 0 | BT7: FERIADO | BV7: =SUM(BQ7:BU7) -> 0 | BW7: RECESSO | BX7: RECESSO | BY7: RECESSO | BZ7: FERIADO | CA7: RECESSO | CB7: =SUM(BW7:CA7) -> 0
A8: Caixas separadas para eliminação | B8: 7 | H8: =SUM(C8:G8) -> 0 | N8: =SUM(I8:M8) -> 0 | T8: =SUM(O8:S8) -> 0 | U8: FERIADO | Z8: =SUM(U8:Y8) -> 0 | AF8: =SUM(AA8:AE8) -> 0 | AL8: =SUM(AG8:AK8) -> 0 | AR8: =SUM(AM8:AQ8) -> 0 | AX8: =SUM(AS8:AW8) -> 0 | BD8: =SUM(AY8:BC8) -> 0 | BJ8: =SUM(BE8:BI8) -> 0 | BP8: =SUM(BK8:BO8) -> 0 | BT8: FERIADO | BV8: =SUM(BQ8:BU8) -> 0 | BW8: RECESSO | BX8: RECESSO | BY8: RECESSO | BZ8: FERIADO | CA8: RECESSO | CB8: =SUM(BW8:CA8) -> 0
A9: Caixas listadas para eliminação | B9: 8 | H9: =SUM(C9:G9) -> 0 | N9: =SUM(I9:M9) -> 0 | T9: =SUM(O9:S9) -> 0 | U9: FERIADO | Z9: =SUM(U9:Y9) -> 0 | AF9: =SUM(AA9:AE9) -> 0 | AL9: =SUM(AG9:AK9) -> 0 | AR9: =SUM(AM9:AQ9) -> 0 | AX9: =SUM(AS9:AW9) -> 0 | BD9: =SUM(AY9:BC9) -> 0 | BJ9: =SUM(BE9:BI9) -> 0 | BP9: =SUM(BK9:BO9) -> 0 | BT9: FERIADO | BV9: =SUM(BQ9:BU9) -> 0 | BW9: RECESSO | BX9: RECESSO | BY9: RECESSO | BZ9: FERIADO | CA9: RECESSO | CB9: =SUM(BW9:CA9) -> 0
A10: Processos/Documentos listados para eliminação | B10: 9 | H10: =SUM(C10:G10) -> 0 | N10: =SUM(I10:M10) -> 0 | T10: =SUM(O10:S10) -> 0 | U10: FERIADO | Z10: =SUM(U10:Y10) -> 0 | AF10: =SUM(AA10:AE10) -> 0 | AL10: =SUM(AG10:AK10) -> 0 | AR10: =SUM(AM10:AQ10) -> 0 | AX10: =SUM(AS10:AW10) -> 0 | BD10: =SUM(AY10:BC10) -> 0 | BJ10: =SUM(BE10:BI10) -> 0 | BP10: =SUM(BK10:BO10) -> 0 | BT10: FERIADO | BV10: =SUM(BQ10:BU10) -> 0 | BW10: RECESSO | BX10: RECESSO | BY10: RECESSO | BZ10: FERIADO | CA10: RECESSO | CB10: =SUM(BW10:CA10) -> 0
A11: Caixas inventariadas | B11: 10 | H11: =SUM(C11:G11) -> 0 | N11: =SUM(I11:M11) -> 0 | T11: =SUM(O11:S11) -> 0 | U11: FERIADO | Z11: =SUM(U11:Y11) -> 0 | AF11: =SUM(AA11:AE11) -> 0 | AL11: =SUM(AG11:AK11) -> 0 | AR11: =SUM(AM11:AQ11) -> 0 | AX11: =SUM(AS11:AW11) -> 0 | BD11: =SUM(AY11:BC11) -> 0 | BJ11: =SUM(BE11:BI11) -> 0 | BP11: =SUM(BK11:BO11) -> 0 | BT11: FERIADO | BV11: =SUM(BQ11:BU11) -> 0 | BW11: RECESSO | BX11: RECESSO | BY11: RECESSO | BZ11: FERIADO | CA11: RECESSO | CB11: =SUM(BW11:CA11) -> 0
A12: Processos/documentos inventariados | B12: 11 | H12: =SUM(C12:G12) -> 0 | N12: =SUM(I12:M12) -> 0 | T12: =SUM(O12:S12) -> 0 | U12: FERIADO | Z12: =SUM(U12:Y12) -> 0 | AF12: =SUM(AA12:AE12) -> 0 | AL12: =SUM(AG12:AK12) -> 0 | AR12: =SUM(AM12:AQ12) -> 0 | AX12: =SUM(AS12:AW12) -> 0 | BD12: =SUM(AY12:BC12) -> 0 | BJ12: =SUM(BE12:BI12) -> 0 | BP12: =SUM(BK12:BO12) -> 0 | BT12: FERIADO | BV12: =SUM(BQ12:BU12) -> 0 | BW12: RECESSO | BX12: RECESSO | BY12: RECESSO | BZ12: FERIADO | CA12: RECESSO | CB12: =SUM(BW12:CA12) -> 0
A13: Documentos administrativos produzidos (Despacho, Nota Técnica, minutas diversas) | B13: 12 | C13: 2 | H13: =SUM(C13:G13) -> 2 | N13: =SUM(I13:M13) -> 0 | T13: =SUM(O13:S13) -> 0 | U13: FERIADO | Z13: =SUM(U13:Y13) -> 0 | AF13: =SUM(AA13:AE13) -> 0 | AL13: =SUM(AG13:AK13) -> 0 | AR13: =SUM(AM13:AQ13) -> 0 | AV13: 1 | AX13: =SUM(AS13:AW13) -> 1 | BD13: =SUM(AY13:BC13) -> 0 | BJ13: =SUM(BE13:BI13) -> 0 | BP13: =SUM(BK13:BO13) -> 0 | BT13: FERIADO | BV13: =SUM(BQ13:BU13) -> 0 | BW13: RECESSO | BX13: RECESSO | BY13: RECESSO | BZ13: FERIADO | CA13: RECESSO | CB13: =SUM(BW13:CA13) -> 0
A14: Orientação técnica / atendimentos realizados | B14: 13 | H14: =SUM(C14:G14) -> 0 | N14: =SUM(I14:M14) -> 0 | T14: =SUM(O14:S14) -> 0 | U14: FERIADO | Z14: =SUM(U14:Y14) -> 0 | AF14: =SUM(AA14:AE14) -> 0 | AL14: =SUM(AG14:AK14) -> 0 | AR14: =SUM(AM14:AQ14) -> 0 | AX14: =SUM(AS14:AW14) -> 0 | BD14: =SUM(AY14:BC14) -> 0 | BJ14: =SUM(BE14:BI14) -> 0 | BP14: =SUM(BK14:BO14) -> 0 | BT14: FERIADO | BV14: =SUM(BQ14:BU14) -> 0 | BW14: RECESSO | BX14: RECESSO | BY14: RECESSO | BZ14: FERIADO | CA14: RECESSO | CB14: =SUM(BW14:CA14) -> 0
A15: Caixas remanejadas | B15: 14 | H15: =SUM(C15:G15) -> 0 | N15: =SUM(I15:M15) -> 0 | T15: =SUM(O15:S15) -> 0 | U15: FERIADO | Z15: =SUM(U15:Y15) -> 0 | AF15: =SUM(AA15:AE15) -> 0 | AI15: 40 | AK15: 65 | AL15: =SUM(AG15:AK15) -> 105 | AM15: 100 | AN15: 126 | AR15: =SUM(AM15:AQ15) -> 226 | AX15: =SUM(AS15:AW15) -> 0 | BD15: =SUM(AY15:BC15) -> 0 | BJ15: =SUM(BE15:BI15) -> 0 | BP15: =SUM(BK15:BO15) -> 0 | BT15: FERIADO | BV15: =SUM(BQ15:BU15) -> 0 | BW15: RECESSO | BX15: RECESSO | BY15: RECESSO | BZ15: FERIADO | CA15: RECESSO | CB15: =SUM(BW15:CA15) -> 0
A16: Caixas conferidas | B16: 15 | C16: 10 | H16: =SUM(C16:G16) -> 10 | I16: 150 | J16: 150 | K16: 150 | L16: 150 | M16: 150 | N16: =SUM(I16:M16) -> 750 | P16: 150 | Q16: 150 | R16: 150 | S16: 150 | T16: =SUM(O16:S16) -> 600 | U16: FERIADO | Z16: =SUM(U16:Y16) -> 0 | AF16: =SUM(AA16:AE16) -> 0 | AL16: =SUM(AG16:AK16) -> 0 | AR16: =SUM(AM16:AQ16) -> 0 | AS16: 20 | AX16: =SUM(AS16:AW16) -> 20 | BD16: =SUM(AY16:BC16) -> 0 | BJ16: =SUM(BE16:BI16) -> 0 | BK16: 20 | BP16: =SUM(BK16:BO16) -> 20 | BT16: FERIADO | BV16: =SUM(BQ16:BU16) -> 0 | BW16: RECESSO | BX16: RECESSO | BY16: RECESSO | BZ16: FERIADO | CA16: RECESSO | CB16: =SUM(BW16:CA16) -> 0
A17: Caixas substituídas(trocadas) | B17: 16 | H17: =SUM(C17:G17) -> 0 | N17: =SUM(I17:M17) -> 0 | T17: =SUM(O17:S17) -> 0 | U17: FERIADO | V17: 10 | X17: 10 | Y17: 10 | Z17: =SUM(U17:Y17) -> 30 | AA17: 10 | AB17: 10 | AC17: 10 | AD17: 10 | AE17: 10 | AF17: =SUM(AA17:AE17) -> 50 | AG17: 10 | AH17: 25 | AL17: =SUM(AG17:AK17) -> 35 | AR17: =SUM(AM17:AQ17) -> 0 | AV17: 50 | AW17: 20 | AX17: =SUM(AS17:AW17) -> 70 | AY17: 15 | AZ17: 15 | BA17: 20 | BB17: 20 | BC17: 20 | BD17: =SUM(AY17:BC17) -> 90 | BH17: 20 | BI17: 20 | BJ17: =SUM(BE17:BI17) -> 40 | BM17: 10 | BN17: 10 | BO17: 10 | BP17: =SUM(BK17:BO17) -> 30 | BT17: FERIADO | BV17: =SUM(BQ17:BU17) -> 0 | BW17: RECESSO | BX17: RECESSO | BY17: RECESSO | BZ17: FERIADO | CA17: RECESSO | CB17: =SUM(BW17:CA17) -> 0
A18: OUTRA ATIVIDADE. QUAL? | C18: Conferência do patrimônio salas 3.25,3.60,3.47,3.11 | D18: Conferência do patrimônio salas 3.25,3.60,3.47,3.11 | E18: Conferência do patrimônio salas 3.25,3.60,3.47,3.11 | F18: Conferência do patrimônio salas 3.25,3.60,3.47,3.11 | G18: Conferência do patrimônio salas 3.25,3.60,3.47,3.11 | I18: 1. Pela manhã ida so Sindicato para assinar rescisão da Works. 2. Realização de Relatório total de audiovisuais para a Patrícia. 3. Pesquisa e busca por processo do MESP. | J18: Pesquisa e busca por processo do MESP. | K18: Pesquisa e busca por processo do MESP. | L18: Pesquisa e busca por processo do MESP. | M18: Pesquisa e busca por processo do MESP. | O18: SOLICITAÇÃO DO CARRO PRA LEVAR OS PROCESSOS(107 processos) | P18: Pesquisa e busca por processo do MESP. | Q18: Pesquisa e busca por processo do MESP. | R18: Pesquisa e busca por processo do MESP. | S18: Pesquisa e busca por processo do MESP. | U18: FERIADO | V18: trocando caixas do arquivo 10 | W18: ARQUIVANDO PROCESSOS DO ESPORTE E MDS 15 | X18: TROCANDO CAIXAS NO ARQUIVO 10 , PROCURANDO PROCESSOS | Y18: REUNIÃO NO PERIODO DA MANHÃ , TROCANDO CAIXAS NO ARQUIVO 10 , PROCURANDO PROCESSOS | AA18: Pesquisa referente a solicitação do processo SEI 71000.108346/2025-60, referente a 03 processos. | AB18: pesquisa da pasta funcional do servidor Luiz Celso Giacomini do ESPORTE | AC18: TROCANDO CAIXAS NO ARQUIVO 10 , | AD18: Organização da sala 4.47 para recepicinar integrantes do arquivo central | AE18: 1. Confraternização CDA pela manhã. 2. Acompanhamento visita dos inteegrantes do Arquivo Nacional. | AG18: TROCANDO CAIXAS NO ARQUIVO 10 , | AH18: TROCANDO CAIXAS NO ARQUIVO 10 , | AI18: colocando os espelhos nas caixas novas | AJ18: colocando os espelhos nas caixas novas | AK18: colocando os espelhos nas caixas novas | AM18: CAIXAS REMANEJADAS DA LBA,ARQUIVO SNAS DA 4.47 PARA 3.71 | AN18: LEITURA DO MODULO 15 DA SALA 3.71 | AO18: PROCURANDO PASTAS FUNCIONAIS | AP18: FERIADO | AQ18: FOLGA | AT18: fazendo resumo da reunião sobre os processos perdidos | AU18: reunião sobre os processos, buscando pasta funcionais | AV18: TROCANDO OS ESPELHOS | AW18: TROCANDO OS ESPELHOS | AY18: TROCANDO OS ESPELHOS | AZ18: TROCANDO OS ESPELHOS | BA18: TROCANDO OS ESPELHOS | BB18: TROCANDO OS ESPELHOS | BC18: TROCANDO OS ESPELHOS | BD18: TROCANDO OS ESPELHOS | BE18: ACOMPANHANDO OBRA DNIT NA SALA 3.11 | BF18: ACOMPANHANDO OBRA DNIT NA SALA 3.11 | BG18: Confraternização | BH18: TROCANDO OS ESPELHOS | BI18: TROCANDO OS ESPELHOS | BK18: CONFERENCIA DAS CAIXAS DA CCLIC 20 | BL18: PESQUISA DOS PROCESSOS DO ESPORTE | BM18: PESQUISA DOS PROCESSOS DO ESPORTE | BN18: TROCANDO OS ESPELHOS | BO18: TROCANDO OS ESPELHOS | BQ18: TROCANDO OS ESPELHOS | BR18: TROCANDO OS ESPELHOS | BS18: TROCANDO OS ESPELHOS | BT18: FERIADO DE NATAL | BU18: TROCANDO OS ESPELHOS | BW18: RECESSO REVEILLON | BX18: RECESSO REVEILLON | BY18: RECESSO REVEILLON | BZ18: FERIADO ANO NOVO | CA18: RECESSO REVEILLON
A19: OBSERVAÇÃO | C19: conferencia de caixas | F19: procurando processo | G19: procurando processo | O19: CARREGANDO O CARRO COM OS PROCESSOS | AN19: GUARDANDO TODAS FITAS VHS/MICROFILMES NA 4.47 | BB19: separando as caixas para CGPC
O20: OLHANDO O SEI

Sheet Aelton
A1: INDICADORES | C1: 45936 | D1: 45937 | E1: 45938 | F1: 45939 | G1: 45940 | H1: TOTAL SEMANA | I1: 45943 | J1: 45944 | K1: 45945 | L1: 45946 | M1: 45947 | N1: TOTAL SEMANA | O1: 45950 | P1: 45951 | Q1: 45952 | R1: 45953 | S1: 45954 | T1: TOTAL SEMANA | U1: 45957 | V1: 45958 | W1: 45959 | X1: 45960 | Y1: 45961 | Z1: TOTAL SEMANA | AA1: 45964 | AB1: 45965 | AC1: 45966 | AD1: 45967 | AE1: 45968 | AF1: TOTAL SEMANA | AG1: 45971 | AH1: 45972 | AI1: 45973 | AJ1: 45974 | AK1: 45975 | AL1: TOTAL SEMANA | AM1: 45978 | AN1: 45979 | AO1: 45980 | AP1: 45981 | AQ1: 45982 | AR1: TOTAL SEMANA | AS1: 45985 | AT1: 45986 | AU1: 45987 | AV1: 45988 | AW1: 45989 | AX1: TOTAL SEMANA | AY1: 45992 | AZ1: 45993 | BA1: 45994 | BB1: 45995 | BC1: 45996 | BD1: TOTAL SEMANA | BE1: 45999 | BF1: 46000 | BG1: 46001 | BH1: 46002 | BI1: 46003 | BJ1: TOTAL SEMANA | BK1: 46006 | BL1: 46007 | BM1: 46008 | BN1: 46009 | BO1: 46010 | BP1: TOTAL SEMANA | BQ1: 46013 | BR1: 46014 | BS1: 46015 | BT1: 46016 | BU1: 46017 | BV1: TOTAL SEMANA | BW1: 46020 | BX1: 46021 | BY1: 46022 | BZ1: 46023 | CA1: 46024 | CB1: TOTAL SEMANA
A2: Desarquivamento de Processos/Documentos - Saída de Guia Fora | B2: 1 | C2: 1 | H2: =SUM(C2:G2) -> 1 | N2: =SUM(I2:M2) -> 0 | O2: 17 | S2: 1 | T2: =SUM(O2:S2) -> 18 | Z2: =SUM(U2:Y2) -> 0 | AC2: 2 | AF2: =SUM(AA2:AE2) -> 2 | AJ2: 6 | AL2: =SUM(AG2:AK2) -> 6 | AM2: 1 | AN2: 1 | AR2: =SUM(AM2:AQ2) -> 2 | AX2: =SUM(AS2:AW2) -> 0 | BD2: =SUM(AY2:BC2) -> 0 | BJ2: =SUM(BE2:BI2) -> 0 | BP2: =SUM(BK2:BO2) -> 0 | BQ2: RECESSO | BR2: RECESSO | BS2: RECESSO | BT2: FERIADO | BU2: RECESSO | BV2: =SUM(BQ2:BU2) -> 0 | BX2: 1 | BZ2: FERIADO | CB2: =SUM(BW2:CA2) -> 1
A3: Caixas consultadas em pesquisa de desarquivamento | B3: 2 | H3: =SUM(C3:G3) -> 0 | N3: =SUM(I3:M3) -> 0 | T3: =SUM(O3:S3) -> 0 | Z3: =SUM(U3:Y3) -> 0 | AF3: =SUM(AA3:AE3) -> 0 | AL3: =SUM(AG3:AK3) -> 0 | AR3: =SUM(AM3:AQ3) -> 0 | AX3: =SUM(AS3:AW3) -> 0 | BD3: =SUM(AY3:BC3) -> 0 | BJ3: =SUM(BE3:BI3) -> 0 | BP3: =SUM(BK3:BO3) -> 0 | BQ3: RECESSO | BR3: RECESSO | BS3: RECESSO | BT3: FERIADO | BU3: RECESSO | BV3: =SUM(BQ3:BU3) -> 0 | BZ3: FERIADO | CB3: =SUM(BW3:CA3) -> 0
A4: Retorno de Processos/Documentos Desarquivados | B4: 3 | H4: =SUM(C4:G4) -> 0 | N4: =SUM(I4:M4) -> 0 | T4: =SUM(O4:S4) -> 0 | W4: 3 | X4: 158 | Z4: =SUM(U4:Y4) -> 161 | AA4: 1 | AB4: 7 | AC4: 7 | AD4: 5 | AF4: =SUM(AA4:AE4) -> 20 | AL4: =SUM(AG4:AK4) -> 0 | AO4: 2 | AR4: =SUM(AM4:AQ4) -> 2 | AW4: 1 | AX4: =SUM(AS4:AW4) -> 1 | BD4: =SUM(AY4:BC4) -> 0 | BJ4: =SUM(BE4:BI4) -> 0 | BP4: =SUM(BK4:BO4) -> 0 | BQ4: RECESSO | BR4: RECESSO | BS4: RECESSO | BT4: FERIADO | BU4: RECESSO | BV4: =SUM(BQ4:BU4) -> 0 | BZ4: FERIADO | CB4: =SUM(BW4:CA4) -> 0
A5: Recebimento de Documentos - Guia de Transferência | B5: 4 | H5: =SUM(C5:G5) -> 0 | N5: =SUM(I5:M5) -> 0 | T5: =SUM(O5:S5) -> 0 | Z5: =SUM(U5:Y5) -> 0 | AF5: =SUM(AA5:AE5) -> 0 | AL5: =SUM(AG5:AK5) -> 0 | AR5: =SUM(AM5:AQ5) -> 0 | AX5: =SUM(AS5:AW5) -> 0 | BD5: =SUM(AY5:BC5) -> 0 | BJ5: =SUM(BE5:BI5) -> 0 | BK5: 1 | BP5: =SUM(BK5:BO5) -> 1 | BQ5: RECESSO | BR5: RECESSO | BS5: RECESSO | BT5: FERIADO | BU5: RECESSO | BV5: =SUM(BQ5:BU5) -> 0 | BZ5: FERIADO | CB5: =SUM(BW5:CA5) -> 0
A6: Caixas separadas para classificação | B6: 5 | H6: =SUM(C6:G6) -> 0 | N6: =SUM(I6:M6) -> 0 | T6: =SUM(O6:S6) -> 0 | Z6: =SUM(U6:Y6) -> 0 | AF6: =SUM(AA6:AE6) -> 0 | AL6: =SUM(AG6:AK6) -> 0 | AR6: =SUM(AM6:AQ6) -> 0 | AX6: =SUM(AS6:AW6) -> 0 | BD6: =SUM(AY6:BC6) -> 0 | BJ6: =SUM(BE6:BI6) -> 0 | BP6: =SUM(BK6:BO6) -> 0 | BQ6: RECESSO | BR6: RECESSO | BS6: RECESSO | BT6: FERIADO | BU6: RECESSO | BV6: =SUM(BQ6:BU6) -> 0 | BZ6: FERIADO | CB6: =SUM(BW6:CA6) -> 0
A7: Processos/Documentos classificados | B7: 6 | H7: =SUM(C7:G7) -> 0 | N7: =SUM(I7:M7) -> 0 | T7: =SUM(O7:S7) -> 0 | Z7: =SUM(U7:Y7) -> 0 | AF7: =SUM(AA7:AE7) -> 0 | AL7: =SUM(AG7:AK7) -> 0 | AR7: =SUM(AM7:AQ7) -> 0 | AX7: =SUM(AS7:AW7) -> 0 | BD7: =SUM(AY7:BC7) -> 0 | BJ7: =SUM(BE7:BI7) -> 0 | BP7: =SUM(BK7:BO7) -> 0 | BQ7: RECESSO | BR7: RECESSO | BS7: RECESSO | BT7: FERIADO | BU7: RECESSO | BV7: =SUM(BQ7:BU7) -> 0 | BZ7: FERIADO | CB7: =SUM(BW7:CA7) -> 0
A8: Caixas separadas para eliminação | B8: 7 | H8: =SUM(C8:G8) -> 0 | N8: =SUM(I8:M8) -> 0 | T8: =SUM(O8:S8) -> 0 | Z8: =SUM(U8:Y8) -> 0 | AF8: =SUM(AA8:AE8) -> 0 | AL8: =SUM(AG8:AK8) -> 0 | AR8: =SUM(AM8:AQ8) -> 0 | AX8: =SUM(AS8:AW8) -> 0 | BD8: =SUM(AY8:BC8) -> 0 | BJ8: =SUM(BE8:BI8) -> 0 | BP8: =SUM(BK8:BO8) -> 0 | BQ8: RECESSO | BR8: RECESSO | BS8: RECESSO | BT8: FERIADO | BU8: RECESSO | BV8: =SUM(BQ8:BU8) -> 0 | BZ8: FERIADO | CB8: =SUM(BW8:CA8) -> 0
A9: Caixas listadas para eliminação | B9: 8 | H9: =SUM(C9:G9) -> 0 | N9: =SUM(I9:M9) -> 0 | T9: =SUM(O9:S9) -> 0 | Z9: =SUM(U9:Y9) -> 0 | AF9: =SUM(AA9:AE9) -> 0 | AL9: =SUM(AG9:AK9) -> 0 | AR9: =SUM(AM9:AQ9) -> 0 | AX9: =SUM(AS9:AW9) -> 0 | BD9: =SUM(AY9:BC9) -> 0 | BJ9: =SUM(BE9:BI9) -> 0 | BP9: =SUM(BK9:BO9) -> 0 | BQ9: RECESSO | BR9: RECESSO | BS9: RECESSO | BT9: FERIADO | BU9: RECESSO | BV9: =SUM(BQ9:BU9) -> 0 | BZ9: FERIADO | CB9: =SUM(BW9:CA9) -> 0
A10: Processos/Documentos listados para eliminação | B10: 9 | H10: =SUM(C10:G10) -> 0 | N10: =SUM(I10:M10) -> 0 | T10: =SUM(O10:S10) -> 0 | Z10: =SUM(U10:Y10) -> 0 | AF10: =SUM(AA10:AE10) -> 0 | AL10: =SUM(AG10:AK10) -> 0 | AR10: =SUM(AM10:AQ10) -> 0 | AX10: =SUM(AS10:AW10) -> 0 | BD10: =SUM(AY10:BC10) -> 0 | BJ10: =SUM(BE10:BI10) -> 0 | BP10: =SUM(BK10:BO10) -> 0 | BQ10: RECESSO | BR10: RECESSO | BS10: RECESSO | BT10: FERIADO | BU10: RECESSO | BV10: =SUM(BQ10:BU10) -> 0 | BZ10: FERIADO | CB10: =SUM(BW10:CA10) -> 0
A11: Caixas inventariadas | B11: 10 | H11: =SUM(C11:G11) -> 0 | N11: =SUM(I11:M11) -> 0 | T11: =SUM(O11:S11) -> 0 | Z11: =SUM(U11:Y11) -> 0 | AF11: =SUM(AA11:AE11) -> 0 | AL11: =SUM(AG11:AK11) -> 0 | AR11: =SUM(AM11:AQ11) -> 0 | AX11: =SUM(AS11:AW11) -> 0 | BD11: =SUM(AY11:BC11) -> 0 | BJ11: =SUM(BE11:BI11) -> 0 | BP11: =SUM(BK11:BO11) -> 0 | BQ11: RECESSO | BR11: RECESSO | BS11: RECESSO | BT11: FERIADO | BU11: RECESSO | BV11: =SUM(BQ11:BU11) -> 0 | BZ11: FERIADO | CB11: =SUM(BW11:CA11) -> 0
A12: Processos/documentos inventariados | B12: 11 | H12: =SUM(C12:G12) -> 0 | N12: =SUM(I12:M12) -> 0 | T12: =SUM(O12:S12) -> 0 | Z12: =SUM(U12:Y12) -> 0 | AF12: =SUM(AA12:AE12) -> 0 | AL12: =SUM(AG12:AK12) -> 0 | AR12: =SUM(AM12:AQ12) -> 0 | AX12: =SUM(AS12:AW12) -> 0 | BD12: =SUM(AY12:BC12) -> 0 | BJ12: =SUM(BE12:BI12) -> 0 | BP12: =SUM(BK12:BO12) -> 0 | BQ12: RECESSO | BR12: RECESSO | BS12: RECESSO | BT12: FERIADO | BU12: RECESSO | BV12: =SUM(BQ12:BU12) -> 0 | BZ12: FERIADO | CB12: =SUM(BW12:CA12) -> 0
A13: Documentos administrativos produzidos (Despacho, Nota Técnica, minutas diversas) | B13: 12 | F13: 1 | H13: =SUM(C13:G13) -> 1 | I13: 1 | L13: 2 | N13: =SUM(I13:M13) -> 3 | O13: 1 | S13: 1 | T13: =SUM(O13:S13) -> 2 | V13: 1 | W13: 1 | X13: 3 | Z13: =SUM(U13:Y13) -> 5 | AA13: 2 | AC13: 1 | AD13: 2 | AF13: =SUM(AA13:AE13) -> 5 | AG13: 1 | AH13: 1 | AL13: =SUM(AG13:AK13) -> 2 | AO13: 1 | AQ13: 1 | AR13: =SUM(AM13:AQ13) -> 2 | AT13: 1 | AW13: 1 | AX13: =SUM(AS13:AW13) -> 2 | BA13: 1 | BB13: 1 | BD13: =SUM(AY13:BC13) -> 2 | BE13: 1 | BH13: 1 | BI13: 1 | BJ13: =SUM(BE13:BI13) -> 3 | BL13: 1 | BO13: 3 | BP13: =SUM(BK13:BO13) -> 4 | BQ13: RECESSO | BR13: RECESSO | BS13: RECESSO | BT13: FERIADO | BU13: RECESSO | BV13: =SUM(BQ13:BU13) -> 0 | BX13: 1 | BZ13: FERIADO | CB13: =SUM(BW13:CA13) -> 1
A14: Orientação técnica / atendimentos realizados | B14: 13 | H14: =SUM(C14:G14) -> 0 | N14: =SUM(I14:M14) -> 0 | Q14: 1 | T14: =SUM(O14:S14) -> 1 | Y14: 1 | Z14: =SUM(U14:Y14) -> 1 | AF14: =SUM(AA14:AE14) -> 0 | AL14: =SUM(AG14:AK14) -> 0 | AR14: =SUM(AM14:AQ14) -> 0 | AX14: =SUM(AS14:AW14) -> 0 | BD14: =SUM(AY14:BC14) -> 0 | BJ14: =SUM(BE14:BI14) -> 0 | BM14: 1 | BP14: =SUM(BK14:BO14) -> 1 | BQ14: RECESSO | BR14: RECESSO | BS14: RECESSO | BT14: FERIADO | BU14: RECESSO | BV14: =SUM(BQ14:BU14) -> 0 | BZ14: FERIADO | CB14: =SUM(BW14:CA14) -> 0
A15: Caixas remanejadas | B15: 14 | H15: =SUM(C15:G15) -> 0 | N15: =SUM(I15:M15) -> 0 | T15: =SUM(O15:S15) -> 0 | Z15: =SUM(U15:Y15) -> 0 | AF15: =SUM(AA15:AE15) -> 0 | AI15: 20 | AL15: =SUM(AG15:AK15) -> 20 | AR15: =SUM(AM15:AQ15) -> 0 | AX15: =SUM(AS15:AW15) -> 0 | AY15: 20 | AZ15: 20 | BA15: 10 | BB15: 16 | BC15: 14 | BD15: =SUM(AY15:BC15) -> 80 | BE15: 23 | BI15: 5 | BJ15: =SUM(BE15:BI15) -> 28 | BN15: 8 | BP15: =SUM(BK15:BO15) -> 8 | BQ15: RECESSO | BR15: RECESSO | BS15: RECESSO | BT15: FERIADO | BU15: RECESSO | BV15: =SUM(BQ15:BU15) -> 0 | BX15: 16 | BY15: 8 | BZ15: FERIADO | CB15: =SUM(BW15:CA15) -> 24
A16: Caixas conferidas | B16: 15 | H16: =SUM(C16:G16) -> 0 | I16: 7 | J16: 7 | K16: 10 | L16: 8 | M16: 11 | N16: =SUM(I16:M16) -> 43 | P16: 21 | T16: =SUM(O16:S16) -> 21 | Z16: =SUM(U16:Y16) -> 0 | AF16: =SUM(AA16:AE16) -> 0 | AL16: =SUM(AG16:AK16) -> 0 | AR16: =SUM(AM16:AQ16) -> 0 | AS16: 20 | AX16: =SUM(AS16:AW16) -> 20 | BD16: =SUM(AY16:BC16) -> 0 | BJ16: =SUM(BE16:BI16) -> 0 | BK16: 5 | BP16: =SUM(BK16:BO16) -> 5 | BQ16: RECESSO | BR16: RECESSO | BS16: RECESSO | BT16: FERIADO | BU16: RECESSO | BV16: =SUM(BQ16:BU16) -> 0 | BZ16: FERIADO | CB16: =SUM(BW16:CA16) -> 0
A17: Caixas substituídas(trocadas) | B17: 16 | H17: =SUM(C17:G17) -> 0 | N17: =SUM(I17:M17) -> 0 | T17: =SUM(O17:S17) -> 0 | Z17: =SUM(U17:Y17) -> 0 | AF17: =SUM(AA17:AE17) -> 0 | AK17: 19 | AL17: =SUM(AG17:AK17) -> 19 | AP17: Feriado Consciência Negra | AR17: =SUM(AM17:AQ17) -> 0 | AW17: 5 | AX17: =SUM(AS17:AW17) -> 5 | AY17: 10 | AZ17: 10 | BB17: 8 | BC17: 7 | BD17: =SUM(AY17:BC17) -> 35 | BG17: 5 | BH17: 5 | BI17: 5 | BJ17: =SUM(BE17:BI17) -> 15 | BN17: 8 | BP17: =SUM(BK17:BO17) -> 8 | BQ17: RECESSO | BR17: RECESSO | BS17: RECESSO | BT17: FERIADO | BU17: RECESSO | BV17: =SUM(BQ17:BU17) -> 0 | BY17: 5 | BZ17: FERIADO | CA17: 10 | CB17: =SUM(BW17:CA17) -> 15
