Workbook

Sheet GLOSSÁRIO
A1: INDICADORES | B1: FONTE
A2: Desarquivamento de Processos/Documentos - Saída de Guia Fora | B2: SEI (Depachos ou Ofícios assinados na unidade Diarq)
A3: Caixas consultadas em pesquisa de desarquivamento | B3: CONTAGEM INDIVIDUAL (Caixas abertas para verificação de conteúdo em contexto de pesquisa para desarquivamento)
A4: Retorno de Processos/Documentos Desarquivados | B4: SEI (Depachos ou Ofícios assinados na unidade Diarq)
A5: Recebimento de Documentos - Guia de Transferência | B5: SEI (Depachos ou Ofícios assinados na unidade Diarq)
A6: Caixas separadas para classificação | B6: CONTAGEM INDIVIDUAL (Caixas "puxadas" nas estantes como uma pré-seleção para classificação)
A7: Processos/Documentos classificados | B7: PLANILHA
A8: Caixas separadas para eliminação | B8: CONTAGEM INDIVIDUAL (Caixas "puxadas" nas estantes como uma pré-seleção para eliminação)
A9: Caixas listadas para eliminação | B9: PLANILHA
A10: Processos/Documentos listados para eliminação | B10: PLANILHA
A11: Caixas inventariadas | B11: PLANILHA
A12: Processos/documentos inventariados | B12: PLANILHA
... A16: Caixas conferidas | B16: CONTAGEM INDIVIDUAL (Caixas consultadas para simples 'conferência de quantitativo' ou do 'conteúdo do espelho' em atividades diversas)

Sheet Patrícia
A1: INDICADORES | C1: 45810 | D1: 45811 | E1: 45812 | F1: 45813 | G1: 45814 | H1: TOTAL SEMANA | I1: 45817 | J1: 45818 | K1: 45819 | L1: 45820 | M1: 45821 | N1: TOTAL SEMANA | O1: 45824 | P1: 45825 | Q1: 45826 | R1: 45827 | S1: 45828 | T1: TOTAL SEMANA | U1: 45831 | V1: 45832 | W1: 45833 | X1: 45834 | Y1: 45835 | Z1: TOTAL SEMANA | AA1: 45838 | AB1: 45839 | AC1: 45840 | AD1: 45841 | AE1: 45842 | AF1: TOTAL SEMANA | AG1: 45845 | AH1: 45846 | AI1: 45847 | AJ1: 45848 | AK1: 45849 | AL1: TOTAL SEMANA | AM1: 45852 | AN1: 45853 | AO1: 45854 | AP1: 45855 | AQ1: 45856 | AR1: TOTAL SEMANA | AS1: 45859 | AT1: 45860 | AU1: 45861 | AV1: 45862 | AW1: 45863 | AX1: TOTAL SEMANA | AY1: 45866 | AZ1: 45867 | BA1: 45868 | BB1: 45869 | BC1: 45870 | BD1: TOTAL SEMANA
A2: Desarquivamento de Processos/Documentos - Saída de Guia Fora | B2: 1 | H2: =SUM(C2:G2) -> 0 | N2: =SUM(I2:M2) -> 0 | T2: =SUM(O2:S2) -> 0 | Z2: =SUM(U2:Y2) -> 0 | AF2: =SUM(AA2:AE2) -> 0 | AL2: =SUM(AG2:AK2) -> 0 | AR2: =SUM(AM2:AQ2) -> 0 | AX2: =SUM(AS2:AW2) -> 0 | BD2: =SUM(AY2:BC2) -> 0
A3: Caixas consultadas em pesquisa de desarquivamento | B3: 2 | H3: =SUM(C3:G3) -> 0 | N3: =SUM(I3:M3) -> 0 | T3: =SUM(O3:S3) -> 0 | Z3: =SUM(U3:Y3) -> 0 | AF3: =SUM(AA3:AE3) -> 0 | AL3: =SUM(AG3:AK3) -> 0 | AR3: =SUM(AM3:AQ3) -> 0 | AX3: =SUM(AS3:AW3) -> 0 | BD3: =SUM(AY3:BC3) -> 0
A4: Retorno de Processos/Documentos Desarquivados | B4: 3 | H4: =SUM(C4:G4) -> 0 | N4: =SUM(I4:M4) -> 0 | T4: =SUM(O4:S4) -> 0 | Z4: =SUM(U4:Y4) -> 0 | AF4: =SUM(AA4:AE4) -> 0 | AL4: =SUM(AG4:AK4) -> 0 | AR4: =SUM(AM4:AQ4) -> 0 | AX4: =SUM(AS4:AW4) -> 0 | BD4: =SUM(AY4:BC4) -> 0
A5: Recebimento de Documentos - Guia de Transferência | B5: 4 | H5: =SUM(C5:G5) -> 0 | N5: =SUM(I5:M5) -> 0 | T5: =SUM(O5:S5) -> 0 | Z5: =SUM(U5:Y5) -> 0 | AF5: =SUM(AA5:AE5) -> 0 | AL5: =SUM(AG5:AK5) -> 0 | AR5: =SUM(AM5:AQ5) -> 0 | AX5: =SUM(AS5:AW5) -> 0 | BD5: =SUM(AY5:BC5) -> 0
A6: Caixas separadas para classificação | B6: 5 | H6: =SUM(C6:G6) -> 0 | N6: =SUM(I6:M6) -> 0 | T6: =SUM(O6:S6) -> 0 | Z6: =SUM(U6:Y6) -> 0 | AF6: =SUM(AA6:AE6) -> 0 | AL6: =SUM(AG6:AK6) -> 0 | AR6: =SUM(AM6:AQ6) -> 0 | AX6: =SUM(AS6:AW6) -> 0 | BD6: =SUM(AY6:BC6) -> 0
A7: Processos/Documentos classificados | B7: 6 | H7: =SUM(C7:G7) -> 0 | N7: =SUM(I7:M7) -> 0 | T7: =SUM(O7:S7) -> 0 | Z7: =SUM(U7:Y7) -> 0 | AF7: =SUM(AA7:AE7) -> 0 | AL7: =SUM(AG7:AK7) -> 0 | AR7: =SUM(AM7:AQ7) -> 0 | AX7: =SUM(AS7:AW7) -> 0 | BD7: =SUM(AY7:BC7) -> 0
A8: Caixas separadas para eliminação | B8: 7 | H8: =SUM(C8:G8) -> 0 | N8: =SUM(I8:M8) -> 0 | T8: =SUM(O8:S8) -> 0 | Z8: =SUM(U8:Y8) -> 0 | AF8: =SUM(AA8:AE8) -> 0 | AL8: =SUM(AG8:AK8) -> 0 | AR8: =SUM(AM8:AQ8) -> 0 | AX8: =SUM(AS8:AW8) -> 0 | BD8: =SUM(AY8:BC8) -> 0
A9: Caixas listadas para eliminação | B9: 8 | H9: =SUM(C9:G9) -> 0 | N9: =SUM(I9:M9) -> 0 | T9: =SUM(O9:S9) -> 0 | Z9: =SUM(U9:Y9) -> 0 | AF9: =SUM(AA9:AE9) -> 0 | AL9: =SUM(AG9:AK9) -> 0 | AR9: =SUM(AM9:AQ9) -> 0 | AX9: =SUM(AS9:AW9) -> 0 | BD9: =SUM(AY9:BC9) -> 0
A10: Processos/Documentos listados para eliminação | B10: 9 | H10: =SUM(C10:G10) -> 0 | N10: =SUM(I10:M10) -> 0 | T10: =SUM(O10:S10) -> 0 | Z10: =SUM(U10:Y10) -> 0 | AF10: =SUM(AA10:AE10) -> 0 | AL10: =SUM(AG10:AK10) -> 0 | AR10: =SUM(AM10:AQ10) -> 0 | AX10: =SUM(AS10:AW10) -> 0 | BD10: =SUM(AY10:BC10) -> 0
A11: Caixas inventariadas | B11: 10 | H11: =SUM(C11:G11) -> 0 | N11: =SUM(I11:M11) -> 0 | T11: =SUM(O11:S11) -> 0 | Z11: =SUM(U11:Y11) -> 0 | AF11: =SUM(AA11:AE11) -> 0 | AL11: =SUM(AG11:AK11) -> 0 | AR11: =SUM(AM11:AQ11) -> 0 | AX11: =SUM(AS11:AW11) -> 0 | BD11: =SUM(AY11:BC11) -> 0
A12: Processos/documentos inventariados | B12: 11 | H12: =SUM(C12:G12) -> 0 | N12: =SUM(I12:M12) -> 0 | T12: =SUM(O12:S12) -> 0 | Z12: =SUM(U12:Y12) -> 0 | AF12: =SUM(AA12:AE12) -> 0 | AL12: =SUM(AG12:AK12) -> 0 | AR12: =SUM(AM12:AQ12) -> 0 | AX12: =SUM(AS12:AW12) -> 0 | BD12: =SUM(AY12:BC12) -> 0
A13: Documentos administrativos produzidos (Despacho, Nota Técnica, minutas diversas) | B13: 12 | H13: =SUM(C13:G13) -> 0 | J13: 1 | M13: 1 | N13: =SUM(I13:M13) -> 2 | P13: 1 | T13: =SUM(O13:S13) -> 1 | U13: 1 | V13: 1 | Z13: =SUM(U13:Y13) -> 2 | AA13: 1 | AC13: 1 | AF13: =SUM(AA13:AE13) -> 2 | AL13: =SUM(AG13:AK13) -> 0 | AR13: =SUM(AM13:AQ13) -> 0 | AX13: =SUM(AS13:AW13) -> 0 | BD13: =SUM(AY13:BC13) -> 0
A14: Orientação técnica / atendimentos realizados | B14: 13 | H14: =SUM(C14:G14) -> 0 | N14: =SUM(I14:M14) -> 0 | T14: =SUM(O14:S14) -> 0 | Z14: =SUM(U14:Y14) -> 0 | AF14: =SUM(AA14:AE14) -> 0 | AL14: =SUM(AG14:AK14) -> 0 | AR14: =SUM(AM14:AQ14) -> 0 | AX14: =SUM(AS14:AW14) -> 0 | BD14: =SUM(AY14:BC14) -> 0
A15: Caixas remanejadas | B15: 14 | H15: =SUM(C15:G15) -> 0 | N15: =SUM(I15:M15) -> 0 | T15: =SUM(O15:S15) -> 0 | Z15: =SUM(U15:Y15) -> 0 | AF15: =SUM(AA15:AE15) -> 0 | AL15: =SUM(AG15:AK15) -> 0 | AR15: =SUM(AM15:AQ15) -> 0 | AX15: =SUM(AS15:AW15) -> 0 | BD15: =SUM(AY15:BC15) -> 0
A16: Caixas conferidas | B16: 15 | H16: =SUM(C16:G16) -> 0 | N16: =SUM(I16:M16) -> 0 | T16: =SUM(O16:S16) -> 0 | Z16: =SUM(U16:Y16) -> 0 | AF16: =SUM(AA16:AE16) -> 0 | AL16: =SUM(AG16:AK16) -> 0 | AR16: =SUM(AM16:AQ16) -> 0 | AX16: =SUM(AS16:AW16) -> 0 | BD16: =SUM(AY16:BC16) -> 0
A17: OUTRA ATIVIDADE. QUAL?
A18: OBSERVAÇÃO

Sheet Marcelo
A1: INDICADORES | C1: 45810 | D1: 45811 | E1: 45812 | F1: 45813 | G1: 45814 | H1: TOTAL SEMANA | I1: 45817 | J1: 45818 | K1: 45819 | L1: 45820 | M1: 45821 | N1: TOTAL SEMANA | O1: 45824 | P1: 45825 | Q1: 45826 | R1: 45827 | S1: 45828 | T1: TOTAL SEMANA | U1: 45831 | V1: 45832 | W1: 45833 | X1: 45834 | Y1: 45835 | Z1: TOTAL SEMANA | AA1: 45838 | AB1: 45839 | AC1: 45840 | AD1: 45841 | AE1: 45842 | AF1: TOTAL SEMANA | AG1: 45845 | AH1: 45846 | AI1: 45847 | AJ1: 45848 | AK1: 45849 | AL1: TOTAL SEMANA | AM1: 45852 | AN1: 45853 | AO1: 45854 | AP1: 45855 | AQ1: 45856 | AR1: TOTAL SEMANA | AS1: 45859 | AT1: 45860 | AU1: 45861 | AV1: 45862 | AW1: 45863 | AX1: TOTAL SEMANA | AY1: 45866 | AZ1: 45867 | BA1: 45868 | BB1: 45869 | BC1: 45870 | BD1: TOTAL SEMANA
A2: Desarquivamento de Processos/Documentos - Saída de Guia Fora | B2: 1 | H2: =SUM(C2:G2) -> 0 | N2: =SUM(I2:M2) -> 0 | T2: =SUM(O2:S2) -> 0 | Z2: =SUM(U2:Y2) -> 0 | AF2: =SUM(AA2:AE2) -> 0 | AL2: =SUM(AG2:AK2) -> 0 | AR2: =SUM(AM2:AQ2) -> 0 | AX2: =SUM(AS2:AW2) -> 0 | BD2: =SUM(AY2:BC2) -> 0
A3: Caixas consultadas em pesquisa de desarquivamento | B3: 2 | H3: =SUM(C3:G3) -> 0 | N3: =SUM(I3:M3) -> 0 | T3: =SUM(O3:S3) -> 0 | Z3: =SUM(U3:Y3) -> 0 | AF3: =SUM(AA3:AE3) -> 0 | AL3: =SUM(AG3:AK3) -> 0 | AR3: =SUM(AM3:AQ3) -> 0 | AX3: =SUM(AS3:AW3) -> 0 | BD3: =SUM(AY3:BC3) -> 0
A4: Retorno de Processos/Documentos Desarquivados | B4: 3 | H4: =SUM(C4:G4) -> 0 | N4: =SUM(I4:M4) -> 0 | T4: =SUM(O4:S4) -> 0 | Z4: =SUM(U4:Y4) -> 0 | AF4: =SUM(AA4:AE4) -> 0 | AL4: =SUM(AG4:AK4) -> 0 | AR4: =SUM(AM4:AQ4) -> 0 | AX4: =SUM(AS4:AW4) -> 0 | BD4: =SUM(AY4:BC4) -> 0
A5: Recebimento de Documentos - Guia de Transferência | B5: 4 | H5: =SUM(C5:G5) -> 0 | N5: =SUM(I5:M5) -> 0 | T5: =SUM(O5:S5) -> 0 | Z5: =SUM(U5:Y5) -> 0 | AF5: =SUM(AA5:AE5) -> 0 | AL5: =SUM(AG5:AK5) -> 0 | AR5: =SUM(AM5:AQ5) -> 0 | AX5: =SUM(AS5:AW5) -> 0 | BD5: =SUM(AY5:BC5) -> 0
A6: Caixas separadas para classificação | B6: 5 | H6: =SUM(C6:G6) -> 0 | N6: =SUM(I6:M6) -> 0 | T6: =SUM(O6:S6) -> 0 | Z6: =SUM(U6:Y6) -> 0 | AF6: =SUM(AA6:AE6) -> 0 | AL6: =SUM(AG6:AK6) -> 0 | AR6: =SUM(AM6:AQ6) -> 0 | AX6: =SUM(AS6:AW6) -> 0 | BD6: =SUM(AY6:BC6) -> 0
A7: Processos/Documentos classificados | B7: 6 | H7: =SUM(C7:G7) -> 0 | N7: =SUM(I7:M7) -> 0 | T7: =SUM(O7:S7) -> 0 | Z7: =SUM(U7:Y7) -> 0 | AF7: =SUM(AA7:AE7) -> 0 | AL7: =SUM(AG7:AK7) -> 0 | AR7: =SUM(AM7:AQ7) -> 0 | AX7: =SUM(AS7:AW7) -> 0 | BD7: =SUM(AY7:BC7) -> 0
A8: Caixas separadas para eliminação | B8: 7 | H8: =SUM(C8:G8) -> 0 | N8: =SUM(I8:M8) -> 0 | T8: =SUM(O8:S8) -> 0 | Z8: =SUM(U8:Y8) -> 0 | AF8: =SUM(AA8:AE8) -> 0 | AL8: =SUM(AG8:AK8) -> 0 | AR8: =SUM(AM8:AQ8) -> 0 | AX8: =SUM(AS8:AW8) -> 0 | BD8: =SUM(AY8:BC8) -> 0
A9: Caixas listadas para eliminação | B9: 8 | H9: =SUM(C9:G9) -> 0 | N9: =SUM(I9:M9) -> 0 | T9: =SUM(O9:S9) -> 0 | Z9: =SUM(U9:Y9) -> 0 | AF9: =SUM(AA9:AE9) -> 0 | AL9: =SUM(AG9:AK9) -> 0 | AR9: =SUM(AM9:AQ9) -> 0 | AX9: =SUM(AS9:AW9) -> 0 | BD9: =SUM(AY9:BC9) -> 0
A10: Processos/Documentos listados para eliminação | B10: 9 | H10: =SUM(C10:G10) -> 0 | N10: =SUM(I10:M10) -> 0 | T10: =SUM(O10:S10) -> 0 | Z10: =SUM(U10:Y10) -> 0 | AF10: =SUM(AA10:AE10) -> 0 | AL10: =SUM(AG10:AK10) -> 0 | AR10: =SUM(AM10:AQ10) -> 0 | AX10: =SUM(AS10:AW10) -> 0 | BD10: =SUM(AY10:BC10) -> 0
A11: Caixas inventariadas | B11: 10 | H11: =SUM(C11:G11) -> 0 | N11: =SUM(I11:M11) -> 0 | T11: =SUM(O11:S11) -> 0 | Z11: =SUM(U11:Y11) -> 0 | AF11: =SUM(AA11:AE11) -> 0 | AL11: =SUM(AG11:AK11) -> 0 | AR11: =SUM(AM11:AQ11) -> 0 | AX11: =SUM(AS11:AW11) -> 0 | BD11: =SUM(AY11:BC11) -> 0
A12: Processos/documentos inventariados | B12: 11 | H12: =SUM(C12:G12) -> 0 | N12: =SUM(I12:M12) -> 0 | T12: =SUM(O12:S12) -> 0 | Z12: =SUM(U12:Y12) -> 0 | AF12: =SUM(AA12:AE12) -> 0 | AL12: =SUM(AG12:AK12) -> 0 | AR12: =SUM(AM12:AQ12) -> 0 | AX12: =SUM(AS12:AW12) -> 0 | BD12: =SUM(AY12:BC12) -> 0
A13: Documentos administrativos produzidos (Despacho, Nota Técnica, minutas diversas) | B13: 12 | H13: =SUM(C13:G13) -> 0 | N13: =SUM(I13:M13) -> 0 | T13: =SUM(O13:S13) -> 0 | Z13: =SUM(U13:Y13) -> 0 | AF13: =SUM(AA13:AE13) -> 0 | AL13: =SUM(AG13:AK13) -> 0 | AR13: =SUM(AM13:AQ13) -> 0 | AX13: =SUM(AS13:AW13) -> 0 | BD13: =SUM(AY13:BC13) -> 0
... A16: Caixas conferidas | B16: 15 | H16: =SUM(C16:G16) -> 0 | N16: =SUM(I16:M16) -> 0 | T16: =SUM(O16:S16) -> 0 | Z16: =SUM(U16:Y16) -> 0 | AF16: =SUM(AA16:AE16) -> 0 | AL16: =SUM(AG16:AK16) -> 0 | AR16: =SUM(AM16:AQ16) -> 0 | AX16: =SUM(AS16:AW16) -> 0 | BD16: =SUM(AY16:BC16) -> 0
A17: OUTRA ATIVIDADE. QUAL?
A18: OBSERVAÇÃO

Sheet TOTAL
A1: INDICADORES | B1: Fonte | C1: 02/06 a 06/06/2025 | D1: 09/06 a 13/06/2025 | E1: 16/06 a 20/06/2025 | F1: 23/06 a 27/06/2025 | G1: 30/06 a 04/07/2025 | H1: 07/07 a 11/07/2025 | I1: 14/07 a 18/07/2025 | J1: 21/07 a 25/07/2025 | K1: 28/07 a 1/08/2025
A2: Desarquivamento de Processos/Documentos - Saída de Guia Fora | B2: SEI | C2: =Diego!H2+Aelton!H2+Leonam!H2+Danilo!H2+Marcos!H2+Carlos!H2+Alessandro!H2 -> 6 | D2: =Diego!N2+Aelton!N2+Leonam!N2+Danilo!N2+Marcos!N2+Carlos!N2+Alessandro!N2 -> 3 | E2: =Diego!T2+Aelton!T2+Leonam!T2+Danilo!T2+Marcos!T2+Carlos!T2+Alessandro!T2 -> 0 | F2: =Diego!Z2+Aelton!Z2+Leonam!Z2+Danilo!Z2+Marcos!Z2+Carlos!Z2+Alessandro!Z2 -> 1 | G2: =Diego!AF2+Aelton!AF2+Leonam!AF2+Danilo!AF2+Marcos!AF2+Carlos!AF2+Alessandro!AF2 -> 6 | H2: =Diego!AL2+Aelton!AL2+Leonam!AL2+Danilo!AL2+Marcos!AL2+Carlos!AL2+Alessandro!AL2 -> 3 | I2: =Diego!AR2+Aelton!AR2+Leonam!AR2+Danilo!AR2+Marcos!AR2+Carlos!AR2+Alessandro!AR2 -> 0 | J2: =Diego!AX2+Aelton!AX2+Leonam!AX2+Danilo!AX2+Marcos!AX2+Carlos!AX2+Alessandro!AX2 -> 0 | K2: =Diego!BD2+Aelton!BD2+Leonam!BD2+Danilo!BD2+Marcos!BD2+Carlos!BD2+Alessandro!BD2 -> 1
A3: Caixas consultadas em pesquisa de desarquivamento | B3: CONTAGEM INDIVIDUAL (das caixas abertas para verificação de conteúdo em contexto de pesquisa para desarquivamento) | C3: =Diego!H3+Aelton!H3+Leonam!H3+Danilo!H3+Marcos!H3+Carlos!H3+Alessandro!H3 -> 2 | D3: =Diego!N3+Aelton!N3+Leonam!N3+Danilo!N3+Marcos!N3+Carlos!N3+Alessandro!N3 -> 1 | E3: =Diego!T3+Aelton!T3+Leonam!T3+Danilo!T3+Marcos!T3+Carlos!T3+Alessandro!T3 -> 0 | F3: =Diego!Z3+Aelton!Z3+Leonam!Z3+Danilo!Z3+Marcos!Z3+Carlos!Z3+Alessandro!Z3 -> 4 | G3: =Diego!AF3+Aelton!AF3+Leonam!AF3+Danilo!AF3+Marcos!AF3+Carlos!AF3+Alessandro!AF3 -> 60 | H3: =Diego!AL3+Aelton!AL3+Leonam!AL3+Danilo!AL3+Marcos!AL3+Carlos!AL3+Alessandro!AL3 -> 0 | I3: =Diego!AM3+Aelton!AM3+Leonam!AM3+Danilo!AM3+Marcos!AM3+Carlos!AM3+Alessandro!AM3 -> 0 | J3: =Diego!AX3+Aelton!AX3+Leonam!AX3+Danilo!AX3+Marcos!AX3+Carlos!AX3+Alessandro!AX3 -> 0 | K3: =Diego!BD3+Aelton!BD3+Leonam!BD3+Danilo!BD3+Marcos!BD3+Carlos!BD3+Alessandro!BD3 -> 3
A4: Retorno de Processos/Documentos Desarquivados | B4: SEI | C4: =Diego!H4+Aelton!H4+Leonam!H4+Danilo!H4+Marcos!H4+Carlos!H4+Alessandro!H4 -> 0 | D4: =Diego!N4+Aelton!N4+Leonam!N4+Danilo!N4+Marcos!N4+Carlos!N4+Alessandro!N4 -> 41 | E4: =Diego!T4+Aelton!T4+Leonam!T4+Danilo!T4+Marcos!T4+Carlos!T4+Alessandro!T4 -> 6 | F4: =Diego!Z4+Aelton!Z4+Leonam!Z4+Danilo!Z4+Marcos!Z4+Carlos!Z4+Alessandro!Z4 -> 0 | G4: =Diego!AF4+Aelton!AF4+Leonam!AF4+Danilo!AF4+Marcos!AF4+Carlos!AF4+Alessandro!AF4 -> 4 | H4: =Diego!AL4+Aelton!AL4+Leonam!AL4+Danilo!AL4+Marcos!AL4+Carlos!AL4+Alessandro!AL4 -> 3 | I4: =Diego!AM4+Aelton!AM4+Leonam!AM4+Danilo!AM4+Marcos!AM4+Carlos!AM4+Alessandro!AM4 -> 0 | J4: =Diego!AX4+Aelton!AX4+Leonam!AX4+Danilo!Z4+Marcos!AX4+Carlos!AX4+Alessandro!AX4 -> 0 | K4: =Diego!BD4+Aelton!BD4+Leonam!BD4+Danilo!BD4+Marcos!BD4+Carlos!BD4+Alessandro!BD4 -> 0
A5: Recebimento de Documentos - Guia de Transferência | B5: SEI | C5: =Diego!H5+Aelton!H5+Leonam!H5+Danilo!H5+Marcos!H5+Carlos!H5+Alessandro!H5 -> 0 | D5: =Diego!N5+Aelton!N5+Leonam!N5+Danilo!N5+Marcos!N5+Carlos!N5+Alessandro!N5 -> 0 | E5: =Diego!T5+Aelton!T5+Leonam!T5+Danilo!T5+Marcos!T5+Carlos!T5+Alessandro!T5 -> 0 | F5: =Diego!Z5+Aelton!Z5+Leonam!Z5+Danilo!Z5+Marcos!Z5+Carlos!Z5+Alessandro!Z5 -> 0 | G5: =Diego!AF5+Aelton!AF5+Leonam!AF5+Danilo!AF5+Marcos!AF5+Carlos!AF5+Alessandro!AF5 -> 0 | H5: =Diego!AL5+Aelton!AL5+Leonam!AL5+Danilo!AL5+Marcos!AL5+Carlos!AL5+Alessandro!AL5 -> 0 | I5: =Diego!AR5+Aelton!AR5+Leonam!AR5+Danilo!AR5+Marcos!AR5+Carlos!AR5+Alessandro!AR5 -> 8 | J5: =Diego!AX5+Aelton!AX5+Leonam!AX5+Danilo!AX5+Marcos!AX5+Carlos!AX5+Alessandro!AX5 -> 0 | K5: =Diego!BD5+Aelton!BD5+Leonam!BD5+Danilo!BD5+Marcos!BD5+Carlos!BD5+Alessandro!BD5 -> 0
A6: Caixas separadas para classificação | B6: CONTAGEM INDIVIDUAL (das caixas "puxadas" nas estantes como uma pré-seleção para classificação) | C6: =Diego!H6+Aelton!H6+Leonam!H6+Danilo!H6+Marcos!H6+Carlos!H6+Alessandro!H6 -> 10 | D6: =Diego!N6+Aelton!N6+Leonam!N6+Danilo!N6+Marcos!N6+Carlos!N6+Alessandro!N6 -> 8 | E6: =Diego!T6+Aelton!T6+Leonam!T6+Danilo!T6+Marcos!T6+Carlos!T6+Alessandro!T6 -> 2 | F6: =Diego!Z6+Aelton!Z6+Leonam!Z6+Danilo!Z6+Marcos!Z6+Carlos!Z6+Alessandro!Z6 -> 2 | G6: =Diego!AF6+Aelton!AF6+Leonam!AF6+Danilo!AF6+Marcos!AF6+Carlos!AF6+Alessandro!AF6 -> 12 | H6: =Diego!AL6+Aelton!AL6+Leonam!AL6+Danilo!AL6+Marcos!AL6+Carlos!AL6+Alessandro!AL6 -> 30 | I6: =Diego!AR6+Aelton!AR6+Leonam!AR6+Danilo!AR6+Marcos!AR6+Carlos!AR6+Alessandro!AR6 -> 0 | J6: =Diego!AX6+Aelton!AX6+Leonam!AX6+Danilo!AX6+Marcos!AX6+Carlos!AX6+Alessandro!AX6 -> 0 | K6: =Diego!BD6+Aelton!BD6+Leonam!BD6+Danilo!BD6+Marcos!BD6+Carlos!BD6+Alessandro!BD6 -> 0
A7: Processos/Documentos classificados | B7: PLANILHA | C7: =Diego!H7+Aelton!H7+Leonam!H7+Danilo!H7+Marcos!H7+Carlos!H7+Alessandro!H7 -> 256 | D7: =Diego!N7+Aelton!N7+Leonam!N7+Danilo!N7+Marcos!N7+Carlos!N7+Alessandro!N7 -> 118 | E7: =Diego!T7+Aelton!T7+Leonam!T7+Danilo!T7+Marcos!T7+Carlos!T7+Alessandro!T7 -> 30 | F7: =Diego!Z7+Aelton!Z7+Leonam!Z7+Danilo!Z7+Marcos!Z7+Carlos!Z7+Alessandro!Z7 -> 34 | G7: =Diego!AF7+Aelton!AF7+Leonam!AF7+Danilo!AF7+Marcos!AF7+Carlos!AF7+Alessandro!AF7 -> 0 | H7: =Diego!AL7+Aelton!AL7+Leonam!AL7+Danilo!AL7+Marcos!AL7+Carlos!AL7+Alessandro!AL7 -> 0 | I7: =Diego!AR7+Aelton!AR7+Leonam!AR7+Danilo!AR7+Marcos!AR7+Carlos!AR7+Alessandro!AR7 -> 0 | J7: =Diego!AX7+Aelton!AX7+Leonam!AX7+Danilo!AX7+Marcos!AX7+Carlos!AX7+Alessandro!AX7 -> 0 | K7: =Diego!BD7+Aelton!BD7+Leonam!BD7+Danilo!BD7+Marcos!BD7+Carlos!BD7+Alessandro!BD7 -> 0
A8: Caixas separadas para eliminação | B8: CONTAGEM INDIVIDUAL (das caixas "puxadas" nas estantes como uma pré-seleção para eliminação) | C8: =Diego!H8+Aelton!H8+Leonam!H8+Danilo!H8+Marcos!H8+Carlos!H8+Alessandro!H8 -> 123 | D8: =Diego!N8+Aelton!N8+Leonam!N8+Danilo!N8+Marcos!N8+Carlos!N8+Alessandro!N8 -> 52 | E8: =Diego!T8+Aelton!T8+Leonam!T8+Danilo!T8+Marcos!T8+Carlos!T8+Alessandro!T8 -> 0 | F8: =Diego!Z8+Aelton!Z8+Leonam!Z8+Danilo!Z8+Marcos!Z8+Carlos!Z8+Alessandro!Z8 -> 0 | G8: =Diego!AF8+Aelton!AF8+Leonam!AF8+Danilo!AF8+Marcos!AF8+Carlos!AF8+Alessandro!AF8 -> 0 | H8: =Diego!AL8+Aelton!AL8+Leonam!AL8+Danilo!AL8+Marcos!AL8+Carlos!AL8+Alessandro!AL8 -> 30 | I8: =Diego!AR8+Aelton!AR8+Leonam!AR8+Danilo!AR8+Marcos!AR8+Carlos!AR8+Alessandro!AR8 -> 0 | J8: =Diego!AX8+Aelton!AX8+Leonam!AX8+Danilo!AX8+Marcos!AX8+Carlos!AX8+Alessandro!AX8 -> 0 | K8: =Diego!BD8+Aelton!BD8+Leonam!BD8+Danilo!BD8+Marcos!BD8+Carlos!BD8+Alessandro!BD8 -> 0
A9: Caixas listadas para eliminação | B9: PLANILHA | C9: =Diego!H9+Aelton!H9+Leonam!H9+Danilo!H9+Marcos!H9+Carlos!H9+Alessandro!H9 -> 123 | D9: =Diego!N9+Aelton!N9+Leonam!N9+Danilo!N9+Marcos!N9+Carlos!N9+Alessandro!N9 -> 83 | E9: =Diego!T9+Aelton!T9+Leonam!T9+Danilo!T9+Marcos!T9+Carlos!T9+Alessandro!T9 -> 0 | F9: =Diego!Z9+Aelton!Z9+Leonam!Z9+Danilo!Z9+Marcos!Z9+Carlos!Z9+Alessandro!Z9 -> 4 | G9: =Diego!AF9+Aelton!AF9+Leonam!AF9+Danilo!AF9+Marcos!AF9+Carlos!AF9+Alessandro!AF9 -> 24 | H9: =Diego!AL9+Aelton!AL9+Leonam!AL9+Danilo!AL9+Marcos!AL9+Carlos!AL9+Alessandro!AL9 -> 13 | I9: =Diego!AR9+Aelton!AR9+Leonam!AR9+Danilo!AR9+Marcos!AR9+Carlos!AR9+Alessandro!AR9 -> 22 | J9: =Diego!AX9+Aelton!AX9+Leonam!AX9+Danilo!AX9+Marcos!AX9+Carlos!AX9+Alessandro!AX9 -> 15 | K9: =Diego!BD9+Aelton!BD9+Leonam!BD9+Danilo!BD9+Marcos!BD9+Carlos!BD9+Alessandro!BD9 -> 0
A10: Processos/Documentos listados para eliminação | B10: PLANILHA | C10: =Diego!H10+Aelton!H10+Leonam!H10+Danilo!H10+Marcos!H10+Carlos!H10+Alessandro!H10 -> 0 | D10: =Diego!N10+Aelton!N10+Leonam!N10+Danilo!N10+Marcos!N10+Carlos!N10+Alessandro!N10 -> 23 | E10: =Diego!T10+Aelton!T10+Leonam!T10+Danilo!T10+Marcos!T10+Carlos!T10+Alessandro!T10 -> 0 | F10: =Diego!Z10+Aelton!Z10+Leonam!Z10+Danilo!Z10+Marcos!Z10+Carlos!Z10+Alessandro!Z10 -> 6 | G10: =Diego!AF10+Aelton!AF10+Leonam!AF10+Danilo!AF10+Marcos!AF10+Carlos!AF10+Alessandro!AF10 -> 12 | H10: =Diego!AL10+Aelton!AL10+Leonam!AL10+Danilo!AL10+Marcos!AL10+Carlos!AL10+Alessandro!AL10 -> 13 | I10: =Diego!AR10+Aelton!AR10+Leonam!AR10+Danilo!AR10+Marcos!AR10+Carlos!AR10+Alessandro!AR10 -> 22 | J10: =Diego!AX10+Aelton!AX10+Leonam!AX10+Danilo!AX10+Marcos!AX10+Carlos!AX10+Alessandro!AX10 -> 15 | K10: =Diego!BD10+Aelton!BD10+Leonam!BD10+Danilo!BD10+Marcos!BD10+Carlos!BD10+Alessandro!BD10 -> 0
A11: Caixas inventariadas | B11: PLANILHA | C11: =Diego!H11+Aelton!H11+Leonam!H11+Danilo!H11+Marcos!H11+Carlos!H11+Alessandro!H11 -> 28 | D11: =Diego!N11+Aelton!N11+Leonam!N11+Danilo!N11+Marcos!N11+Carlos!N11+Alessandro!N11 -> 56 | E11: =Diego!T11+Aelton!T11+Leonam!T11+Danilo!T11+Marcos!T11+Carlos!T11+Alessandro!T11 -> 13 | F11: =Diego!Z11+Leonam!Z11+Danilo!Z11+Marcos!Z11+Alessandro!AX11 -> 49 | G11: =Diego!AF11+Aelton!AF11+Leonam!AF11+Danilo!AF11+Marcos!AF11+Carlos!AF11+Alessandro!AF11 -> 67 | H11: =Diego!AL11+Aelton!AL11+Leonam!AL11+Danilo!AL11+Marcos!AL11+Carlos!AL11+Alessandro!AL11 -> 9 | I11: =Diego!AR11+Aelton!AR11+Leonam!AR11+Danilo!AR11+Marcos!AR11+Carlos!AR11+Alessandro!AR11 -> 43 | J11: =Diego!AX11+Aelton!AX11+Leonam!AX11+Danilo!AX11+Marcos!AX11+Carlos!AX11+Alessandro!AX11 -> 25 | K11: =Diego!BD11+Aelton!BD11+Leonam!BD11+Danilo!BD11+Marcos!BD11+Carlos!BD11+Alessandro!BD11 -> 10
A12: Processos/documentos inventariados | B12: PLANILHA | C12: =Diego!H12+Aelton!H12+Leonam!H12+Danilo!H12+Marcos!H12+Carlos!H12+Alessandro!H12 -> 543 | D12: =Diego!N12+Aelton!N12+Leonam!N12+Danilo!N12+Marcos!N12+Carlos!N12+Alessandro!N12 -> 685 | E12: =Diego!T12+Aelton!T12+Leonam!T12+Danilo!T12+Marcos!T12+Carlos!T12+Alessandro!T12 -> 314 | F12: =Diego!Z12+Aelton!Z12+Leonam!AF12+Danilo!AF12+Marcos!AF12+Alessandro!Z12 -> 1793 | G12: =Diego!AF12+Aelton!AF12+Leonam!AF12+Danilo!AF12+Marcos!AF12+Carlos!AF12+Alessandro!AF12 -> 2162 | H12: =Diego!AL12+Aelton!AL12+Leonam!AL12+Danilo!AL12+Marcos!AL12+Carlos!AL12+Alessandro!AL12 -> 304 | I12: =Diego!AR12+Aelton!AR12+Leonam!AR12+Danilo!AR12+Marcos!AR12+Carlos!AR12+Alessandro!AR12 -> 1511 | J12: =Diego!AX12+Aelton!AX12+Leonam!AX12+Danilo!AX12+Marcos!AX12+Carlos!AX12+Alessandro!AX12 -> 958 | K12: =Diego!BD12+Aelton!BD12+Leonam!BD12+Danilo!BD12+Marcos!BD12+Carlos!BD12+Alessandro!BD12 -> 578
A13: Documentos administrativos produzidos (Despacho, Nota Técnica, minutas diversas) | B13: SEI | C13: =Diego!H13+Aelton!H13+Leonam!H13+Danilo!H13+Marcos!H13+Carlos!H13+Alessandro!H13 -> 2 | D13: =Diego!N13+Aelton!N13+Leonam!N13+Danilo!N13+Marcos!N13+Carlos!N13+Alessandro!N13 -> 5 | E13: =Diego!T13+Aelton!T13+Leonam!T13+Danilo!T13+Marcos!T13+Carlos!T13+Alessandro!T13+Patrícia!T13 -> 1 | F13: =Patrícia!Z13+Danilo!Z13+Alessandro!Z13 -> 3 | G13: =Diego!AF13+Aelton!AF13+Leonam!AF13+Danilo!AF13+Marcos!AF13+Carlos!AF13+Alessandro!AF13 -> 4 | H13: =Patrícia!AL13+Marcelo!AL13+Diego!AL13+Aelton!AL13+Leonam!AL13+Danilo!AL13+Marcos!AL13+Carlos!AL13+Alessandro!AL13 -> 3 | I13: =Diego!AR13+Aelton!AR13+Leonam!AR13+Danilo!AR13+Marcos!AR13+Carlos!AR13+Alessandro!AR13+Patrícia!AR13+Marcelo!AR13 -> 1 | J13: =Patrícia!AX13+Marcelo!AX13+Diego!AX13+Aelton!AX13+Leonam!AX13+Danilo!AX13+Marcos!AX13+Carlos!AX13+Alessandro!AX13 -> 0 | K13: =Patrícia!BD13+Marcelo!BD13+Diego!BD13+Aelton!BD13+Leonam!BD13+Danilo!BD13+Marcos!BD13+Carlos!BD13+Alessandro!BD13 -> 2
A14: Orientação técnica / atendimentos realizados | B14: SEI, E-MAIL, TELEFONE | C14: =Diego!H14+Aelton!H14+Leonam!H14+Danilo!H14+Marcos!H14+Carlos!H14+Alessandro!H14 -> 0 | D14: =Diego!N14+Aelton!N14+Leonam!N14+Danilo!N14+Marcos!N14+Carlos!N14+Alessandro!N14 -> 1 | E14: =Diego!T14+Aelton!T14+Leonam!T14+Danilo!T14+Marcos!T14+Carlos!T14+Alessandro!T14 -> 0 | F14: =Diego!Z14+Aelton!Z14+Leonam!Z14+Danilo!Z14+Marcos!Z14+Carlos!Z14+Alessandro!Z14 -> 0 | G14: =Diego!AF14+Aelton!AF14+Leonam!AF14+Danilo!AF14+Marcos!AF14+Carlos!AF14+Alessandro!AF14 -> 0 | H14: =Diego!AL14+Aelton!AL14+Leonam!AL14+Danilo!AL14+Marcos!AL14+Carlos!AL14+Alessandro!AL14 -> 0 | I14: =Patrícia!AR14+Marcelo!AR14 -> 0 | J14: =Patrícia!AX14+Marcelo!AX14 -> 0 | K14: =Patrícia!BD14+Marcelo!BD14 -> 0
A15: Caixas remanejada | B15: CONTAGEM INDIVIDUAL (de caixas deslocadas visando reorganização temporária ou permanente) | C15: =Diego!H15+Aelton!H15+Leonam!H15+Danilo!H15+Marcos!H15+Carlos!H15+Alessandro!H15 -> 259 | D15: =Diego!N15+Aelton!N15+Leonam!N15+Danilo!N15+Marcos!N15+Carlos!N15+Alessandro!N15 -> 603 | E15: =Diego!T15+Aelton!T15+Leonam!T15+Danilo!T15+Marcos!T15+Carlos!T15+Alessandro!T15 -> 11 | F15: =Diego!Z15+Aelton!Z15+Leonam!Z15+Danilo!Z15+Marcos!Z15+Carlos!Z15+Alessandro!Z15 -> 19 | G15: =Diego!AF15+Aelton!AF15+Leonam!AF15+Danilo!AF15+Marcos!AF15+Carlos!AF15+Alessandro!AF15 -> 11 | H15: =Diego!AL15+Aelton!AL15+Leonam!AL15+Danilo!AL15+Marcos!AL15+Carlos!AL15+Alessandro!AL15 -> 318 | I15: 71 | J15: =Diego!AX15+Aelton!AX15+Leonam!AX15+Danilo!AX15+Marcos!AX15+Carlos!AX15+Alessandro!AX15 -> 114 | K15: =Diego!BD15+Aelton!BD15+Leonam!BD15+Danilo!BD15+Marcos!BD15+Carlos!BD15+Alessandro!BD15 -> 64
A16: Caixas conferidas | B16: CONTAGEM INDIVIDUAL (de caixas para simples conferência de quantitativo ou do conteúdo do espelho em atividades diversas) | C16: =Diego!H16+Aelton!H16+Leonam!H16+Danilo!H16+Marcos!H16+Carlos!H16+Alessandro!H16 -> 38881 | D16: =Diego!N16+Aelton!N16+Leonam!N16+Danilo!N16+Marcos!N16+Carlos!N16+Alessandro!N16 -> 11355 | E16: =Diego!T16+Aelton!T16+Leonam!T16+Danilo!T16+Marcos!T16+Carlos!T16+Alessandro!T16 -> 0 | F16: =Diego!Z16+Aelton!Z16+Leonam!Z16+Danilo!Z16+Marcos!Z16+Carlos!Z16+Alessandro!Z16 -> 9 | G16: =Diego!AF16+Aelton!AF16+Leonam!AF16+Danilo!AF16+Marcos!AF16+Carlos!AF16+Alessandro!AF16 -> 0 | H16: =Diego!AL16+Aelton!AL16+Leonam!AL16+Danilo!AL16+Marcos!AL16+Carlos!AL16+Alessandro!AL16 -> 60 | I16: =Diego!AR16+Aelton!AR16+Leonam!AR16+Danilo!AR16+Marcos!AR16+Carlos!AR16+Alessandro!AR16 -> 1736 | J16: =Diego!AX16+Aelton!AX16+Leonam!AX16+Danilo!AX16+Marcos!AX16+Carlos!AX16+Alessandro!AX16 -> 13 | K16: =Diego!BD16+Aelton!BD16+Leonam!BD16+Danilo!BD16+Marcos!BD16+Carlos!BD16+Alessandro!BD16 -> 4
A17: OUTRA ATIVIDADE. QUAL?
A18: OBSERVAÇÃO

Sheet Diego
A1: INDICADORES | C1: 45810 | D1: 45811 | E1: 45812 | F1: 45813 | G1: 45814 | H1: TOTAL SEMANA | I1: 45817 | J1: 45818 | K1: 45819 | L1: 45820 | M1: 45821 | N1: TOTAL SEMANA | O1: 45824 | P1: 45825 | Q1: 45826 | R1: 45827 | S1: 45828 | T1: TOTAL SEMANA | U1: 45831 | V1: 45832 | W1: 45833 | X1: 45834 | Y1: 45835 | Z1: TOTAL SEMANA | AA1: 45838 | AB1: 45839 | AC1: 45840 | AD1: 45841 | AE1: 45842 | AF1: TOTAL SEMANA | AG1: 45845 | AH1: 45846 | AI1: 09/JU | AJ1: 45848 | AK1: 45849 | AL1: TOTAL SEMANA | AM1: 45852 | AN1: 45853 | AO1: 45854 | AP1: 45855 | AQ1: 45856 | AR1: TOTAL SEMANA | AS1: 45859 | AT1: 45860 | AU1: 45861 | AV1: 45862 | AW1: 45863 | AX1: TOTAL SEMANA | AY1: 45866 | AZ1: 45867 | BA1: 45868 | BB1: 45869 | BC1: 45870 | BD1: TOTAL SEMANA
A2: Desarquivamento de Processos/Documentos - Saída de Guia Fora | B2: 1 | H2: =SUM(C2:G2) -> 0 | N2: =SUM(I2:M2) -> 0 | T2: =SUM(O2:S2) -> 0 | Z2: =SUM(U2:Y2) -> 0 | AD2: 2 | AF2: =SUM(AA2:AE2) -> 2 | AL2: =SUM(AG2:AK2) -> 0 | AR2: =SUM(AM2:AQ2) -> 0 | AX2: =SUM(AS2:AW2) -> 0 | BD2: =SUM(AY2:BC2) -> 0
A3: Caixas consultadas em pesquisa de desarquivamento | B3: 2 | H3: =SUM(C3:G3) -> 0 | N3: =SUM(I3:M3) -> 0 | T3: =SUM(O3:S3) -> 0 | Z3: =SUM(U3:Y3) -> 0 | AD3: 30 | AF3: =SUM(AA3:AE3) -> 30 | AL3: =SUM(AG3:AK3) -> 0 | AR3: =SUM(AM3:AQ3) -> 0 | AX3: =SUM(AS3:AW3) -> 0 | BD3: =SUM(AY3:BC3) -> 0
A4: Retorno de Processos/Documentos Desarquivados | B4: 3 | H4: =SUM(C4:G4) -> 0 | N4: =SUM(I4:M4) -> 0 | T4: =SUM(O4:S4) -> 0 | Z4: =SUM(U4:Y4) -> 0 | AF4: =SUM(AA4:AE4) -> 0 | AL4: =SUM(AG4:AK4) -> 0 | AR4: =SUM(AM4:AQ4) -> 0 | AX4: =SUM(AS4:AW4) -> 0 | BD4: =SUM(AY4:BC4) -> 0
A5: Recebimento de Documentos - Guia de Transferência | B5: 4 | H5: =SUM(C5:G5) -> 0 | N5: =SUM(I5:M5) -> 0 | T5: =SUM(O5:S5) -> 0 | Z5: =SUM(U5:Y5) -> 0 | AF5: =SUM(AA5:AE5) -> 0 | AL5: =SUM(AG5:AK5) -> 0 | AN5: 7 | AR5: =SUM(AM5:AQ5) -> 7 | AX5: =SUM(AS5:AW5) -> 0 | BD5: =SUM(AY5:BC5) -> 0
A6: Caixas separadas para classificação | B6: 5 | H6: =SUM(C6:G6) -> 0 | N6: =SUM(I6:M6) -> 0 | T6: =SUM(O6:S6) -> 0 | Z6: =SUM(U6:Y6) -> 0 | AB6: 12 | AF6: =SUM(AA6:AE6) -> 12 | AG6: 20 | AL6: =SUM(AG6:AK6) -> 20 | AR6: =SUM(AM6:AQ6) -> 0 | AX6: =SUM(AS6:AW6) -> 0 | BD6: =SUM(AY6:BC6) -> 0
A7: Processos/Documentos classificados | B7: 6 | H7: =SUM(C7:G7) -> 0 | N7: =SUM(I7:M7) -> 0 | T7: =SUM(O7:S7) -> 0 | Z7: =SUM(U7:Y7) -> 0 | AF7: =SUM(AA7:AE7) -> 0 | AL7: =SUM(AG7:AK7) -> 0 | AR7: =SUM(AM7:AQ7) -> 0 | AX7: =SUM(AS7:AW7) -> 0 | BD7: =SUM(AY7:BC7) -> 0
A8: Caixas separadas para eliminação | B8: 7 | D8: 9 | E8: 34 | H8: =SUM(C8:G8) -> 43 | K8: 20 | L8: 14 | N8: =SUM(I8:M8) -> 34 | T8: =SUM(O8:S8) -> 0 | Z8: =SUM(U8:Y8) -> 0 | AF8: =SUM(AA8:AE8) -> 0 | AG8: 20 | AL8: =SUM(AG8:AK8) -> 20 | AR8: =SUM(AM8:AQ8) -> 0 | AX8: =SUM(AS8:AW8) -> 0 | BD8: =SUM(AY8:BC8) -> 0
A9: Caixas listadas para eliminação | B9: 8 | D9: 9 | E9: 34 | H9: =SUM(C9:G9) -> 43 | K9: 20 | L9: 14 | M9: 9 | N9: =SUM(I9:M9) -> 43 | T9: =SUM(O9:S9) -> 0 | Z9: =SUM(U9:Y9) -> 0 | AF9: =SUM(AA9:AE9) -> 0 | AL9: =SUM(AG9:AK9) -> 0 | AR9: =SUM(AM9:AQ9) -> 0 | AX9: =SUM(AS9:AW9) -> 0 | BD9: =SUM(AY9:BC9) -> 0
A10: Processos/Documentos listados para eliminação | B10: 9 | H10: =SUM(C10:G10) -> 0 | N10: =SUM(I10:M10) -> 0 | T10: =SUM(O10:S10) -> 0 | Z10: =SUM(U10:Y10) -> 0 | AF10: =SUM(AA10:AE10) -> 0 | AL10: =SUM(AG10:AK10) -> 0 | AR10: =SUM(AM10:AQ10) -> 0 | AX10: =SUM(AS10:AW10) -> 0 | BD10: =SUM(AY10:BC10) -> 0
A11: Caixas inventariadas | B11: 10 | H11: =SUM(C11:G11) -> 0 | N11: =SUM(I11:M11) -> 0 | T11: =SUM(O11:S11) -> 0 | W11: 2 | X11: 4 | Y11: 3 | Z11: =SUM(U11:Y11) -> 9 | AA11: 2 | AB11: 3 | AC11: 3 | AD11: 2 | AE11: 3 | AF11: =SUM(AA11:AE11) -> 13 | AH11: 2 | AJ11: 1 | AK11: 1 | AL11: =SUM(AG11:AK11) -> 4 | AN11: 1 | AO11: 1 | AP11: 1 | AQ11: 1 | AR11: =SUM(AM11:AQ11) -> 4 | AS11: FOLGA | AT11: 1 | AU11: 1 | AV11: 1 | AX11: =SUM(AS11:AW11) -> 3 | AY11: 4 | AZ11: 3 | BD11: =SUM(AY11:BC11) -> 7
A12: Processos/documentos inventariados | B12: 11 | H12: =SUM(C12:G12) -> 0 | N12: =SUM(I12:M12) -> 0 | T12: =SUM(O12:S12) -> 0 | W12: 78 | X12: 144 | Y12: 78 | Z12: =SUM(U12:Y12) -> 300 | AA12: 72 | AB12: 96 | AC12: 97 | AD12: 34 | AE12: 96 | AF12: =SUM(AA12:AE12) -> 395 | AH12: 72 | AJ12: 34 | AK12: 30 | AL12: =SUM(AG12:AK12) -> 136 | AN12: 52 | AO12: 53 | AP12: 47 | AQ12: 52 | AR12: =SUM(AM12:AQ12) -> 204 | AT12: 52 | AU12: 43 | AV12: 35 | AW12: 12 | AX12: =SUM(AS12:AW12) -> 142 | AY12: 118 | AZ12: 85 | BA12: 24 | BB12: 18 | BC12: 78 | BD12: =SUM(AY12:BC12) -> 323
A13: Documentos administrativos produzidos (Despacho, Nota Técnica, minutas diversas) | B13: 12 | G13: 1 | H13: =SUM(C13:G13) -> 1 | J13: 1 | K13: 1 | M13: 1 | N13: =SUM(I13:M13) -> 3 | T13: =SUM(O13:S13) -> 0 | Z13: =SUM(U13:Y13) -> 0 | AD13: 1 | AF13: =SUM(AA13:AE13) -> 1 | AL13: =SUM(AG13:AK13) -> 0 | AR13: =SUM(AM13:AQ13) -> 0 | AX13: =SUM(AS13:AW13) -> 0 | BD13: =SUM(AY13:BC13) -> 0
A14: Orientação técnica / atendimentos realizados | B14: 13 | H14: =SUM(C14:G14) -> 0 | L14: 1 | N14: =SUM(I14:M14) -> 1 | T14: =SUM(O14:S14) -> 0 | Z14: =SUM(U14:Y14) -> 0 | AF14: =SUM(AA14:AE14) -> 0 | AL14: =SUM(AG14:AK14) -> 0 | AR14: =SUM(AM14:AQ14) -> 0 | AX14: =SUM(AS14:AW14) -> 0 | BD14: =SUM(AY14:BC14) -> 0
A15: Caixas remanejadas | B15: 14 | C15: 10 | D15: 30 | F15: 55 | H15: =SUM(C15:G15) -> 95 | J15: 140 | L15: 30 | M15: 27 | N15: =SUM(I15:M15) -> 197 | P15: 11 | T15: =SUM(O15:S15) -> 11 | Z15: =SUM(U15:Y15) -> 0 | AF15: =SUM(AA15:AE15) -> 0 | AG15: 95 | AI15: 51 | AL15: =SUM(AG15:AK15) -> 146 | AM15: 40 | AN15: 20 | AP15: 11 | AR15: =SUM(AM15:AQ15) -> 71 | AV15: 15 | AX15: =SUM(AS15:AW15) -> 15 | AY15: 22 | BA15: 14 | BD15: =SUM(AY15:BC15) -> 36
A16: Caixas conferidas | B16: 15 | E16: 164 | F16: 2286 | G16: 15687 | H16: =SUM(C16:G16) -> 18137 | I16: 3724 | N16: =SUM(I16:M16) -> 3724 | T16: =SUM(O16:S16) -> 0 | Z16: =SUM(U16:Y16) -> 0 | AF16: =SUM(AA16:AE16) -> 0 | AL16: =SUM(AG16:AK16) -> 0 | AR16: =SUM(AM16:AQ16) -> 0 | AX16: =SUM(AS16:AW16) -> 0 | BD16: =SUM(AY16:BC16) -> 0
A17: OUTRA ATIVIDADE. QUAL? | C17: PROCURANDO CAIXAS PARA ELIMINAÇÃO | F17: PROCURANDO CAIXAS PARA ELIMINAÇÃO | G17: PROCURANDO CAIXAS PARA ELIMINAÇÃO | I17: PROCURANDO CAIXAS PARA ELIMINAÇÃO | J17: PROCURANDO CAIXAS PARA ELIMINAÇÃO | O17: FAZENDO PALETES 80 CAIXAS PRA CADA | Q17: DIGITALIZANDO LIVROS DA LBA | R17: FERIADO | S17: PONTO FACULTATIVO | U17: DIGITALIZANDO LIVROS DA LBA | V17: DIGITALIZANDO LIVROS DA LBA | W17: DIGITALIZANDO LIVROS DA LBA | AA17: PROCURANDO CAIXAS PARA ELIMINAÇÃO | AD17: PROCURANDO CAIXAS DA CGEOF/SESAN | AG17: PROCURANDO CAIXAS PARA ELIMINAÇÃO PRA SEU CARLOS | AK17: confatrenização da festa junina | AM17: Separando caixas para eliminação | AS17: Falta comunicada a chefia | AT17: Separando caixas para eliminação | AV17: PROCURANDO CAIXAS PARA ELIMINAÇÃO | AW17: PROCURANDO CAIXAS DE VHS | AZ17: Olhando tds a salas na parte da tarde com a CPMT
A18: OBSERVAÇÃO | J18: Fazendo palletes | Q18: ALMOÇO PELA PARTE DA TARDE | U18: MUDANÇA NO PERÍODO DA MANHA PARA 2° ANDAR | W18: 78 FITAS DE MICRO FILMES NUMERADAS | X18: 144 FITAS DE MICRO FILMES NUMERADAS | Y18: 78 FITAS DE MICRO FILMES NUMERADAS | AA18: 72 FITAS DE MICRO FILMES NUMERADAS | AB18: 96 FITAS DE MICRO FILMES NUMERADAS | AC18: 97 FITAS DE MICRO FILMES NUMERADAS | AD18: 2 PROCESSOS COM 34 VOLUMES | AE18: 96 FITAS DE MICRO FILMES NUMERADAS | AG18: RECEBIMENTO DE 70 CAIXAS DA CGPC E MANDANDO MAIS 70 CAIXAS PARA CGPC | AH18: 72 FITAS DE MICRO FILMES NUMERADAS | AJ18: passando a planilha escrita dos micros-filmes para planilha digital | AK18: passando a planilha escrita dos micros-filmes para planilha digital | AN18: passando a planilha escrita dos micros-filmes para planilha digital | AO18: passando a planilha escrita dos micros-filmes para planilha digital | AP18: passando a planilha escrita dos micros-filmes para planilha digital | AQ18: passando a planilha escrita dos micros-filmes para planilha digital | AT18: passando a planilha escrita dos micros-filmes para planilha digital | AU18: passando a planilha escrita dos micros-filmes para planilha digital | AW18: PLANILHANDO FITAS VHS | AY18: passando a planilha escrita dos micros-filmes para planilha digital | AZ18: passando a planilha escrita dos micros-filmes para planilha digital | BA18: PROCURANDO CAIXAS PARA ELIMINAÇÃO | BB18: PROCURANDO CAIXAS PARA ELIMINAÇÃO NO TOTAL OLHEI 3000 MIL CAIXAS

Sheet Aelton
A1: INDICADORES | C1: 45810 | D1: 45811 | E1: 45812 | F1: 45813 | G1: 45814 | H1: TOTAL SEMANA | I1: 45817 | J1: 45818 | K1: 45819 | L1: 45820 | M1: 45821 | N1: TOTAL SEMANA | O1: 45824 | P1: 45825 | Q1: 45826 | R1: 45827 | S1: 45828 | T1: TOTAL SEMANA | U1: 45831 | V1: 45832 | W1: 45833 | X1: 45834 | Y1: 45835 | Z1: TOTAL SEMANA | AA1: 45838 | AB1: 45839 | AC1: 45840 | AD1: 45841 | AE1: 45842 | AF1: TOTAL SEMANA | AG1: 45845 | AH1: 45846 | AI1: 45847 | AJ1: 45848 | AK1: 11/07/2025 Atestado Médico | AL1: TOTAL SEMANA | AM1: 45852 | AN1: 45853 | AO1: 45854 | AP1: 45855 | AQ1: 45856 | AR1: TOTAL SEMANA | AS1: 45859 | AT1: 45860 | AU1: 45861 | AV1: 45862 | AW1: 45863 | AX1: TOTAL SEMANA | AY1: 45866 | AZ1: 45867 | BA1: 45868 | BB1: 45869 | BC1: 45870 | BD1: TOTAL SEMANA | BE1: 45873 | BF1: 45874 | BG1: 45875 | BH1: 45876 | BI1: 45877 | BJ1: TOTAL SEMANA | BK1: 45880 | BL1: 45881 | BM1: 45882 | BN1: 45883 | BO1: 45884 | BP1: TOTAL SEMANA
A2: Desarquivamento de Processos/Documentos - Saída de Guia Fora | B2: 1 | G2: 6 | H2: =SUM(C2:G2) -> 6 | N2: =SUM(I2:M2) -> 0 | R2: FERIADO | S2: PONTO FACULTATIVO | T2: =SUM(O2:S2) -> 0 | Z2: =SUM(U2:Y2) -> 0 | AD2: 2 | AF2: =SUM(AA2:AE2) -> 2 | AG2: 1 | AH2: 1 | AL2: =SUM(AG2:AK2) -> 2 | AR2: =SUM(AM2:AQ2) -> 0 | AX2: =SUM(AS2:AW2) -> 0 | BD2: =SUM(AY2:BC2) -> 0 | BJ2: =SUM(BE2:BI2) -> 0 | BP2: =SUM(BK2:BO2) -> 0
A3: Caixas consultadas em pesquisa de desarquivamento | B3: 2 | H3: =SUM(C3:G3) -> 0 | N3: =SUM(I3:M3) -> 0 | T3: =SUM(O3:S3) -> 0 | Z3: =SUM(U3:Y3) -> 0 | AF3: =SUM(AA3:AE3) -> 0 | AL3: =SUM(AG3:AK3) -> 0 | AR3: =SUM(AM3:AQ3) -> 0 | AX3: =SUM(AS3:AW3) -> 0 | BD3: =SUM(AY3:BC3) -> 0 | BJ3: =SUM(BE3:BI3) -> 0 | BP3: =SUM(BK3:BO3) -> 0
A4: Retorno de Processos/Documentos Desarquivados | B4: 3 | H4: =SUM(C4:G4) -> 0 | K4: 41 | N4: =SUM(I4:M4) -> 41 | Q4: 6 | T4: =SUM(O4:S4) -> 6 | Z4: =SUM(U4:Y4) -> 0 | AF4: =SUM(AA4:AE4) -> 0 | AG4: 1 | AH4: 1 | AL4: =SUM(AG4:AK4) -> 2 | AR4: =SUM(AM4:AQ4) -> 0 | AX4: =SUM(AS4:AW4) -> 0 | BD4: =SUM(AY4:BC4) -> 0 | BJ4: =SUM(BE4:BI4) -> 0 | BP4: =SUM(BK4:BO4) -> 0
A5: Recebimento de Documentos - Guia de Transferência | B5: 4 | H5: =SUM(C5:G5) -> 0 | N5: =SUM(I5:M5) -> 0 | T5: =SUM(O5:S5) -> 0 | Z5: =SUM(U5:Y5) -> 0 | AF5: =SUM(AA5:AE5) -> 0 | AL5: =SUM(AG5:AK5) -> 0 | AR5: =SUM(AM5:AQ5) -> 0 | AX5: =SUM(AS5:AW5) -> 0 | BD5: =SUM(AY5:BC5) -> 0 | BJ5: =SUM(BE5:BI5) -> 0 | BP5: =SUM(BK5:BO5) -> 0
A6: Caixas separadas para classificação | B6: 5 | H6: =SUM(C6:G6) -> 0 | N6: =SUM(I6:M6) -> 0 | T6: =SUM(O6:S6) -> 0 | Z6: =SUM(U6:Y6) -> 0 | AF6: =SUM(AA6:AE6) -> 0 | AL6: =SUM(AG6:AK6) -> 0 | AR6: =SUM(AM6:AQ6) -> 0 | AX6: =SUM(AS6:AW6) -> 0 | BD6: =SUM(AY6:BC6) -> 0 | BJ6: =SUM(BE6:BI6) -> 0 | BP6: =SUM(BK6:BO6) -> 0
A7: Processos/Documentos classificados | B7: 6 | H7: =SUM(C7:G7) -> 0 | N7: =SUM(I7:M7) -> 0 | T7: =SUM(O7:S7) -> 0 | Z7: =SUM(U7:Y7) -> 0 | AF7: =SUM(AA7:AE7) -> 0 | AL7: =SUM(AG7:AK7) -> 0 | AR7: =SUM(AM7:AQ7) -> 0 | AX7: =SUM(AS7:AW7) -> 0 | BD7: =SUM(AY7:BC7) -> 0 | BJ7: =SUM(BE7:BI7) -> 0 | BP7: =SUM(BK7:BO7) -> 0
A8: Caixas separadas para eliminação | B8: 7 | H8: =SUM(C8:G8) -> 0 | N8: =SUM(I8:M8) -> 0 | T8: =SUM(O8:S8) -> 0 | Z8: =SUM(U8:Y8) -> 0 | AF8: =SUM(AA8:AE8) -> 0 | AL8: =SUM(AG8:AK8) -> 0 | AR8: =SUM(AM8:AQ8) -> 0 | AX8: =SUM(AS8:AW8) -> 0 | BD8: =SUM(AY8:BC8) -> 0 | BJ8: =SUM(BE8:BI8) -> 0 | BP8: =SUM(BK8:BO8) -> 0
A9: Caixas listadas para eliminação | B9: 8 | H9: =SUM(C9:G9) -> 0 | N9: =SUM(I9:M9) -> 0 | T9: =SUM(O9:S9) -> 0 | Z9: =SUM(U9:Y9) -> 0 | AF9: =SUM(AA9:AE9) -> 0 | AL9: =SUM(AG9:AK9) -> 0 | AR9: =SUM(AM9:AQ9) -> 0 | AX9: =SUM(AS9:AW9) -> 0 | BD9: =SUM(AY9:BC9) -> 0 | BJ9: =SUM(BE9:BI9) -> 0 | BP9: =SUM(BK9:BO9) -> 0
A10: Processos/Documentos listados para eliminação | B10: 9 | H10: =SUM(C10:G10) -> 0 | N10: =SUM(I10:M10) -> 0 | T10: =SUM(O10:S10) -> 0 | Z10: =SUM(U10:Y10) -> 0 | AF10: =SUM(AA10:AE10) -> 0 | AL10: =SUM(AG10:AK10) -> 0 | AR10: =SUM(AM10:AQ10) -> 0 | AX10: =SUM(AS10:AW10) -> 0 | BD10: =SUM(AY10:BC10) -> 0 | BJ10: =SUM(BE10:BI10) -> 0 | BP10: =SUM(BK10:BO10) -> 0
A11: Caixas inventariadas | B11: 10 | H11: =SUM(C11:G11) -> 0 | N11: =SUM(I11:M11) -> 0 | T11: =SUM(O11:S11) -> 0 | Z11: =SUM(U11:Y11) -> 0 | AA11: 4 | AB11: 3 | AD11: 1 | AE11: 1 | AF11: =SUM(AA11:AE11) -> 9 | AG11: 1 | AL11: =SUM(AG11:AK11) -> 1 | AM11: 2 | AN11: 2 | AO11: 2 | AP11: 2 | AQ11: 2 | AR11: =SUM(AM11:AQ11) -> 10 | AS11: 7 | AX11: =SUM(AS11:AW11) -> 7 | AZ11: 3 | BD11: =SUM(AY11:BC11) -> 3 | BJ11: =SUM(BE11:BI11) -> 0 | BN11: 1 | BO11: 2 | BP11: =SUM(BK11:BO11) -> 3
A12: Processos/documentos inventariados | B12: 11 | H12: =SUM(C12:G12) -> 0 | N12: =SUM(I12:M12) -> 0 | T12: =SUM(O12:S12) -> 0 | Y12: 67 | Z12: =SUM(U12:Y12) -> 67 | AA12: 138 | AB12: 102 | AD12: 35 | AE12: 30 | AF12: =SUM(AA12:AE12) -> 305 | AG12: 30 | AL12: =SUM(AG12:AK12) -> 30 | AM12: 70 | AN12: 68 | AO12: 66 | AP12: 63 | AQ12: 70 | AR12: =SUM(AM12:AQ12) -> 337 | AS12: 36 | AX12: =SUM(AS12:AW12) -> 36 | AZ12: 21 | BD12: =SUM(AY12:BC12) -> 21 | BJ12: =SUM(BE12:BI12) -> 0 | BP12: =SUM(BK12:BO12) -> 0
A13: Documentos administrativos produzidos (Despacho, Nota Técnica, minutas diversas) | B13: 12 | G13: 1 | H13: =SUM(C13:G13) -> 1 | N13: =SUM(I13:M13) -> 0 | T13: =SUM(O13:S13) -> 0 | Z13: =SUM(U13:Y13) -> 0 | AF13: =SUM(AA13:AE13) -> 0 | AH13: 1 | AL13: =SUM(AG13:AK13) -> 1 | AR13: =SUM(AM13:AQ13) -> 0 | AX13: =SUM(AS13:AW13) -> 0 | BD13: =SUM(AY13:BC13) -> 0 | BJ13: =SUM(BE13:BI13) -> 0 | BP13: =SUM(BK13:BO13) -> 0
A14: Orientação técnica / atendimentos realizados | B14: 13 | H14: =SUM(C14:G14) -> 0 | N14: =SUM(I14:M14) -> 0 | T14: =SUM(O14:S14) -> 0 | Z14: =SUM(U14:Y14) -> 0 | AF14: =SUM(AA14:AE14) -> 0 | AL14: =SUM(AG14:AK14) -> 0 | AR14: =SUM(AM14:AQ14) -> 0 | AX14: =SUM(AS14:AW14) -> 0 | BD14: =SUM(AY14:BC14) -> 0 | BJ14: =SUM(BE14:BI14) -> 0 | BL14: 1 | BP14: =SUM(BK14:BO14) -> 1
A15: Recebimento/Caixas remanejadas | B15: 14 | G15: 14 | H15: =SUM(C15:G15) -> 14 | M15: 12 | N15: =SUM(I15:M15) -> 12 | T15: =SUM(O15:S15) -> 0 | X15: 5 | Z15: =SUM(U15:X15) -> 5 | AF15: =SUM(AA15:AE15) -> 0 | AG15: 70 | AL15: =SUM(AG15:AK15) -> 70 | AR15: =SUM(AM15:AQ15) -> 0 | AV15: 6 | AX15: =SUM(AS15:AW15) -> 6 | BD15: =SUM(AY15:BC15) -> 0 | BJ15: =SUM(BE15:BI15) -> 0 | BP15: =SUM(BK15:BO15) -> 0
A16: Caixas conferidas | B16: 15 | F16: 7 | H16: =SUM(C16:G16) -> 7 | I16: 13 | N16: =SUM(I16:M16) -> 13 | T16: =SUM(O16:S16) -> 0 | X16: 9 | Z16: =SUM(U16:X16) -> 9 | AF16: =SUM(AA16:AE16) -> 0 | AI16: 30 | AJ16: 30 | AL16: =SUM(AG16:AK16) -> 60 | AR16: =SUM(AM16:AQ16) -> 0 | AW16: 7 | AX16: =SUM(AS16:AW16) -> 7 | AY16: 4 | BD16: =SUM(AY16:BC16) -> 4 | BJ16: =SUM(BE16:BI16) -> 0 | BP16: =SUM(BK16:BO16) -> 0
A17: OUTRA ATIVIDADE. QUAL? | C17: 1. Listando filmes da LBA -DNIT, Sl. 4.47. 2. Procura da localização das caixas LBA para o pesquisador Prof. Dr. Bruno Sanches. Solicitação e-mail de 24/04/2025. | D17: Listando filmes da LBA -DNIT, Sl. 4.47 | E17: 1. Listando filmes da LBA -DNIT, Sl. 4.47. 2. Procura da localização das caixas LBA para o pesquisador Prof. Dr. Bruno Sanches. Solicitação e-mail de 24/04/2025. | F17: 1. Procura da localização das caixas LBA para o pesquisador Prof. Dr. Bruno Sanches. Solicitação e-mail de 24/04/2025. 2. Pesquisa e busca dos processos 23132.000386/1996-21 23132.000139/1995-51 | G17: 1. Atualização da planilha das caixas LBA para o pesquisador Prof. Dr. Bruno Sanches. 2. Caixas remanejadas para a sala 3.11, para o pesquisador prof. Dr. Bruno Sanches analisar. | I17: Separação das 13 caixas da LBA, conferindo o conteúdo de cada caixa, no Bloco A - Sala G-15, para o pesquisador Prof. Dr. Bruno Sanches. Solicitação e-mail de 24/04/2025. | J17: Acompanhando, no Bloco A - Sala G-15, o pesquisador Prof. Dr. Bruno Sanches em sua pesquisa. | K17: 1. Movimentação de 31 documentos de que estavam na sala 4.47 fora da caixa correspondente. 2. Movimentação de 10 processos que estavam na sala 4.47 fora da caixa correspondente. | L17: Pesquisando e reunindo o material da LBA, para digitalização, buscando localização, solicitado pela professora Gracyelle - Email de 12/02/2025. | M17: 1. Acompanhando, no DNIT - Sala 1S 3.11, o pesquisador Prof. Dr. Bruno Sanches em sua pesquisa. 2. Pesquisa para o prof. Bruno Saches sobre uma creche "A Casa da Criança" de Londrina Paraná. Encontrado no Relatório Paraná 1955. 3. Digitalização material da LBA, solicitado pela professora Gracyelle - Email de 12/02/2025. | O17: Digitalização material da LBA, solicitado pela professora Gracyelle - Email de 12/02/2025. | P17: Digitalização material da LBA, solicitado pela professora Gracyelle - Email de 12/02/2025. | Q17: 1. Digitalização material da LBA, solicitado pela professora Gracyelle - Email de 12/02/2025. 2. À tarde fui levar minha filha ao dentista. | U17: 1. Pela manhã - Nossa mudança do subsolo sala 1S 3.11 para o 2º andar sala 24.32. 2. Digitalização material da LBA, solicitado pela professora Gracyelle - Email de 12/02/2025. | V17: Digitalização material da LBA, solicitado pela professora Gracyelle - Email de 12/02/2025. | W17: Digitalização material da LBA, solicitado pela professora Gracyelle - Email de 12/02/2025. | X17: 1. Digitalização material da LBA, solicitado pela professora Gracyelle - Email de 12/02/2025. 2. Ajuda na pesquisa do documento averbação da servidora MARILUZA PORTELA RIOS VIEIRA. | Y17: 1. Ajuda na pesquisa do documento averbação da servidora MARILUZA PORTELA RIOS VIEIRA. Encontrado apenas no SEI (0500971). 2. Inventário microfilmes: 2 Caixas 67 microfilmes. | AA17: Inventário microfilmes: 4 Caixas 138 microfilmes. | AB17: 1. Inventário microfilmes. 3 Caixas 102 microfilmes 2. Ajuda na pesquisa do documento averbação da servidora MARILUZA PORTELA RIOS VIEIRA. | AC17: Ajuda na pesquisa do documento averbação da servidora MARILUZA PORTELA RIOS VIEIRA. | AD17: 1. Pesquisa do documento averbação da servidora MARILUZA PORTELA RIOS VIEIRA. 2. Pesquisa e busca processos: 00070.002379/2003-10 00070.007055/2003-78 3. Inventário microfilmes. 1 Caixa 35 microfilmes | AE17: 1. Pesquisa do documento averbação da servidora MARILUZA PORTELA RIOS VIEIRA. 2. Inventário microfilmes. 1 Caixa 30 microfilmes. | AG17: 1. Inventário microfilmes. 1 Caixa 30 microfilmes. 2. Envio de 70 caixas para DAP/CGPC. 3. Recebimento de 70 caixas para DAP/CGPC. | AH17: 1. Ida ao Bloco A com os chefes, Patrícia e Marcelo, para ver localização dos microfilmes para inventáriá-los. 2. Ida ao Bloco A para localização e análise das prováveis caixas onde possa estar o processo do FUNDESPORTE. | AI17: Conferência das caixas da CGPC/DEFNAS. | AJ17: Conferência das caixas da CGPC/DEFNAS. | AM17: Inventário microfilmes. 2 Caixas 70 microfilmes | AN17: Inventário microfilmes. 2 Caixas 68 microfilmes | AO17: Inventário microfilmes. 2 Caixas 66 microfilmes | AP17: Inventário microfilmes. 2 Caixas 63 microfilmes | AQ17: Inventário microfilmes. 2 Caixas 70 microfilmes | AS17: Inventário microfilmes. 7 Caixas 34 VHS e 2 DVD | AT17: Preenchimento Planilha Inventário audiovisuais LBA. | AU17: Preenchimento Planilha Inventário audiovisuais LBA. | AV17: 1. Preenchimento Planilha Inventário audiovisuais LBA. 2. Guarda e remanejamento das caixas LBA que o professor Bruno pesquisou. Total 13 caixas. | AW17: Pesquisa e busca por processo referente ao 214/95 (SIAFI nº 138116) FUNDESPORTE. 23132.000438/95-22. Total: 13 caixas. | AY17: 1. Busca e conferência de caixas de microfilmes LBA. Total: 4 caixas, sendo 1 de fita k-7. 2. Aguardando o pessoal para retirar as 6 baias da sala 3.11. | AZ17: 1. Aguardando o pessoal para retirar as 6 baias da sala 3.11. 2. Reunião às 10h da manhã com a chefe Patrícia. 3. Inventário fitas k-7 LBA. Total: 21 | BA17: Levantamento de espaços de caixa nos Arquivos - DNIT. | BB17: Levantamento de espaços de caixa nos Arquivos - DNIT. Total de espaços: 1604. | BC17: Alimentação planilha Espaços em Aberto de caixa nos Arquivos - DNIT. | BE17: 1. Procura de caixas para eliminação. 2. Acompanhamento da conferência dos parimônios no Bloco A, sala G-15 | BF17: Procura de caixas para eliminação. | BG17: 1. Procura de caixas para eliminação. 2. Acompanhamento da conferência dos parimônios no Bloco A, sala G-15 | BH17: Palestra no Arquivo Nacional Fomos liberados do Ponto Eletrônico. | BI17: Pesquisa e busca pelo processo 71000.004542/2005-12 (SESAN) | BK17: Pesquisa e busca pelo processo 71000.004542/2005-12 (SESAN) Não encontrado registro de entrada neste arquivo. | BL17: 1. E-mail de orientação de desarquivamento para o Wederson da CGPC. 2. Pesquisa e busca pelo processo 44000.006180/1997-51 | BM17: 1. Pesquisa e busca pelo processo 44000.006180/1997-51. 2. Pesquisa e busca pela pasta funcional - DYLENY TEIXEIRA ALVES DA SILVA | BN17: 1. Pesquisa e busca pelo processo 44000.006180/1997-51. 2. Inventário de fotos LBA. | BO17: Inventário de Fotos LBA.
A18: OBSERVAÇÃO

Sheet Leonam
A1: INDICADORES | C1: 45810 | D1: 45811 | E1: 45812 | F1: 45813 | G1: 45814 | H1: TOTAL SEMANA | I1: 45817 | J1: 45818 | K1: 45819 | L1: 45820 | M1: 45821 | N1: TOTAL SEMANA | O1: 45824 | P1: 45825 | Q1: 45826 | R1: 45827 | S1: 45828 | T1: TOTAL SEMANA | U1: 45831 | V1: 45832 | W1: 45833 | X1: 45834 | Y1: 45835 | Z1: TOTAL SEMANA | AA1: 45838 | AB1: 45839 | AC1: 45840 | AD1: 45841 | AE1: 45842 | AF1: TOTAL SEMANA | AG1: 45845 | AH1: 45846 | AI1: 45847 | AJ1: 45848 | AK1: 45849 | AL1: TOTAL SEMANA | AM1: 45852 | AN1: 45853 | AO1: 45854 | AP1: 45855 | AQ1: 45856 | AR1: TOTAL SEMANA | AS1: 45859 | AT1: 45860 | AU1: 45861 | AV1: 45862 | AW1: 45863 | AX1: TOTAL SEMANA | AY1: 45866 | AZ1: 45867 | BA1: 45868 | BB1: 45869 | BC1: 45870 | BD1: TOTAL SEMANA
A2: Desarquivamento de Processos/Documentos - Saída de Guia Fora | B2: 1 | H2: =SUM(C2:G2) -> 0 | M2: 3 | N2: =SUM(I2:M2) -> 3 | T2: =SUM(O2:S2) -> 0 | Z2: =SUM(U2:Y2) -> 0 | AD2: 2 | AF2: =SUM(AA2:AE2) -> 2 | AG2: 1 | AL2: =SUM(AG2:AK2) -> 1 | AR2: =SUM(AM2:AQ2) -> 0 | AX2: =SUM(AS2:AW2) -> 0 | BD2: =SUM(AY2:BC2) -> 0
A3: Caixas consultadas em pesquisa de desarquivamento | B3: 2 | F3: 2 | H3: =SUM(C3:G3) -> 2 | J3: 1 | N3: =SUM(I3:M3) -> 1 | T3: =SUM(O3:S3) -> 0 | Z3: =SUM(U3:Y3) -> 0 | AD3: 30 | AF3: =SUM(AA3:AE3) -> 30 | AL3: =SUM(AG3:AK3) -> 0 | AR3: =SUM(AM3:AQ3) -> 0 | AX3: =SUM(AS3:AW3) -> 0 | BD3: =SUM(AY3:BC3) -> 0
A4: Retorno de Processos/Documentos Desarquivados | B4: 3 | H4: =SUM(C4:G4) -> 0 | N4: =SUM(I4:M4) -> 0 | T4: =SUM(O4:S4) -> 0 | Z4: =SUM(U4:Y4) -> 0 | AA4: 4 | AF4: =SUM(AA4:AE4) -> 4 | AG4: 1 | AL4: =SUM(AG4:AK4) -> 1 | AR4: =SUM(AM4:AQ4) -> 0 | AX4: =SUM(AS4:AW4) -> 0 | BD4: =SUM(AY4:BC4) -> 0
A5: Recebimento de Documentos - Guia de Transferência | B5: 4 | H5: =SUM(C5:G5) -> 0 | N5: =SUM(I5:M5) -> 0 | T5: =SUM(O5:S5) -> 0 | Z5: =SUM(U5:Y5) -> 0 | AF5: =SUM(AA5:AE5) -> 0 | AL5: =SUM(AG5:AK5) -> 0 | AM5: 1 | AR5: =SUM(AM5:AQ5) -> 1 | AX5: =SUM(AS5:AW5) -> 0 | BD5: =SUM(AY5:BC5) -> 0
A6: Caixas separadas para classificação | B6: 5 | H6: =SUM(C6:G6) -> 0 | N6: =SUM(I6:M6) -> 0 | T6: =SUM(O6:S6) -> 0 | Z6: =SUM(U6:Y6) -> 0 | AF6: =SUM(AA6:AE6) -> 0 | AL6: =SUM(AG6:AK6) -> 0 | AR6: =SUM(AM6:AQ6) -> 0 | AX6: =SUM(AS6:AW6) -> 0 | BD6: =SUM(AY6:BC6) -> 0
A7: Processos/Documentos classificados | B7: 6 | H7: =SUM(C7:G7) -> 0 | N7: =SUM(I7:M7) -> 0 | T7: =SUM(O7:S7) -> 0 | Z7: =SUM(U7:Y7) -> 0 | AF7: =SUM(AA7:AE7) -> 0 | AL7: =SUM(AG7:AK7) -> 0 | AR7: =SUM(AM7:AQ7) -> 0 | AX7: =SUM(AS7:AW7) -> 0 | BD7: =SUM(AY7:BC7) -> 0
A8: Caixas separadas para eliminação | B8: 7 | D8: 9 | E8: 38 | H8: =SUM(C8:G8) -> 47 | K8: 18 | N8: =SUM(I8:M8) -> 18 | T8: =SUM(O8:S8) -> 0 | Z8: =SUM(U8:Y8) -> 0 | AF8: =SUM(AA8:AE8) -> 0 | AL8: =SUM(AG8:AK8) -> 0 | AR8: =SUM(AM8:AQ8) -> 0 | AX8: =SUM(AS8:AW8) -> 0 | BD8: =SUM(AY8:BC8) -> 0
A9: Caixas listadas para eliminação | B9: 8 | D9: 9 | E9: 38 | H9: =SUM(C9:G9) -> 47 | K9: 19 | N9: =SUM(I9:M9) -> 19 | T9: =SUM(O9:S9) -> 0 | Z9: =SUM(U9:Y9) -> 0 | AF9: =SUM(AA9:AE9) -> 0 | AL9: =SUM(AG9:AK9) -> 0 | AR9: =SUM(AM9:AQ9) -> 0 | AX9: =SUM(AS9:AW9) -> 0 | BD9: =SUM(AY9:BC9) -> 0
A10: Processos/Documentos listados para eliminação | B10: 9 | H10: =SUM(C10:G10) -> 0 | N10: =SUM(I10:M10) -> 0 | T10: =SUM(O10:S10) -> 0 | Z10: =SUM(U10:Y10) -> 0 | AF10: =SUM(AA10:AE10) -> 0 | AL10: =SUM(AG10:AK10) -> 0 | AR10: =SUM(AM10:AQ10) -> 0 | AX10: =SUM(AS10:AW10) -> 0 | BD10: =SUM(AY10:BC10) -> 0
A11: Caixas inventariadas | B11: 10 | H11: =SUM(C11:G11) -> 0 | N11: =SUM(I11:M11) -> 0 | T11: =SUM(O11:S11) -> 0 | X11: 4 | Y11: 4 | Z11: =SUM(U11:Y11) -> 8 | AA11: 3 | AB11: 2 | AC11: 2 | AD11: 1 | AF11: =SUM(AA11:AE11) -> 8 | AG11: 1 | AL11: =SUM(AG11:AK11) -> 1 | AR11: =SUM(AM11:AQ11) -> 0 | AX11: =SUM(AS11:AW11) -> 0 | BD11: =SUM(AY11:BC11) -> 0
A12: Processos/documentos inventariados | B12: 11 | H12: =SUM(C12:G12) -> 0 | N12: =SUM(I12:M12) -> 0 | T12: =SUM(O12:S12) -> 0 | X12: 136 | Y12: 136 | Z12: =SUM(U12:Y12) -> 272 | AA12: 90 | AB12: 63 | AC12: 55 | AD12: 30 | AF12: =SUM(AA12:AE12) -> 238 | AG12: 30 | AL12: =SUM(AG12:AK12) -> 30 | AR12: =SUM(AM12:AQ12) -> 0 | AS12: 39 | AT12: 32 | AU12: 30 | AV12: 26 | AX12: =SUM(AS12:AW12) -> 127 | AY12: 81 | AZ12: 31 | BB12: 35 | BC12: 35 | BD12: =SUM(AY12:BC12) -> 182
A13: Documentos administrativos produzidos (Despacho, Nota Técnica, minutas diversas) | B13: 12 | H13: =SUM(C13:G13) -> 0 | J13: 1 | M13: 1 | N13: =SUM(I13:M13) -> 2 | T13: =SUM(O13:S13) -> 0 | Z13: =SUM(U13:Y13) -> 0 | AA13: 1 | AD13: 1 | AF13: =SUM(AA13:AE13) -> 2 | AL13: =SUM(AG13:AK13) -> 0 | AR13: =SUM(AM13:AQ13) -> 0 | AX13: =SUM(AS13:AW13) -> 0 | BD13: =SUM(AY13:BC13) -> 0
A14: Orientação técnica / atendimentos realizados | B14: 13 | H14: =SUM(C14:G14) -> 0 | N14: =SUM(I14:M14) -> 0 | T14: =SUM(O14:S14) -> 0 | Z14: =SUM(U14:Y14) -> 0 | AF14: =SUM(AA14:AE14) -> 0 | AL14: =SUM(AG14:AK14) -> 0 | AR14: =SUM(AM14:AQ14) -> 0 | AX14: =SUM(AS14:AW14) -> 0 | BD14: =SUM(AY14:BC14) -> 0
A15: Caixas remanejadas | B15: 14 | F15: 55 | H15: =SUM(C15:G15) -> 55 | J15: 140 | L15: 30 | M15: 27 | N15: =SUM(I15:M15) -> 197 | T15: =SUM(O15:S15) -> 0 | Z15: =SUM(U15:Y15) -> 0 | AF15: =SUM(AA15:AE15) -> 0 | AI15: 51 | AL15: =SUM(AG15:AK15) -> 51 | AR15: =SUM(AM15:AQ15) -> 0 | AS15: 40 | AT15: 20 | AV15: 11 | AX15: =SUM(AS15:AW15) -> 71 | BD15: =SUM(AY15:BC15) -> 0
A16: Caixas conferidas | B16: 15 | E16: 164 | F16: 2286 | G16: 15687 | H16: =SUM(C16:G16) -> 18137 | I16: 3724 | N16: =SUM(I16:M16) -> 3724 | T16: =SUM(O16:S16) -> 0 | Z16: =SUM(U16:Y16) -> 0 | AF16: =SUM(AA16:AE16) -> 0 | AL16: =SUM(AG16:AK16) -> 0 | AM16: 10 | AR16: =SUM(AM16:AQ16) -> 10 | AX16: =SUM(AS16:AW16) -> 0 | BD16: =SUM(AY16:BC16) -> 0
A17: OUTRA ATIVIDADE. QUAL? | G17: acompanhano a instalação do ponto de rede e tomada na 4.47 | I17: PROCURANDO CAIXAS PARA ELIMINAÇÃO | J17: PROCURANDO CAIXAS PARA ELIMINAÇÃO | O17: FAZENDO PALETES 80 CAIXAS PRA CADA | Q17: DIGITALIZANDO LIVROS DA LBA | U17: Pela manhã - Nossa mudança do subsolo sala 1S 3.11 para o 2º andar sala 24.32. | V17: DIGITALIZANDO LIVROS DA LBA | W17: DIGITALIZANDO LIVROS DA LBA | Y17: fazendo etiquetas para os micros-filmes | AA17: fazendo etiquetas para os micros-filmes | AB17: fazendo etiquetas para os micros-filmes | AC17: fazendo etiquetas para os micros-filmes | AD17: PROCURANDO CAIXAS DA CGEOF/SESAN | AG17: 1. Inventário microfilmes. 1 Caixa 30 microfilmes. 2. Envio de 70 caixas para DAP/CGPC. 3. Recebimento de 70 caixas para DAP/CGPC. | AH17: 1. Ida ao Bloco A com os chefes, Patrícia e Marcelo, para ver localização dos microfilmes para inventáriá-los. 2. Ida ao Bloco A para localização e análise das prováveis caixas onde possa estar o processo do FUNDESPORTE. | AI17: passando a planilha escrita dos micros-filmes para planilha digital | AJ17: passando a planilha escrita dos micros-filmes para planilha digital | AK17: confatrenização da festa junina | AM17: 01-fazendo etiquetas para os micros-filmes 02- passando a planilha escrita dos micros-filmes para planilha digital | AN17: passando a planilha escrita dos micros-filmes para planilha digital | AO17: atestado | AP17: atestado | AQ17: atestado | AS17: 01-procurando caixas para eliminação para seu Carlos 02- passando a planilha escrita dos micros-filmes para planilha digital | AT17: 01-procurando caixas para eliminação para seu Carlos 02- passando a planilha escrita dos micros-filmes para planilha digital | AU17: passando a planilha escrita dos micros-filmes para planilha digital | AV17: passando a planilha escrita dos micros-filmes para planilha digital | AW17: procurando caixas de eliminação p/ o Carlos | AY17: passando a planilha escrita dos micros-filmes para planilha digital | AZ17: passando a planilha escrita dos micros-filmes para planilha digital | BA17: passando a planilha escrita dos micros-filmes para planilha digital | BB17: passando a planilha escrita dos micros-filmes para planilha digital | BC17: passando a planilha escrita dos micros-filmes para planilha digital
A18: OBSERVAÇÃO | C18: PROCURANDO CAIXAS PARA ELIMINAÇÃO | D18: lanche na sala nova a CDA | F18: PROCURANDO CAIXAS PARA ELIMINAÇÃO | G18: PROCURANDO CAIXAS PARA ELIMINAÇÃO | J18: Fazendo palletes | Q18: ALMOÇO PELA PARTE DA TARDE | AD18: 2 PROCESSOS COM 34 VOLUMES | AG18: fazendo curso | AH18: fazendo curso | AI18: fazendo curso | AJ18: fazendo curso / café da manhã CGLA | AK18: fazendo curso | AM18: fazendo curso | AN18: fazendo curso | AS18: fazendo curso | AT18: fazendo curso | AU18: fazendo curso | AV18: fazendo curso | AW18: fazendo curso | AZ18: procurando caixas de eliminação p/ o Carlos | BA18: procurando caixas de eliminação p/ o Carlos | BB18: procurando caixas de eliminação p/ o Carlos

Sheet Danilo
A1: INDICADORES | C1: 45810 | D1: 45811 | E1: 45812 | F1: 45813 | G1: 45814 | H1: TOTAL SEMANA | I1: 45817 | J1: 45818 | K1: 45819 | L1: 45820 | M1: 45821 | N1: TOTAL SEMANA | O1: 45824 | P1: 45825 | Q1: 45826 | R1: 45827 | S1: 45828 | T1: TOTAL SEMANA | U1: 45831 | V1: 45832 | W1: 45833 | X1: 45834 | Y1: 45835 | Z1: TOTAL SEMANA | AA1: 45838 | AB1: 45839 | AC1: 45840 | AD1: 45841 | AE1: 45842 | AF1: TOTAL SEMANA | AG1: 45845 | AH1: 45846 | AI1: 45847 | AJ1: 45848 | AK1: 45849 | AL1: TOTAL SEMANA | AM1: 45852 | AN1: 45853 | AO1: 45854 | AP1: 45855 | AQ1: 45856 | AR1: TOTAL SEMANA | AS1: 45859 | AT1: 45860 | AU1: 45861 | AV1: 45862 | AW1: 45863 | AX1: TOTAL SEMANA | AY1: 45866 | AZ1: 45867 | BA1: 45868 | BB1: 45869 | BC1: 45870 | BD1: TOTAL SEMANA
A2: Desarquivamento de Processos/Documentos - Saída de Guia Fora | B2: 1 | H2: =SUM(C2:G2) -> 0 | N2: =SUM(I2:M2) -> 0 | T2: =SUM(O2:S2) -> 0 | X2: 1 | Z2: =SUM(U2:Y2) -> 1 | AF2: =SUM(AA2:AE2) -> 0 | AL2: =SUM(AG2:AK2) -> 0 | AR2: =SUM(AM2:AQ2) -> 0 | AX2: =SUM(AS2:AW2) -> 0 | BB2: 1 | BD2: =SUM(AY2:BC2) -> 1
A3: Caixas consultadas em pesquisa de desarquivamento | B3: 2 | H3: =SUM(C3:G3) -> 0 | N3: =SUM(I3:M3) -> 0 | T3: =SUM(O3:S3) -> 0 | X3: 4 | Z3: =SUM(U3:Y3) -> 4 | AF3: =SUM(AA3:AE3) -> 0 | AL3: =SUM(AG3:AK3) -> 0 | AR3: =SUM(AM3:AQ3) -> 0 | AX3: =SUM(AS3:AW3) -> 0 | BB3: 3 | BD3: =SUM(AY3:BC3) -> 3
A4: Retorno de Processos/Documentos Desarquivados | B4: 3 | H4: =SUM(C4:G4) -> 0 | N4: =SUM(I4:M4) -> 0 | T4: =SUM(O4:S4) -> 0 | Z4: =SUM(U4:Y4) -> 0 | AF4: =SUM(AA4:AE4) -> 0 | AL4: =SUM(AG4:AK4) -> 0 | AR4: =SUM(AM4:AQ4) -> 0 | AX4: =SUM(AS4:AW4) -> 0 | BD4: =SUM(AY4:BC4) -> 0
A5: Recebimento de Documentos - Guia de Transferência | B5: 4 | H5: =SUM(C5:G5) -> 0 | N5: =SUM(I5:M5) -> 0 | T5: =SUM(O5:S5) -> 0 | Z5: =SUM(U5:Y5) -> 0 | AF5: =SUM(AA5:AE5) -> 0 | AL5: =SUM(AG5:AK5) -> 0 | AR5: =SUM(AM5:AQ5) -> 0 | AX5: =SUM(AS5:AW5) -> 0 | BD5: =SUM(AY5:BC5) -> 0
A6: Caixas separadas para classificação | B6: 5 | H6: =SUM(C6:G6) -> 0 | N6: =SUM(I6:M6) -> 0 | T6: =SUM(O6:S6) -> 0 | Z6: =SUM(U6:Y6) -> 0 | AF6: =SUM(AA6:AE6) -> 0 | AG6: 10 | AL6: =SUM(AG6:AK6) -> 10 | AR6: =SUM(AM6:AQ6) -> 0 | AX6: =SUM(AS6:AW6) -> 0 | BD6: =SUM(AY6:BC6) -> 0
A7: Processos/Documentos classificados | B7: 6 | C7: 33 | D7: 9 | F7: 65 | G7: 49 | H7: =SUM(C7:G7) -> 156 | I7: 12 | K7: 2 | M7: 18 | N7: =SUM(I7:M7) -> 32 | O7: 8 | Q7: 8 | T7: =SUM(O7:S7) -> 16 | U7: 10 | V7: 2 | Z7: =SUM(U7:Y7) -> 12 | AF7: =SUM(AA7:AE7) -> 0 | AL7: =SUM(AG7:AK7) -> 0 | AR7: =SUM(AM7:AQ7) -> 0 | AX7: =SUM(AS7:AW7) -> 0 | BD7: =SUM(AY7:BC7) -> 0
A8: Caixas separadas para eliminação | B8: 7 | H8: =SUM(C8:G8) -> 0 | N8: =SUM(I8:M8) -> 0 | T8: =SUM(O8:S8) -> 0 | Z8: =SUM(U8:Y8) -> 0 | AF8: =SUM(AA8:AE8) -> 0 | AG8: 10 | AL8: =SUM(AG8:AK8) -> 10 | AR8: =SUM(AM8:AQ8) -> 0 | AX8: =SUM(AS8:AW8) -> 0 | BD8: =SUM(AY8:BC8) -> 0
A9: Caixas listadas para eliminação | B9: 8 | H9: =SUM(C9:G9) -> 0 | N9: =SUM(I9:M9) -> 0 | T9: =SUM(O9:S9) -> 0 | Z9: =SUM(U9:Y9) -> 0 | AF9: =SUM(AA9:AE9) -> 0 | AL9: =SUM(AG9:AK9) -> 0 | AR9: =SUM(AM9:AQ9) -> 0 | AX9: =SUM(AS9:AW9) -> 0 | BD9: =SUM(AY9:BC9) -> 0
A10: Processos/Documentos listados para eliminação | B10: 9 | H10: =SUM(C10:G10) -> 0 | N10: =SUM(I10:M10) -> 0 | T10: =SUM(O10:S10) -> 0 | Z10: =SUM(U10:Y10) -> 0 | AF10: =SUM(AA10:AE10) -> 0 | AL10: =SUM(AG10:AK10) -> 0 | AR10: =SUM(AM10:AQ10) -> 0 | AX10: =SUM(AS10:AW10) -> 0 | BD10: =SUM(AY10:BC10) -> 0
A11: Caixas inventariadas | B11: 10 | C11: 3 | D11: 3 | F11: 4 | G11: 3 | H11: =SUM(C11:G11) -> 13 | I11: 4 | J11: 4 | K11: 3 | M11: 4 | N11: =SUM(I11:M11) -> 15 | O11: 2 | P11: 3 | Q11: 2 | T11: =SUM(O11:S11) -> 7 | U11: 2 | V11: 4 | W11: 3 | Y11: 4 | Z11: =SUM(U11:Y11) -> 13 | AA11: 4 | AB11: 3 | AC11: 3 | AE11: 2 | AF11: =SUM(AA11:AE11) -> 12 | AH11: 3 | AL11: =SUM(AG11:AK11) -> 3 | AR11: =SUM(AM11:AQ11) -> 0 | AX11: =SUM(AS11:AW11) -> 0 | BD11: =SUM(AY11:BC11) -> 0
A12: Processos/documentos inventariados | B12: 11 | C12: 51 | D12: 35 | F12: 100 | G12: 63 | H12: =SUM(C12:G12) -> 249 | I12: 100 | J12: 81 | K12: 71 | M12: 63 | N12: =SUM(I12:M12) -> 315 | O12: 78 | P12: 58 | Q12: 46 | T12: =SUM(O12:S12) -> 182 | U12: 54 | V12: 39 | W12: 53 | Y12: 136 | Z12: =SUM(U12:Y12) -> 282 | AA12: 136 | AB12: 108 | AC12: 108 | AE12: 72 | AF12: =SUM(AA12:AE12) -> 424 | AH12: 108 | AL12: =SUM(AG12:AK12) -> 108 | AM12: 40 | AN12: 60 | AO12: 63 | AP12: 54 | AQ12: 63 | AR12: =SUM(AM12:AQ12) -> 280 | AS12: 65 | AT12: 60 | AU12: 50 | AV12: 45 | AW12: 40 | AX12: =SUM(AS12:AW12) -> 260 | AZ12: 21 | BD12: =SUM(AY12:BC12) -> 21
A13: Documentos administrativos produzidos (Despacho, Nota Técnica, minutas diversas) | B13: 12 | H13: =SUM(C13:G13) -> 0 | N13: =SUM(I13:M13) -> 0 | T13: =SUM(O13:S13) -> 0 | X13: 1 | Z13: =SUM(U13:Y13) -> 1 | AF13: =SUM(AA13:AE13) -> 0 | AL13: =SUM(AG13:AK13) -> 0 | AR13: =SUM(AM13:AQ13) -> 0 | AX13: =SUM(AS13:AW13) -> 0 | BB13: 2 | BD13: =SUM(AY13:BC13) -> 2
