Workbook

Sheet GLOSSÁRIO
A1: INDICADORES | B1: FONTE
A2: Desarquivamento de Processos/Documentos - Saída de Guia Fora | B2: SEI (Depachos ou Ofícios assinados na unidade Diarq)
A3: Caixas consultadas em pesquisa de desarquivamento | B3: CONTAGEM INDIVIDUAL (Caixas abertas para verificação de conteúdo em contexto de pesquisa para desarquivamento)
A4: Retorno de Processos/Documentos Desarquivados | B4: SEI (Depachos ou Ofícios assinados na unidade Diarq)
A5: Recebimento de Documentos - Guia de Transferência | B5: SEI (Depachos ou Ofícios assinados na unidade Diarq)
A6: Caixas separadas para classificação | B6: CONTAGEM INDIVIDUAL (Caixas "puxadas" nas estantes como uma pré-seleção para classificação)
A7: Processos/Documentos classificados | B7: PLANILHA
A8: Caixas separadas para eliminação | B8: CONTAGEM INDIVIDUAL (Caixas "puxadas" nas estantes como uma pré-seleção para eliminação)
A9: Caixas listadas para eliminação | B9: PLANILHA
A10: Processos/Documentos listados para eliminação | B10: PLANILHA
A11: Caixas inventariadas | B11: PLANILHA
A12: Processos/documentos inventariados | B12: PLANILHA
... A16: Caixas conferidas | B16: CONTAGEM INDIVIDUAL (Caixas consultadas para simples 'conferência de quantitativo' ou do 'conteúdo do espelho' em atividades diversas)

Sheet Patrícia
A1: INDICADORES | C1: 46083 | D1: 46084 | E1: 46085 | F1: 46086 | G1: 46087 | H1: TOTAL SEMANA | I1: 46090 | J1: 46091 | K1: 46092 | L1: 46093 | M1: 46094 | N1: TOTAL SEMANA | O1: 46097 | P1: 46098 | Q1: 46099 | R1: 46100 | S1: 46101 | T1: TOTAL SEMANA | U1: 46104 | V1: 46105 | W1: 46106 | X1: 46107 | Y1: 46108 | Z1: TOTAL SEMANA | AA1: 46111 | AB1: 46112 | AC1: 46113 | AD1: 46114 | AE1: 46115 | AF1: TOTAL SEMANA | AG1: 46118 | AH1: 46119 | AI1: 46120 | AJ1: 46121 | AK1: 46122 | AL1: TOTAL SEMANA | AM1: 46125 | AN1: 46126 | AO1: 46127 | AP1: 46128 | AQ1: 46129 | AR1: TOTAL SEMANA | AS1: 46132 | AT1: 46133 | AU1: 46134 | AV1: 46135 | AW1: 46136 | AX1: TOTAL SEMANA | AY1: 46139 | AZ1: 46140 | BA1: 46141 | BB1: 46142 | BC1: 46143 | BD1: TOTAL SEMANA
A2: Documentos administrativos produzidos (Despacho, Nota Técnica, minutas diversas) | B2: 1 | H2: =SUM(C2:G2) -> 0 | N2: =SUM(I2:M2) -> 0 | T2: =SUM(O2:S2) -> 0 | Z2: =SUM(U2:Y2) -> 0 | AF2: =SUM(AA2:AE2) -> 0 | AL2: =SUM(AG2:AK2) -> 0 | AR2: =SUM(AM2:AQ2) -> 0 | AX2: =SUM(AS2:AW2) -> 0 | BD2: =SUM(AY2:BC2) -> 0
A3: Orientação técnica / atendimentos realizados | B3: 2 | H3: =SUM(C3:G3) -> 0 | N3: =SUM(I3:M3) -> 0 | T3: =SUM(O3:S3) -> 0 | Z3: =SUM(U3:Y3) -> 0 | AF3: =SUM(AA3:AE3) -> 0 | AL3: =SUM(AG3:AK3) -> 0 | AR3: =SUM(AM3:AQ3) -> 0 | AX3: =SUM(AS3:AW3) -> 0 | BD3: =SUM(AY3:BC3) -> 0
A4: OUTRA ATIVIDADE. QUAL?
A5: OBSERVAÇÃO

Sheet Leonardo
A1: INDICADORES | C1: 46083 | D1: 46084 | E1: 46085 | F1: 46086 | G1: 46087 | H1: TOTAL SEMANA | I1: 46090 | J1: 46091 | K1: 46092 | L1: 46093 | M1: 46094 | N1: TOTAL SEMANA | O1: 46097 | P1: 46098 | Q1: 46099 | R1: 46100 | S1: 46101 | T1: TOTAL SEMANA | U1: 46104 | V1: 46105 | W1: 46106 | X1: 46107 | Y1: 46108 | Z1: TOTAL SEMANA | AA1: 46111 | AB1: 46112 | AC1: 46113 | AD1: 46114 | AE1: 46115 | AF1: TOTAL SEMANA | AG1: 46118 | AH1: 46119 | AI1: 46120 | AJ1: 46121 | AK1: 46122 | AL1: TOTAL SEMANA | AM1: 46125 | AN1: 46126 | AO1: 46127 | AP1: 46128 | AQ1: 46129 | AR1: TOTAL SEMANA | AS1: 46132 | AT1: 46133 | AU1: 46134 | AV1: 46135 | AW1: 46136 | AX1: TOTAL SEMANA | AY1: 46139 | AZ1: 46140 | BA1: 46141 | BB1: 46142 | BC1: 46143 | BD1: TOTAL SEMANA
A2: Documentos administrativos produzidos (Despacho, Nota Técnica, minutas diversas) | B2: 1 | H2: =SUM(C2:G2) -> 0 | N2: =SUM(I2:M2) -> 0 | T2: =SUM(O2:S2) -> 0 | Z2: =SUM(U2:Y2) -> 0 | AF2: =SUM(AA2:AE2) -> 0 | AL2: =SUM(AG2:AK2) -> 0 | AR2: =SUM(AM2:AQ2) -> 0 | AX2: =SUM(AS2:AW2) -> 0 | BD2: =SUM(AY2:BC2) -> 0
A3: Orientação técnica / atendimentos realizados | B3: 2 | H3: =SUM(C3:G3) -> 0 | N3: =SUM(I3:M3) -> 0 | T3: =SUM(O3:S3) -> 0 | Z3: =SUM(U3:Y3) -> 0 | AF3: =SUM(AA3:AE3) -> 0 | AL3: =SUM(AG3:AK3) -> 0 | AR3: =SUM(AM3:AQ3) -> 0 | AX3: =SUM(AS3:AW3) -> 0 | BD3: =SUM(AY3:BC3) -> 0
A4: OUTRA ATIVIDADE. QUAL?
A5: OBSERVAÇÃO

Sheet TOTAL
A1: INDICADORES | B1: Fonte | C1: 04/05 a 08/05/2026 | D1: 11/05 a 15/05/2026 | E1: 18/05 a 22/05/2026 | F1: 25/05 a 29/05/2026 | G1: 01/06 a 05/06/2026 | H1: 08/06 a 12/06/2026 | I1: 15/06 a 19/06/2026 | J1: 22/06 a 26/06/2026 | K1: 29/06 a 30/06/2026
A2: Desarquivamento de Processos/Documentos - Saída de Guia Fora | B2: SEI | C2: =Diego!H2+Aelton!H2+Leonam!H2+Danilo!H2+Marcos!H2+Alessandro!H2 -> 0 | D2: =Diego!N2+Aelton!N2+Leonam!N2+Danilo!N2+Marcos!N2+Alessandro!AL2+Carlos!N2 -> 0 | E2: =Diego!T2+Aelton!T2+Leonam!T2+Danilo!T2+Marcos!T2+Alessandro!T2 -> 0 | F2: =Diego!Z2+Aelton!Z2+Leonam!Z2+Danilo!Z2+Marcos!Z2+Alessandro!Z2 -> 0 | G2: =Diego!AF2+Aelton!AF2+Leonam!AF2+Danilo!AF2+Marcos!AF2+Alessandro!AF2 -> 0 | H2: =Diego!AL2+Aelton!AL2+Leonam!AL2+Danilo!AL2+Marcos!AL2+Alessandro!AL2 -> 0 | I2: =Diego!AR2+Aelton!AR2+Leonam!AR2+Danilo!AR2+Marcos!AR2+Alessandro!AR2 -> 0 | J2: =Diego!AX2+Aelton!AX2+Leonam!AX2+Danilo!AX2+Marcos!AX2+Alessandro!AX2 -> 0 | K2: =Diego!BA2+Aelton!BA2+Leonam!BA2+Danilo!BA2+Marcos!BA2+Alessandro!BA2+Carlos!BA2 -> 0
A3: Caixas consultadas em pesquisa de desarquivamento | B3: CONTAGEM INDIVIDUAL (das caixas abertas para verificação de conteúdo em contexto de pesquisa para desarquivamento) | C3: =Diego!H3+Aelton!H3+Leonam!H3+Danilo!H3+Marcos!H3+Alessandro!H3 -> 0 | D3: =Diego!N3+Aelton!N3+Leonam!N3+Danilo!N3+Marcos!N3+Alessandro!AL3+Carlos!N3 -> 0 | E3: =Diego!T3+Aelton!T3+Leonam!T3+Danilo!T3+Marcos!T3+Alessandro!T3 -> 0 | F3: =Diego!Z3+Aelton!Z3+Leonam!Z3+Danilo!Z3+Marcos!Z3+Alessandro!Z3 -> 0 | G3: =Diego!AF3+Aelton!AF3+Leonam!AF3+Danilo!AF3+Marcos!AF3+Alessandro!AF3 -> 0 | H3: =Diego!AL3+Aelton!AL3+Leonam!AL3+Danilo!AL3+Marcos!AL3+Alessandro!AL3 -> 70 | I3: =Diego!AR3+Aelton!AR3+Leonam!AR3+Danilo!AR3+Marcos!AR3+Alessandro!AR3 -> 0 | J3: =Diego!AX3+Aelton!AX3+Leonam!AX3+Danilo!AX3+Marcos!AX3+Alessandro!AX3 -> 0 | K3: =Diego!BA3+Aelton!BA3+Leonam!BA3+Danilo!BA3+Marcos!BA3+Alessandro!BA3+Carlos!BA3 -> 0
A4: Retorno de Processos/Documentos Desarquivados | B4: SEI | C4: =Diego!H4+Aelton!H4+Leonam!H4+Danilo!H4+Marcos!H4+Alessandro!H4 -> 57 | D4: =Diego!N4+Aelton!N4+Leonam!N4+Danilo!N4+Marcos!N4+Alessandro!N4 -> 0 | E4: =Diego!T4+Aelton!T4+Leonam!T4+Danilo!T4+Marcos!T4+Alessandro!T4 -> 0 | F4: =Diego!Z4+Aelton!Z4+Leonam!Z4+Danilo!Z4+Marcos!Z4+Alessandro!Z4 -> 0 | G4: =Diego!AF4+Aelton!AF4+Leonam!AF4+Danilo!AF4+Marcos!AF4+Alessandro!AF4 -> 0 | H4: =Diego!AL4+Aelton!AL4+Leonam!AL4+Danilo!AL4+Marcos!AL4+Alessandro!AL4 -> 50 | I4: =Diego!AR4+Aelton!AR4+Leonam!AR4+Danilo!AR4+Marcos!AR4+Alessandro!AR4 -> 0 | J4: =Diego!AX4+Aelton!AX4+Leonam!AX4+Danilo!AX4+Marcos!AX4+Alessandro!AX4 -> 0 | K4: =Diego!BA4+Aelton!BA4+Leonam!BA4+Danilo!BA4+Marcos!BA4+Alessandro!BA4+Carlos!BA4 -> 0
A5: Recebimento de Documentos - Guia de Transferência | B5: SEI | C5: =Diego!H5+Aelton!H5+Leonam!H5+Danilo!H5+Marcos!H5+Alessandro!H5 -> 0 | D5: =Diego!N5+Aelton!N5+Leonam!N5+Danilo!N5+Marcos!N5+Alessandro!N5 -> 0 | E5: =Diego!T5+Aelton!T5+Leonam!T5+Danilo!T5+Marcos!T5+Alessandro!T5 -> 0 | F5: =Diego!Z5+Aelton!Z5+Leonam!Z5+Danilo!Z5+Marcos!Z5+Alessandro!Z5 -> 0 | G5: =Diego!AF5+Aelton!AF5+Leonam!AF5+Danilo!AF5+Marcos!AF5+Alessandro!AF5 -> 0 | H5: =Diego!AL5+Aelton!AL5+Leonam!AL5+Danilo!AL5+Marcos!AL5+Alessandro!AL5 -> 0 | I5: =Diego!AR5+Aelton!AR5+Leonam!AR5+Danilo!AR5+Marcos!AR5+Alessandro!AR5 -> 0 | J5: =Diego!AX5+Aelton!AX5+Leonam!AX5+Danilo!AX5+Marcos!AX5+Alessandro!AX5 -> 0 | K5: =Diego!BA5+Aelton!BA5+Leonam!BA5+Danilo!BA5+Marcos!BA5+Alessandro!BA5+Carlos!BA5 -> 0
A6: Caixas separadas para classificação | B6: CONTAGEM INDIVIDUAL (das caixas "puxadas" nas estantes como uma pré-seleção para classificação) | C6: =Diego!H6+Aelton!H6+Leonam!H6+Danilo!H6+Marcos!H6+Alessandro!H6 -> 0 | D6: =Diego!N6+Aelton!N6+Leonam!N6+Danilo!N6+Marcos!N6+Alessandro!N6 -> 0 | E6: =Diego!T6+Aelton!T6+Leonam!T6+Danilo!T6+Marcos!T6+Alessandro!T6 -> 0 | F6: =Diego!Z6+Aelton!Z6+Leonam!Z6+Danilo!Z6+Marcos!Z6+Alessandro!Z6 -> 0 | G6: =Diego!AF6+Aelton!AF6+Leonam!AF6+Danilo!AF6+Marcos!AF6+Alessandro!AF6 -> 0 | H6: =Diego!AL6+Aelton!AL6+Leonam!AL6+Danilo!AL6+Marcos!AL6+Alessandro!AL6 -> 0 | I6: =Diego!AR6+Aelton!AR6+Leonam!AR6+Danilo!AR6+Marcos!AR6+Alessandro!AR6 -> 0 | J6: =Diego!AX6+Aelton!AX6+Leonam!AX6+Danilo!AX6+Marcos!AX6+Alessandro!AX6 -> 0 | K6: =Diego!BA6+Aelton!BA6+Leonam!BA6+Danilo!BA6+Marcos!BA6+Alessandro!BA6+Carlos!BA6 -> 0
A7: Processos/Documentos classificados | B7: PLANILHA | C7: =Diego!H7+Aelton!H7+Leonam!H7+Danilo!H7+Marcos!H7+Alessandro!H7 -> 0 | D7: =Diego!N7+Aelton!N7+Leonam!N7+Danilo!N7+Marcos!N7+Alessandro!N7 -> 0 | E7: =Diego!T7+Aelton!T7+Leonam!T7+Danilo!T7+Marcos!T7+Alessandro!T7 -> 0 | F7: =Diego!Z7+Aelton!Z7+Leonam!Z7+Danilo!Z7+Marcos!Z7+Alessandro!Z7 -> 0 | G7: =Diego!AF7+Aelton!AF7+Leonam!AF7+Danilo!AF7+Marcos!AF7+Alessandro!AF7 -> 0 | H7: =Diego!AL7+Aelton!AL7+Leonam!AL7+Danilo!AL7+Marcos!AL7+Alessandro!AL7 -> 0 | I7: =Diego!AR7+Aelton!AR7+Leonam!AR7+Danilo!AR7+Marcos!AR7+Alessandro!AR7 -> 0 | J7: =Diego!AX7+Aelton!AX7+Leonam!AX7+Danilo!AX7+Marcos!AX7+Alessandro!AX7 -> 0 | K7: =Diego!BA7+Aelton!BA7+Leonam!BA7+Danilo!BA7+Marcos!BA7+Alessandro!BA7+Carlos!BA7 -> 0
A8: Caixas separadas para eliminação | B8: CONTAGEM INDIVIDUAL (das caixas "puxadas" nas estantes como uma pré-seleção para eliminação) | C8: =Diego!H8+Aelton!H8+Leonam!H8+Danilo!H8+Marcos!H8+Alessandro!H8 -> 0 | D8: =Diego!N8+Aelton!N8+Leonam!N8+Danilo!N8+Marcos!N8+Alessandro!N8 -> 0 | E8: =Diego!T8+Aelton!T8+Leonam!T8+Danilo!T8+Marcos!T8+Alessandro!T8 -> 0 | F8: =Diego!Z8+Aelton!Z8+Leonam!Z8+Danilo!Z8+Marcos!Z8+Alessandro!Z8 -> 0 | G8: =Diego!AF8+Aelton!AF8+Leonam!AF8+Danilo!AF8+Marcos!AF8+Alessandro!AF8 -> 0 | H8: =Diego!AL8+Aelton!AL8+Leonam!AL8+Danilo!AL8+Marcos!AL8+Alessandro!AL8 -> 0 | I8: =Diego!AR8+Aelton!AR8+Leonam!AR8+Danilo!AR8+Marcos!AR8+Alessandro!AR8 -> 0 | J8: =Diego!AX8+Aelton!AX8+Leonam!AX8+Danilo!AX8+Marcos!AX8+Alessandro!AX8 -> 0 | K8: =Diego!BA8+Aelton!BA8+Leonam!BA8+Danilo!BA8+Marcos!BA8+Alessandro!BA8+Carlos!BA8 -> 0
A9: Caixas listadas para eliminação | B9: PLANILHA | C9: =Diego!H9+Aelton!H9+Leonam!H9+Danilo!H9+Marcos!H9+Alessandro!H9 -> 0 | D9: =Diego!N9+Aelton!N9+Leonam!N9+Danilo!N9+Marcos!N9+Alessandro!N9 -> 0 | E9: =Diego!T9+Aelton!T9+Leonam!T9+Danilo!T9+Marcos!T9+Alessandro!T9 -> 0 | F9: =Diego!Z9+Aelton!Z9+Leonam!Z9+Danilo!Z9+Marcos!Z9+Alessandro!Z9 -> 0 | G9: =Diego!AF9+Aelton!AF9+Leonam!AF9+Danilo!AF9+Marcos!AF9+Alessandro!AF9 -> 0 | H9: =Diego!AL9+Aelton!AL9+Leonam!AL9+Danilo!AL9+Marcos!AL9+Alessandro!AL9 -> 0 | I9: =Diego!AR9+Aelton!AR9+Leonam!AR9+Danilo!AR9+Marcos!AR9+Alessandro!AR9 -> 0 | J9: =Diego!AX9+Aelton!AX9+Leonam!AX9+Danilo!AX9+Marcos!AX9+Alessandro!AX9 -> 0 | K9: =Diego!BA9+Aelton!BA9+Leonam!BA9+Danilo!BA9+Marcos!BA9+Alessandro!BA9+Carlos!BA9 -> 0
A10: Processos/Documentos listados para eliminação | B10: PLANILHA | C10: =Diego!H10+Aelton!H10+Leonam!H10+Danilo!H10+Marcos!H10+Alessandro!H10 -> 0 | D10: =Diego!N10+Aelton!N10+Leonam!N10+Danilo!N10+Marcos!N10+Alessandro!N10 -> 0 | E10: =Diego!T10+Aelton!T10+Leonam!T10+Danilo!T10+Marcos!T10+Alessandro!T10 -> 0 | F10: =Diego!Z10+Aelton!Z10+Leonam!Z10+Danilo!Z10+Marcos!Z10+Alessandro!Z10 -> 0 | G10: =Diego!AF10+Aelton!AF10+Leonam!AF10+Danilo!AF10+Marcos!AF10+Alessandro!AF10 -> 0 | H10: =Diego!AL10+Aelton!AL10+Leonam!AL10+Danilo!AL10+Marcos!AL10+Alessandro!AL10 -> 0 | I10: =Diego!AR10+Aelton!AR10+Leonam!AR10+Danilo!AR10+Marcos!AR10+Alessandro!AR10 -> 0 | J10: =Diego!AX10+Aelton!AX10+Leonam!AX10+Danilo!AX10+Marcos!AX10+Alessandro!AX10 -> 0 | K10: =Diego!BA10+Aelton!BA10+Leonam!BA10+Danilo!BA10+Marcos!BA10+Alessandro!BA10+Carlos!BA10 -> 0
A11: Caixas inventariadas | B11: PLANILHA | C11: =Diego!H11+Aelton!H11+Leonam!H11+Danilo!H11+Alessandro!H11+Marcos!H11+Carlos!H11 -> 29 | D11: =Diego!N11+Aelton!N11+Leonam!N11+Danilo!N11+Alessandro!N11+Marcos!N11+Carlos!N11 -> 39 | E11: =+Diego!T12+Aelton!T11+Leonam!T11+Danilo!T11+Alessandro!T11+Marcos!T11+Carlos!T11 -> 67 | F11: =+Diego!Z11+Aelton!Z11+Leonam!Z11+Danilo!Z11+Alessandro!Z11+Marcos!Z11+Carlos!Z11 -> 67 | G11: =Diego!AF11+Aelton!AF11+Leonam!AF11+Danilo!AF11+Alessandro!AF11+Marcos!AF11+Carlos!AF11 -> 31 | H11: =Diego!AL11+Aelton!AL11+Leonam!AL11+Danilo!AL11+Alessandro!AL11+Marcos!AL11+Carlos!AL11 -> 44 | I11: =Diego!AY11+Aelton!AY11+Leonam!AY11+Danilo!AY11+Marcos!AY11+Alessandro!AY11+Carlos!AY11 -> 0 | J11: =Diego!AZ11+Aelton!AZ11+Leonam!AZ11+Danilo!AZ11+Marcos!AZ11+Alessandro!AZ11+Carlos!AZ11 -> 0 | K11: =Diego!BA11+Aelton!BA11+Leonam!BA11+Danilo!BA11+Marcos!BA11+Alessandro!BA11+Carlos!BA11 -> 0
A12: Processos/documentos inventariados | B12: PLANILHA | C12: =Diego!H12+Aelton!H12+Leonam!H12+Danilo!H12+Alessandro!H12+Marcos!H12+Carlos!H12 -> 189 | D12: =Diego!N12+Aelton!N12+Leonam!N12+Danilo!N12+Marcos!N12+Alessandro!N12+Carlos!N12 -> 256 | E12: =+Diego!T12+Aelton!T12+Leonam!T12+Danilo!T12+Alessandro!T12+Marcos!T12+Carlos!T12 -> 430 | F12: =Diego!Z12+Aelton!Z12+Leonam!Z12+Danilo!Z12+Alessandro!Z12+Marcos!Z12+Carlos!Z12 -> 415 | G12: =Diego!AF12+Aelton!AF12+Leonam!AF12+Danilo!AF12+Marcos!AF12+Alessandro!AF12+Carlos!AF12 -> 239 | H12: =Diego!AL12+Aelton!AL12+Leonam!AL12+Danilo!AL12+Alessandro!AL12+Marcos!AL12+Carlos!AL12 -> 310 | I12: =Diego!AR12+Aelton!AR12+Leonam!AR12+Danilo!AR12+Marcos!AR12+Alessandro!AR12+Carlos!AR12 -> 0 | J12: =Diego!AX12+Aelton!AX12+Leonam!AX12+Danilo!AX12+Marcos!AX12+Alessandro!AX12+Carlos!AX12 -> 0 | K12: =Diego!BA12+Aelton!BA12+Leonam!BA12+Danilo!BA12+Marcos!BA12+Alessandro!BA12+Carlos!BA12 -> 0
A13: Documentos administrativos produzidos (Despacho, Nota Técnica, minutas diversas) | B13: SEI | C13: =Diego!H13+Aelton!H13+Leonam!H13+Danilo!H13+Alessandro!H13+Marcos!H13+Carlos!H13 -> 0 | D13: =Diego!N13+Aelton!N13+Leonam!N13+Danilo!N13+Marcos!N13+Alessandro!N13+Patrícia!N2+Leonardo!N2 -> 1 | E13: =Diego!T13+Aelton!T13+Leonam!T13+Danilo!T13+Marcos!T13+Alessandro!T13+Patrícia!T2+Leonardo!T2 -> 2 | F13: =Diego!Z13+Aelton!Z13+Leonam!Z13+Danilo!Z13+Marcos!Z13+Alessandro!Z13+Patrícia!Z2+Leonardo!Z2 -> 0 | G13: =Diego!AF13+Aelton!AF13+Leonam!AF13+Danilo!AF13+Marcos!AF13+Alessandro!AF13+Patrícia!AF2+Leonardo!AF2 -> 0 | H13: =Diego!AL13+Aelton!AL13+Leonam!AL13+Danilo!AL13+Marcos!AL13+Alessandro!AL13+Patrícia!AL2+Leonardo!AL2 -> 2 | I13: =Diego!AR13+Aelton!AR13+Leonam!AR13+Danilo!AR13+Marcos!AR13+Alessandro!AR13+Patrícia!AR2+Leonardo!AR2 -> 0 | J13: =Diego!AX13+Aelton!AX13+Leonam!AX13+Danilo!AX13+Marcos!AX13+Alessandro!AX13+Patrícia!AX2+Leonardo!AX2 -> 0 | K13: =Diego!BA13+Aelton!BA13+Leonam!BA13+Danilo!BA13+Marcos!BA13+Alessandro!BA13+Carlos!BA13 -> 0
A14: Orientação técnica / atendimentos realizados | B14: SEI, E-MAIL, TELEFONE | C14: =Diego!H14+Aelton!H14+Leonam!H14+Danilo!H14+Marcos!H14+Alessandro!H14+Patrícia!H3+Leonardo!H3 -> 0 | D14: =Diego!N14+Aelton!N14+Leonam!N14+Danilo!N14+Marcos!N14+Alessandro!N14+Patrícia!N3+Leonardo!N3 -> 5 | E14: =Diego!T14+Aelton!T14+Leonam!T14+Danilo!T14+Marcos!T14+Alessandro!T14+Patrícia!T3+Leonardo!T3 -> 0 | F14: =Diego!Z14+Aelton!Z14+Leonam!Z14+Danilo!Z14+Marcos!Z14+Alessandro!Z14+Patrícia!Z3+Leonardo!Z3 -> 0 | G14: =Diego!AF14+Aelton!AF14+Leonam!AF14+Danilo!AF14+Marcos!AF14+Alessandro!AF14+Patrícia!AF3+Leonardo!AF3 -> 0 | H14: =Diego!AL14+Aelton!AL14+Leonam!AL14+Danilo!AL14+Marcos!AL14+Alessandro!AL14+Patrícia!AL3+Leonardo!AL3 -> 0 | I14: =Diego!AR14+Aelton!AR14+Leonam!AR14+Danilo!AR14+Marcos!AR14+Alessandro!AR14+Patrícia!AR3+Leonardo!AR3 -> 209 | J14: =Diego!AX14+Aelton!AX14+Leonam!AX14+Danilo!AX14+Marcos!AX14+Alessandro!AX14+Patrícia!AX3+Leonardo!AX3 -> 0 | K14: =Diego!BA14+Aelton!BA14+Leonam!BA14+Danilo!BA14+Marcos!BA14+Alessandro!BA14+Carlos!BA14 -> 0
A15: Caixas remanejadas | B15: CONTAGEM INDIVIDUAL (de caixas deslocadas visando reorganização temporária ou permanente) | C15: =Diego!H15+Aelton!H15+Leonam!H15+Danilo!H15+Marcos!H15+Alessandro!H15 -> 100 | D15: =Diego!N15+Aelton!N15+Leonam!N15+Danilo!N15+Marcos!N15+Alessandro!N15+Carlos!N15 -> 50 | E15: =Diego!T15+Aelton!T15+Leonam!T15+Danilo!T15+Marcos!T15+Alessandro!T15 -> 368 | F15: =Diego!Z15+Aelton!Z15+Leonam!Z15+Danilo!Z15+Marcos!Z15+Alessandro!Z15 -> 365 | G15: =Diego!AF15+Aelton!AF15+Leonam!AF15+Danilo!AF15+Marcos!AF15+Alessandro!AF15 -> 50 | H15: 120 | I15: =Diego!AR15+Aelton!AR15+Leonam!AR15+Danilo!AR15+Marcos!AR15+Alessandro!AR15 -> 50 | J15: =Diego!AX15+Aelton!AX15+Leonam!AX15+Danilo!AX15+Marcos!AX15+Alessandro!AX15 -> 0 | K15: =Diego!BA15+Aelton!BA15+Leonam!BA15+Danilo!BA15+Marcos!BA15+Alessandro!BA15+Carlos!BA15 -> 0
A16: Caixas conferidas | B16: CONTAGEM INDIVIDUAL (de caixas para simples conferência de quantitativo ou do conteúdo do espelho em atividades diversas) | C16: =Diego!H16+Aelton!H16+Leonam!H16+Danilo!H16+Marcos!H16+Alessandro!H16 -> 52 | D16: =Diego!N16+Aelton!N16+Leonam!N16+Danilo!N16+Marcos!N16+Alessandro!N16 -> 65 | E16: =Diego!T16+Aelton!T16+Leonam!T16+Danilo!T16+Marcos!T16+Alessandro!T16 -> 65 | F16: =Diego!Z16+Aelton!Z16+Leonam!Z16+Danilo!Z16+Marcos!Z16+Alessandro!Z16 -> 45 | G16: =Diego!AF16+Aelton!AF16+Leonam!AF16+Danilo!AF16+Marcos!AF16+Alessandro!AF16 -> 29 | H16: 22 | I16: =Diego!AR16+Aelton!AR16+Leonam!AR16+Danilo!AR16+Marcos!AR16+Alessandro!AR16 -> 20 | J16: =Diego!AX16+Aelton!AX16+Leonam!AX16+Danilo!AX16+Marcos!AX16+Alessandro!AX16 -> 0 | K16: =Diego!BA16+Aelton!BA16+Leonam!BA16+Danilo!BA16+Marcos!BA16+Alessandro!BA16+Carlos!BA16 -> 0
A17: Caixas substituídas(trocadas) | B17: Substituição de caixas degradadas por novas | C17: =Diego!H17+Aelton!H17+Leonam!H17+Danilo!H17+Marcos!H17+Alessandro!H17 -> 28 | D17: =Diego!N17+Aelton!N17+Leonam!N17+Danilo!N17+Marcos!N17+Alessandro!N17 -> 0 | E17: =Diego!T17+Aelton!T17+Leonam!T17+Danilo!T17+Marcos!T17+Alessandro!T17 -> 0 | F17: =Diego!Z17+Aelton!Z17+Leonam!Z17+Danilo!Z17+Marcos!Z17+Alessandro!Z17 -> 15 | G17: =Diego!AF17+Aelton!AF17+Leonam!AF17+Danilo!AF17+Marcos!AF17+Alessandro!AF17 -> 15 | H17: =Diego!AL17+Aelton!AL17+Leonam!AL17+Danilo!AL17+Marcos!AL17+Alessandro!AL17 -> 0 | I17: =Diego!AR17+Aelton!AR17+Leonam!AR17+Danilo!AR17+Marcos!AR17+Alessandro!AR17 -> 0 | J17: =Diego!AX17+Aelton!AX17+Leonam!AX17+Danilo!AX17+Marcos!AX17+Alessandro!AX17 -> 0 | K17: =Diego!BA17+Aelton!BA17+Leonam!BA17+Danilo!BA17+Marcos!BA17+Alessandro!BA17+Carlos!BA17 -> 0
A18: OUTRA ATIVIDADE. QUAL?
A19: OBSERVAÇÃO

Sheet Diego
A1: INDICADORES | C1: 46146 | D1: 46147 | E1: 46148 | F1: 46149 | G1: 46150 | H1: TOTAL SEMANA | I1: 46153 | J1: 46154 | K1: 46155 | L1: 46156 | M1: 46157 | N1: TOTAL SEMANA | O1: 46160 | P1: 46161 | Q1: 46162 | R1: 46163 | S1: 46164 | T1: TOTAL SEMANA | U1: 46167 | V1: 46168 | W1: 46169 | X1: 46170 | Y1: 46171 | Z1: TOTAL SEMANA | AA1: 46174 | AB1: 46175 | AC1: 46176 | AD1: 46177 | AE1: 46178 | AF1: TOTAL SEMANA | AG1: 46181 | AH1: 46182 | AI1: 46183 | AJ1: 46184 | AK1: 46185 | AL1: TOTAL SEMANA | AM1: 46188 | AN1: 46189 | AO1: 46190 | AP1: 46191 | AQ1: 46192 | AR1: TOTAL SEMANA | AS1: 46195 | AT1: 46196 | AU1: 46197 | AV1: 46198 | AW1: 46199 | AX1: TOTAL SEMANA | AY1: 46202 | AZ1: 46203 | BA1: TOTAL SEMANA
A2: Desarquivamento de Processos/Documentos - Saída de Guia Fora | B2: 1 | H2: =SUM(C2:G2) -> 0 | N2: =SUM(I2:M2) -> 0 | T2: =SUM(O2:S2) -> 0 | Z2: =SUM(U2:Y2) -> 0 | AD2: RECESSO | AE2: FERIADO | AF2: =SUM(AA2:AE2) -> 0 | AL2: =SUM(AG2:AK2) -> 0 | AR2: =SUM(AM2:AQ2) -> 0 | AX2: =SUM(AS2:AW2) -> 0 | BA2: =SUM(AY2:AZ2) -> 0
A3: Caixas consultadas em pesquisa de desarquivamento | B3: 2 | H3: =SUM(C3:G3) -> 0 | N3: =SUM(I3:M3) -> 0 | T3: =SUM(O3:S3) -> 0 | Z3: =SUM(U3:Y3) -> 0 | AD3: RECESSO | AE3: FERIADO | AF3: =SUM(AA3:AE3) -> 0 | AL3: =SUM(AG3:AK3) -> 0 | AR3: =SUM(AM3:AQ3) -> 0 | AX3: =SUM(AS3:AW3) -> 0 | BA3: =SUM(AY3:AZ3) -> 0
A4: Retorno de Processos/Documentos Desarquivados | B4: 3 | H4: =SUM(C4:G4) -> 0 | N4: =SUM(I4:M4) -> 0 | T4: =SUM(O4:S4) -> 0 | Z4: =SUM(U4:Y4) -> 0 | AD4: RECESSO | AE4: FERIADO | AF4: =SUM(AA4:AE4) -> 0 | AL4: =SUM(AG4:AK4) -> 0 | AR4: =SUM(AM4:AQ4) -> 0 | AX4: =SUM(AS4:AW4) -> 0 | BA4: =SUM(AY4:AZ4) -> 0
A5: Recebimento de Documentos - Guia de Transferência | B5: 4 | H5: =SUM(C5:G5) -> 0 | N5: =SUM(I5:M5) -> 0 | T5: =SUM(O5:S5) -> 0 | Z5: =SUM(U5:Y5) -> 0 | AD5: RECESSO | AE5: FERIADO | AF5: =SUM(AA5:AE5) -> 0 | AL5: =SUM(AG5:AK5) -> 0 | AR5: =SUM(AM5:AQ5) -> 0 | AX5: =SUM(AS5:AW5) -> 0 | BA5: =SUM(AY5:AZ5) -> 0
A6: Caixas separadas para classificação | B6: 5 | H6: =SUM(C6:G6) -> 0 | N6: =SUM(I6:M6) -> 0 | T6: =SUM(O6:S6) -> 0 | Z6: =SUM(U6:Y6) -> 0 | AD6: RECESSO | AE6: FERIADO | AF6: =SUM(AA6:AE6) -> 0 | AL6: =SUM(AG6:AK6) -> 0 | AR6: =SUM(AM6:AQ6) -> 0 | AX6: =SUM(AS6:AW6) -> 0 | BA6: =SUM(AY6:AZ6) -> 0
A7: Processos/Documentos classificados | B7: 6 | H7: =SUM(C7:G7) -> 0 | N7: =SUM(I7:M7) -> 0 | T7: =SUM(O7:S7) -> 0 | Z7: =SUM(U7:Y7) -> 0 | AD7: RECESSO | AE7: FERIADO | AF7: =SUM(AA7:AE7) -> 0 | AL7: =SUM(AG7:AK7) -> 0 | AR7: =SUM(AM7:AQ7) -> 0 | AX7: =SUM(AS7:AW7) -> 0 | BA7: =SUM(AY7:AZ7) -> 0
A8: Caixas separadas para eliminação | B8: 7 | H8: =SUM(C8:G8) -> 0 | N8: =SUM(I8:M8) -> 0 | T8: =SUM(O8:S8) -> 0 | Z8: =SUM(U8:Y8) -> 0 | AD8: RECESSO | AE8: FERIADO | AF8: =SUM(AA8:AE8) -> 0 | AL8: =SUM(AG8:AK8) -> 0 | AR8: =SUM(AM8:AQ8) -> 0 | AX8: =SUM(AS8:AW8) -> 0 | BA8: =SUM(AY8:AZ8) -> 0
A9: Caixas listadas para eliminação | B9: 8 | H9: =SUM(C9:G9) -> 0 | N9: =SUM(I9:M9) -> 0 | T9: =SUM(O9:S9) -> 0 | Z9: =SUM(U9:Y9) -> 0 | AD9: RECESSO | AE9: FERIADO | AF9: =SUM(AA9:AE9) -> 0 | AL9: =SUM(AG9:AK9) -> 0 | AR9: =SUM(AM9:AQ9) -> 0 | AX9: =SUM(AS9:AW9) -> 0 | BA9: =SUM(AY9:AZ9) -> 0
A10: Processos/Documentos listados para eliminação | B10: 9 | H10: =SUM(C10:G10) -> 0 | N10: =SUM(I10:M10) -> 0 | T10: =SUM(O10:S10) -> 0 | Z10: =SUM(U10:Y10) -> 0 | AD10: RECESSO | AE10: FERIADO | AF10: =SUM(AA10:AE10) -> 0 | AL10: =SUM(AG10:AK10) -> 0 | AR10: =SUM(AM10:AQ10) -> 0 | AX10: =SUM(AS10:AW10) -> 0 | BA10: =SUM(AY10:AZ10) -> 0
A11: Caixas inventariadas | B11: 10 | H11: =SUM(C11:G11) -> 0 | N11: =SUM(I11:M11) -> 0 | T11: =SUM(O11:S11) -> 0 | Z11: =SUM(U11:Y11) -> 0 | AD11: RECESSO | AE11: FERIADO | AF11: =SUM(AA11:AE11) -> 0 | AL11: =SUM(AG11:AK11) -> 0 | AR11: =SUM(AM11:AQ11) -> 0 | AX11: =SUM(AS11:AW11) -> 0 | BA11: =SUM(AY11:AZ11) -> 0
A12: Processos/documentos inventariados | B12: 11 | H12: =SUM(C12:G12) -> 0 | N12: =SUM(I12:M12) -> 0 | T12: =SUM(O12:S12) -> 0 | Z12: =SUM(U12:Y12) -> 0 | AD12: RECESSO | AE12: FERIADO | AF12: =SUM(AA12:AE12) -> 0 | AL12: =SUM(AG12:AK12) -> 0 | AR12: =SUM(AM12:AQ12) -> 0 | AX12: =SUM(AS12:AW12) -> 0 | BA12: =SUM(AY12:AZ12) -> 0
A13: Documentos administrativos produzidos (Despacho, Nota Técnica, minutas diversas) | B13: 12 | H13: =SUM(C13:G13) -> 0 | N13: =SUM(I13:M13) -> 0 | T13: =SUM(O13:S13) -> 0 | Z13: =SUM(U13:Y13) -> 0 | AD13: RECESSO | AE13: FERIADO | AF13: =SUM(AA13:AE13) -> 0 | AL13: =SUM(AG13:AK13) -> 0 | AR13: =SUM(AM13:AQ13) -> 0 | AX13: =SUM(AS13:AW13) -> 0 | BA13: =SUM(AY13:AZ13) -> 0
... A17: Caixas substituídas(trocadas) | B17: 16 | H17: =SUM(C17:G17) -> 0 | N17: =SUM(I17:M17) -> 0 | T17: =SUM(O17:S17) -> 0 | Z17: =SUM(U17:Y17) -> 0 | AD17: RECESSO | AE17: FERIADO | AF17: =SUM(AA17:AE17) -> 0 | AL17: =SUM(AG17:AK17) -> 0 | AR17: =SUM(AM17:AQ17) -> 0 | AX17: =SUM(AS17:AW17) -> 0 | BA17: =SUM(AY17:AZ17) -> 0
A18: OUTRA ATIVIDADE. QUAL? | C18: Pesquisa e busca processo 23132.000438/95-22, convênio nº 214/95, SIAFI nº 138116, Fundação de Desporto e Lazer de Mato Grosso | D18: Pesquisa e busca processo 23132.000438/95-22, convênio nº 214/95, SIAFI nº 138116, Fundação de Desporto e Lazer de Mato Grosso | E18: Pesquisa e busca processo 23132.000438/95-22, convênio nº 214/95, SIAFI nº 138116, Fundação de Desporto e Lazer de Mato Grosso | F18: Pesquisa e busca processo 23132.000438/95-22, convênio nº 214/95, SIAFI nº 138116, Fundação de Desporto e Lazer de Mato Grosso | G18: Pesquisa e busca processo 23132.000438/95-22, convênio nº 214/95, SIAFI nº 138116, Fundação de Desporto e Lazer de Mato Grosso | I18: Pesquisa e busca processo 23132.000438/95-22, convênio nº 214/95, SIAFI nº 138116, Fundação de Desporto e Lazer de Mato Grosso | J18: Pesquisa e busca processo 23132.000438/95-22, convênio nº 214/95, SIAFI nº 138116, Fundação de Desporto e Lazer de Mato Grosso | K18: Pesquisa e busca processo 23132.000438/95-22, convênio nº 214/95, SIAFI nº 138116, Fundação de Desporto e Lazer de Mato Grosso | L18: Pesquisa e busca processo 23132.000438/95-22, convênio nº 214/95, SIAFI nº 138116, Fundação de Desporto e Lazer de Mato Grosso | M18: Pesquisa e busca processo 23132.000438/95-22, convênio nº 214/95, SIAFI nº 138116, Fundação de Desporto e Lazer de Mato Grosso | O18: Pesquisa e busca processo 23132.000438/95-22, convênio nº 214/95, SIAFI nº 138116, Fundação de Desporto e Lazer de Mato Grosso | P18: Pesquisa e busca processo 23132.000438/95-22, convênio nº 214/95, SIAFI nº 138116, Fundação de Desporto e Lazer de Mato Grosso | Q18: Pesquisa e busca processo 23132.000438/95-22, convênio nº 214/95, SIAFI nº 138116, Fundação de Desporto e Lazer de Mato Grosso | R18: Pesquisa e busca processo 23132.000438/95-22, convênio nº 214/95, SIAFI nº 138116, Fundação de Desporto e Lazer de Mato Grosso | S18: Pesquisa e busca processo 23132.000438/95-22, convênio nº 214/95, SIAFI nº 138116, Fundação de Desporto e Lazer de Mato Grosso | U18: Pesquisa e busca processo 23132.000438/95-22, convênio nº 214/95, SIAFI nº 138116, Fundação de Desporto e Lazer de Mato Grosso | V18: Pesquisa e busca processo 23132.000438/95-22, convênio nº 214/95, SIAFI nº 138116, Fundação de Desporto e Lazer de Mato Grosso | W18: Pesquisa e busca processo 23132.000438/95-22, convênio nº 214/95, SIAFI nº 138116, Fundação de Desporto e Lazer de Mato Grosso | X18: Pesquisa e busca processo 23132.000438/95-22, convênio nº 214/95, SIAFI nº 138116, Fundação de Desporto e Lazer de Mato Grosso | Y18: Pesquisa e busca processo 23132.000438/95-22, convênio nº 214/95, SIAFI nº 138116, Fundação de Desporto e Lazer de Mato Grosso | AA18: Pesquisa e busca processo 23132.000438/95-22, convênio nº 214/95, SIAFI nº 138116, Fundação de Desporto e Lazer de Mato Grosso | AB18: Pesquisa e busca processo 23132.000438/95-22, convênio nº 214/95, SIAFI nº 138116, Fundação de Desporto e Lazer de Mato Grosso | AC18: Pesquisa e busca processo 23132.000438/95-22, convênio nº 214/95, SIAFI nº 138116, Fundação de Desporto e Lazer de Mato Grosso | AG18: Pesquisa e busca processo 23132.000438/95-22, convênio nº 214/95, SIAFI nº 138116, Fundação de Desporto e Lazer de Mato Grosso | AH18: Pesquisa e busca processo 23132.000438/95-22, convênio nº 214/95, SIAFI nº 138116, Fundação de Desporto e Lazer de Mato Grosso | AI18: Pesquisa e busca processo 23132.000438/95-22, convênio nº 214/95, SIAFI nº 138116, Fundação de Desporto e Lazer de Mato Grosso | AJ18: Pesquisa e busca processo 23132.000438/95-22, convênio nº 214/95, SIAFI nº 138116, Fundação de Desporto e Lazer de Mato Grosso | AK18: Pesquisa e busca processo 23132.000438/95-22, convênio nº 214/95, SIAFI nº 138116, Fundação de Desporto e Lazer de Mato Grosso | AM18: REUNIÃO NO MESP
A19: OBSERVAÇÃO | AA19: CONTAGEM DAS CAIXAS DO ARQUIVO

Sheet Aelton
A1: INDICADORES | C1: 46146 | D1: 46147 | E1: 46148 | F1: 46149 | G1: 46150 | H1: TOTAL SEMANA | I1: 46153 | J1: 46154 | K1: 46155 | L1: 46156 | M1: 46157 | N1: TOTAL SEMANA | O1: 46160 | P1: 46161 | Q1: 46162 | R1: 46163 | S1: 46164 | T1: TOTAL SEMANA | U1: 46167 | V1: 46168 | W1: 46169 | X1: 46170 | Y1: 46171 | Z1: TOTAL SEMANA | AA1: 46174 | AB1: 46175 | AC1: 46176 | AD1: 46177 | AE1: 46178 | AF1: TOTAL SEMANA | AG1: 46181 | AH1: 46182 | AI1: 46183 | AJ1: 46184 | AK1: 46185 | AL1: TOTAL SEMANA | AM1: 46188 | AN1: 46189 | AO1: 46190 | AP1: 46191 | AQ1: 46192 | AR1: TOTAL SEMANA | AS1: 46195 | AT1: 46196 | AU1: 46197 | AV1: 46198 | AW1: 46199 | AX1: TOTAL SEMANA | AY1: 46202 | AZ1: 46203 | BA1: TOTAL SEMANA
A2: Desarquivamento de Processos/Documentos - Saída de Guia Fora | B2: 1 | H2: =SUM(C2:G2) -> 0 | N2: =SUM(I2:M2) -> 0 | T2: =SUM(O2:S2) -> 0 | Z2: =SUM(U2:Y2) -> 0 | AF2: =SUM(AA2:AE2) -> 0 | AL2: =SUM(AG2:AK2) -> 0 | AR2: =SUM(AM2:AQ2) -> 0 | AX2: =SUM(AS2:AW2) -> 0 | BA2: =SUM(AY2:AZ2) -> 0
A3: Caixas consultadas em pesquisa de desarquivamento | B3: 2 | H3: =SUM(C3:G3) -> 0 | N3: =SUM(I3:M3) -> 0 | T3: =SUM(O3:S3) -> 0 | Z3: =SUM(U3:Y3) -> 0 | AF3: =SUM(AA3:AE3) -> 0 | AL3: =SUM(AG3:AK3) -> 0 | AR3: =SUM(AM3:AQ3) -> 0 | AX3: =SUM(AS3:AW3) -> 0 | BA3: =SUM(AY3:AZ3) -> 0
A4: Retorno de Processos/Documentos Desarquivados | B4: 3 | H4: =SUM(C4:G4) -> 0 | N4: =SUM(I4:M4) -> 0 | T4: =SUM(O4:S4) -> 0 | Z4: =SUM(U4:Y4) -> 0 | AF4: =SUM(AA4:AE4) -> 0 | AL4: =SUM(AG4:AK4) -> 0 | AR4: =SUM(AM4:AQ4) -> 0 | AX4: =SUM(AS4:AW4) -> 0 | BA4: =SUM(AY4:AZ4) -> 0
A5: Recebimento de Documentos - Guia de Transferência | B5: 4 | H5: =SUM(C5:G5) -> 0 | N5: =SUM(I5:M5) -> 0 | T5: =SUM(O5:S5) -> 0 | Z5: =SUM(U5:Y5) -> 0 | AF5: =SUM(AA5:AE5) -> 0 | AL5: =SUM(AG5:AK5) -> 0 | AR5: =SUM(AM5:AQ5) -> 0 | AX5: =SUM(AS5:AW5) -> 0 | BA5: =SUM(AY5:AZ5) -> 0
A6: Caixas separadas para classificação | B6: 5 | H6: =SUM(C6:G6) -> 0 | N6: =SUM(I6:M6) -> 0 | T6: =SUM(O6:S6) -> 0 | Z6: =SUM(U6:Y6) -> 0 | AF6: =SUM(AA6:AE6) -> 0 | AL6: =SUM(AG6:AK6) -> 0 | AR6: =SUM(AM6:AQ6) -> 0 | AX6: =SUM(AS6:AW6) -> 0 | BA6: =SUM(AY6:AZ6) -> 0
A7: Processos/Documentos classificados | B7: 6 | H7: =SUM(C7:G7) -> 0 | N7: =SUM(I7:M7) -> 0 | T7: =SUM(O7:S7) -> 0 | Z7: =SUM(U7:Y7) -> 0 | AF7: =SUM(AA7:AE7) -> 0 | AL7: =SUM(AG7:AK7) -> 0 | AR7: =SUM(AM7:AQ7) -> 0 | AX7: =SUM(AS7:AW7) -> 0 | BA7: =SUM(AY7:AZ7) -> 0
A8: Caixas separadas para eliminação | B8: 7 | H8: =SUM(C8:G8) -> 0 | N8: =SUM(I8:M8) -> 0 | T8: =SUM(O8:S8) -> 0 | Z8: =SUM(U8:Y8) -> 0 | AF8: =SUM(AA8:AE8) -> 0 | AL8: =SUM(AG8:AK8) -> 0 | AR8: =SUM(AM8:AQ8) -> 0 | AX8: =SUM(AS8:AW8) -> 0 | BA8: =SUM(AY8:AZ8) -> 0
A9: Caixas listadas para eliminação | B9: 8 | H9: =SUM(C9:G9) -> 0 | N9: =SUM(I9:M9) -> 0 | T9: =SUM(O9:S9) -> 0 | Z9: =SUM(U9:Y9) -> 0 | AF9: =SUM(AA9:AE9) -> 0 | AL9: =SUM(AG9:AK9) -> 0 | AR9: =SUM(AM9:AQ9) -> 0 | AX9: =SUM(AS9:AW9) -> 0 | BA9: =SUM(AY9:AZ9) -> 0
A10: Processos/Documentos listados para eliminação | B10: 9 | H10: =SUM(C10:G10) -> 0 | N10: =SUM(I10:M10) -> 0 | T10: =SUM(O10:S10) -> 0 | Z10: =SUM(U10:Y10) -> 0 | AF10: =SUM(AA10:AE10) -> 0 | AL10: =SUM(AG10:AK10) -> 0 | AR10: =SUM(AM10:AQ10) -> 0 | AX10: =SUM(AS10:AW10) -> 0 | BA10: =SUM(AY10:AZ10) -> 0
A11: Caixas inventariadas | B11: 10 | H11: =SUM(C11:G11) -> 0 | N11: =SUM(I11:M11) -> 0 | T11: =SUM(O11:S11) -> 0 | Z11: =SUM(U11:Y11) -> 0 | AF11: =SUM(AA11:AE11) -> 0 | AL11: =SUM(AG11:AK11) -> 0 | AR11: =SUM(AM11:AQ11) -> 0 | AX11: =SUM(AS11:AW11) -> 0 | BA11: =SUM(AY11:AZ11) -> 0
A12: Processos/documentos inventariados | B12: 11 | H12: =SUM(C12:G12) -> 0 | N12: =SUM(I12:M12) -> 0 | T12: =SUM(O12:S12) -> 0 | Z12: =SUM(U12:Y12) -> 0 | AF12: =SUM(AA12:AE12) -> 0 | AL12: =SUM(AG12:AK12) -> 0 | AR12: =SUM(AM12:AQ12) -> 0 | AX12: =SUM(AS12:AW12) -> 0 | BA12: =SUM(AY12:AZ12) -> 0
A13: Documentos administrativos produzidos (Despacho, Nota Técnica, minutas diversas) | B13: 12 | H13: =SUM(C13:G13) -> 0 | N13: =SUM(I13:M13) -> 0 | T13: =SUM(O13:S13) -> 0 | Z13: =SUM(U13:Y13) -> 0 | AF13: =SUM(AA13:AE13) -> 0 | AL13: =SUM(AG13:AK13) -> 0 | AR13: =SUM(AM13:AQ13) -> 0 | AX13: =SUM(AS13:AW13) -> 0 | BA13: =SUM(AY13:AZ13) -> 0
... A17: Caixas substituídas(trocadas) | B17: 16 | H17: =SUM(C17:G17) -> 0 | N17: =SUM(I17:M17) -> 0 | T17: =SUM(O17:S17) -> 0 | Z17: =SUM(U17:Y17) -> 0 | AF17: =SUM(AA17:AE17) -> 0 | AL17: =SUM(AG17:AK17) -> 0 | AR17: =SUM(AM17:AQ17) -> 0 | AX17: =SUM(AS17:AW17) -> 0 | BA17: =SUM(AY17:AZ17) -> 0
A18: OUTRA ATIVIDADE. QUAL? | C18: Pesquisa e busca processo 23132.000438/95-22, convênio nº 214/95, SIAFI nº 138116, Fundação de Desporto e Lazer de Mato Grosso | D18: Pesquisa e busca processo 23132.000438/95-22, convênio nº 214/95, SIAFI nº 138116, Fundação de Desporto e Lazer de Mato Grosso | E18: Pesquisa e busca processo 23132.000438/95-22, convênio nº 214/95, SIAFI nº 138116, Fundação de Desporto e Lazer de Mato Grosso | F18: Pesquisa e busca processo 23132.000438/95-22, convênio nº 214/95, SIAFI nº 138116, Fundação de Desporto e Lazer de Mato Grosso | G18: Pesquisa e busca processo 23132.000438/95-22, convênio nº 214/95, SIAFI nº 138116, Fundação de Desporto e Lazer de Mato Grosso | I18: Pesquisa e busca processo 23132.000438/95-22, convênio nº 214/95, SIAFI nº 138116, Fundação de Desporto e Lazer de Mato Grosso | J18: Pesquisa e busca processo 23132.000438/95-22, convênio nº 214/95, SIAFI nº 138116, Fundação de Desporto e Lazer de Mato Grosso | K18: Pesquisa e busca processo 23132.000438/95-22, convênio nº 214/95, SIAFI nº 138116, Fundação de Desporto e Lazer de Mato Grosso | L18: Pesquisa e busca processo 23132.000438/95-22, convênio nº 214/95, SIAFI nº 138116, Fundação de Desporto e Lazer de Mato Grosso | M18: Pesquisa e busca processo 23132.000438/95-22, convênio nº 214/95, SIAFI nº 138116, Fundação de Desporto e Lazer de Mato Grosso | O18: Pesquisa e busca processo 23132.000438/95-22, convênio nº 214/95, SIAFI nº 138116, Fundação de Desporto e Lazer de Mato Grosso | P18: Pesquisa e busca processo 23132.000438/95-22, convênio nº 214/95, SIAFI nº 138116, Fundação de Desporto e Lazer de Mato Grosso | Q18: Pesquisa e busca processo 23132.000438/95-22, convênio nº 214/95, SIAFI nº 138116, Fundação de Desporto e Lazer de Mato Grosso | R18: Pesquisa e busca processo 23132.000438/95-22, convênio nº 214/95, SIAFI nº 138116, Fundação de Desporto e Lazer de Mato Grosso | S18: Pesquisa e busca processo 23132.000438/95-22, convênio nº 214/95, SIAFI nº 138116, Fundação de Desporto e Lazer de Mato Grosso | U18: Pesquisa e busca processo 23132.000438/95-22, convênio nº 214/95, SIAFI nº 138116, Fundação de Desporto e Lazer de Mato Grosso | V18: Pesquisa e busca processo 23132.000438/95-22, convênio nº 214/95, SIAFI nº 138116, Fundação de Desporto e Lazer de Mato Grosso | W18: Pesquisa e busca processo 23132.000438/95-22, convênio nº 214/95, SIAFI nº 138116, Fundação de Desporto e Lazer de Mato Grosso | X18: Pesquisa e busca processo 23132.000438/95-22, convênio nº 214/95, SIAFI nº 138116, Fundação de Desporto e Lazer de Mato Grosso | Y18: Pesquisa e busca processo 23132.000438/95-22, convênio nº 214/95, SIAFI nº 138116, Fundação de Desporto e Lazer de Mato Grosso | AA18: 1. Contagem caixas no DNIT Eu e Diego contamos as caixas das salas: 3,71 - 11.157 caixas 3.25 - 14,197caixas LBA Sala 3.25 - 29 Sala 3.25 - 9 Total = 38 caixas 2 À pedido da Juelice, por ordem do Pedro, EM CARÁTER DE URGÊNCIA, disponibilizei o documento (18750823) para assinatura à Ariane da SAA. 3. Pesquisa e busca processo 23132.000438/95-22, convênio nº 214/95, SIAFI nº 138116, Fundação de Desporto e Lazer de Mato Grosso | AB18: Pesquisa e busca processo 23132.000438/95-22, convênio nº 214/95, SIAFI nº 138116, Fundação de Desporto e Lazer de Mato Grosso | AC18: Pesquisa e busca processo 23132.000438/95-22, convênio nº 214/95, SIAFI nº 138116, Fundação de Desporto e Lazer de Mato Grosso | AD18: FERIADO CORPUS CHRISTI | AE18: PONTO FACULTATIVO | AG18: Pesquisa e busca processo 23132.000438/95-22, convênio nº 214/95, SIAFI nº 138116, Fundação de Desporto e Lazer de Mato Grosso | AH18: Pesquisa e busca processo 23132.000438/95-22, convênio nº 214/95, SIAFI nº 138116, Fundação de Desporto e Lazer de Mato Grosso | AI18: Pesquisa e busca processo 23132.000438/95-22, convênio nº 214/95, SIAFI nº 138116, Fundação de Desporto e Lazer de Mato Grosso | AJ18: Pesquisa e busca processo 23132.000438/95-22, convênio nº 214/95, SIAFI nº 138116, Fundação de Desporto e Lazer de Mato Grosso | AK18: Pesquisa e busca processo 23132.000438/95-22, convênio nº 214/95, SIAFI nº 138116, Fundação de Desporto e Lazer de Mato Grosso
A19: OBSERVAÇÃO

Sheet Leonam
A1: INDICADORES | C1: 46146 | D1: 46147 | E1: 46148 | F1: 46149 | G1: 46150 | H1: TOTAL SEMANA | I1: 46153 | J1: 46154 | K1: 46155 | L1: 46156 | M1: 46157 | N1: TOTAL SEMANA | O1: 46160 | P1: 46161 | Q1: 46162 | R1: 46163 | S1: 46164 | T1: TOTAL SEMANA | U1: 46167 | V1: 46168 | W1: 46169 | X1: 46170 | Y1: 46171 | Z1: TOTAL SEMANA | AA1: 46174 | AB1: 46175 | AC1: 46176 | AD1: 46177 | AE1: 46178 | AF1: TOTAL SEMANA | AG1: 46181 | AH1: 46182 | AI1: 46183 | AJ1: 46184 | AK1: 46185 | AL1: TOTAL SEMANA | AM1: 46188 | AN1: 46189 | AO1: 46190 | AP1: 46191 | AQ1: 46192 | AR1: TOTAL SEMANA | AS1: 46195 | AT1: 46196 | AU1: 46197 | AV1: 46198 | AW1: 46199 | AX1: TOTAL SEMANA | AY1: 46202 | AZ1: 46203 | BA1: TOTAL SEMANA
A2: Desarquivamento de Processos/Documentos - Saída de Guia Fora | B2: 1 | C2: Atestado | D2: Atestado | E2: Atestado | F2: Atestado | G2: Atestado | H2: =SUM(C2:G2) -> 0 | N2: =SUM(I2:M2) -> 0 | T2: =SUM(O2:S2) -> 0 | Z2: =SUM(U2:Y2) -> 0 | AD2: RECESSO | AE2: FERIADO | AF2: =SUM(AA2:AE2) -> 0 | AL2: =SUM(AG2:AK2) -> 0 | AR2: =SUM(AM2:AQ2) -> 0 | AX2: =SUM(AS2:AW2) -> 0 | BA2: =SUM(AY2:AZ2) -> 0
A3: Caixas consultadas em pesquisa de desarquivamento | B3: 2 | C3: Atestado | D3: Atestado | E3: Atestado | F3: Atestado | G3: Atestado | H3: =SUM(C3:G3) -> 0 | N3: =SUM(I3:M3) -> 0 | T3: =SUM(O3:S3) -> 0 | Z3: =SUM(U3:Y3) -> 0 | AD3: RECESSO | AE3: FERIADO | AF3: =SUM(AA3:AE3) -> 0 | AI3: 70 | AL3: =SUM(AG3:AK3) -> 70 | AR3: =SUM(AM3:AQ3) -> 0 | AX3: =SUM(AS3:AW3) -> 0 | BA3: =SUM(AY3:AZ3) -> 0
A4: Retorno de Processos/Documentos Desarquivados | B4: 3 | C4: Atestado | D4: Atestado | E4: Atestado | F4: Atestado | G4: Atestado | H4: =SUM(C4:G4) -> 0 | N4: =SUM(I4:M4) -> 0 | T4: =SUM(O4:S4) -> 0 | Z4: =SUM(U4:Y4) -> 0 | AD4: RECESSO | AE4: FERIADO | AF4: =SUM(AA4:AE4) -> 0 | AI4: 50 | AL4: =SUM(AG4:AK4) -> 50 | AR4: =SUM(AM4:AQ4) -> 0 | AX4: =SUM(AS4:AW4) -> 0 | BA4: =SUM(AY4:AZ4) -> 0
A5: Recebimento de Documentos - Guia de Transferência | B5: 4 | C5: Atestado | D5: Atestado | E5: Atestado | F5: Atestado | G5: Atestado | H5: =SUM(C5:G5) -> 0 | N5: =SUM(I5:M5) -> 0 | T5: =SUM(O5:S5) -> 0 | Z5: =SUM(U5:Y5) -> 0 | AD5: RECESSO | AE5: FERIADO | AF5: =SUM(AA5:AE5) -> 0 | AL5: =SUM(AG5:AK5) -> 0 | AR5: =SUM(AM5:AQ5) -> 0 | AX5: =SUM(AS5:AW5) -> 0 | BA5: =SUM(AY5:AZ5) -> 0
A6: Caixas separadas para classificação | B6: 5 | C6: Atestado | D6: Atestado | E6: Atestado | F6: Atestado | G6: Atestado | H6: =SUM(C6:G6) -> 0 | N6: =SUM(I6:M6) -> 0 | T6: =SUM(O6:S6) -> 0 | Z6: =SUM(U6:Y6) -> 0 | AD6: RECESSO | AE6: FERIADO | AF6: =SUM(AA6:AE6) -> 0 | AL6: =SUM(AG6:AK6) -> 0 | AR6: =SUM(AM6:AQ6) -> 0 | AX6: =SUM(AS6:AW6) -> 0 | BA6: =SUM(AY6:AZ6) -> 0
A7: Processos/Documentos classificados | B7: 6 | C7: Atestado | D7: Atestado | E7: Atestado | F7: Atestado | G7: Atestado | H7: =SUM(C7:G7) -> 0 | N7: =SUM(I7:M7) -> 0 | T7: =SUM(O7:S7) -> 0 | Z7: =SUM(U7:Y7) -> 0 | AD7: RECESSO | AE7: FERIADO | AF7: =SUM(AA7:AE7) -> 0 | AL7: =SUM(AG7:AK7) -> 0 | AR7: =SUM(AM7:AQ7) -> 0 | AX7: =SUM(AS7:AW7) -> 0 | BA7: =SUM(AY7:AZ7) -> 0
A8: Caixas separadas para eliminação | B8: 7 | C8: Atestado | D8: Atestado | E8: Atestado | F8: Atestado | G8: Atestado | H8: =SUM(C8:G8) -> 0 | N8: =SUM(I8:M8) -> 0 | T8: =SUM(O8:S8) -> 0 | Z8: =SUM(U8:Y8) -> 0 | AD8: RECESSO | AE8: FERIADO | AF8: =SUM(AA8:AE8) -> 0 | AL8: =SUM(AG8:AK8) -> 0 | AR8: =SUM(AM8:AQ8) -> 0 | AX8: =SUM(AS8:AW8) -> 0 | BA8: =SUM(AY8:AZ8) -> 0
A9: Caixas listadas para eliminação | B9: 8 | C9: Atestado | D9: Atestado | E9: Atestado | F9: Atestado | G9: Atestado | H9: =SUM(C9:G9) -> 0 | N9: =SUM(I9:M9) -> 0 | T9: =SUM(O9:S9) -> 0 | Z9: =SUM(U9:Y9) -> 0 | AD9: RECESSO | AE9: FERIADO | AF9: =SUM(AA9:AE9) -> 0 | AL9: =SUM(AG9:AK9) -> 0 | AR9: =SUM(AM9:AQ9) -> 0 | AX9: =SUM(AS9:AW9) -> 0 | BA9: =SUM(AY9:AZ9) -> 0
A10: Processos/Documentos listados para eliminação | B10: 9 | C10: Atestado | D10: Atestado | E10: Atestado | F10: Atestado | G10: Atestado | H10: =SUM(C10:G10) -> 0 | N10: =SUM(I10:M10) -> 0 | T10: =SUM(O10:S10) -> 0 | Z10: =SUM(U10:Y10) -> 0 | AD10: RECESSO | AE10: FERIADO | AF10: =SUM(AA10:AE10) -> 0 | AL10: =SUM(AG10:AK10) -> 0 | AR10: =SUM(AM10:AQ10) -> 0 | AX10: =SUM(AS10:AW10) -> 0 | BA10: =SUM(AY10:AZ10) -> 0
A11: Caixas inventariadas | B11: 10 | C11: Atestado | D11: Atestado | E11: Atestado | F11: Atestado | G11: Atestado | H11: =SUM(C11:G11) -> 0 | N11: =SUM(I11:M11) -> 0 | T11: =SUM(O11:S11) -> 0 | Z11: =SUM(U11:Y11) -> 0 | AD11: RECESSO | AE11: FERIADO | AF11: =SUM(AA11:AE11) -> 0 | AL11: =SUM(AG11:AK11) -> 0 | AR11: =SUM(AM11:AQ11) -> 0 | AX11: =SUM(AS11:AW11) -> 0 | BA11: =SUM(AY11:AZ11) -> 0
A12: Processos/documentos inventariados | B12: 11 | C12: Atestado | D12: Atestado | E12: Atestado | F12: Atestado | G12: Atestado | H12: =SUM(C12:G12) -> 0 | N12: =SUM(I12:M12) -> 0 | T12: =SUM(O12:S12) -> 0 | Z12: =SUM(U12:Y12) -> 0 | AD12: RECESSO | AE12: FERIADO | AF12: =SUM(AA12:AE12) -> 0 | AL12: =SUM(AG12:AK12) -> 0 | AR12: =SUM(AM12:AQ12) -> 0 | AX12: =SUM(AS12:AW12) -> 0 | BA12: =SUM(AY12:AZ12) -> 0
A13: Documentos administrativos produzidos (Despacho, Nota Técnica, minutas diversas) | B13: 12 | C13: Atestado | D13: Atestado | E13: Atestado | F13: Atestado | G13: Atestado | H13: =SUM(C13:G13) -> 0 | N13: =SUM(I13:M13) -> 0 | T13: =SUM(O13:S13) -> 0 | Z13: =SUM(U13:Y13) -> 0 | AD13: RECESSO | AE13: FERIADO | AF13: =SUM(AA13:AE13) -> 0 | AL13: =SUM(AG13:AK13) -> 0 | AR13: =SUM(AM13:AQ13) -> 0 | AX13: =SUM(AS13:AW13) -> 0 | BA13: =SUM(AY13:AZ13) -> 0
A14: Orientação técnica / atendimentos realizados | B14: 13 | C14: Atestado | D14: Atestado | E14: Atestado | F14: Atestado | G14: Atestado | H14: =SUM(C14:G14) -> 0 | N14: =SUM(I14:M14) -> 0 | T14: =SUM(O14:S14) -> 0 | Z14: =SUM(U14:Y14) -> 0 | AD14: RECESSO | AE14: FERIADO | AF14: =SUM(AA14:AE14) -> 0 | AL14: =SUM(AG14:AK14) -> 0 | AR14: =SUM(AM14:AQ14) -> 0 | AX14: =SUM(AS14:AW14) -> 0 | BA14: =SUM(AY14:AZ14) -> 0
A15: Caixas remanejadas | B15: 14 | C15: Atestado | D15: Atestado | E15: Atestado | F15: Atestado | G15: Atestado | H15: =SUM(C15:G15) -> 0 | N15: =SUM(I15:M15) -> 0 | T15: =SUM(O15:S15) -> 0 | Z15: =SUM(U15:Y15) -> 0 | AD15: RECESSO | AE15: FERIADO | AF15: =SUM(AA15:AE15) -> 0 | AI15: 120 | AL15: =SUM(AG15:AK15) -> 120 | AR15: =SUM(AM15:AQ15) -> 0 | AX15: =SUM(AS15:AW15) -> 0 | BA15: =SUM(AY15:AZ15) -> 0
A16: Caixas conferidas | B16: 15 | C16: Atestado | D16: Atestado | E16: Atestado | F16: Atestado | G16: Atestado | H16: =SUM(C16:G16) -> 0 | N16: =SUM(I16:M16) -> 0 | T16: =SUM(O16:S16) -> 0 | Z16: =SUM(U16:Y16) -> 0 | AD16: RECESSO | AE16: FERIADO | AF16: =SUM(AA16:AE16) -> 0 | AI16: 120 | AL16: =SUM(AG16:AK16) -> 120 | AR16: =SUM(AM16:AQ16) -> 0 | AX16: =SUM(AS16:AW16) -> 0 | BA16: =SUM(AY16:AZ16) -> 0
A17: Caixas substituídas(trocadas) | B17: 16 | C17: Atestado | D17: Atestado | E17: Atestado | F17: Atestado | G17: Atestado | H17: =SUM(C17:G17) -> 0 | N17: =SUM(I17:M17) -> 0 | T17: =SUM(O17:S17) -> 0 | Z17: =SUM(U17:Y17) -> 0 | AD17: RECESSO | AE17: FERIADO | AF17: =SUM(AA17:AE17) -> 0 | AL17: =SUM(AG17:AK17) -> 0 | AR17: =SUM(AM17:AQ17) -> 0 | AX17: =SUM(AS17:AW17) -> 0 | BA17: =SUM(AY17:AZ17) -> 0
A18: OUTRA ATIVIDADE. QUAL? | I18: Programando o sistema da Diarq | J18: Programando o sistema da Diarq | K18: Programando o sistema da Diarq | L18: Programando o sistema da Diarq | M18: Programando o sistema da Diarq | O18: Programando o sistema da Diarq | P18: Programando o sistema da Diarq | Q18: Programando o sistema da Diarq | R18: Programando o sistema da Diarq | S18: Programando o sistema da Diarq | U18: Programando o sistema da Diarq | V18: Programando o sistema da Diarq | W18: Programando o sistema da Diarq | X18: Programando o sistema da Diarq | Y18: Programando o sistema da Diarq | AA18: Programando o sistema da Diarq | AB18: Programando o sistema da Diarq | AC18: Programando o sistema da Diarq | AG18: Programando o sistema da Diarq | AH18: Programando o sistema da Diarq | AI18: Programando o sistema da Diarq | AJ18: Programando o sistema da Diarq | AK18: Programando o sistema da Diarq | AM18: Programando o sistema da Diarq | AN18: Programando o sistema da Diarq
A19: OBSERVAÇÃO | AA19: CONTAGEM DAS CAIXAS DA SALA 3.61 E 3.60 E 05 CAIXAIS DA SNAS CONFERIDA | AC19: fazendo login no GoDocs para o Mesp | AM19: reunião no bloco A com a Pátricia sobre o MESP

Sheet Danilo
A1: INDICADORES | C1: 46146 | D1: 46147 | E1: 46148 | F1: 46149 | G1: 46150 | H1: TOTAL SEMANA | I1: 46153 | J1: 46154 | K1: 46155 | L1: 46156 | M1: 46157 | N1: TOTAL SEMANA | O1: 46160 | P1: 46161 | Q1: 46162 | R1: 46163 | S1: 46164 | T1: TOTAL SEMANA | U1: 46167 | V1: 46168 | W1: 46169 | X1: 46170 | Y1: 46171 | Z1: TOTAL SEMANA | AA1: 46174 | AB1: 46175 | AC1: 46176 | AD1: 46177 | AE1: 46178 | AF1: TOTAL SEMANA | AG1: 46181 | AH1: 46182 | AI1: 46183 | AJ1: 46184 | AK1: 46185 | AL1: TOTAL SEMANA | AM1: 46188 | AN1: 46189 | AO1: 46190 | AP1: 46191 | AQ1: 46192 | AR1: TOTAL SEMANA | AS1: 46195 | AT1: 46196 | AU1: 46197 | AV1: 46198 | AW1: 46199 | AX1: TOTAL SEMANA | AY1: 46202 | AZ1: 46203 | BA1: TOTAL SEMANA
A2: Desarquivamento de Processos/Documentos - Saída de Guia Fora | B2: 1 | H2: =SUM(C2:G2) -> 0 | N2: =SUM(I2:M2) -> 0 | T2: =SUM(O2:S2) -> 0 | Z2: =SUM(U2:Y2) -> 0 | AF2: =SUM(AA2:AE2) -> 0 | AL2: =SUM(AG2:AK2) -> 0 | AR2: =SUM(AM2:AQ2) -> 0 | AX2: =SUM(AS2:AW2) -> 0 | BA2: =SUM(AY2:AZ2) -> 0
A3: Caixas consultadas em pesquisa de desarquivamento | B3: 2 | H3: =SUM(C3:G3) -> 0 | N3: =SUM(I3:M3) -> 0 | T3: =SUM(O3:S3) -> 0 | Z3: =SUM(U3:Y3) -> 0 | AF3: =SUM(AA3:AE3) -> 0 | AL3: =SUM(AG3:AK3) -> 0 | AR3: =SUM(AM3:AQ3) -> 0 | AX3: =SUM(AS3:AW3) -> 0 | BA3: =SUM(AY3:AZ3) -> 0
A4: Retorno de Processos/Documentos Desarquivados | B4: 3 | E4: 50 | F4: 7 | H4: =SUM(C4:G4) -> 57 | N4: =SUM(I4:M4) -> 0 | T4: =SUM(O4:S4) -> 0 | Z4: =SUM(U4:Y4) -> 0 | AF4: =SUM(AA4:AE4) -> 0 | AL4: =SUM(AG4:AK4) -> 0 | AR4: =SUM(AM4:AQ4) -> 0 | AX4: =SUM(AS4:AW4) -> 0 | BA4: =SUM(AY4:AZ4) -> 0
A5: Recebimento de Documentos - Guia de Transferência | B5: 4 | H5: =SUM(C5:G5) -> 0 | N5: =SUM(I5:M5) -> 0 | T5: =SUM(O5:S5) -> 0 | Z5: =SUM(U5:Y5) -> 0 | AF5: =SUM(AA5:AE5) -> 0 | AL5: =SUM(AG5:AK5) -> 0 | AR5: =SUM(AM5:AQ5) -> 0 | AX5: =SUM(AS5:AW5) -> 0 | BA5: =SUM(AY5:AZ5) -> 0
A6: Caixas separadas para classificação | B6: 5 | H6: =SUM(C6:G6) -> 0 | N6: =SUM(I6:M6) -> 0 | T6: =SUM(O6:S6) -> 0 | Z6: =SUM(U6:Y6) -> 0 | AF6: =SUM(AA6:AE6) -> 0 | AL6: =SUM(AG6:AK6) -> 0 | AR6: =SUM(AM6:AQ6) -> 0 | AX6: =SUM(AS6:AW6) -> 0 | BA6: =SUM(AY6:AZ6) -> 0
A7: Processos/Documentos classificados | B7: 6 | H7: =SUM(C7:G7) -> 0 | N7: =SUM(I7:M7) -> 0 | T7: =SUM(O7:S7) -> 0 | Z7: =SUM(U7:Y7) -> 0 | AF7: =SUM(AA7:AE7) -> 0 | AL7: =SUM(AG7:AK7) -> 0 | AR7: =SUM(AM7:AQ7) -> 0 | AX7: =SUM(AS7:AW7) -> 0 | BA7: =SUM(AY7:AZ7) -> 0
A8: Caixas separadas para eliminação | B8: 7 | H8: =SUM(C8:G8) -> 0 | N8: =SUM(I8:M8) -> 0 | T8: =SUM(O8:S8) -> 0 | Z8: =SUM(U8:Y8) -> 0 | AF8: =SUM(AA8:AE8) -> 0 | AL8: =SUM(AG8:AK8) -> 0 | AR8: =SUM(AM8:AQ8) -> 0 | AX8: =SUM(AS8:AW8) -> 0 | BA8: =SUM(AY8:AZ8) -> 0
A9: Caixas listadas para eliminação | B9: 8 | H9: =SUM(C9:G9) -> 0 | N9: =SUM(I9:M9) -> 0 | T9: =SUM(O9:S9) -> 0 | Z9: =SUM(U9:Y9) -> 0 | AF9: =SUM(AA9:AE9) -> 0 | AL9: =SUM(AG9:AK9) -> 0 | AR9: =SUM(AM9:AQ9) -> 0 | AX9: =SUM(AS9:AW9) -> 0 | BA9: =SUM(AY9:AZ9) -> 0
A10: Processos/Documentos listados para eliminação | B10: 9 | H10: =SUM(C10:G10) -> 0 | N10: =SUM(I10:M10) -> 0 | T10: =SUM(O10:S10) -> 0 | Z10: =SUM(U10:Y10) -> 0 | AF10: =SUM(AA10:AE10) -> 0 | AL10: =SUM(AG10:AK10) -> 0 | AR10: =SUM(AM10:AQ10) -> 0 | AX10: =SUM(AS10:AW10) -> 0 | BA10: =SUM(AY10:AZ10) -> 0
A11: Caixas inventariadas | B11: 10 | H11: =SUM(C11:G11) -> 0 | N11: =SUM(I11:M11) -> 0 | T11: =SUM(O11:S11) -> 0 | Z11: =SUM(U11:Y11) -> 0 | AF11: =SUM(AA11:AE11) -> 0 | AL11: =SUM(AG11:AK11) -> 0 | AR11: =SUM(AM11:AQ11) -> 0 | AX11: =SUM(AS11:AW11) -> 0 | BA11: =SUM(AY11:AZ11) -> 0
A12: Processos/documentos inventariados | B12: 11 | H12: =SUM(C12:G12) -> 0 | N12: =SUM(I12:M12) -> 0 | T12: =SUM(O12:S12) -> 0 | Z12: =SUM(U12:Y12) -> 0 | AF12: =SUM(AA12:AE12) -> 0 | AL12: =SUM(AG12:AK12) -> 0 | AR12: =SUM(AM12:AQ12) -> 0 | AX12: =SUM(AS12:AW12) -> 0 | BA12: =SUM(AY12:AZ12) -> 0
A13: Documentos administrativos produzidos (Despacho, Nota Técnica, minutas diversas) | B13: 12 | H13: =SUM(C13:G13) -> 0 | N13: =SUM(I13:M13) -> 0 | T13: =SUM(O13:S13) -> 0 | Z13: =SUM(U13:Y13) -> 0 | AF13: =SUM(AA13:AE13) -> 0 | AL13: =SUM(AG13:AK13) -> 0 | AR13: =SUM(AM13:AQ13) -> 0 | AX13: =SUM(AS13:AW13) -> 0 | BA13: =SUM(AY13:AZ13) -> 0
A14: Orientação técnica / atendimentos realizados | B14: 13 | H14: =SUM(C14:G14) -> 0 | N14: =SUM(I14:M14) -> 0 | T14: =SUM(O14:S14) -> 0 | Z14: =SUM(U14:Y14) -> 0 | AF14: =SUM(AA14:AE14) -> 0 | AL14: =SUM(AG14:AK14) -> 0 | AR14: =SUM(AM14:AQ14) -> 0 | AX14: =SUM(AS14:AW14) -> 0 | BA14: =SUM(AY14:AZ14) -> 0
A15: Caixas remanejadas | B15: 14 | H15: =SUM(C15:G15) -> 0 | N15: =SUM(I15:M15) -> 0 | T15: =SUM(O15:S15) -> 0 | Z15: =SUM(U15:Y15) -> 0 | AF15: =SUM(AA15:AE15) -> 0 | AL15: =SUM(AG15:AK15) -> 0 | AR15: =SUM(AM15:AQ15) -> 0 | AX15: =SUM(AS15:AW15) -> 0 | BA15: =SUM(AY15:AZ15) -> 0
A16: Caixas conferidas | B16: 15 | C16: 10 | D16: 10 | G16: 10 | H16: =SUM(C16:G16) -> 30 | I16: 3 | J16: 3 | K16: 3 | L16: 3 | M16: 3 | N16: =SUM(I16:M16) -> 15 | O16: 3 | P16: 3 | Q16: 3 | R16: 3 | S16: 3 | T16: =SUM(O16:S16) -> 15 | U16: 3 | V16: 4 | W16: 3 | X16: 2 | Y16: 3 | Z16: =SUM(U16:Y16) -> 15 | AA16: 2 | AB16: 4 | AC16: 3 | AF16: =SUM(AA16:AE16) -> 9 | AL16: =SUM(AG16:AK16) -> 0 | AR16: =SUM(AM16:AQ16) -> 0 | AX16: =SUM(AS16:AW16) -> 0 | BA16: =SUM(AY16:AZ16) -> 0
A17: Caixas substituídas(trocadas) | B17: 16 | H17: =SUM(C17:G17) -> 0 | N17: =SUM(I17:M17) -> 0 | T17: =SUM(O17:S17) -> 0 | U17: 10 | W17: 5 | Z17: =SUM(U17:Y17) -> 15 | AA17: 5 | AB17: 7 | AC17: 3 | AF17: =SUM(AA17:AE17) -> 15 | AL17: =SUM(AG17:AK17) -> 0 | AR17: =SUM(AM17:AQ17) -> 0 | AX17: =SUM(AS17:AW17) -> 0 | BA17: =SUM(AY17:AZ17) -> 0
A18: OUTRA ATIVIDADE. QUAL? | E18: ORGANIZAÃO DE 50 CAIXA PARA O LOCAL DE ORIGEM, APÓS RETORNO DE DESARQUIVAMENTO | F18: ORGANIZAÇÃO DE 50 CAIXAS PARA CONFERENCIA | I18: ACOMPANHAMENTO DA LIMPEZA DAS ESTANTES E CAIXAS DO BLOCO A E CONFERÊNCIA DE 03 CAIXAS SNAS/DNIT | J18: ACOMPANHAMENTO DA LIMPEZA DAS ESTANTES E CAIXAS DO BLOCO A E CONFERÊNCIA DE 03 CAIXAS SNAS/DNIT | K18: ACOMPANHAMENTO DA LIMPESA DAS ESTANTES E CAIXAS DO BLOCO ACONFERÊNCIA DE 03 CAIXAS SNAS/DNIT | L18: ACOMPANHAMENTO DA LIMPESA DAS ESTANTES E CAIXAS DO BLOCO ACONFERÊNCIA DE 03 CAIXAS SNAS/DNIT | M18: ACOMPANHAMENTO DA LIMPESA DAS ESTANTES E CAIXAS DO BLOCO ACONFERÊNCIA DE 03 CAIXAS SNAS/DNIT | O18: ACOMPANHAMENTO DA LIMPEZA DAS ESTANTES E CAIXAS DO BLOCO A E CONFERÊNCIA DE 03 CAIXAS SNAS/DNIT | P18: ACOMPANHAMENTO DA LIMPEZA DAS ESTANTES E CAIXAS DO BLOCO A E CONFERÊNCIA DE 03 CAIXAS SNAS/DNIT | Q18: ACOMPANHAMENTO DA LIMPESA DAS ESTANTES E CAIXAS DO BLOCO ACONFERÊNCIA DE 03 CAIXAS SNAS/DNIT | R18: ACOMPANHAMENTO DA LIMPESA DAS ESTANTES E CAIXAS DO BLOCO ACONFERÊNCIA DE 03 CAIXAS SNAS/DNIT | S18: ACOMPANHAMENTO DA LIMPESA DAS ESTANTES E CAIXAS DO BLOCO ACONFERÊNCIA DE 03 CAIXAS SNAS/DNIT | U18: ACOMPANHAMENTO DA LIMPESA DAS ESTANTES E CAIXAS DO BLOCO ACONFERÊNCIA DE 03 CAIXAS SNAS/DNIT | V18: ACOMPANHAMENTO DA LIMPESA DAS ESTANTES E CAIXAS DO BLOCO ACONFERÊNCIA DE 04 CAIXAS SNAS/DNIT | W18: ACOMPANHAMENTO DA LIMPESA DAS ESTANTES E CAIXAS DO BLOCO ACONFERÊNCIA DE 03 CAIXAS SNAS/DNIT | X18: ACOMPANHAMENTO DA LIMPESA DAS ESTANTES E CAIXAS DO BLOCO ACONFERÊNCIA DE 02 CAIXAS SNAS/DNIT | Y18: ACOMPANHAMENTO DA LIMPESA DAS ESTANTES E CAIXAS DO BLOCO ACONFERÊNCIA DE 03 CAIXAS SNAS/DNIT | AA18: ACOMPANHAMENTO DA LIMPESA DAS ESTANTES E CAIXAS DO BLOCO ACONFERÊNCIA DE 02 CAIXAS SNAS/DNIT | AB18: ACOMPANHAMENTO DA LIMPESA DAS ESTANTES E CAIXAS DO BLOCO ACONFERÊNCIA DE 04 CAIXAS SNAS/DNIT | AC18: ACOMPANHAMENTO DA LIMPESA DAS ESTANTES E CAIXAS DO BLOCO ACONFERÊNCIA DE 03 CAIXAS SNAS/DNIT | AD18: FERIADO | AE18: PONTO FACUTATIVO | AG18: ACOMPANHAMENTO DA LIMPESA DAS ESTANTES E CAIXAS DO BLOCO A | AH18: ACOMPANHAMENTO DA LIMPESA DAS ESTANTES E CAIXAS DO BLOCO A | AI18: ACOMPANHAMENTO DA LIMPESA DAS ESTANTES E CAIXAS DO BLOCO A | AJ18: ACOMPANHAMENTO DA LIMPESA DAS ESTANTES E CAIXAS DO BLOCO A | AK18: ACOMPANHAMENTO DA LIMPESA DAS ESTANTES E CAIXAS DO BLOCO A
A19: OBSERVAÇÃO | X19: 108 CAIXAS ARQUIVADAS NA SALA 3.61 E 3.25 DA SNAS/CGCEB

Sheet Alessandro
A1: INDICADORES | C1: 46146 | D1: 46147 | E1: 46148 | F1: 46149 | G1: 46150 | H1: TOTAL SEMANA | I1: 46153 | J1: 46154 | K1: 46155 | L1: 46156 | M1: 46157 | N1: TOTAL SEMANA | O1: 46160 | P1: 46161 | Q1: 46162 | R1: 46163 | S1: 46164 | T1: TOTAL SEMANA | U1: 46167 | V1: 46168 | W1: 46169 | X1: 46170 | Y1: 46171 | Z1: TOTAL SEMANA | AA1: 46174 | AB1: 46175 | AC1: 46176 | AD1: 46177 | AE1: 46178 | AF1: TOTAL SEMANA | AG1: 46181 | AH1: 46182 | AI1: 46183 | AJ1: 46184 | AK1: 46185 | AL1: TOTAL SEMANA | AM1: 46188 | AN1: 46189 | AO1: 46190 | AP1: 46191 | AQ1: 46192 | AR1: TOTAL SEMANA | AS1: 46195 | AT1: 46196 | AU1: 46197 | AV1: 46198 | AW1: 46199 | AX1: TOTAL SEMANA | AY1: 46202 | AZ1: 46203 | BA1: TOTAL SEMANA
A2: Desarquivamento de Processos/Documentos - Saída de Guia Fora | B2: 1 | H2: =SUM(C2:G2) -> 0 | K2: 2 | N2: =SUM(I2:M2) -> 2 | T2: =SUM(O2:S2) -> 0 | Z2: =SUM(U2:Y2) -> 0 | AD2: RECESSO | AE2: FERIADO | AF2: =SUM(AA2:AE2) -> 0 | AL2: =SUM(AG2:AK2) -> 0 | AR2: =SUM(AM2:AQ2) -> 0 | AX2: =SUM(AS2:AW2) -> 0 | BA2: =SUM(AY2:AZ2) -> 0
A3: Caixas consultadas em pesquisa de desarquivamento | B3: 2 | H3: =SUM(C3:G3) -> 0 | N3: =SUM(I3:M3) -> 0 | T3: =SUM(O3:S3) -> 0 | Z3: =SUM(U3:Y3) -> 0 | AD3: RECESSO | AE3: FERIADO | AF3: =SUM(AA3:AE3) -> 0 | AL3: =SUM(AG3:AK3) -> 0 | AR3: =SUM(AM3:AQ3) -> 0 | AX3: =SUM(AS3:AW3) -> 0 | BA3: =SUM(AY3:AZ3) -> 0
A4: Retorno de Processos/Documentos Desarquivados | B4: 3 | H4: =SUM(C4:G4) -> 0 | N4: =SUM(I4:M4) -> 0 | T4: =SUM(O4:S4) -> 0 | Z4: =SUM(U4:Y4) -> 0 | AD4: RECESSO | AE4: FERIADO | AF4: =SUM(AA4:AE4) -> 0 | AL4: =SUM(AG4:AK4) -> 0 | AR4: =SUM(AM4:AQ4) -> 0 | AX4: =SUM(AS4:AW4) -> 0 | BA4: =SUM(AY4:AZ4) -> 0
A5: Recebimento de Documentos - Guia de Transferência | B5: 4 | H5: =SUM(C5:G5) -> 0 | N5: =SUM(I5:M5) -> 0 | T5: =SUM(O5:S5) -> 0 | Z5: =SUM(U5:Y5) -> 0 | AD5: RECESSO | AE5: FERIADO | AF5: =SUM(AA5:AE5) -> 0 | AL5: =SUM(AG5:AK5) -> 0 | AR5: =SUM(AM5:AQ5) -> 0 | AX5: =SUM(AS5:AW5) -> 0 | BA5: =SUM(AY5:AZ5) -> 0
A6: Caixas separadas para classificação | B6: 5 | H6: =SUM(C6:G6) -> 0 | N6: =SUM(I6:M6) -> 0 | T6: =SUM(O6:S6) -> 0 | Z6: =SUM(U6:Y6) -> 0 | AD6: RECESSO | AE6: FERIADO | AF6: =SUM(AA6:AE6) -> 0 | AL6: =SUM(AG6:AK6) -> 0 | AR6: =SUM(AM6:AQ6) -> 0 | AX6: =SUM(AS6:AW6) -> 0 | BA6: =SUM(AY6:AZ6) -> 0
A7: Processos/Documentos classificados | B7: 6 | H7: =SUM(C7:G7) -> 0 | N7: =SUM(I7:M7) -> 0 | T7: =SUM(O7:S7) -> 0 | Z7: =SUM(U7:Y7) -> 0 | AD7: RECESSO | AE7: FERIADO | AF7: =SUM(AA7:AE7) -> 0 | AL7: =SUM(AG7:AK7) -> 0 | AR7: =SUM(AM7:AQ7) -> 0 | AX7: =SUM(AS7:AW7) -> 0 | BA7: =SUM(AY7:AZ7) -> 0
A8: Caixas separadas para eliminação | B8: 7 | H8: =SUM(C8:G8) -> 0 | N8: =SUM(I8:M8) -> 0 | T8: =SUM(O8:S8) -> 0 | Z8: =SUM(U8:Y8) -> 0 | AD8: RECESSO | AE8: FERIADO | AF8: =SUM(AA8:AE8) -> 0 | AL8: =SUM(AG8:AK8) -> 0 | AR8: =SUM(AM8:AQ8) -> 0 | AX8: =SUM(AS8:AW8) -> 0 | BA8: =SUM(AY8:AZ8) -> 0
A9: Caixas listadas para eliminação | B9: 8 | H9: =SUM(C9:G9) -> 0 | N9: =SUM(I9:M9) -> 0 | T9: =SUM(O9:S9) -> 0 | Z9: =SUM(U9:Y9) -> 0 | AD9: RECESSO | AE9: FERIADO | AF9: =SUM(AA9:AE9) -> 0 | AL9: =SUM(AG9:AK9) -> 0 | AR9: =SUM(AM9:AQ9) -> 0 | AX9: =SUM(AS9:AW9) -> 0 | BA9: =SUM(AY9:AZ9) -> 0
A10: Processos/Documentos listados para eliminação | B10: 9 | H10: =SUM(C10:G10) -> 0 | N10: =SUM(I10:M10) -> 0 | T10: =SUM(O10:S10) -> 0 | Z10: =SUM(U10:Y10) -> 0 | AD10: RECESSO | AE10: FERIADO | AF10: =SUM(AA10:AE10) -> 0 | AL10: =SUM(AG10:AK10) -> 0 | AR10: =SUM(AM10:AQ10) -> 0 | AX10: =SUM(AS10:AW10) -> 0 | BA10: =SUM(AY10:AZ10) -> 0
A11: Caixas inventariadas | B11: 10 | F11: 6 | G11: 3 | H11: =SUM(C11:G11) -> 9 | K11: 5 | L11: 6 | M11: 5 | N11: =SUM(I11:M11) -> 16 | O11: 5 | P11: 7 | Q11: 8 | R11: 7 | S11: 9 | T11: =SUM(O11:S11) -> 36 | U11: 4 | V11: 11 | W11: 11 | X11: 6 | Y11: 7 | Z11: =SUM(U11:Y11) -> 39 | AA11: 7 | AB11: 4 | AC11: 6 | AD11: RECESSO | AE11: FERIADO | AF11: =SUM(AA11:AE11) -> 17 | AG11: 4 | AH11: 5 | AI11: 5 | AJ11: 2 | AK11: 3 | AL11: =SUM(AG11:AK11) -> 19 | AR11: =SUM(AM11:AQ11) -> 0 | AX11: =SUM(AS11:AW11) -> 0 | BA11: =SUM(AY11:AZ11) -> 0
A12: Processos/documentos inventariados | B12: 11 | F12: 36 | G12: 23 | H12: =SUM(C12:G12) -> 59 | K12: 36 | L12: 41 | M12: 27 | N12: =SUM(I12:M12) -> 104 | O12: 31 | P12: 51 | Q12: 60 | R12: 61 | S12: 63 | T12: =SUM(O12:S12) -> 266 | U12: 25 | V12: 62 | W12: 80 | X12: 42 | Y12: 48 | Z12: =SUM(U12:Y12) -> 257 | AA12: 50 | AB12: 21 | AC12: 52 | AD12: RECESSO | AE12: FERIADO | AF12: =SUM(AA12:AE12) -> 123 | AG12: 33 | AH12: 44 | AI12: 35 | AJ12: 16 | AK12: 24 | AL12: =SUM(AG12:AK12) -> 152 | AR12: =SUM(AM12:AQ12) -> 0 | AX12: =SUM(AS12:AW12) -> 0 | BA12: =SUM(AY12:AZ12) -> 0
A13: Documentos administrativos produzidos (Despacho, Nota Técnica, minutas diversas, e-mails) | B13: 12 | H13: =SUM(C13:G13) -> 0 | J13: 1 | N13: =SUM(I13:M13) -> 1 | O13: 1 | R13: 1 | T13: =SUM(O13:S13) -> 2 | Z13: =SUM(U13:Y13) -> 0 | AD13: RECESSO | AE13: FERIADO | AF13: =SUM(AA13:AE13) -> 0 | AG13: 1 | AI13: 1 | AL13: =SUM(AG13:AK13) -> 2 | AR13: =SUM(AM13:AQ13) -> 0 | AX13: =SUM(AS13:AW13) -> 0 | BA13: =SUM(AY13:AZ13) -> 0
A14: Orientação técnica / atendimentos realizados | B14: 13 | H14: =SUM(C14:G14) -> 0 | I14: 2 | K14: 1 | L14: 2 | N14: =SUM(I14:M14) -> 5 | T14: =SUM(O14:S14) -> 0 | Z14: =SUM(U14:Y14) -> 0 | AD14: RECESSO | AE14: FERIADO | AF14: =SUM(AA14:AE14) -> 0 | AL14: =SUM(AG14:AK14) -> 0 | AR14: =SUM(AM14:AQ14) -> 0 | AX14: =SUM(AS14:AW14) -> 0 | BA14: =SUM(AY14:AZ14) -> 0
A15: Caixas remanejadas | B15: 14 | H15: =SUM(C15:G15) -> 0 | N15: =SUM(I15:M15) -> 0 | T15: =SUM(O15:S15) -> 0 | Z15: =SUM(U15:Y15) -> 0 | AD15: RECESSO | AE15: FERIADO | AF15: =SUM(AA15:AE15) -> 0 | AL15: =SUM(AG15:AK15) -> 0 | AR15: =SUM(AM15:AQ15) -> 0 | AX15: =SUM(AS15:AW15) -> 0 | BA15: =SUM(AY15:AZ15) -> 0
A16: Caixas conferidas | B16: 15 | D16: 11 | H16: =SUM(C16:G16) -> 11 | N16: =SUM(I16:M16) -> 0 | T16: =SUM(O16:S16) -> 0 | Z16: =SUM(U16:Y16) -> 0 | AD16: RECESSO | AE16: FERIADO | AF16: =SUM(AA16:AE16) -> 0 | AL16: =SUM(AG16:AK16) -> 0 | AR16: =SUM(AM16:AQ16) -> 0 | AX16: =SUM(AS16:AW16) -> 0 | BA16: =SUM(AY16:AZ16) -> 0
A17: Caixas substituídas(trocadas) | B17: 16 | H17: =SUM(C17:G17) -> 0 | N17: =SUM(I17:M17) -> 0 | T17: =SUM(O17:S17) -> 0 | Z17: =SUM(U17:Y17) -> 0 | AD17: RECESSO | AE17: FERIADO | AF17: =SUM(AA17:AE17) -> 0 | AL17: =SUM(AG17:AK17) -> 0 | AR17: =SUM(AM17:AQ17) -> 0 | AX17: =SUM(AS17:AW17) -> 0 | BA17: =SUM(AY17:AZ17) -> 0
A18: OUTRA ATIVIDADE. QUAL? | C18: Alimentação de planilha de controle de atividades (Gustavo)/ Pesquisa de contatos de empresas de manutenção de deslizantes e confirmação de e-mails enviados | I18: Alimentação de planilha de controle de atividades (Gustavo) | O18: Alimentação de planilha de controle de atividades (Gustavo)/ | Q18: Acompanhamento de processo SEI - CPAD | R18: Acompanhamento de processo SEI - CPAD | S18: Acompanhamento de processo SEI - CPAD | U18: Alimentação de planilha de controle de atividades (Gustavo)/ | V18: Acompanhamento de processo SEI - CPAD | W18: Acompanhamento de processo SEI - CPAD | X18: Acompanhamento de processo SEI - CPAD | Y18: Acompanhamento de processo SEI - CPAD | AA18: Alimentação de planilha de controle de atividades (Gustavo) Acompanhamento de processo SEI - CPAD Contagem de Caixas Acervo Sala 4.47 (DNIT) | AB18: Acompanhamento de processo SEI - CPAD | AC18: Acompanhamento de processo SEI - CPAD | AG18: Alimentação de planilha de controle de atividades (Gustavo) Acompanhamento de processo SEI - CPAD | AH18: Acompanhamento de processo SEI - CPAD | AI18: Acompanhamento de processo SEI - CPAD Atualização de dados do Sistema CGLA (Pedro) | AJ18: Acompanhamento de processo SEI - CPAD Atualização de dados do Sistema CGLA (Pedro) | AK18: Acompanhamento de processo SEI - CPAD Atualização de dados do Sistema CGLA (Pedro)
A19: OBSERVAÇÃO
